<?xml version="1.0" encoding="utf-8"?>
<mujocoinclude>
  <body name="floating_base">
    <inertial pos="0 0 0" quat="1 0 0 0" mass="0.01" diaginertia="0.01 0.01 0.01"/>
    <joint name="ARTx" pos="0 0 0" axis="1 0 0" type="slide" range="-1 1" damping="20" armature="0.01" frictionloss="0.1" forcelimited="true" forcerange="-500 500"/>
    <body name="ARTx_child" pos="0 0 0">
      <inertial pos="0 0 0" quat="1 0 0 0" mass="0.001" diaginertia="0.001 0.001 0.001"/>
      <joint name="ARTy" pos="0 0 0" axis="0 1 0" type="slide" range="-1 1" damping="20" armature="0.01" frictionloss="0.1" forcelimited="true" forcerange="-500 500"/>
      <body name="ARTy_child" pos="0 0 0">
        <inertial pos="0 0 0" quat="1 0 0 0" mass="0.001" diaginertia="0.001 0.001 0.001"/>
        <joint name="ARTz" pos="0 0 0" axis="0 0 1" type="slide" range="-1 1" damping="20" armature="0.01" frictionloss="0.1" forcelimited="true" forcerange="-500 500"/>
        <body name="ARTz_child" pos="0 0 0">
          <inertial pos="0 0 0" quat="1 0 0 0" mass="0.001" diaginertia="0.001 0.001 0.001"/>
          <joint name="ARRx" pos="0 0 0" axis="1 0 0" type="hinge" range="-3.14 3.14" damping="20" armature="0.01" frictionloss="0.1" forcelimited="true" forcerange="-100 100"/>
          <body name="ARRx_child" pos="0 0 0">
            <inertial pos="0 0 0" quat="1 0 0 0" mass="0.001" diaginertia="0.001 0.001 0.001"/>
            <joint name="ARRy" pos="0 0 0" axis="0 1 0" type="hinge" range="-3.14 3.14" damping="20" armature="0.01" frictionloss="0.1" forcelimited="true" forcerange="-100 100"/>
            <body name="ARRy_child" pos="0 0 0">
              <inertial pos="0 0 0" quat="1 0 0 0" mass="0.001" diaginertia="0.001 0.001 0.001"/>
              <joint name="ARRz" pos="0 0 0" axis="0 0 1" type="hinge" range="-3.14 3.14" damping="20" armature="0.01" frictionloss="0.1" forcelimited="true" forcerange="-100 100"/>
              <body name="hand_base">
                <body name="right_hand_base" pos="0 0 0" quat="0.7071067811865476 0.0 0.7071067811865475 0.0">
                  <geom pos="0 0 -0.17" quat="0.707388 0 0 -0.706825" type="mesh" contype="0" conaffinity="0" group="1" density="0" rgba="0.3 0.3 0.3 1" mesh="r_p_link0"/>
                  <geom pos="0 0 -0.17" quat="0.707388 0 0 -0.706825" type="mesh" rgba="0.3 0.3 0.3 1" mesh="r_p_link0"/>
                  <geom pos="0.032685 0.023881 0.10707" quat="0.775137 0.151553 0.0221905 0.612945" type="mesh" contype="0" conaffinity="0" group="1" density="0" rgba="0.3 0.3 0.3 1" mesh="r_p_link1"/>
                  <geom pos="0.032685 0.023881 0.10707" quat="0.775137 0.151553 0.0221905 0.612945" type="mesh" rgba="0.3 0.3 0.3 1" mesh="r_p_link1"/>
                  <geom pos="0.032685 0.023881 0.10707" quat="0.775137 0.151553 0.0221905 0.612945" type="mesh" contype="0" conaffinity="0" group="1" density="0" rgba="0.3 0.3 0.3 1" mesh="r_p_link3"/>
                  <geom pos="0.032685 0.023881 0.10707" quat="0.775137 0.151553 0.0221905 0.612945" type="mesh" rgba="0.3 0.3 0.3 1" mesh="r_p_link3"/>
                  <geom pos="0.032685 0.023881 0.10707" quat="0.775137 0.151553 0.0221905 0.612945" type="mesh" contype="0" conaffinity="0" group="1" density="0" rgba="0.9 0.9 0.9 1" mesh="r_p_link4"/>
                  <geom pos="0.032685 0.023881 0.10707" quat="0.775137 0.151553 0.0221905 0.612945" type="mesh" rgba="0.9 0.9 0.9 1" mesh="r_p_link4"/>
                  <geom pos="0.032685 0.023881 0.10707" quat="0.775137 0.151553 0.0221905 0.612945" type="mesh" contype="0" conaffinity="0" group="1" density="0" rgba="0.3 0.3 0.3 1" mesh="r_p_link5"/>
                  <geom pos="0.032685 0.023881 0.10707" quat="0.775137 0.151553 0.0221905 0.612945" type="mesh" rgba="0.3 0.3 0.3 1" mesh="r_p_link5"/>
                  <geom pos="0.032685 0.023881 0.10707" quat="0.775137 0.151553 0.0221905 0.612945" type="mesh" contype="0" conaffinity="0" group="1" density="0" rgba="0.9 0.9 0.9 1" mesh="r_p_link6"/>
                  <geom pos="0.032685 0.023881 0.10707" quat="0.775137 0.151553 0.0221905 0.612945" type="mesh" rgba="0.9 0.9 0.9 1" mesh="r_p_link6"/>
                  <geom pos="0.032685 0.023881 0.10707" quat="0.775137 0.151553 0.0221905 0.612945" type="mesh" contype="0" conaffinity="0" group="1" density="0" rgba="0.9 0.9 0.9 1" mesh="r_p_link2"/>
                  <geom pos="0.032685 0.023881 0.10707" quat="0.775137 0.151553 0.0221905 0.612945" type="mesh" rgba="0.9 0.9 0.9 1" mesh="r_p_link2"/>
                  <body name="r_f_link1_1" pos="0.032685 0.023881 0.10707" quat="0.775137 0.151553 0.0221905 0.612945">
                    <inertial pos="0.00205223 -0.000372643 -0.0185288" quat="0.71769 0.0508968 0.0297657 0.693863" mass="0.00518035" diaginertia="1.21881e-06 1.15459e-06 2.51191e-07"/>
                    <joint name="r_f_joint1_1" pos="0 0 0" axis="0 0 -1" range="0 2.2" actuatorfrcrange="-10 10"/>
                    <geom type="mesh" contype="0" conaffinity="0" group="1" density="0" rgba="0.3 0.3 0.3 1" mesh="r_f_link1_1"/>
                    <geom type="mesh" rgba="0.3 0.3 0.3 1" mesh="r_f_link1_1"/>
                    <body name="r_f_link1_2" pos="0.0083307 0 0" quat="0.707073 0.707076 0.0067524 -0.00675243">
                      <inertial pos="0.0217194 0.000635197 0.00102982" quat="-0.0118779 0.705581 -0.0460466 0.707032" mass="0.00931794" diaginertia="1.81442e-06 1.76774e-06 6.45119e-07"/>
                      <joint name="r_f_joint1_2" pos="0 0 0" axis="0 0 1" range="0 1.3" actuatorfrcrange="-10 10"/>
                      <geom type="mesh" contype="0" conaffinity="0" group="1" density="0" rgba="0.3 0.3 0.3 1" mesh="r_f_link1_2"/>
                      <geom type="mesh" rgba="0.3 0.3 0.3 1" mesh="r_f_link1_2"/>
                      <geom type="mesh" contype="0" conaffinity="0" group="1" density="0" rgba="0.3 0.3 0.3 1" mesh="r_f_link1_2_1"/>
                      <geom type="mesh" rgba="0.3 0.3 0.3 1" mesh="r_f_link1_2_1"/>
                      <geom type="mesh" contype="0" conaffinity="0" group="1" density="0" rgba="0.9 0.9 0.9 1" mesh="r_f_link1_2_2"/>
                      <geom type="mesh" rgba="0.9 0.9 0.9 1" mesh="r_f_link1_2_2"/>
                      <body name="r_f_link1_3" pos="0.043 0 0">
                        <inertial pos="0.0130893 -0.000676815 0.00129681" quat="0.0232598 0.704008 -0.0263538 0.709322" mass="0.00492936" diaginertia="4.30587e-07 4.03231e-07 2.21805e-07"/>
                        <joint name="r_f_joint1_3" pos="0 0 0" axis="0 0 1" range="0 1.3" actuatorfrcrange="-10 10"/>
                        <geom type="mesh" contype="0" conaffinity="0" group="1" density="0" rgba="0.3 0.3 0.3 1" mesh="r_f_link1_3"/>
                        <geom type="mesh" rgba="0.3 0.3 0.3 1" mesh="r_f_link1_3"/>
                        <geom type="mesh" contype="0" conaffinity="0" group="1" density="0" rgba="0.3 0.3 0.3 1" mesh="r_f_link1_3_1"/>
                        <geom type="mesh" rgba="0.3 0.3 0.3 1" mesh="r_f_link1_3_1"/>
                        <geom type="mesh" contype="0" conaffinity="0" group="1" density="0" rgba="0.9 0.9 0.9 1" mesh="r_f_link1_3_2"/>
                        <geom type="mesh" rgba="0.9 0.9 0.9 1" mesh="r_f_link1_3_2"/>
                        <body name="r_f_link1_4" pos="0.025 0 0">
                          <inertial pos="0.0193624 -0.00256773 0.00110888" quat="0.2638 0.691979 0.183116 0.646563" mass="0.00867734" diaginertia="1.28899e-06 1.28389e-06 3.95612e-07"/>
                          <joint name="r_f_joint1_4" pos="0 0 0" axis="0 0 1" range="0 1.3" actuatorfrcrange="-10 10"/>
                          <geom type="mesh" contype="0" conaffinity="0" group="1" density="0" rgba="0.3 0.3 0.3 1" mesh="r_f_link1_4"/>
                          <geom type="mesh" rgba="0.3 0.3 0.3 1" mesh="r_f_link1_4"/>
                          <geom type="mesh" contype="0" conaffinity="0" group="1" density="0" rgba="0.3 0.3 0.3 1" mesh="r_f_link1_4_1"/>
                          <geom type="mesh" rgba="0.3 0.3 0.3 1" mesh="r_f_link1_4_1"/>
                          <geom type="mesh" contype="0" conaffinity="0" group="1" density="0" rgba="0.9 0.9 0.9 1" mesh="r_f_link1_4_2"/>
                          <geom type="mesh" rgba="0.9 0.9 0.9 1" mesh="r_f_link1_4_2"/>
                          <geom size="0.002" pos="0.035 -0.004 0" contype="0" conaffinity="0" group="1" density="0" rgba="1 0 0 1"/>
                          <geom size="0.002" pos="0.035 -0.004 0" rgba="1 0 0 1"/>
                          <geom size="0.006 0.0005 0.003" pos="0.026 0.0025 0.001" quat="0.974794 0 0 -0.223106" type="box" contype="0" conaffinity="0" group="1" density="0" rgba="0 1 0 1"/>
                          <geom size="0.006 0.0005 0.003" pos="0.026 0.0025 0.001" quat="0.974794 0 0 -0.223106" type="box" rgba="0 1 0 1"/>
                          <site name="site_r_f_link1_tip" pos="0.035 -0.004 0" quat="1.0 0.0 0.0 0.0" type="sphere" size="0.002" rgba="1 0 0 1"/>
                          <site name="site_r_f_link1_pad" pos="0.026 0.0025 0.001" quat="0.9747941070689433 0.0 0.0 -0.22310636213174545" type="box" size="0.006 0.0005 0.003" rgba="0 1 0 1"/>
                        </body>
                      </body>
                    </body>
                  </body>
                  <body name="r_f_link2_1" pos="0.0069382 0.0349175 0.1597" quat="0.000289373 -0.707107 -0.00029197 -0.707107">
                    <inertial pos="0.00800686 1.83389e-05 -0.00158423" quat="0.366432 0.601227 0.609221 0.364834" mass="0.00351858" diaginertia="3.71993e-07 3.23705e-07 2.04962e-07"/>
                    <joint name="r_f_joint2_1" pos="0 0 0" axis="0 0 -1" range="0 0.6" actuatorfrcrange="-10 10"/>
                    <geom type="mesh" contype="0" conaffinity="0" group="1" density="0" rgba="0.3 0.3 0.3 1" mesh="r_f_link2_1"/>
                    <geom type="mesh" rgba="0.3 0.3 0.3 1" mesh="r_f_link2_1"/>
                    <body name="r_f_link2_2" pos="0.017 0 0" quat="0.707105 0.707108 0 0">
                      <inertial pos="0.0214625 -0.000312324 -0.000276541" quat="0.514364 0.49694 0.502968 0.485286" mass="0.00860339" diaginertia="1.79436e-06 1.76074e-06 5.64762e-07"/>
                      <joint name="r_f_joint2_2" pos="0 0 0" axis="0 0 1" range="0 1.3" actuatorfrcrange="-10 10"/>
                      <geom type="mesh" contype="0" conaffinity="0" group="1" density="0" rgba="0.3 0.3 0.3 1" mesh="r_f_link2_2"/>
                      <geom type="mesh" rgba="0.3 0.3 0.3 1" mesh="r_f_link2_2"/>
                      <geom type="mesh" contype="0" conaffinity="0" group="1" density="0" rgba="0.3 0.3 0.3 1" mesh="r_f_link2_2_1"/>
                      <geom type="mesh" rgba="0.3 0.3 0.3 1" mesh="r_f_link2_2_1"/>
                      <geom type="mesh" contype="0" conaffinity="0" group="1" density="0" rgba="0.9 0.9 0.9 1" mesh="r_f_link2_2_2"/>
                      <geom type="mesh" rgba="0.9 0.9 0.9 1" mesh="r_f_link2_2_2"/>
                      <body name="r_f_link2_3" pos="0.043 0 0">
                        <inertial pos="0.0131211 -0.000590719 -1.26084e-05" quat="0.0239512 0.703828 -0.0289604 0.709375" mass="0.00474675" diaginertia="4.25746e-07 3.96949e-07 2.15446e-07"/>
                        <joint name="r_f_joint2_3" pos="0 0 0" axis="0 0 1" range="0 1.3" actuatorfrcrange="-10 10"/>
                        <geom type="mesh" contype="0" conaffinity="0" group="1" density="0" rgba="0.3 0.3 0.3 1" mesh="r_f_link2_3"/>
                        <geom type="mesh" rgba="0.3 0.3 0.3 1" mesh="r_f_link2_3"/>
                        <geom type="mesh" contype="0" conaffinity="0" group="1" density="0" rgba="0.3 0.3 0.3 1" mesh="r_f_link2_3_1"/>
                        <geom type="mesh" rgba="0.3 0.3 0.3 1" mesh="r_f_link2_3_1"/>
                        <geom type="mesh" contype="0" conaffinity="0" group="1" density="0" rgba="0.9 0.9 0.9 1" mesh="r_f_link2_3_2"/>
                        <geom type="mesh" rgba="0.9 0.9 0.9 1" mesh="r_f_link2_3_2"/>
                        <body name="r_f_link2_4" pos="0.025 0 0">
                          <inertial pos="0.0193485 -0.00255949 -7.94241e-07" quat="0.0419787 0.705389 -0.0494777 0.705845" mass="0.0086892" diaginertia="1.28832e-06 1.28613e-06 3.95468e-07"/>
                          <joint name="r_f_joint2_4" pos="0 0 0" axis="0 0 1" range="0 1.3" actuatorfrcrange="-10 10"/>
                          <geom type="mesh" contype="0" conaffinity="0" group="1" density="0" rgba="0.3 0.3 0.3 1" mesh="r_f_link2_4"/>
                          <geom type="mesh" rgba="0.3 0.3 0.3 1" mesh="r_f_link2_4"/>
                          <geom type="mesh" contype="0" conaffinity="0" group="1" density="0" rgba="0.3 0.3 0.3 1" mesh="r_f_link2_4_1"/>
                          <geom type="mesh" rgba="0.3 0.3 0.3 1" mesh="r_f_link2_4_1"/>
                          <geom type="mesh" contype="0" conaffinity="0" group="1" density="0" rgba="0.9 0.9 0.9 1" mesh="r_f_link2_4_2"/>
                          <geom type="mesh" rgba="0.9 0.9 0.9 1" mesh="r_f_link2_4_2"/>
                          <geom size="0.002" pos="0.035 -0.004 0" contype="0" conaffinity="0" group="1" density="0" rgba="1 0 0 1"/>
                          <geom size="0.002" pos="0.035 -0.004 0" rgba="1 0 0 1"/>
                          <geom size="0.006 0.0005 0.003" pos="0.026 0.0025 0" quat="0.974794 0 0 -0.223106" type="box" contype="0" conaffinity="0" group="1" density="0" rgba="0 1 0 1"/>
                          <geom size="0.006 0.0005 0.003" pos="0.026 0.0025 0" quat="0.974794 0 0 -0.223106" type="box" rgba="0 1 0 1"/>
                          <site name="site_r_f_link2_tip" pos="0.035 -0.004 0" quat="1.0 0.0 0.0 0.0" type="sphere" size="0.002" rgba="1 0 0 1"/>
                          <site name="site_r_f_link2_pad" pos="0.026 0.0025 0.000" quat="0.9747941070689433 0.0 0.0 -0.22310636213174545" type="box" size="0.006 0.0005 0.003" rgba="0 1 0 1"/>
                        </body>
                      </body>
                    </body>
                  </body>
                  <body name="r_f_link3_1" pos="0.00695755 0.0106175 0.1687" quat="0.000278947 -0.707107 -0.000281544 -0.707107">
                    <inertial pos="0.00800686 1.83389e-05 -0.00158423" quat="0.366432 0.601227 0.609221 0.364834" mass="0.00351858" diaginertia="3.71993e-07 3.23705e-07 2.04962e-07"/>
                    <joint name="r_f_joint3_1" pos="0 0 0" axis="0 0 1" range="-0.001 0.001" actuatorfrcrange="-10 10"/>
                    <geom type="mesh" contype="0" conaffinity="0" group="1" density="0" rgba="0.9 0.9 0.9 1" mesh="r_f_link3_1"/>
                    <geom type="mesh" rgba="0.9 0.9 0.9 1" mesh="r_f_link3_1"/>
                    <body name="r_f_link3_2" pos="0.017 0 0" quat="0.707105 0.707108 0 0">
                      <inertial pos="0.0214625 -0.000312324 -0.000276541" quat="0.514364 0.49694 0.502968 0.485286" mass="0.00860339" diaginertia="1.79436e-06 1.76074e-06 5.64762e-07"/>
                      <joint name="r_f_joint3_2" pos="0 0 0" axis="0 0 1" range="0 1.3" actuatorfrcrange="-10 10"/>
                      <geom type="mesh" contype="0" conaffinity="0" group="1" density="0" rgba="0.3 0.3 0.3 1" mesh="r_f_link3_2"/>
                      <geom type="mesh" rgba="0.3 0.3 0.3 1" mesh="r_f_link3_2"/>
                      <geom type="mesh" contype="0" conaffinity="0" group="1" density="0" rgba="0.3 0.3 0.3 1" mesh="r_f_link3_2_1"/>
                      <geom type="mesh" rgba="0.3 0.3 0.3 1" mesh="r_f_link3_2_1"/>
                      <geom type="mesh" contype="0" conaffinity="0" group="1" density="0" rgba="0.9 0.9 0.9 1" mesh="r_f_link3_2_2"/>
                      <geom type="mesh" rgba="0.9 0.9 0.9 1" mesh="r_f_link3_2_2"/>
                      <body name="r_f_link3_3" pos="0.043 0 0">
                        <inertial pos="0.0131211 -0.000590719 -1.26084e-05" quat="0.0239512 0.703828 -0.0289604 0.709375" mass="0.00474675" diaginertia="4.25746e-07 3.96949e-07 2.15446e-07"/>
                        <joint name="r_f_joint3_3" pos="0 0 0" axis="0 0 1" range="0 1.3" actuatorfrcrange="-10 10"/>
                        <geom type="mesh" contype="0" conaffinity="0" group="1" density="0" rgba="0.3 0.3 0.3 1" mesh="r_f_link3_3"/>
                        <geom type="mesh" rgba="0.3 0.3 0.3 1" mesh="r_f_link3_3"/>
                        <geom type="mesh" contype="0" conaffinity="0" group="1" density="0" rgba="0.9 0.9 0.9 1" mesh="r_f_link3_3_1"/>
                        <geom type="mesh" rgba="0.9 0.9 0.9 1" mesh="r_f_link3_3_1"/>
                        <geom type="mesh" contype="0" conaffinity="0" group="1" density="0" rgba="0.9 0.9 0.9 1" mesh="r_f_link3_3_2"/>
                        <geom type="mesh" rgba="0.9 0.9 0.9 1" mesh="r_f_link3_3_2"/>
                        <body name="r_f_link3_4" pos="0.025 0 0">
                          <inertial pos="0.0193485 -0.00255949 -7.94242e-07" quat="0.0419787 0.705389 -0.0494777 0.705845" mass="0.0086892" diaginertia="1.28832e-06 1.28613e-06 3.95468e-07"/>
                          <joint name="r_f_joint3_4" pos="0 0 0" axis="0 0 1" range="0 1.3" actuatorfrcrange="-10 10"/>
                          <geom type="mesh" contype="0" conaffinity="0" group="1" density="0" rgba="0.3 0.3 0.3 1" mesh="r_f_link3_4"/>
                          <geom type="mesh" rgba="0.3 0.3 0.3 1" mesh="r_f_link3_4"/>
                          <geom type="mesh" contype="0" conaffinity="0" group="1" density="0" rgba="0.3 0.3 0.3 1" mesh="r_f_link3_4_1"/>
                          <geom type="mesh" rgba="0.3 0.3 0.3 1" mesh="r_f_link3_4_1"/>
                          <geom type="mesh" contype="0" conaffinity="0" group="1" density="0" rgba="0.9 0.9 0.9 1" mesh="r_f_link3_4_2"/>
                          <geom type="mesh" rgba="0.9 0.9 0.9 1" mesh="r_f_link3_4_2"/>
                          <geom size="0.002" pos="0.035 -0.004 0" contype="0" conaffinity="0" group="1" density="0" rgba="1 0 0 1"/>
                          <geom size="0.002" pos="0.035 -0.004 0" rgba="1 0 0 1"/>
                          <geom size="0.006 0.0005 0.003" pos="0.026 0.0025 0" quat="0.974794 0 0 -0.223106" type="box" contype="0" conaffinity="0" group="1" density="0" rgba="0 1 0 1"/>
                          <geom size="0.006 0.0005 0.003" pos="0.026 0.0025 0" quat="0.974794 0 0 -0.223106" type="box" rgba="0 1 0 1"/>
                          <site name="site_r_f_link3_tip" pos="0.035 -0.004 0" quat="1.0 0.0 0.0 0.0" type="sphere" size="0.002" rgba="1 0 0 1"/>
                          <site name="site_r_f_link3_pad" pos="0.026 0.0025 0.000" quat="0.9747941070689433 0.0 0.0 -0.22310636213174545" type="box" size="0.006 0.0005 0.003" rgba="0 1 0 1"/>
                        </body>
                      </body>
                    </body>
                  </body>
                  <body name="r_f_link4_1" pos="0.0069769 -0.0136824 0.1597" quat="0.000278947 -0.707107 -0.000281544 -0.707107">
                    <inertial pos="0.00800686 1.83389e-05 -0.00158423" quat="0.366432 0.601227 0.609221 0.364834" mass="0.00351858" diaginertia="3.71993e-07 3.23705e-07 2.04962e-07"/>
                    <joint name="r_f_joint4_1" pos="0 0 0" axis="0 0 1" range="0 0.6" actuatorfrcrange="-10 10"/>
                    <geom type="mesh" contype="0" conaffinity="0" group="1" density="0" rgba="0.9 0.9 0.9 1" mesh="r_f_link4_1"/>
                    <geom type="mesh" rgba="0.9 0.9 0.9 1" mesh="r_f_link4_1"/>
                    <body name="r_f_link4_2" pos="0.017 0 0" quat="0.707105 0.707108 0 0">
                      <inertial pos="0.0214625 -0.000312324 -0.000276541" quat="0.514364 0.49694 0.502968 0.485286" mass="0.00860339" diaginertia="1.79436e-06 1.76074e-06 5.64762e-07"/>
                      <joint name="r_f_joint4_2" pos="0 0 0" axis="0 0 1" range="0 1.3" actuatorfrcrange="-10 10"/>
                      <geom type="mesh" contype="0" conaffinity="0" group="1" density="0" rgba="0.3 0.3 0.3 1" mesh="r_f_link4_2"/>
                      <geom type="mesh" rgba="0.3 0.3 0.3 1" mesh="r_f_link4_2"/>
                      <geom type="mesh" contype="0" conaffinity="0" group="1" density="0" rgba="0.3 0.3 0.3 1" mesh="r_f_link4_2_1"/>
                      <geom type="mesh" rgba="0.3 0.3 0.3 1" mesh="r_f_link4_2_1"/>
                      <geom type="mesh" contype="0" conaffinity="0" group="1" density="0" rgba="0.9 0.9 0.9 1" mesh="r_f_link4_2_2"/>
                      <geom type="mesh" rgba="0.9 0.9 0.9 1" mesh="r_f_link4_2_2"/>
                      <body name="r_f_link4_3" pos="0.043 0 0">
                        <inertial pos="0.0131211 -0.000590719 -1.26084e-05" quat="0.0239528 0.703828 -0.028962 0.709375" mass="0.00474675" diaginertia="4.25746e-07 3.96949e-07 2.15446e-07"/>
                        <joint name="r_f_joint4_3" pos="0 0 0" axis="0 0 1" range="0 1.3" actuatorfrcrange="-10 10"/>
                        <geom type="mesh" contype="0" conaffinity="0" group="1" density="0" rgba="0.3 0.3 0.3 1" mesh="r_f_link4_3"/>
                        <geom type="mesh" rgba="0.3 0.3 0.3 1" mesh="r_f_link4_3"/>
                        <geom type="mesh" contype="0" conaffinity="0" group="1" density="0" rgba="0.9 0.9 0.9 1" mesh="r_f_link4_3_2"/>
                        <geom type="mesh" rgba="0.9 0.9 0.9 1" mesh="r_f_link4_3_2"/>
                        <geom type="mesh" contype="0" conaffinity="0" group="1" density="0" rgba="0.3 0.3 0.3 1" mesh="r_f_link4_3_1"/>
                        <geom type="mesh" rgba="0.3 0.3 0.3 1" mesh="r_f_link4_3_1"/>
                        <body name="r_f_link4_4" pos="0.025 0 0">
                          <inertial pos="0.0193485 -0.00255949 -7.94241e-07" quat="0.0419787 0.705389 -0.0494777 0.705845" mass="0.0086892" diaginertia="1.28832e-06 1.28613e-06 3.95468e-07"/>
                          <joint name="r_f_joint4_4" pos="0 0 0" axis="0 0 1" range="0 1.3" actuatorfrcrange="-10 10"/>
                          <geom type="mesh" contype="0" conaffinity="0" group="1" density="0" rgba="0.3 0.3 0.3 1" mesh="r_f_link4_4"/>
                          <geom type="mesh" rgba="0.3 0.3 0.3 1" mesh="r_f_link4_4"/>
                          <geom type="mesh" contype="0" conaffinity="0" group="1" density="0" rgba="0.3 0.3 0.3 1" mesh="r_f_link4_4_1"/>
                          <geom type="mesh" rgba="0.3 0.3 0.3 1" mesh="r_f_link4_4_1"/>
                          <geom type="mesh" contype="0" conaffinity="0" group="1" density="0" rgba="0.9 0.9 0.9 1" mesh="r_f_link4_4_2"/>
                          <geom type="mesh" rgba="0.9 0.9 0.9 1" mesh="r_f_link4_4_2"/>
                          <geom size="0.002" pos="0.035 -0.004 0" contype="0" conaffinity="0" group="1" density="0" rgba="1 0 0 1"/>
                          <geom size="0.002" pos="0.035 -0.004 0" rgba="1 0 0 1"/>
                          <geom size="0.006 0.0005 0.003" pos="0.026 0.0025 0" quat="0.974794 0 0 -0.223106" type="box" contype="0" conaffinity="0" group="1" density="0" rgba="0 1 0 1"/>
                          <geom size="0.006 0.0005 0.003" pos="0.026 0.0025 0" quat="0.974794 0 0 -0.223106" type="box" rgba="0 1 0 1"/>
                          <site name="site_r_f_link4_tip" pos="0.035 -0.004 0" quat="1.0 0.0 0.0 0.0" type="sphere" size="0.002" rgba="1 0 0 1"/>
                          <site name="site_r_f_link4_pad" pos="0.026 0.0025 0.000" quat="0.9747941070689433 0.0 0.0 -0.22310636213174545" type="box" size="0.006 0.0005 0.003" rgba="0 1 0 1"/>
                        </body>
                      </body>
                    </body>
                  </body>
                  <body name="r_f_link5_1" pos="0.00699625 -0.0379824 0.1457" quat="0.000278947 -0.707107 -0.000281544 -0.707107">
                    <inertial pos="0.00800686 1.83389e-05 -0.00158423" quat="0.366432 0.601227 0.609221 0.364834" mass="0.00351858" diaginertia="3.71993e-07 3.23705e-07 2.04962e-07"/>
                    <joint name="r_f_joint5_1" pos="0 0 0" axis="0 0 1" range="0 0.6" actuatorfrcrange="-10 10"/>
                    <geom type="mesh" contype="0" conaffinity="0" group="1" density="0" rgba="0.9 0.9 0.9 1" mesh="r_f_link5_1"/>
                    <geom type="mesh" rgba="0.9 0.9 0.9 1" mesh="r_f_link5_1"/>
                    <body name="r_f_link5_2" pos="0.017 0 0" quat="0.707105 0.707108 0 0">
                      <inertial pos="0.0214625 -0.000312324 -0.000276541" quat="0.514364 0.49694 0.502968 0.485286" mass="0.00860339" diaginertia="1.79436e-06 1.76074e-06 5.64762e-07"/>
                      <joint name="r_f_joint5_2" pos="0 0 0" axis="0 0 1" range="0 1.3" actuatorfrcrange="-10 10"/>
                      <geom type="mesh" contype="0" conaffinity="0" group="1" density="0" rgba="0.3 0.3 0.3 1" mesh="r_f_link5_2"/>
                      <geom type="mesh" rgba="0.3 0.3 0.3 1" mesh="r_f_link5_2"/>
                      <geom type="mesh" contype="0" conaffinity="0" group="1" density="0" rgba="0.3 0.3 0.3 1" mesh="r_f_link5_2_1"/>
                      <geom type="mesh" rgba="0.3 0.3 0.3 1" mesh="r_f_link5_2_1"/>
                      <geom type="mesh" contype="0" conaffinity="0" group="1" density="0" rgba="0.9 0.9 0.9 1" mesh="r_f_link5_2_2"/>
                      <geom type="mesh" rgba="0.9 0.9 0.9 1" mesh="r_f_link5_2_2"/>
                      <body name="r_f_link5_3" pos="0.043 0 0">
                        <inertial pos="0.0131211 -0.000590719 -1.26084e-05" quat="0.0239512 0.703828 -0.0289604 0.709375" mass="0.00474675" diaginertia="4.25746e-07 3.96949e-07 2.15446e-07"/>
                        <joint name="r_f_joint5_3" pos="0 0 0" axis="0 0 1" range="0 1.3" actuatorfrcrange="-10 10"/>
                        <geom type="mesh" contype="0" conaffinity="0" group="1" density="0" rgba="0.3 0.3 0.3 1" mesh="r_f_link5_3"/>
                        <geom type="mesh" rgba="0.3 0.3 0.3 1" mesh="r_f_link5_3"/>
                        <geom type="mesh" contype="0" conaffinity="0" group="1" density="0" rgba="0.3 0.3 0.3 1" mesh="r_f_link5_3_1"/>
                        <geom type="mesh" rgba="0.3 0.3 0.3 1" mesh="r_f_link5_3_1"/>
                        <geom type="mesh" contype="0" conaffinity="0" group="1" density="0" rgba="0.9 0.9 0.9 1" mesh="r_f_link5_3_2"/>
                        <geom type="mesh" rgba="0.9 0.9 0.9 1" mesh="r_f_link5_3_2"/>
                        <body name="r_f_link5_4" pos="0.025 0 0">
                          <inertial pos="0.0193485 -0.00255949 -7.94249e-07" quat="0.0419787 0.705389 -0.0494777 0.705845" mass="0.0086892" diaginertia="1.28832e-06 1.28613e-06 3.95468e-07"/>
                          <joint name="r_f_joint5_4" pos="0 0 0" axis="0 0 1" range="0 1.3" actuatorfrcrange="-10 10"/>
                          <geom type="mesh" contype="0" conaffinity="0" group="1" density="0" rgba="0.3 0.3 0.3 1" mesh="r_f_link5_4"/>
                          <geom type="mesh" rgba="0.3 0.3 0.3 1" mesh="r_f_link5_4"/>
                          <geom type="mesh" contype="0" conaffinity="0" group="1" density="0" rgba="0.3 0.3 0.3 1" mesh="r_f_link5_4_1"/>
                          <geom type="mesh" rgba="0.3 0.3 0.3 1" mesh="r_f_link5_4_1"/>
                          <geom type="mesh" contype="0" conaffinity="0" group="1" density="0" rgba="0.9 0.9 0.9 1" mesh="r_f_link5_4_2"/>
                          <geom type="mesh" rgba="0.9 0.9 0.9 1" mesh="r_f_link5_4_2"/>
                          <geom size="0.002" pos="0.035 -0.004 0" contype="0" conaffinity="0" group="1" density="0" rgba="1 0 0 1"/>
                          <geom size="0.002" pos="0.035 -0.004 0" rgba="1 0 0 1"/>
                          <geom size="0.006 0.0005 0.003" pos="0.026 0.0025 0" quat="0.974794 0 0 -0.223106" type="box" contype="0" conaffinity="0" group="1" density="0" rgba="0 1 0 1"/>
                          <geom size="0.006 0.0005 0.003" pos="0.026 0.0025 0" quat="0.974794 0 0 -0.223106" type="box" rgba="0 1 0 1"/>
                          <site name="site_r_f_link5_tip" pos="0.035 -0.004 0" quat="1.0 0.0 0.0 0.0" type="sphere" size="0.002" rgba="1 0 0 1"/>
                          <site name="site_r_f_link5_pad" pos="0.026 0.0025 0.000" quat="0.9747941070689433 0.0 0.0 -0.22310636213174545" type="box" size="0.006 0.0005 0.003" rgba="0 1 0 1"/>
                        </body>
                      </body>
                    </body>
                  </body>
                </body>
              </body>
            </body>
          </body>
        </body>
      </body>
    </body>
  </body>
</mujocoinclude>
