<?xml version="1.0" encoding="utf-8"?>
<mujocoinclude>
  <body name="floating_base_root">
    <inertial pos="0 0 0" quat="1 0 0 0" mass="0.01" diaginertia="0.01 0.01 0.01"/>
    <body name="floating_base" pos="0 0 0">
      <inertial pos="0 0 0" quat="1 0 0 0" mass="0.01" diaginertia="0.01 0.01 0.01"/>
      <joint name="ARTx" pos="0 0 0" axis="1 0 0" type="slide" range="-1 1" limited="true" damping="20" armature="0.01" frictionloss="0.1"/>
      <body name="ARTx_child" pos="0 0 0">
        <inertial pos="0 0 0" quat="1 0 0 0" mass="0.001" diaginertia="0.001 0.001 0.001"/>
        <joint name="ARTy" pos="0 0 0" axis="0 1 0" type="slide" range="-1 1" limited="true" damping="20" armature="0.01" frictionloss="0.1"/>
        <body name="ARTy_child" pos="0 0 0">
          <inertial pos="0 0 0" quat="1 0 0 0" mass="0.001" diaginertia="0.001 0.001 0.001"/>
          <joint name="ARTz" pos="0 0 0" axis="0 0 1" type="slide" range="-1 1" limited="true" damping="20" armature="0.01" frictionloss="0.1"/>
          <body name="ARTz_child" pos="0 0 0">
            <inertial pos="0 0 0" quat="1 0 0 0" mass="0.001" diaginertia="0.001 0.001 0.001"/>
            <joint name="ARRx" pos="0 0 0" axis="1 0 0" type="hinge" range="-3.14 3.14" limited="true" damping="20" armature="0.01" frictionloss="0.1"/>
            <body name="ARRx_child" pos="0 0 0">
              <inertial pos="0 0 0" quat="1 0 0 0" mass="0.001" diaginertia="0.001 0.001 0.001"/>
              <joint name="ARRy" pos="0 0 0" axis="0 1 0" type="hinge" range="-3.14 3.14" limited="true" damping="20" armature="0.01" frictionloss="0.1"/>
              <body name="ARRy_child" pos="0 0 0">
                <inertial pos="0 0 0" quat="1 0 0 0" mass="0.001" diaginertia="0.001 0.001 0.001"/>
                <joint name="ARRz" pos="0 0 0" axis="0 0 1" type="hinge" range="-3.14 3.14" limited="true" damping="20" armature="0.01" frictionloss="0.1"/>
                <body name="hand_base">
                  <body name="right_hand_base" pos="0 0 0" quat="0.7071067811865476 0.0 0.7071067811865475 0.0">
                    <geom type="mesh" contype="0" conaffinity="0" group="1" density="0" rgba="0.75294 0.75294 0.75294 1" mesh="right_hand_base"/>
                    <geom type="mesh" rgba="0.75294 0.75294 0.75294 1" mesh="right_hand_base" contype="0" conaffinity="0" group="1" density="0"/>
                    <body name="r_f_link1_1" pos="0.032783 0.023781 0.11211" quat="0.151551 -0.775385 -0.612635 0.0221215">
                      <inertial pos="0.00197785 -0.000351482 0.0134505" quat="0.716208 -0.0775695 -0.0529929 0.691535" mass="0.00440996" diaginertia="4.39581e-07 3.79862e-07 1.98309e-07"/>
                      <joint name="r_f_joint1_1" pos="0 0 0" axis="0 0 1" range="0 2.2" actuatorfrcrange="-10 10" limited="true"/>
                      <geom type="mesh" contype="0" conaffinity="0" group="1" density="0" rgba="0.6 0.6 0.6 1" mesh="r_f_link1_1"/>
                      <geom type="mesh" rgba="0.6 0.6 0.6 1" mesh="r_f_link1_1" contype="0" conaffinity="0" group="1" density="0"/>
                      <body name="r_f_link1_2" pos="0.0083307 0 0" quat="0.707105 -0.707108 0 0">
                        <inertial pos="0.0214331 0.000179495 -0.00129805" quat="0.0128566 0.706495 -0.0167187 0.707404" mass="0.00995222" diaginertia="1.71013e-06 1.65574e-06 6.19077e-07"/>
                        <joint name="r_f_joint1_2" pos="0 0 0" axis="0 0 1" range="0 1.3" actuatorfrcrange="-10 10" limited="true"/>
                        <geom type="mesh" contype="0" conaffinity="0" group="1" density="0" rgba="0.6 0.6 0.6 1" mesh="r_f_link1_2"/>
                        <geom type="mesh" rgba="0.6 0.6 0.6 1" mesh="r_f_link1_2" contype="0" conaffinity="0" group="1" density="0"/>
                        <body name="r_f_link1_3" pos="0.043 0 0">
                          <inertial pos="0.0134587 -0.000699996 -0.00129335" quat="0.0204189 0.706708 -0.0207895 0.706905" mass="0.00457333" diaginertia="3.7975e-07 3.56572e-07 2.03242e-07"/>
                          <joint name="r_f_joint1_3" pos="0 0 0" axis="0 0 1" range="0 1.3" actuatorfrcrange="-10 10" limited="true"/>
                          <geom type="mesh" contype="0" conaffinity="0" group="1" density="0" rgba="0.6 0.6 0.6 1" mesh="r_f_link1_3"/>
                          <geom type="mesh" rgba="0.6 0.6 0.6 1" mesh="r_f_link1_3" contype="0" conaffinity="0" group="1" density="0"/>
                          <body name="r_f_link1_4" pos="0.025 0 0">
                            <inertial pos="0.0197512 -0.0029745 -0.00109785" quat="-0.0170159 0.689951 -0.100438 0.716652" mass="0.00815928" diaginertia="1.11902e-06 1.10174e-06 3.47089e-07"/>
                            <joint name="r_f_joint1_4" pos="0 0 0" axis="0 0 1" range="0 1.3" actuatorfrcrange="-10 10" limited="true"/>
                            <geom type="mesh" contype="0" conaffinity="0" group="1" density="0" rgba="0.6 0.6 0.6 1" mesh="r_f_link1_4"/>
                            <geom type="mesh" rgba="0.6 0.6 0.6 1" mesh="r_f_link1_4" contype="0" conaffinity="0" group="1" density="0"/>
                            <geom size="0.002" pos="0.035 -0.004 0" contype="0" conaffinity="0" group="1" density="0" rgba="1 0 0 1"/>
                            <geom size="0.002" pos="0.035 -0.004 0" rgba="1 0 0 1" contype="0" conaffinity="0" group="1" density="0"/>
                            <geom size="0.006 0.0005 0.003" pos="0.026 0.0025 -0.001" quat="0.974794 0 0 -0.223106" type="box" contype="0" conaffinity="0" group="1" density="0" rgba="0 1 0 1"/>
                            <geom size="0.006 0.0005 0.003" pos="0.026 0.0025 -0.001" quat="0.974794 0 0 -0.223106" type="box" rgba="0 1 0 1" contype="0" conaffinity="0" group="1" density="0"/>
                            <body name="r_f_link1_tip" pos="0.035 -0.004 0" quat="1.0 0.0 0.0 0.0">
                              <geom name="geom_r_f_link1_tip" type="sphere" size="0.002" rgba="1 0 0 1" contype="0" conaffinity="0" group="1" density="0"/>
                            </body>
                            <body name="r_f_link1_pad" pos="0.026 0.0025 -0.001" quat="0.9747941070689433 0.0 0.0 -0.22310636213174545">
                              <geom name="geom_r_f_link1_pad" type="box" size="0.006 0.0005 0.003" rgba="0 1 0 1" contype="0" conaffinity="0" group="1" density="0"/>
                            </body>
                            <site name="site_r_f_link1_pad" pos="0.026 0.0025 -0.001" quat="0.9747941070689433 0.0 0.0 -0.22310636213174545" type="box" size="0.006 0.0005 0.003" rgba="0 1 0 1"/>
                            <site name="site_r_f_link1_4" pos="0.0143 0.006 0" size="0.0001" type="sphere" rgba="1 0 0 1" zaxis="0.46 1 0"/>
                            <body name="ts_wrapper_r_f_link1_pad" pos="0.0425 -0.0188 -0.0055" quat="0.69101 -0.15003 -0.69101 -0.15003">
                              <body name="force1_f1" pos="0 0 0.02">
                                <geom type="mesh" rgba="1 0.3 0.3 1" mesh="f1" contype="0" conaffinity="0" group="1" density="0"/>
                              </body>
                              <body name="force1_f2" pos="0 0 0.0192">
                                <geom type="mesh" rgba="1 0.3 0.3 1" mesh="f2" contype="0" conaffinity="0" group="1" density="0"/>
                              </body>
                              <body name="force1_f3" pos="0.00545 0 0.02">
                                <geom type="mesh" rgba="1 0.3 0.3 1" mesh="f3" contype="0" conaffinity="0" group="1" density="0"/>
                              </body>
                              <body name="force1_f4" pos="0 0 0.02465">
                                <geom type="mesh" rgba="1 0.3 0.3 1" mesh="f4" contype="0" conaffinity="0" group="1" density="0"/>
                              </body>
                              <body name="force1_f5" pos="-0.0001 0 0.0285">
                                <geom type="mesh" rgba="1 0.3 0.3 1" mesh="f5" contype="0" conaffinity="0" group="1" density="0"/>
                              </body>
                              <body name="force1_f6" pos="0.0055 0 0.0285">
                                <geom type="mesh" rgba="1 0.3 0.3 1" mesh="f6" contype="0" conaffinity="0" group="1" density="0"/>
                              </body>
                              <body name="force1_f7" pos="0 0 0.01362">
                                <geom type="mesh" rgba="1 0.3 0.3 1" mesh="f7" contype="0" conaffinity="0" group="1" density="0"/>
                              </body>
                            </body>
                            <geom name="col_r_f_link1_4" type="capsule" contype="1" conaffinity="1" group="3" size="0.0095" fromto="0.0 0 -0.001 0.027 -0.007 -0.001"/>
                          </body>
                          <geom name="col_r_f_link1_3" type="capsule" contype="1" conaffinity="1" group="3" size="0.007" fromto="0.0125 0.003 -0.0045 0.0125 0.003 0.0023"/>
                        </body>
                        <geom name="col_r_f_link1_2" type="capsule" contype="1" conaffinity="1" group="3" size="0.0095" fromto="0.0 0 0 0.03 0 -0.002"/>
                      </body>
                    </body>
                    <body name="r_f_link2_1" pos="0.006966 0.034912 0.1644" quat="0.707105 0 -0.707108 0">
                      <inertial pos="0.00700207 9.3578e-08 0.000968546" quat="0.602139 0.37074 0.370772 0.602087" mass="0.00409704" diaginertia="3.18125e-07 2.71726e-07 2.04208e-07"/>
                      <joint name="r_f_joint2_1" pos="0 0 0" axis="0 0 1" range="0 0.3" actuatorfrcrange="-10 10" limited="true"/>
                      <geom type="mesh" contype="0" conaffinity="0" group="1" density="0" rgba="0.79216 0.81961 0.93333 1" mesh="r_f_link2_1"/>
                      <geom type="mesh" rgba="0.79216 0.81961 0.93333 1" mesh="r_f_link2_1" contype="0" conaffinity="0" group="1" density="0"/>
                      <body name="r_f_link2_2" pos="0.017 0 0" quat="0.707105 -0.707108 0 0">
                        <inertial pos="0.0211623 -0.000590509 -2.03591e-06" quat="0.507059 0.504013 0.495283 0.493514" mass="0.0094284" diaginertia="1.65775e-06 1.64329e-06 5.54341e-07"/>
                        <joint name="r_f_joint2_2" pos="0 0 0" axis="0 0 1" range="0 1.3" actuatorfrcrange="-10 10" limited="true"/>
                        <geom type="mesh" contype="0" conaffinity="0" group="1" density="0" rgba="0.6 0.6 0.6 1" mesh="r_f_link2_2"/>
                        <geom type="mesh" rgba="0.6 0.6 0.6 1" mesh="r_f_link2_2" contype="0" conaffinity="0" group="1" density="0"/>
                        <body name="r_f_link2_3" pos="0.043 0 0">
                          <inertial pos="0.0134587 -0.000699996 -9.33093e-07" quat="0.0204189 0.706708 -0.0207895 0.706905" mass="0.00457333" diaginertia="3.7975e-07 3.56572e-07 2.03242e-07"/>
                          <joint name="r_f_joint2_3" pos="0 0 0" axis="0 0 1" range="0 1.3" actuatorfrcrange="-10 10" limited="true"/>
                          <geom type="mesh" contype="0" conaffinity="0" group="1" density="0" rgba="0.6 0.6 0.6 1" mesh="r_f_link2_3"/>
                          <geom type="mesh" rgba="0.6 0.6 0.6 1" mesh="r_f_link2_3" contype="0" conaffinity="0" group="1" density="0"/>
                          <body name="r_f_link2_4" pos="0.025 0 0">
                            <inertial pos="0.0197512 -0.0029745 2.99885e-07" quat="0.043096 0.705808 -0.0423577 0.705821" mass="0.00815928" diaginertia="1.11794e-06 1.10078e-06 3.46237e-07"/>
                            <joint name="r_f_joint2_4" pos="0 0 0" axis="0 0 1" range="0 1.3" actuatorfrcrange="-10 10" limited="true"/>
                            <geom type="mesh" contype="0" conaffinity="0" group="1" density="0" rgba="0.6 0.6 0.6 1" mesh="r_f_link2_4"/>
                            <geom type="mesh" rgba="0.6 0.6 0.6 1" mesh="r_f_link2_4" contype="0" conaffinity="0" group="1" density="0"/>
                            <geom size="0.002" pos="0.035 -0.004 0" contype="0" conaffinity="0" group="1" density="0" rgba="1 0 0 1"/>
                            <geom size="0.002" pos="0.035 -0.004 0" rgba="1 0 0 1" contype="0" conaffinity="0" group="1" density="0"/>
                            <geom size="0.006 0.0005 0.003" pos="0.026 0.0025 0" quat="0.974794 0 0 -0.223106" type="box" contype="0" conaffinity="0" group="1" density="0" rgba="0 1 0 1"/>
                            <geom size="0.006 0.0005 0.003" pos="0.026 0.0025 0" quat="0.974794 0 0 -0.223106" type="box" rgba="0 1 0 1" contype="0" conaffinity="0" group="1" density="0"/>
                            <body name="r_f_link2_tip" pos="0.035 -0.004 0" quat="1.0 0.0 0.0 0.0">
                              <geom name="geom_r_f_link2_tip" type="sphere" size="0.002" rgba="1 0 0 1" contype="0" conaffinity="0" group="1" density="0"/>
                            </body>
                            <body name="r_f_link2_pad" pos="0.026 0.0025 0.000" quat="0.9747941070689433 0.0 0.0 -0.22310636213174545">
                              <geom name="geom_r_f_link2_pad" type="box" size="0.006 0.0005 0.003" rgba="0 1 0 1" contype="0" conaffinity="0" group="1" density="0"/>
                            </body>
                            <site name="site_r_f_link2_pad" pos="0.026 0.0025 0.000" quat="0.9747941070689433 0.0 0.0 -0.22310636213174545" type="box" size="0.006 0.0005 0.003" rgba="0 1 0 1"/>
                            <site name="site_r_f_link2_4" pos="0.0143 0.006 0" size="0.0001" type="sphere" rgba="1 0 0 1" zaxis="0.46 1 0"/>
                            <body name="ts_wrapper_r_f_link2_pad" pos="0.0425 -0.0188 -0.0055" quat="0.69101 -0.15003 -0.69101 -0.15003">
                              <body name="force2_f1" pos="0 0 0.02">
                                <geom type="mesh" rgba="1 0.3 0.3 1" mesh="f1" contype="0" conaffinity="0" group="1" density="0"/>
                              </body>
                              <body name="force2_f2" pos="0 0 0.0192">
                                <geom type="mesh" rgba="1 0.3 0.3 1" mesh="f2" contype="0" conaffinity="0" group="1" density="0"/>
                              </body>
                              <body name="force2_f3" pos="0.00545 0 0.02">
                                <geom type="mesh" rgba="1 0.3 0.3 1" mesh="f3" contype="0" conaffinity="0" group="1" density="0"/>
                              </body>
                              <body name="force2_f4" pos="0 0 0.02465">
                                <geom type="mesh" rgba="1 0.3 0.3 1" mesh="f4" contype="0" conaffinity="0" group="1" density="0"/>
                              </body>
                              <body name="force2_f5" pos="-0.0001 0 0.0285">
                                <geom type="mesh" rgba="1 0.3 0.3 1" mesh="f5" contype="0" conaffinity="0" group="1" density="0"/>
                              </body>
                              <body name="force2_f6" pos="0.0055 0 0.0285">
                                <geom type="mesh" rgba="1 0.3 0.3 1" mesh="f6" contype="0" conaffinity="0" group="1" density="0"/>
                              </body>
                              <body name="force2_f7" pos="0 0 0.01362">
                                <geom type="mesh" rgba="1 0.3 0.3 1" mesh="f7" contype="0" conaffinity="0" group="1" density="0"/>
                              </body>
                            </body>
                            <geom name="col_r_f_link2_4" type="capsule" contype="1" conaffinity="1" group="3" size="0.0095" fromto="0.0 0 0 0.026 -0.007 0"/>
                          </body>
                          <geom name="col_r_f_link2_3" type="capsule" contype="1" conaffinity="1" group="3" size="0.007" fromto="0.012 0.003 -0.0035 0.012 0.003 0.0035"/>
                        </body>
                        <geom name="col_r_f_link2_2" type="capsule" contype="1" conaffinity="1" group="3" size="0.0095" fromto="0.005 0 0 0.03 0 0"/>
                      </body>
                    </body>
                    <body name="r_f_link3_1" pos="0.006966 0.010612 0.1734" quat="0.707105 0 -0.707108 0">
                      <inertial pos="0.00700207 9.45418e-08 0.000968552" quat="0.602139 0.37074 0.370772 0.602087" mass="0.00409704" diaginertia="3.18126e-07 2.71726e-07 2.04209e-07"/>
                      <joint name="r_f_joint3_1" pos="0 0 0" axis="0 0 1" range="-0.001 0.001" limited="true"/>
                      <geom type="mesh" contype="0" conaffinity="0" group="1" density="0" rgba="0.79216 0.81961 0.93333 1" mesh="r_f_link3_1"/>
                      <geom type="mesh" rgba="0.79216 0.81961 0.93333 1" mesh="r_f_link3_1" contype="0" conaffinity="0" group="1" density="0"/>
                      <body name="r_f_link3_2" pos="0.017 0 0" quat="0.707105 -0.707108 0 0">
                        <inertial pos="0.0211623 -0.000590509 -2.03591e-06" quat="0.507059 0.504013 0.495283 0.493514" mass="0.0094284" diaginertia="1.65775e-06 1.64329e-06 5.54341e-07"/>
                        <joint name="r_f_joint3_2" pos="0 0 0" axis="0 0 1" range="0 1.3" actuatorfrcrange="-10 10" limited="true"/>
                        <geom type="mesh" contype="0" conaffinity="0" group="1" density="0" rgba="0.6 0.6 0.6 1" mesh="r_f_link3_2"/>
                        <geom type="mesh" rgba="0.6 0.6 0.6 1" mesh="r_f_link3_2" contype="0" conaffinity="0" group="1" density="0"/>
                        <body name="r_f_link3_3" pos="0.043 0 0">
                          <inertial pos="0.0134587 -0.000699996 -9.33093e-07" quat="0.0204189 0.706708 -0.0207895 0.706905" mass="0.00457333" diaginertia="3.7975e-07 3.56572e-07 2.03242e-07"/>
                          <joint name="r_f_joint3_3" pos="0 0 0" axis="0 0 1" range="0 1.3" actuatorfrcrange="-10 10" limited="true"/>
                          <geom type="mesh" contype="0" conaffinity="0" group="1" density="0" rgba="0.6 0.6 0.6 1" mesh="r_f_link3_3"/>
                          <geom type="mesh" rgba="0.6 0.6 0.6 1" mesh="r_f_link3_3" contype="0" conaffinity="0" group="1" density="0"/>
                          <body name="r_f_link3_4" pos="0.025 0 0">
                            <inertial pos="0.0197512 -0.0029745 2.99885e-07" quat="0.043096 0.705808 -0.0423577 0.705821" mass="0.00815928" diaginertia="1.11794e-06 1.10078e-06 3.46237e-07"/>
                            <joint name="r_f_joint3_4" pos="0 0 0" axis="0 0 1" range="0 1.3" actuatorfrcrange="-10 10" limited="true"/>
                            <geom type="mesh" contype="0" conaffinity="0" group="1" density="0" rgba="0.6 0.6 0.6 1" mesh="r_f_link3_4"/>
                            <geom type="mesh" rgba="0.6 0.6 0.6 1" mesh="r_f_link3_4" contype="0" conaffinity="0" group="1" density="0"/>
                            <geom size="0.002" pos="0.035 -0.004 0" contype="0" conaffinity="0" group="1" density="0" rgba="1 0 0 1"/>
                            <geom size="0.002" pos="0.035 -0.004 0" rgba="1 0 0 1" contype="0" conaffinity="0" group="1" density="0"/>
                            <geom size="0.006 0.0005 0.003" pos="0.026 0.0025 0" quat="0.974794 0 0 -0.223106" type="box" contype="0" conaffinity="0" group="1" density="0" rgba="0 1 0 1"/>
                            <geom size="0.006 0.0005 0.003" pos="0.026 0.0025 0" quat="0.974794 0 0 -0.223106" type="box" rgba="0 1 0 1" contype="0" conaffinity="0" group="1" density="0"/>
                            <body name="r_f_link3_tip" pos="0.035 -0.004 0" quat="1.0 0.0 0.0 0.0">
                              <geom name="geom_r_f_link3_tip" type="sphere" size="0.002" rgba="1 0 0 1" contype="0" conaffinity="0" group="1" density="0"/>
                            </body>
                            <body name="r_f_link3_pad" pos="0.026 0.0025 0.000" quat="0.9747941070689433 0.0 0.0 -0.22310636213174545">
                              <geom name="geom_r_f_link3_pad" type="box" size="0.006 0.0005 0.003" rgba="0 1 0 1" contype="0" conaffinity="0" group="1" density="0"/>
                            </body>
                            <site name="site_r_f_link3_pad" pos="0.026 0.0025 0.000" quat="0.9747941070689433 0.0 0.0 -0.22310636213174545" type="box" size="0.006 0.0005 0.003" rgba="0 1 0 1"/>
                            <site name="site_r_f_link3_4" pos="0.0143 0.006 0" size="0.0001" type="sphere" rgba="1 0 0 1" zaxis="0.46 1 0"/>
                            <body name="ts_wrapper_r_f_link3_pad" pos="0.0425 -0.0188 -0.0055" quat="0.69101 -0.15003 -0.69101 -0.15003">
                              <body name="force3_f1" pos="0 0 0.02">
                                <geom type="mesh" rgba="1 0.3 0.3 1" mesh="f1" contype="0" conaffinity="0" group="1" density="0"/>
                              </body>
                              <body name="force3_f2" pos="0 0 0.0192">
                                <geom type="mesh" rgba="1 0.3 0.3 1" mesh="f2" contype="0" conaffinity="0" group="1" density="0"/>
                              </body>
                              <body name="force3_f3" pos="0.00545 0 0.02">
                                <geom type="mesh" rgba="1 0.3 0.3 1" mesh="f3" contype="0" conaffinity="0" group="1" density="0"/>
                              </body>
                              <body name="force3_f4" pos="0 0 0.02465">
                                <geom type="mesh" rgba="1 0.3 0.3 1" mesh="f4" contype="0" conaffinity="0" group="1" density="0"/>
                              </body>
                              <body name="force3_f5" pos="-0.0001 0 0.0285">
                                <geom type="mesh" rgba="1 0.3 0.3 1" mesh="f5" contype="0" conaffinity="0" group="1" density="0"/>
                              </body>
                              <body name="force3_f6" pos="0.0055 0 0.0285">
                                <geom type="mesh" rgba="1 0.3 0.3 1" mesh="f6" contype="0" conaffinity="0" group="1" density="0"/>
                              </body>
                              <body name="force3_f7" pos="0 0 0.01362">
                                <geom type="mesh" rgba="1 0.3 0.3 1" mesh="f7" contype="0" conaffinity="0" group="1" density="0"/>
                              </body>
                            </body>
                            <geom name="col_r_f_link3_4" type="capsule" contype="1" conaffinity="1" group="3" size="0.0095" fromto="0.0 0 0 0.026 -0.007 0"/>
                          </body>
                          <geom name="col_r_f_link3_3" type="capsule" contype="1" conaffinity="1" group="3" size="0.007" fromto="0.012 0.003 -0.0035 0.012 0.003 0.0035"/>
                        </body>
                        <geom name="col_r_f_link3_2" type="capsule" contype="1" conaffinity="1" group="3" size="0.0095" fromto="0.005 0 0 0.03 0 0"/>
                      </body>
                    </body>
                    <body name="r_f_link4_1" pos="0.006966 -0.013688 0.1644" quat="-2.59734e-06 0.707105 2.59735e-06 0.707108">
                      <inertial pos="0.00700206 -9.456e-08 -0.000968554" quat="0.370772 0.602087 0.602139 0.37074" mass="0.00409704" diaginertia="3.18126e-07 2.71726e-07 2.04209e-07"/>
                      <joint name="r_f_joint4_1" pos="0 0 0" axis="0 0 1" range="0 0.3" actuatorfrcrange="-10 10" limited="true"/>
                      <geom type="mesh" contype="0" conaffinity="0" group="1" density="0" rgba="0.79216 0.81961 0.93333 1" mesh="r_f_link4_1"/>
                      <geom type="mesh" rgba="0.79216 0.81961 0.93333 1" mesh="r_f_link4_1" contype="0" conaffinity="0" group="1" density="0"/>
                      <body name="r_f_link4_2" pos="0.017 0 0" quat="0.707105 0.707108 0 0">
                        <inertial pos="0.0211623 -0.000590509 -2.03591e-06" quat="0.507059 0.504013 0.495283 0.493514" mass="0.0094284" diaginertia="1.65775e-06 1.64329e-06 5.54341e-07"/>
                        <joint name="r_f_joint4_2" pos="0 0 0" axis="0 0 1" range="0 1.3" actuatorfrcrange="-10 10" limited="true"/>
                        <geom type="mesh" contype="0" conaffinity="0" group="1" density="0" rgba="0.6 0.6 0.6 1" mesh="r_f_link4_2"/>
                        <geom type="mesh" rgba="0.6 0.6 0.6 1" mesh="r_f_link4_2" contype="0" conaffinity="0" group="1" density="0"/>
                        <body name="r_f_link4_3" pos="0.043 0 0">
                          <inertial pos="0.0134587 -0.000699996 -9.33093e-07" quat="0.0204189 0.706708 -0.0207895 0.706905" mass="0.00457333" diaginertia="3.7975e-07 3.56572e-07 2.03242e-07"/>
                          <joint name="r_f_joint4_3" pos="0 0 0" axis="0 0 1" range="0 1.3" actuatorfrcrange="-10 10" limited="true"/>
                          <geom type="mesh" contype="0" conaffinity="0" group="1" density="0" rgba="0.6 0.6 0.6 1" mesh="r_f_link4_3"/>
                          <geom type="mesh" rgba="0.6 0.6 0.6 1" mesh="r_f_link4_3" contype="0" conaffinity="0" group="1" density="0"/>
                          <body name="r_f_link4_4" pos="0.025 0 0">
                            <inertial pos="0.0197512 -0.0029745 2.99885e-07" quat="0.043096 0.705808 -0.0423577 0.705821" mass="0.00815928" diaginertia="1.11794e-06 1.10078e-06 3.46237e-07"/>
                            <joint name="r_f_joint4_4" pos="0 0 0" axis="0 0 1" range="0 1.3" actuatorfrcrange="-10 10" limited="true"/>
                            <geom type="mesh" contype="0" conaffinity="0" group="1" density="0" rgba="0.6 0.6 0.6 1" mesh="r_f_link4_4"/>
                            <geom type="mesh" rgba="0.6 0.6 0.6 1" mesh="r_f_link4_4" contype="0" conaffinity="0" group="1" density="0"/>
                            <geom size="0.002" pos="0.035 -0.004 0" contype="0" conaffinity="0" group="1" density="0" rgba="1 0 0 1"/>
                            <geom size="0.002" pos="0.035 -0.004 0" rgba="1 0 0 1" contype="0" conaffinity="0" group="1" density="0"/>
                            <geom size="0.006 0.0005 0.003" pos="0.026 0.0025 0" quat="0.974794 0 0 -0.223106" type="box" contype="0" conaffinity="0" group="1" density="0" rgba="0 1 0 1"/>
                            <geom size="0.006 0.0005 0.003" pos="0.026 0.0025 0" quat="0.974794 0 0 -0.223106" type="box" rgba="0 1 0 1" contype="0" conaffinity="0" group="1" density="0"/>
                            <body name="r_f_link4_tip" pos="0.035 -0.004 0" quat="1.0 0.0 0.0 0.0">
                              <geom name="geom_r_f_link4_tip" type="sphere" size="0.002" rgba="1 0 0 1" contype="0" conaffinity="0" group="1" density="0"/>
                            </body>
                            <body name="r_f_link4_pad" pos="0.026 0.0025 0.000" quat="0.9747941070689433 0.0 0.0 -0.22310636213174545">
                              <geom name="geom_r_f_link4_pad" type="box" size="0.006 0.0005 0.003" rgba="0 1 0 1" contype="0" conaffinity="0" group="1" density="0"/>
                            </body>
                            <site name="site_r_f_link4_pad" pos="0.026 0.0025 0.000" quat="0.9747941070689433 0.0 0.0 -0.22310636213174545" type="box" size="0.006 0.0005 0.003" rgba="0 1 0 1"/>
                            <site name="site_r_f_link4_4" pos="0.0143 0.006 0" size="0.0001" type="sphere" rgba="1 0 0 1" zaxis="0.46 1 0"/>
                            <body name="ts_wrapper_r_f_link4_pad" pos="0.0425 -0.0188 -0.0055" quat="0.69101 -0.15003 -0.69101 -0.15003">
                              <body name="force4_f1" pos="0 0 0.02">
                                <geom type="mesh" rgba="1 0.3 0.3 1" mesh="f1" contype="0" conaffinity="0" group="1" density="0"/>
                              </body>
                              <body name="force4_f2" pos="0 0 0.0192">
                                <geom type="mesh" rgba="1 0.3 0.3 1" mesh="f2" contype="0" conaffinity="0" group="1" density="0"/>
                              </body>
                              <body name="force4_f3" pos="0.00545 0 0.02">
                                <geom type="mesh" rgba="1 0.3 0.3 1" mesh="f3" contype="0" conaffinity="0" group="1" density="0"/>
                              </body>
                              <body name="force4_f4" pos="0 0 0.02465">
                                <geom type="mesh" rgba="1 0.3 0.3 1" mesh="f4" contype="0" conaffinity="0" group="1" density="0"/>
                              </body>
                              <body name="force4_f5" pos="-0.0001 0 0.0285">
                                <geom type="mesh" rgba="1 0.3 0.3 1" mesh="f5" contype="0" conaffinity="0" group="1" density="0"/>
                              </body>
                              <body name="force4_f6" pos="0.0055 0 0.0285">
                                <geom type="mesh" rgba="1 0.3 0.3 1" mesh="f6" contype="0" conaffinity="0" group="1" density="0"/>
                              </body>
                              <body name="force4_f7" pos="0 0 0.01362">
                                <geom type="mesh" rgba="1 0.3 0.3 1" mesh="f7" contype="0" conaffinity="0" group="1" density="0"/>
                              </body>
                            </body>
                            <geom name="col_r_f_link4_4" type="capsule" contype="1" conaffinity="1" group="3" size="0.0095" fromto="0.0 0 0 0.026 -0.007 0"/>
                          </body>
                          <geom name="col_r_f_link4_3" type="capsule" contype="1" conaffinity="1" group="3" size="0.007" fromto="0.012 0.003 -0.0035 0.012 0.003 0.0035"/>
                        </body>
                        <geom name="col_r_f_link4_2" type="capsule" contype="1" conaffinity="1" group="3" size="0.0095" fromto="0.005 0 0 0.03 0 0"/>
                      </body>
                    </body>
                    <body name="r_f_link5_1" pos="0.006966 -0.037988 0.1504" quat="-2.59734e-06 0.707105 2.59735e-06 0.707108">
                      <inertial pos="0.00700207 -9.35677e-08 -0.000968542" quat="0.370771 0.602088 0.602139 0.37074" mass="0.00409703" diaginertia="3.18125e-07 2.71726e-07 2.04208e-07"/>
                      <joint name="r_f_joint5_1" pos="0 0 0" axis="0 0 1" range="0 0.6" actuatorfrcrange="-10 10" limited="true"/>
                      <geom type="mesh" contype="0" conaffinity="0" group="1" density="0" rgba="0.792157 0.819608 0.933333 1" mesh="r_f_link5_1"/>
                      <geom type="mesh" rgba="0.792157 0.819608 0.933333 1" mesh="r_f_link5_1" contype="0" conaffinity="0" group="1" density="0"/>
                      <body name="r_f_link5_2" pos="0.017 0 0" quat="0.707105 0.707108 0 0">
                        <inertial pos="0.0211623 -0.000590509 -2.03591e-06" quat="0.507059 0.504013 0.495283 0.493514" mass="0.0094284" diaginertia="1.65775e-06 1.64329e-06 5.54341e-07"/>
                        <joint name="r_f_joint5_2" pos="0 0 0" axis="0 0 1" range="0 1.3" actuatorfrcrange="-10 10" limited="true"/>
                        <geom type="mesh" contype="0" conaffinity="0" group="1" density="0" rgba="0.6 0.6 0.6 1" mesh="r_f_link5_2"/>
                        <geom type="mesh" rgba="0.6 0.6 0.6 1" mesh="r_f_link5_2" contype="0" conaffinity="0" group="1" density="0"/>
                        <body name="r_f_link5_3" pos="0.043 0 0">
                          <inertial pos="0.0134587 -0.000699996 -9.33093e-07" quat="0.0204189 0.706708 -0.0207895 0.706905" mass="0.00457333" diaginertia="3.7975e-07 3.56572e-07 2.03242e-07"/>
                          <joint name="r_f_joint5_3" pos="0 0 0" axis="0 0 1" range="0 1.3" actuatorfrcrange="-10 10" limited="true"/>
                          <geom type="mesh" contype="0" conaffinity="0" group="1" density="0" rgba="0.6 0.6 0.6 1" mesh="r_f_link5_3"/>
                          <geom type="mesh" rgba="0.6 0.6 0.6 1" mesh="r_f_link5_3" contype="0" conaffinity="0" group="1" density="0"/>
                          <body name="r_f_link5_4" pos="0.025 0 0">
                            <inertial pos="0.0197512 -0.0029745 2.99885e-07" quat="0.043096 0.705808 -0.0423577 0.705821" mass="0.00815928" diaginertia="1.11794e-06 1.10078e-06 3.46237e-07"/>
                            <joint name="r_f_joint5_4" pos="0 0 0" axis="0 0 1" range="0 1.3" actuatorfrcrange="-10 10" limited="true"/>
                            <geom type="mesh" contype="0" conaffinity="0" group="1" density="0" rgba="0.6 0.6 0.6 1" mesh="r_f_link5_4"/>
                            <geom type="mesh" rgba="0.6 0.6 0.6 1" mesh="r_f_link5_4" contype="0" conaffinity="0" group="1" density="0"/>
                            <geom size="0.002" pos="0.035 -0.004 0" contype="0" conaffinity="0" group="1" density="0" rgba="1 0 0 1"/>
                            <geom size="0.002" pos="0.035 -0.004 0" rgba="1 0 0 1" contype="0" conaffinity="0" group="1" density="0"/>
                            <geom size="0.006 0.0005 0.003" pos="0.026 0.0025 0" quat="0.974794 0 0 -0.223106" type="box" contype="0" conaffinity="0" group="1" density="0" rgba="0 1 0 1"/>
                            <geom size="0.006 0.0005 0.003" pos="0.026 0.0025 0" quat="0.974794 0 0 -0.223106" type="box" rgba="0 1 0 1" contype="0" conaffinity="0" group="1" density="0"/>
                            <body name="r_f_link5_tip" pos="0.035 -0.004 0" quat="1.0 0.0 0.0 0.0">
                              <geom name="geom_r_f_link5_tip" type="sphere" size="0.002" rgba="1 0 0 1" contype="0" conaffinity="0" group="1" density="0"/>
                            </body>
                            <body name="r_f_link5_pad" pos="0.026 0.0025 0.000" quat="0.9747941070689433 0.0 0.0 -0.22310636213174545">
                              <geom name="geom_r_f_link5_pad" type="box" size="0.006 0.0005 0.003" rgba="0 1 0 1" contype="0" conaffinity="0" group="1" density="0"/>
                            </body>
                            <site name="site_r_f_link5_pad" pos="0.026 0.0025 0.000" quat="0.9747941070689433 0.0 0.0 -0.22310636213174545" type="box" size="0.006 0.0005 0.003" rgba="0 1 0 1"/>
                            <site name="site_r_f_link5_4" pos="0.0143 0.006 0" size="0.0001" type="sphere" rgba="1 0 0 1" zaxis="0.46 1 0"/>
                            <body name="ts_wrapper_r_f_link5_pad" pos="0.0425 -0.0188 -0.0055" quat="0.69101 -0.15003 -0.69101 -0.15003">
                              <body name="force5_f1" pos="0 0 0.02">
                                <geom type="mesh" rgba="1 0.3 0.3 1" mesh="f1" contype="0" conaffinity="0" group="1" density="0"/>
                              </body>
                              <body name="force5_f2" pos="0 0 0.0192">
                                <geom type="mesh" rgba="1 0.3 0.3 1" mesh="f2" contype="0" conaffinity="0" group="1" density="0"/>
                              </body>
                              <body name="force5_f3" pos="0.00545 0 0.02">
                                <geom type="mesh" rgba="1 0.3 0.3 1" mesh="f3" contype="0" conaffinity="0" group="1" density="0"/>
                              </body>
                              <body name="force5_f4" pos="0 0 0.02465">
                                <geom type="mesh" rgba="1 0.3 0.3 1" mesh="f4" contype="0" conaffinity="0" group="1" density="0"/>
                              </body>
                              <body name="force5_f5" pos="-0.0001 0 0.0285">
                                <geom type="mesh" rgba="1 0.3 0.3 1" mesh="f5" contype="0" conaffinity="0" group="1" density="0"/>
                              </body>
                              <body name="force5_f6" pos="0.0055 0 0.0285">
                                <geom type="mesh" rgba="1 0.3 0.3 1" mesh="f6" contype="0" conaffinity="0" group="1" density="0"/>
                              </body>
                              <body name="force5_f7" pos="0 0 0.01362">
                                <geom type="mesh" rgba="1 0.3 0.3 1" mesh="f7" contype="0" conaffinity="0" group="1" density="0"/>
                              </body>
                            </body>
                            <geom name="col_r_f_link5_4" type="capsule" contype="1" conaffinity="1" group="3" size="0.0095" fromto="0.0 0 0 0.026 -0.007 0"/>
                          </body>
                          <geom name="col_r_f_link5_3" type="capsule" contype="1" conaffinity="1" group="3" size="0.007" fromto="0.012 0.003 -0.0035 0.012 0.003 0.0035"/>
                        </body>
                        <geom name="col_r_f_link5_2" type="capsule" contype="1" conaffinity="1" group="3" size="0.0095" fromto="0.005 0 0 0.03 0 0"/>
                      </body>
                    </body>
                    <geom name="col_right_hand_base" type="box" contype="1" conaffinity="1" group="3" size="0.0273 0.05 0.05" pos="-0.0022 0 0.11"/>
                  </body>
                </body>
              </body>
            </body>
          </body>
        </body>
      </body>
    </body>
  </body>
</mujocoinclude>
