<?xml version="1.0" encoding="utf-8"?>
<mujoco model="dexhand021_left">
  <visual>
    <global offwidth="1920" offheight="1080"/>
  </visual>
  <option gravity="0 0 -9.81" iterations="100" solver="Newton" integrator="implicit" timestep="0.001"/>
  <default>
    <joint damping="1"/>
    <geom condim="3" solref="0.02 1" solimp="0.9 0.95 0.001" friction="2 2 2"/>
  </default>
  <size njmax="1000" nconmax="1000"/>
  <compiler angle="radian" meshdir="../meshes/dexhand021/"/>
  <asset>
    <mesh name="l_p_link0" file="l_p_link0.STL"/>
    <mesh name="l_f_link1_1" file="l_f_link1_1.STL"/>
    <mesh name="l_f_link1_2" file="l_f_link1_2.STL"/>
    <mesh name="l_f_link1_3" file="l_f_link1_3.STL"/>
    <mesh name="l_f_link1_4" file="l_f_link1_4.STL"/>
    <mesh name="l_f_link1_4_1" file="l_f_link1_4_1.STL"/>
    <mesh name="l_f_link1_4_2" file="l_f_link1_4_2.STL"/>
    <mesh name="l_f_link1_3_1" file="l_f_link1_3_1.STL"/>
    <mesh name="l_f_link1_3_2" file="l_f_link1_3_2.STL"/>
    <mesh name="l_f_link1_2_1" file="l_f_link1_2_1.STL"/>
    <mesh name="l_f_link1_2_2" file="l_f_link1_2_2.STL"/>
    <mesh name="l_f_link2_1" file="l_f_link2_1.STL"/>
    <mesh name="l_f_link2_2" file="l_f_link2_2.STL"/>
    <mesh name="l_f_link2_3" file="l_f_link2_3.STL"/>
    <mesh name="l_f_link2_4" file="l_f_link2_4.STL"/>
    <mesh name="l_f_link2_4_1" file="l_f_link2_4_1.STL"/>
    <mesh name="l_f_link2_4_2" file="l_f_link2_4_2.STL"/>
    <mesh name="l_f_link2_3_1" file="l_f_link2_3_1.STL"/>
    <mesh name="l_f_link2_3_2" file="l_f_link2_3_2.STL"/>
    <mesh name="l_f_link2_2_1" file="l_f_link2_2_1.STL"/>
    <mesh name="l_f_link2_2_2" file="l_f_link2_2_2.STL"/>
    <mesh name="l_f_link3_1" file="l_f_link3_1.STL"/>
    <mesh name="l_f_link3_2" file="l_f_link3_2.STL"/>
    <mesh name="l_f_link3_3" file="l_f_link3_3.STL"/>
    <mesh name="l_f_link3_4" file="l_f_link3_4.STL"/>
    <mesh name="l_f_link3_4_1" file="l_f_link3_4_1.STL"/>
    <mesh name="l_f_link3_4_2" file="l_f_link3_4_2.STL"/>
    <mesh name="l_f_link3_3_1" file="l_f_link3_3_1.STL"/>
    <mesh name="l_f_link3_3_2" file="l_f_link3_3_2.STL"/>
    <mesh name="l_f_link3_2_1" file="l_f_link3_2_1.STL"/>
    <mesh name="l_f_link3_2_2" file="l_f_link3_2_2.STL"/>
    <mesh name="l_f_link4_1" file="l_f_link4_1.STL"/>
    <mesh name="l_f_link4_2" file="l_f_link4_2.STL"/>
    <mesh name="l_f_link4_3" file="l_f_link4_3.STL"/>
    <mesh name="l_f_link4_4" file="l_f_link4_4.STL"/>
    <mesh name="l_f_link4_4_1" file="l_f_link4_4_1.STL"/>
    <mesh name="l_f_link4_4_2" file="l_f_link4_4_2.STL"/>
    <mesh name="l_f_link4_3_1" file="l_f_link4_3_1.STL"/>
    <mesh name="l_f_link4_3_2" file="l_f_link4_3_2.STL"/>
    <mesh name="l_f_link4_2_1" file="l_f_link4_2_1.STL"/>
    <mesh name="l_f_link4_2_2" file="l_f_link4_2_2.STL"/>
    <mesh name="l_f_link5_1" file="l_f_link5_1.STL"/>
    <mesh name="l_f_link5_2" file="l_f_link5_2.STL"/>
    <mesh name="l_f_link5_3" file="l_f_link5_3.STL"/>
    <mesh name="l_f_link5_4" file="l_f_link5_4.STL"/>
    <mesh name="l_f_link5_4_1" file="l_f_link5_4_1.STL"/>
    <mesh name="l_f_link5_4_2" file="l_f_link5_4_2.STL"/>
    <mesh name="l_f_link5_3_1" file="l_f_link5_3_1.STL"/>
    <mesh name="l_f_link5_3_2" file="l_f_link5_3_2.STL"/>
    <mesh name="l_f_link5_2_1" file="l_f_link5_2_1.STL"/>
    <mesh name="l_f_link5_2_2" file="l_f_link5_2_2.STL"/>
    <mesh name="l_p_link1" file="l_p_link1.STL"/>
    <mesh name="l_p_link2" file="l_p_link2.STL"/>
    <mesh name="l_p_link3" file="l_p_link3.STL"/>
    <mesh name="l_p_link4" file="l_p_link4.STL"/>
    <mesh name="l_p_link5" file="l_p_link5.STL"/>
    <mesh name="l_p_link6" file="l_p_link6.STL"/>
  </asset>
  <worldbody>
    <body name="left_hand_base" pos="0 0 0" quat="1 0 0 0">
      <geom pos="0 0 -0.17" quat="0.707388 0 0 0.706825" type="mesh" contype="0" conaffinity="0" group="1" density="0" rgba="0.3 0.3 0.3 1" mesh="l_p_link0"/>
      <geom pos="0 0 -0.17" quat="0.707388 0 0 0.706825" type="mesh" rgba="0.3 0.3 0.3 1" mesh="l_p_link0"/>
      <geom pos="0.031185 -0.0238798 0.10607" quat="0.788446 -0.0464709 -0.0600256 -0.610402" type="mesh" contype="0" conaffinity="0" group="1" density="0" rgba="0.3 0.3 0.3 1" mesh="l_p_link1"/>
      <geom pos="0.031185 -0.0238798 0.10607" quat="0.788446 -0.0464709 -0.0600256 -0.610402" type="mesh" rgba="0.3 0.3 0.3 1" mesh="l_p_link1"/>
      <geom pos="0.031185 -0.0238798 0.10607" quat="0.788446 -0.0464709 -0.0600256 -0.610402" type="mesh" contype="0" conaffinity="0" group="1" density="0" rgba="0.9 0.9 0.9 1" mesh="l_p_link2"/>
      <geom pos="0.031185 -0.0238798 0.10607" quat="0.788446 -0.0464709 -0.0600256 -0.610402" type="mesh" rgba="0.9 0.9 0.9 1" mesh="l_p_link2"/>
      <geom pos="0.031185 -0.0238798 0.10607" quat="0.788446 -0.0464709 -0.0600256 -0.610402" type="mesh" contype="0" conaffinity="0" group="1" density="0" rgba="0.3 0.3 0.3 1" mesh="l_p_link3"/>
      <geom pos="0.031185 -0.0238798 0.10607" quat="0.788446 -0.0464709 -0.0600256 -0.610402" type="mesh" rgba="0.3 0.3 0.3 1" mesh="l_p_link3"/>
      <geom pos="0.031185 -0.0238798 0.10607" quat="0.788446 -0.0464709 -0.0600256 -0.610402" type="mesh" contype="0" conaffinity="0" group="1" density="0" rgba="0.9 0.9 0.9 1" mesh="l_p_link4"/>
      <geom pos="0.031185 -0.0238798 0.10607" quat="0.788446 -0.0464709 -0.0600256 -0.610402" type="mesh" rgba="0.9 0.9 0.9 1" mesh="l_p_link4"/>
      <geom pos="0.031185 -0.0238798 0.10607" quat="0.788446 -0.0464709 -0.0600256 -0.610402" type="mesh" contype="0" conaffinity="0" group="1" density="0" rgba="0.3 0.3 0.3 1" mesh="l_p_link5"/>
      <geom pos="0.031185 -0.0238798 0.10607" quat="0.788446 -0.0464709 -0.0600256 -0.610402" type="mesh" rgba="0.3 0.3 0.3 1" mesh="l_p_link5"/>
      <geom pos="0.031185 -0.0238798 0.10607" quat="0.788446 -0.0464709 -0.0600256 -0.610402" type="mesh" contype="0" conaffinity="0" group="1" density="0" rgba="0.9 0.9 0.9 1" mesh="l_p_link6"/>
      <geom pos="0.031185 -0.0238798 0.10607" quat="0.788446 -0.0464709 -0.0600256 -0.610402" type="mesh" rgba="0.9 0.9 0.9 1" mesh="l_p_link6"/>
      <body name="l_f_link1_1" pos="0.031185 -0.0238798 0.10607" quat="0.788446 -0.0464709 -0.0600256 -0.610402">
        <inertial pos="0.0020614 -0.005282 -0.0178" quat="0.722396 -0.0166514 0.136866 0.677594" mass="0.0055493" diaginertia="3.99841e-07 3.48612e-07 2.47836e-07"/>
        <joint name="l_a_joint1_1" pos="0 0 0" axis="0 0.26521 0.964191" range="0 2.2" actuatorfrcrange="-10 10"/>
        <geom type="mesh" contype="0" conaffinity="0" group="1" density="0" rgba="0.3 0.3 0.3 1" mesh="l_f_link1_1"/>
        <geom type="mesh" rgba="0.3 0.3 0.3 1" mesh="l_f_link1_1"/>
        <body name="l_f_link1_2" pos="0.0083307 0 0" quat="0.795298 0.606144 -0.00578778 0.00759551">
          <inertial pos="0.0216674 -0.000280411 -0.000960861" quat="-0.0486627 0.707009 -0.0150464 0.705368" mass="0.0144433" diaginertia="1.94807e-06 1.89327e-06 6.94194e-07"/>
          <joint name="l_f_joint1_2" pos="0 0 0" axis="0 0 1" range="0 1.3" actuatorfrcrange="-10 10"/>
          <geom type="mesh" contype="0" conaffinity="0" group="1" density="0" rgba="0.3 0.3 0.3 1" mesh="l_f_link1_2"/>
          <geom type="mesh" rgba="0.3 0.3 0.3 1" mesh="l_f_link1_2"/>
          <geom quat="0.000796327 1 0 0" type="mesh" contype="0" conaffinity="0" group="1" density="0" rgba="0.3 0.3 0.3 1" mesh="l_f_link1_2_1"/>
          <geom quat="0.000796327 1 0 0" type="mesh" rgba="0.3 0.3 0.3 1" mesh="l_f_link1_2_1"/>
          <geom quat="0.000796327 1 0 0" type="mesh" contype="0" conaffinity="0" group="1" density="0" rgba="0.9 0.9 0.9 1" mesh="l_f_link1_2_2"/>
          <geom quat="0.000796327 1 0 0" type="mesh" rgba="0.9 0.9 0.9 1" mesh="l_f_link1_2_2"/>
          <body name="l_f_link1_3" pos="0.043 0 0">
            <inertial pos="0.0130871 0.000679282 -0.00129588" quat="-0.026909 0.709347 0.0231898 0.703964" mass="0.00527423" diaginertia="4.60778e-07 4.30817e-07 2.36595e-07"/>
            <joint name="l_f_joint1_3" pos="0 0 0" axis="0 0 1" range="0 1.3" actuatorfrcrange="-10 10"/>
            <geom quat="0.000796327 1 0 0" type="mesh" contype="0" conaffinity="0" group="1" density="0" rgba="0.3 0.3 0.3 1" mesh="l_f_link1_3"/>
            <geom quat="0.000796327 1 0 0" type="mesh" rgba="0.3 0.3 0.3 1" mesh="l_f_link1_3"/>
            <geom quat="0.000796327 1 0 0" type="mesh" contype="0" conaffinity="0" group="1" density="0" rgba="0.3 0.3 0.3 1" mesh="l_f_link1_3_1"/>
            <geom quat="0.000796327 1 0 0" type="mesh" rgba="0.3 0.3 0.3 1" mesh="l_f_link1_3_1"/>
            <geom quat="0.000796327 1 0 0" type="mesh" contype="0" conaffinity="0" group="1" density="0" rgba="0.9 0.9 0.9 1" mesh="l_f_link1_3_2"/>
            <geom quat="0.000796327 1 0 0" type="mesh" rgba="0.9 0.9 0.9 1" mesh="l_f_link1_3_2"/>
            <body name="l_f_link1_4" pos="0.025 0 0">
              <inertial pos="0.0133604 -0.00223169 -0.000768065" quat="0.325351 0.353708 0.578063 0.659455" mass="0.0120157" diaginertia="1.03764e-06 9.10431e-07 3.90012e-07"/>
              <joint name="l_f_joint1_4" pos="0 0 0" axis="0 0 1" range="0 1.3" actuatorfrcrange="-10 10"/>
              <geom quat="0.000796327 1 0 0" type="mesh" contype="0" conaffinity="0" group="1" density="0" rgba="0.3 0.3 0.3 1" mesh="l_f_link1_4"/>
              <geom quat="0.000796327 1 0 0" type="mesh" rgba="0.3 0.3 0.3 1" mesh="l_f_link1_4"/>
              <geom quat="0.000796327 1 0 0" type="mesh" contype="0" conaffinity="0" group="1" density="0" rgba="0.3 0.3 0.3 1" mesh="l_f_link1_4_1"/>
              <geom quat="0.000796327 1 0 0" type="mesh" rgba="0.3 0.3 0.3 1" mesh="l_f_link1_4_1"/>
              <geom quat="0.000796327 1 0 0" type="mesh" contype="0" conaffinity="0" group="1" density="0" rgba="0.9 0.9 0.9 1" mesh="l_f_link1_4_2"/>
              <geom quat="0.000796327 1 0 0" type="mesh" rgba="0.9 0.9 0.9 1" mesh="l_f_link1_4_2"/>
              <geom size="0.002" pos="0.035 -0.004 0" contype="0" conaffinity="0" group="1" density="0" rgba="1 0 0 1"/>
              <geom size="0.002" pos="0.02 0 0" rgba="1 0 0 1"/>
              <site name="site_l_f_link1_4" pos="0.025 0.003 0" size="0.01" type="sphere"/>
            </body>
          </body>
        </body>
      </body>
      <body name="l_f_link2_1" pos="0.0054382 -0.0349163 0.1587" quat="0.000281544 0.707107 -0.000278947 0.707107">
        <inertial pos="0.0080017 1.8832e-05 -0.0015869" quat="0.366604 0.60097 0.60931 0.364936" mass="0.003769" diaginertia="3.9885e-07 3.46938e-07 2.19942e-07"/>
        <joint name="l_f_joint2_1" pos="0 0 0" axis="0 0 1" range="0 0.6" actuatorfrcrange="-10 10"/>
        <geom type="mesh" contype="0" conaffinity="0" group="1" density="0" rgba="0.3 0.3 0.3 1" mesh="l_f_link2_1"/>
        <geom type="mesh" rgba="0.3 0.3 0.3 1" mesh="l_f_link2_1"/>
        <body name="l_f_link2_2" pos="0.017 0 0" quat="0.707105 0.707108 0 0">
          <inertial pos="0.0214621 -0.000317209 -0.000279086" quat="0.515427 0.495684 0.504138 0.484229" mass="0.0092144" diaginertia="1.92287e-06 1.88786e-06 6.04776e-07"/>
          <joint name="l_f_joint2_2" pos="0 0 0" axis="0 0 1" range="0 1.3" actuatorfrcrange="-10 10"/>
          <geom type="mesh" contype="0" conaffinity="0" group="1" density="0" rgba="0.3 0.3 0.3 1" mesh="l_f_link2_2"/>
          <geom type="mesh" rgba="0.3 0.3 0.3 1" mesh="l_f_link2_2"/>
          <geom type="mesh" contype="0" conaffinity="0" group="1" density="0" rgba="0.3 0.3 0.3 1" mesh="l_f_link2_2_1"/>
          <geom type="mesh" rgba="0.3 0.3 0.3 1" mesh="l_f_link2_2_1"/>
          <geom type="mesh" contype="0" conaffinity="0" group="1" density="0" rgba="0.9 0.9 0.9 1" mesh="l_f_link2_2_2"/>
          <geom type="mesh" rgba="0.9 0.9 0.9 1" mesh="l_f_link2_2_2"/>
          <body name="l_f_link2_3" pos="0.043 0 0">
            <inertial pos="0.0131191 -0.000594087 -1.28443e-05" quat="0.0241845 0.703776 -0.0291852 0.70941" mass="0.00507867" diaginertia="4.55549e-07 4.23953e-07 2.29611e-07"/>
            <joint name="l_f_joint2_3" pos="0 0 0" axis="0 0 1" range="0 1.3" actuatorfrcrange="-10 10"/>
            <geom type="mesh" contype="0" conaffinity="0" group="1" density="0" rgba="0.3 0.3 0.3 1" mesh="l_f_link2_3"/>
            <geom type="mesh" rgba="0.3 0.3 0.3 1" mesh="l_f_link2_3"/>
            <geom type="mesh" contype="0" conaffinity="0" group="1" density="0" rgba="0.3 0.3 0.3 1" mesh="l_f_link2_3_1"/>
            <geom type="mesh" rgba="0.3 0.3 0.3 1" mesh="l_f_link2_3_1"/>
            <geom type="mesh" contype="0" conaffinity="0" group="1" density="0" rgba="0.9 0.9 0.9 1" mesh="l_f_link2_3_2"/>
            <geom type="mesh" rgba="0.9 0.9 0.9 1" mesh="l_f_link2_3_2"/>
            <body name="l_f_link2_4" pos="0.025 0 0">
              <inertial pos="0.0164099 -0.00106284 0.000767994" quat="0.628501 0.551042 0.417671 0.356217" mass="0.00649596" diaginertia="6.08006e-07 5.16473e-07 1.91531e-07"/>
              <joint name="l_f_joint2_4" pos="0 0 0" axis="0 0 1" range="0 1.3" actuatorfrcrange="-10 10"/>
              <geom type="mesh" contype="0" conaffinity="0" group="1" density="0" rgba="0.3 0.3 0.3 1" mesh="l_f_link2_4"/>
              <geom type="mesh" rgba="0.3 0.3 0.3 1" mesh="l_f_link2_4"/>
              <geom type="mesh" contype="0" conaffinity="0" group="1" density="0" rgba="0.3 0.3 0.3 1" mesh="l_f_link2_4_1"/>
              <geom type="mesh" rgba="0.3 0.3 0.3 1" mesh="l_f_link2_4_1"/>
              <geom type="mesh" contype="0" conaffinity="0" group="1" density="0" rgba="0.9 0.9 0.9 1" mesh="l_f_link2_4_2"/>
              <geom type="mesh" rgba="0.9 0.9 0.9 1" mesh="l_f_link2_4_2"/>
              <geom size="0.002" pos="0.035 -0.004 0" contype="0" conaffinity="0" group="1" density="0" rgba="1 0 0 1"/>
              <geom size="0.002" pos="0.02 0 0" rgba="1 0 0 1"/>
              <site name="site_l_f_link2_4" pos="0.025 0.003 0" size="0.01" type="sphere"/>
            </body>
          </body>
        </body>
      </body>
      <body name="l_f_link3_1" pos="0.00545755 -0.0106163 0.1677" quat="0.000561789 0.707107 1.29867e-06 0.707107">
        <inertial pos="0.0080017 2.4921e-05 -0.0015869" quat="0.366466 0.600737 0.609537 0.365078" mass="0.003769" diaginertia="3.98851e-07 3.46938e-07 2.19941e-07"/>
        <joint name="l_f_joint3_1" pos="0 0 0" axis="0 0 1" range="-0.001 0.001" actuatorfrcrange="-10 10"/>
        <geom type="mesh" contype="0" conaffinity="0" group="1" density="0" rgba="0.3 0.3 0.3 1" mesh="l_f_link3_1"/>
        <geom type="mesh" rgba="0.3 0.3 0.3 1" mesh="l_f_link3_1"/>
        <body name="l_f_link3_2" pos="0.017 1.2935e-05 0" quat="0.707105 0.707108 0.000269005 0.000269004">
          <inertial pos="0.0214621 -0.000317178 -0.000279086" quat="0.515426 0.495684 0.504138 0.484229" mass="0.0092144" diaginertia="1.92287e-06 1.88786e-06 6.04775e-07"/>
          <joint name="l_f_joint3_2" pos="0 0 0" axis="0 0 1" range="0 1.3" actuatorfrcrange="-10 10"/>
          <geom type="mesh" contype="0" conaffinity="0" group="1" density="0" rgba="0.3 0.3 0.3 1" mesh="l_f_link3_2"/>
          <geom type="mesh" rgba="0.3 0.3 0.3 1" mesh="l_f_link3_2"/>
          <geom type="mesh" contype="0" conaffinity="0" group="1" density="0" rgba="0.3 0.3 0.3 1" mesh="l_f_link3_2_1"/>
          <geom type="mesh" rgba="0.3 0.3 0.3 1" mesh="l_f_link3_2_1"/>
          <geom type="mesh" contype="0" conaffinity="0" group="1" density="0" rgba="0.9 0.9 0.9 1" mesh="l_f_link3_2_2"/>
          <geom type="mesh" rgba="0.9 0.9 0.9 1" mesh="l_f_link3_2_2"/>
          <body name="l_f_link3_3" pos="0.043 0 0">
            <inertial pos="0.00674026 0.000173553 -1.18339e-05" quat="0.56124 0.54358 0.451727 0.430667" mass="0.00554396" diaginertia="1.59272e-06 1.58143e-06 2.11525e-07"/>
            <joint name="l_f_joint3_3" pos="0 0 0" axis="0 0 1" range="0 1.3" actuatorfrcrange="-10 10"/>
            <geom type="mesh" contype="0" conaffinity="0" group="1" density="0" rgba="0.3 0.3 0.3 1" mesh="l_f_link3_3"/>
            <geom type="mesh" rgba="0.3 0.3 0.3 1" mesh="l_f_link3_3"/>
            <geom type="mesh" contype="0" conaffinity="0" group="1" density="0" rgba="0.3 0.3 0.3 1" mesh="l_f_link3_3_1"/>
            <geom type="mesh" rgba="0.3 0.3 0.3 1" mesh="l_f_link3_3_1"/>
            <geom type="mesh" contype="0" conaffinity="0" group="1" density="0" rgba="0.9 0.9 0.9 1" mesh="l_f_link3_3_2"/>
            <geom type="mesh" rgba="0.9 0.9 0.9 1" mesh="l_f_link3_3_2"/>
            <body name="l_f_link3_4" pos="0.025 0 0">
              <inertial pos="0.0164099 -0.00106284 0.000767994" quat="0.628501 0.551042 0.417671 0.356217" mass="0.00649596" diaginertia="6.08006e-07 5.16473e-07 1.91531e-07"/>
              <joint name="l_f_joint3_4" pos="0 0 0" axis="0 0 1" range="0 1.3" actuatorfrcrange="-10 10"/>
              <geom type="mesh" contype="0" conaffinity="0" group="1" density="0" rgba="0.3 0.3 0.3 1" mesh="l_f_link3_4"/>
              <geom type="mesh" rgba="0.3 0.3 0.3 1" mesh="l_f_link3_4"/>
              <geom type="mesh" contype="0" conaffinity="0" group="1" density="0" rgba="0.3 0.3 0.3 1" mesh="l_f_link3_4_1"/>
              <geom type="mesh" rgba="0.3 0.3 0.3 1" mesh="l_f_link3_4_1"/>
              <geom type="mesh" contype="0" conaffinity="0" group="1" density="0" rgba="0.9 0.9 0.9 1" mesh="l_f_link3_4_2"/>
              <geom type="mesh" rgba="0.9 0.9 0.9 1" mesh="l_f_link3_4_2"/>
              <geom size="0.002" pos="0.035 -0.004 0" contype="0" conaffinity="0" group="1" density="0" rgba="1 0 0 1"/>
              <geom size="0.002" pos="0.02 0 0" rgba="1 0 0 1"/>
              <site name="site_l_f_link3_4" pos="0.025 0.003 0" size="0.01" type="sphere"/>
            </body>
          </body>
        </body>
      </body>
      <body name="l_f_link4_1" pos="0.0054769 0.0136836 0.1587" quat="0.000561789 0.707107 1.29867e-06 0.707107">
        <inertial pos="0.0080017 2.4921e-05 -0.0015869" quat="0.366466 0.600737 0.609537 0.365078" mass="0.003769" diaginertia="3.98851e-07 3.46938e-07 2.19941e-07"/>
        <joint name="l_f_joint4_1" pos="0 0 0" axis="0 0 -1" range="0 0.6" actuatorfrcrange="-10 10"/>
        <geom type="mesh" contype="0" conaffinity="0" group="1" density="0" rgba="0.3 0.3 0.3 1" mesh="l_f_link4_1"/>
        <geom type="mesh" rgba="0.3 0.3 0.3 1" mesh="l_f_link4_1"/>
        <body name="l_f_link4_2" pos="0.017 1.2935e-05 0" quat="0.707105 0.707108 0.000269005 0.000269004">
          <inertial pos="0.0214621 -0.000317209 -0.000279088" quat="0.515426 0.495685 0.504137 0.48423" mass="0.0092144" diaginertia="1.92287e-06 1.88786e-06 6.04776e-07"/>
          <joint name="l_f_joint4_2" pos="0 0 0" axis="0 0 1" range="0 1.3" actuatorfrcrange="-10 10"/>
          <geom type="mesh" contype="0" conaffinity="0" group="1" density="0" rgba="0.3 0.3 0.3 1" mesh="l_f_link4_2"/>
          <geom type="mesh" rgba="0.3 0.3 0.3 1" mesh="l_f_link4_2"/>
          <geom type="mesh" contype="0" conaffinity="0" group="1" density="0" rgba="0.3 0.3 0.3 1" mesh="l_f_link4_2_1"/>
          <geom type="mesh" rgba="0.3 0.3 0.3 1" mesh="l_f_link4_2_1"/>
          <geom type="mesh" contype="0" conaffinity="0" group="1" density="0" rgba="0.9 0.9 0.9 1" mesh="l_f_link4_2_2"/>
          <geom type="mesh" rgba="0.9 0.9 0.9 1" mesh="l_f_link4_2_2"/>
          <body name="l_f_link4_3" pos="0.043 0 0">
            <inertial pos="0.0131191 -0.000594087 -1.28443e-05" quat="0.0241845 0.703776 -0.0291852 0.70941" mass="0.00507867" diaginertia="4.55549e-07 4.23953e-07 2.29611e-07"/>
            <joint name="l_f_joint4_3" pos="0 0 0" axis="0 0 1" range="0 1.3" actuatorfrcrange="-10 10"/>
            <geom type="mesh" contype="0" conaffinity="0" group="1" density="0" rgba="0.3 0.3 0.3 1" mesh="l_f_link4_3"/>
            <geom type="mesh" rgba="0.3 0.3 0.3 1" mesh="l_f_link4_3"/>
            <geom type="mesh" contype="0" conaffinity="0" group="1" density="0" rgba="0.3 0.3 0.3 1" mesh="l_f_link4_3_1"/>
            <geom type="mesh" rgba="0.3 0.3 0.3 1" mesh="l_f_link4_3_1"/>
            <geom type="mesh" contype="0" conaffinity="0" group="1" density="0" rgba="0.9 0.9 0.9 1" mesh="l_f_link4_3_2"/>
            <geom type="mesh" rgba="0.9 0.9 0.9 1" mesh="l_f_link4_3_2"/>
            <body name="l_f_link4_4" pos="0.025 0 0">
              <inertial pos="0.0164099 -0.00106284 0.000767994" quat="0.628501 0.551042 0.417671 0.356217" mass="0.00649596" diaginertia="6.08006e-07 5.16473e-07 1.91531e-07"/>
              <joint name="l_f_joint4_4" pos="0 0 0" axis="0 0 1" range="0 1.3" actuatorfrcrange="-10 10"/>
              <geom type="mesh" contype="0" conaffinity="0" group="1" density="0" rgba="0.3 0.3 0.3 1" mesh="l_f_link4_4"/>
              <geom type="mesh" rgba="0.3 0.3 0.3 1" mesh="l_f_link4_4"/>
              <geom type="mesh" contype="0" conaffinity="0" group="1" density="0" rgba="0.3 0.3 0.3 1" mesh="l_f_link4_4_1"/>
              <geom type="mesh" rgba="0.3 0.3 0.3 1" mesh="l_f_link4_4_1"/>
              <geom type="mesh" contype="0" conaffinity="0" group="1" density="0" rgba="0.9 0.9 0.9 1" mesh="l_f_link4_4_2"/>
              <geom type="mesh" rgba="0.9 0.9 0.9 1" mesh="l_f_link4_4_2"/>
              <geom size="0.002" pos="0.035 -0.004 0" contype="0" conaffinity="0" group="1" density="0" rgba="1 0 0 1"/>
              <geom size="0.002" pos="0.02 0 0" rgba="1 0 0 1"/>
              <site name="site_l_f_link4_4" pos="0.025 0.003 0" size="0.01" type="sphere"/>
            </body>
          </body>
        </body>
      </body>
      <body name="l_f_link5_1" pos="0.00549625 0.0379836 0.1447" quat="0.000561789 0.707107 1.29867e-06 0.707107">
        <inertial pos="0.0080017 2.4921e-05 -0.0015869" quat="0.366466 0.600737 0.609537 0.365078" mass="0.003769" diaginertia="3.98851e-07 3.46938e-07 2.19941e-07"/>
        <joint name="l_f_joint5_1" pos="0 0 0" axis="0 0 -1" range="0 0.6" actuatorfrcrange="-10 10"/>
        <geom type="mesh" contype="0" conaffinity="0" group="1" density="0" rgba="0.3 0.3 0.3 1" mesh="l_f_link5_1"/>
        <geom type="mesh" rgba="0.3 0.3 0.3 1" mesh="l_f_link5_1"/>
        <body name="l_f_link5_2" pos="0.017 1.2935e-05 0" quat="0.707105 0.707108 0.000269005 0.000269004">
          <inertial pos="0.0214621 -0.000317209 -0.000279086" quat="0.515427 0.495684 0.504138 0.484229" mass="0.0092144" diaginertia="1.92287e-06 1.88786e-06 6.04776e-07"/>
          <joint name="l_f_joint5_2" pos="0 0 0" axis="0 0 1" range="0 1.3" actuatorfrcrange="-10 10"/>
          <geom type="mesh" contype="0" conaffinity="0" group="1" density="0" rgba="0.3 0.3 0.3 1" mesh="l_f_link5_2"/>
          <geom type="mesh" rgba="0.3 0.3 0.3 1" mesh="l_f_link5_2"/>
          <geom type="mesh" contype="0" conaffinity="0" group="1" density="0" rgba="0.3 0.3 0.3 1" mesh="l_f_link5_2_1"/>
          <geom type="mesh" rgba="0.3 0.3 0.3 1" mesh="l_f_link5_2_1"/>
          <geom type="mesh" contype="0" conaffinity="0" group="1" density="0" rgba="0.9 0.9 0.9 1" mesh="l_f_link5_2_2"/>
          <geom type="mesh" rgba="0.9 0.9 0.9 1" mesh="l_f_link5_2_2"/>
          <body name="l_f_link5_3" pos="0.043 0 0">
            <inertial pos="0.0131191 -0.000594087 -1.28443e-05" quat="0.0241845 0.703776 -0.0291852 0.70941" mass="0.00507867" diaginertia="4.55549e-07 4.23953e-07 2.29611e-07"/>
            <joint name="l_f_joint5_3" pos="0 0 0" axis="0 0 1" range="0 1.3" actuatorfrcrange="-10 10"/>
            <geom type="mesh" contype="0" conaffinity="0" group="1" density="0" rgba="0.3 0.3 0.3 1" mesh="l_f_link5_3"/>
            <geom type="mesh" rgba="0.3 0.3 0.3 1" mesh="l_f_link5_3"/>
            <geom type="mesh" contype="0" conaffinity="0" group="1" density="0" rgba="0.3 0.3 0.3 1" mesh="l_f_link5_3_1"/>
            <geom type="mesh" rgba="0.3 0.3 0.3 1" mesh="l_f_link5_3_1"/>
            <geom type="mesh" contype="0" conaffinity="0" group="1" density="0" rgba="0.9 0.9 0.9 1" mesh="l_f_link5_3_2"/>
            <geom type="mesh" rgba="0.9 0.9 0.9 1" mesh="l_f_link5_3_2"/>
            <body name="l_f_link5_4" pos="0.025 0 0">
              <inertial pos="0.0164099 -0.00106284 0.000767994" quat="0.628501 0.551042 0.417671 0.356217" mass="0.00649596" diaginertia="6.08006e-07 5.16473e-07 1.91531e-07"/>
              <joint name="l_f_joint5_4" pos="0 0 0" axis="0 0 1" range="0 1.3" actuatorfrcrange="-10 10"/>
              <geom type="mesh" contype="0" conaffinity="0" group="1" density="0" rgba="0.3 0.3 0.3 1" mesh="l_f_link5_4"/>
              <geom type="mesh" rgba="0.3 0.3 0.3 1" mesh="l_f_link5_4"/>
              <geom type="mesh" contype="0" conaffinity="0" group="1" density="0" rgba="0.3 0.3 0.3 1" mesh="l_f_link5_4_1"/>
              <geom type="mesh" rgba="0.3 0.3 0.3 1" mesh="l_f_link5_4_1"/>
              <geom type="mesh" contype="0" conaffinity="0" group="1" density="0" rgba="0.9 0.9 0.9 1" mesh="l_f_link5_4_2"/>
              <geom type="mesh" rgba="0.9 0.9 0.9 1" mesh="l_f_link5_4_2"/>
              <geom size="0.002" pos="0.035 -0.004 0" contype="0" conaffinity="0" group="1" density="0" rgba="1 0 0 1"/>
              <geom size="0.002" pos="0.02 0 0" rgba="1 0 0 1"/>
              <site name="site_l_f_link5_4" pos="0.025 0.003 0" size="0.01" type="sphere"/>
            </body>
          </body>
        </body>
      </body>
    </body>
  </worldbody>
  <actuator>
    <position name="act_l_f_joint1_2" joint="l_f_joint1_2" kp="20" kv="0.1" ctrlrange="0 1.3" forcerange="-20 20"/>
    <position name="act_l_f_joint1_3" joint="l_f_joint1_3" kp="20" kv="0.1" ctrlrange="0 1.3" forcerange="-20 20"/>
    <position name="act_l_f_joint1_4" joint="l_f_joint1_4" kp="20" kv="0.1" ctrlrange="0 1.3" forcerange="-20 20"/>
    <position name="act_l_f_joint2_2" joint="l_f_joint2_2" kp="20" kv="0.1" ctrlrange="0 1.3" forcerange="-20 20"/>
    <position name="act_l_f_joint2_3" joint="l_f_joint2_3" kp="20" kv="0.1" ctrlrange="0 1.3" forcerange="-20 20"/>
    <position name="act_l_f_joint2_4" joint="l_f_joint2_4" kp="20" kv="0.1" ctrlrange="0 1.3" forcerange="-20 20"/>
    <position name="act_l_f_joint3_2" joint="l_f_joint3_2" kp="20" kv="0.1" ctrlrange="0 1.3" forcerange="-20 20"/>
    <position name="act_l_f_joint3_3" joint="l_f_joint3_3" kp="20" kv="0.1" ctrlrange="0 1.3" forcerange="-20 20"/>
    <position name="act_l_f_joint3_4" joint="l_f_joint3_4" kp="20" kv="0.1" ctrlrange="0 1.3" forcerange="-20 20"/>
    <position name="act_l_f_joint4_2" joint="l_f_joint4_2" kp="20" kv="0.1" ctrlrange="0 1.3" forcerange="-20 20"/>
    <position name="act_l_f_joint4_3" joint="l_f_joint4_3" kp="20" kv="0.1" ctrlrange="0 1.3" forcerange="-20 20"/>
    <position name="act_l_f_joint4_4" joint="l_f_joint4_4" kp="20" kv="0.1" ctrlrange="0 1.3" forcerange="-20 20"/>
    <position name="act_l_f_joint5_2" joint="l_f_joint5_2" kp="20" kv="0.1" ctrlrange="0 1.3" forcerange="-20 20"/>
    <position name="act_l_f_joint5_3" joint="l_f_joint5_3" kp="20" kv="0.1" ctrlrange="0 1.3" forcerange="-20 20"/>
    <position name="act_l_f_joint5_4" joint="l_f_joint5_4" kp="20" kv="0.1" ctrlrange="0 1.3" forcerange="-20 20"/>
    <position name="act_l_f_joint2_1" joint="l_f_joint2_1" kp="20" kv="1" ctrlrange="0 0.3" forcerange="-20 20"/>
    <position name="act_l_f_joint3_1" joint="l_f_joint3_1" kp="20" kv="1" ctrlrange="-0.0001 0.0001" forcerange="-20 20"/>
    <position name="act_l_f_joint4_1" joint="l_f_joint4_1" kp="20" kv="1" ctrlrange="0 0.3" forcerange="-20 20"/>
    <position name="act_l_f_joint5_1" joint="l_f_joint5_1" kp="20" kv="1" ctrlrange="0 0.6" forcerange="-20 20"/>
  </actuator>
  <sensor>
    <touch name="touch_l_f_link1_4" site="site_l_f_link1_4"/>
    <touch name="touch_l_f_link2_4" site="site_l_f_link2_4"/>
    <touch name="touch_l_f_link3_4" site="site_l_f_link3_4"/>
    <touch name="touch_l_f_link4_4" site="site_l_f_link4_4"/>
    <touch name="touch_l_f_link5_4" site="site_l_f_link5_4"/>
  </sensor>
  <contact>
    <exclude body1="left_hand_base" body2="l_f_link1_1"/>
    <exclude body1="left_hand_base" body2="l_f_link1_2"/>
    <exclude body1="left_hand_base" body2="l_f_link1_3"/>
    <exclude body1="left_hand_base" body2="l_f_link1_4"/>
    <exclude body1="left_hand_base" body2="l_f_link2_1"/>
    <exclude body1="left_hand_base" body2="l_f_link2_2"/>
    <exclude body1="left_hand_base" body2="l_f_link2_3"/>
    <exclude body1="left_hand_base" body2="l_f_link2_4"/>
    <exclude body1="left_hand_base" body2="l_f_link3_1"/>
    <exclude body1="left_hand_base" body2="l_f_link3_2"/>
    <exclude body1="left_hand_base" body2="l_f_link3_3"/>
    <exclude body1="left_hand_base" body2="l_f_link3_4"/>
    <exclude body1="left_hand_base" body2="l_f_link4_1"/>
    <exclude body1="left_hand_base" body2="l_f_link4_2"/>
    <exclude body1="left_hand_base" body2="l_f_link4_3"/>
    <exclude body1="left_hand_base" body2="l_f_link4_4"/>
    <exclude body1="left_hand_base" body2="l_f_link5_1"/>
    <exclude body1="left_hand_base" body2="l_f_link5_2"/>
    <exclude body1="left_hand_base" body2="l_f_link5_3"/>
    <exclude body1="left_hand_base" body2="l_f_link5_4"/>
    <exclude body1="l_f_link1_1" body2="l_f_link1_2"/>
    <exclude body1="l_f_link1_1" body2="l_f_link1_3"/>
    <exclude body1="l_f_link1_1" body2="l_f_link1_4"/>
    <exclude body1="l_f_link1_1" body2="l_f_link2_1"/>
    <exclude body1="l_f_link1_1" body2="l_f_link2_2"/>
    <exclude body1="l_f_link1_1" body2="l_f_link2_3"/>
    <exclude body1="l_f_link1_1" body2="l_f_link2_4"/>
    <exclude body1="l_f_link1_1" body2="l_f_link3_1"/>
    <exclude body1="l_f_link1_1" body2="l_f_link3_2"/>
    <exclude body1="l_f_link1_1" body2="l_f_link3_3"/>
    <exclude body1="l_f_link1_1" body2="l_f_link3_4"/>
    <exclude body1="l_f_link1_1" body2="l_f_link4_1"/>
    <exclude body1="l_f_link1_1" body2="l_f_link4_2"/>
    <exclude body1="l_f_link1_1" body2="l_f_link4_3"/>
    <exclude body1="l_f_link1_1" body2="l_f_link4_4"/>
    <exclude body1="l_f_link1_1" body2="l_f_link5_1"/>
    <exclude body1="l_f_link1_1" body2="l_f_link5_2"/>
    <exclude body1="l_f_link1_1" body2="l_f_link5_3"/>
    <exclude body1="l_f_link1_1" body2="l_f_link5_4"/>
    <exclude body1="l_f_link1_2" body2="l_f_link1_3"/>
    <exclude body1="l_f_link1_2" body2="l_f_link1_4"/>
    <exclude body1="l_f_link1_2" body2="l_f_link2_1"/>
    <exclude body1="l_f_link1_2" body2="l_f_link2_2"/>
    <exclude body1="l_f_link1_2" body2="l_f_link2_3"/>
    <exclude body1="l_f_link1_2" body2="l_f_link2_4"/>
    <exclude body1="l_f_link1_2" body2="l_f_link3_1"/>
    <exclude body1="l_f_link1_2" body2="l_f_link3_2"/>
    <exclude body1="l_f_link1_2" body2="l_f_link3_3"/>
    <exclude body1="l_f_link1_2" body2="l_f_link3_4"/>
    <exclude body1="l_f_link1_2" body2="l_f_link4_1"/>
    <exclude body1="l_f_link1_2" body2="l_f_link4_2"/>
    <exclude body1="l_f_link1_2" body2="l_f_link4_3"/>
    <exclude body1="l_f_link1_2" body2="l_f_link4_4"/>
    <exclude body1="l_f_link1_2" body2="l_f_link5_1"/>
    <exclude body1="l_f_link1_2" body2="l_f_link5_2"/>
    <exclude body1="l_f_link1_2" body2="l_f_link5_3"/>
    <exclude body1="l_f_link1_2" body2="l_f_link5_4"/>
    <exclude body1="l_f_link1_3" body2="l_f_link1_4"/>
    <exclude body1="l_f_link1_3" body2="l_f_link2_1"/>
    <exclude body1="l_f_link1_3" body2="l_f_link2_2"/>
    <exclude body1="l_f_link1_3" body2="l_f_link2_3"/>
    <exclude body1="l_f_link1_3" body2="l_f_link2_4"/>
    <exclude body1="l_f_link1_3" body2="l_f_link3_1"/>
    <exclude body1="l_f_link1_3" body2="l_f_link3_2"/>
    <exclude body1="l_f_link1_3" body2="l_f_link3_3"/>
    <exclude body1="l_f_link1_3" body2="l_f_link3_4"/>
    <exclude body1="l_f_link1_3" body2="l_f_link4_1"/>
    <exclude body1="l_f_link1_3" body2="l_f_link4_2"/>
    <exclude body1="l_f_link1_3" body2="l_f_link4_3"/>
    <exclude body1="l_f_link1_3" body2="l_f_link4_4"/>
    <exclude body1="l_f_link1_3" body2="l_f_link5_1"/>
    <exclude body1="l_f_link1_3" body2="l_f_link5_2"/>
    <exclude body1="l_f_link1_3" body2="l_f_link5_3"/>
    <exclude body1="l_f_link1_3" body2="l_f_link5_4"/>
    <exclude body1="l_f_link1_4" body2="l_f_link2_1"/>
    <exclude body1="l_f_link1_4" body2="l_f_link2_2"/>
    <exclude body1="l_f_link1_4" body2="l_f_link2_3"/>
    <exclude body1="l_f_link1_4" body2="l_f_link3_1"/>
    <exclude body1="l_f_link1_4" body2="l_f_link3_2"/>
    <exclude body1="l_f_link1_4" body2="l_f_link3_3"/>
    <exclude body1="l_f_link1_4" body2="l_f_link4_1"/>
    <exclude body1="l_f_link1_4" body2="l_f_link4_2"/>
    <exclude body1="l_f_link1_4" body2="l_f_link4_3"/>
    <exclude body1="l_f_link1_4" body2="l_f_link5_1"/>
    <exclude body1="l_f_link1_4" body2="l_f_link5_2"/>
    <exclude body1="l_f_link1_4" body2="l_f_link5_3"/>
    <exclude body1="l_f_link2_1" body2="l_f_link2_2"/>
    <exclude body1="l_f_link2_1" body2="l_f_link2_3"/>
    <exclude body1="l_f_link2_1" body2="l_f_link2_4"/>
    <exclude body1="l_f_link2_1" body2="l_f_link3_1"/>
    <exclude body1="l_f_link2_1" body2="l_f_link3_2"/>
    <exclude body1="l_f_link2_1" body2="l_f_link3_3"/>
    <exclude body1="l_f_link2_1" body2="l_f_link3_4"/>
    <exclude body1="l_f_link2_1" body2="l_f_link4_1"/>
    <exclude body1="l_f_link2_1" body2="l_f_link4_2"/>
    <exclude body1="l_f_link2_1" body2="l_f_link4_3"/>
    <exclude body1="l_f_link2_1" body2="l_f_link4_4"/>
    <exclude body1="l_f_link2_1" body2="l_f_link5_1"/>
    <exclude body1="l_f_link2_1" body2="l_f_link5_2"/>
    <exclude body1="l_f_link2_1" body2="l_f_link5_3"/>
    <exclude body1="l_f_link2_1" body2="l_f_link5_4"/>
    <exclude body1="l_f_link2_2" body2="l_f_link2_3"/>
    <exclude body1="l_f_link2_2" body2="l_f_link2_4"/>
    <exclude body1="l_f_link2_2" body2="l_f_link3_1"/>
    <exclude body1="l_f_link2_2" body2="l_f_link3_2"/>
    <exclude body1="l_f_link2_2" body2="l_f_link3_3"/>
    <exclude body1="l_f_link2_2" body2="l_f_link3_4"/>
    <exclude body1="l_f_link2_2" body2="l_f_link4_1"/>
    <exclude body1="l_f_link2_2" body2="l_f_link4_2"/>
    <exclude body1="l_f_link2_2" body2="l_f_link4_3"/>
    <exclude body1="l_f_link2_2" body2="l_f_link4_4"/>
    <exclude body1="l_f_link2_2" body2="l_f_link5_1"/>
    <exclude body1="l_f_link2_2" body2="l_f_link5_2"/>
    <exclude body1="l_f_link2_2" body2="l_f_link5_3"/>
    <exclude body1="l_f_link2_2" body2="l_f_link5_4"/>
    <exclude body1="l_f_link2_3" body2="l_f_link2_4"/>
    <exclude body1="l_f_link2_3" body2="l_f_link3_1"/>
    <exclude body1="l_f_link2_3" body2="l_f_link3_2"/>
    <exclude body1="l_f_link2_3" body2="l_f_link3_3"/>
    <exclude body1="l_f_link2_3" body2="l_f_link3_4"/>
    <exclude body1="l_f_link2_3" body2="l_f_link4_1"/>
    <exclude body1="l_f_link2_3" body2="l_f_link4_2"/>
    <exclude body1="l_f_link2_3" body2="l_f_link4_3"/>
    <exclude body1="l_f_link2_3" body2="l_f_link4_4"/>
    <exclude body1="l_f_link2_3" body2="l_f_link5_1"/>
    <exclude body1="l_f_link2_3" body2="l_f_link5_2"/>
    <exclude body1="l_f_link2_3" body2="l_f_link5_3"/>
    <exclude body1="l_f_link2_3" body2="l_f_link5_4"/>
    <exclude body1="l_f_link2_4" body2="l_f_link3_1"/>
    <exclude body1="l_f_link2_4" body2="l_f_link3_2"/>
    <exclude body1="l_f_link2_4" body2="l_f_link3_3"/>
    <exclude body1="l_f_link2_4" body2="l_f_link4_1"/>
    <exclude body1="l_f_link2_4" body2="l_f_link4_2"/>
    <exclude body1="l_f_link2_4" body2="l_f_link4_3"/>
    <exclude body1="l_f_link2_4" body2="l_f_link5_1"/>
    <exclude body1="l_f_link2_4" body2="l_f_link5_2"/>
    <exclude body1="l_f_link2_4" body2="l_f_link5_3"/>
    <exclude body1="l_f_link3_1" body2="l_f_link3_2"/>
    <exclude body1="l_f_link3_1" body2="l_f_link3_3"/>
    <exclude body1="l_f_link3_1" body2="l_f_link3_4"/>
    <exclude body1="l_f_link3_1" body2="l_f_link4_1"/>
    <exclude body1="l_f_link3_1" body2="l_f_link4_2"/>
    <exclude body1="l_f_link3_1" body2="l_f_link4_3"/>
    <exclude body1="l_f_link3_1" body2="l_f_link4_4"/>
    <exclude body1="l_f_link3_1" body2="l_f_link5_1"/>
    <exclude body1="l_f_link3_1" body2="l_f_link5_2"/>
    <exclude body1="l_f_link3_1" body2="l_f_link5_3"/>
    <exclude body1="l_f_link3_1" body2="l_f_link5_4"/>
    <exclude body1="l_f_link3_2" body2="l_f_link3_3"/>
    <exclude body1="l_f_link3_2" body2="l_f_link3_4"/>
    <exclude body1="l_f_link3_2" body2="l_f_link4_1"/>
    <exclude body1="l_f_link3_2" body2="l_f_link4_2"/>
    <exclude body1="l_f_link3_2" body2="l_f_link4_3"/>
    <exclude body1="l_f_link3_2" body2="l_f_link4_4"/>
    <exclude body1="l_f_link3_2" body2="l_f_link5_1"/>
    <exclude body1="l_f_link3_2" body2="l_f_link5_2"/>
    <exclude body1="l_f_link3_2" body2="l_f_link5_3"/>
    <exclude body1="l_f_link3_2" body2="l_f_link5_4"/>
    <exclude body1="l_f_link3_3" body2="l_f_link3_4"/>
    <exclude body1="l_f_link3_3" body2="l_f_link4_1"/>
    <exclude body1="l_f_link3_3" body2="l_f_link4_2"/>
    <exclude body1="l_f_link3_3" body2="l_f_link4_3"/>
    <exclude body1="l_f_link3_3" body2="l_f_link4_4"/>
    <exclude body1="l_f_link3_3" body2="l_f_link5_1"/>
    <exclude body1="l_f_link3_3" body2="l_f_link5_2"/>
    <exclude body1="l_f_link3_3" body2="l_f_link5_3"/>
    <exclude body1="l_f_link3_3" body2="l_f_link5_4"/>
    <exclude body1="l_f_link3_4" body2="l_f_link4_1"/>
    <exclude body1="l_f_link3_4" body2="l_f_link4_2"/>
    <exclude body1="l_f_link3_4" body2="l_f_link4_3"/>
    <exclude body1="l_f_link3_4" body2="l_f_link5_1"/>
    <exclude body1="l_f_link3_4" body2="l_f_link5_2"/>
    <exclude body1="l_f_link3_4" body2="l_f_link5_3"/>
    <exclude body1="l_f_link4_1" body2="l_f_link4_2"/>
    <exclude body1="l_f_link4_1" body2="l_f_link4_3"/>
    <exclude body1="l_f_link4_1" body2="l_f_link4_4"/>
    <exclude body1="l_f_link4_1" body2="l_f_link5_1"/>
    <exclude body1="l_f_link4_1" body2="l_f_link5_2"/>
    <exclude body1="l_f_link4_1" body2="l_f_link5_3"/>
    <exclude body1="l_f_link4_1" body2="l_f_link5_4"/>
    <exclude body1="l_f_link4_2" body2="l_f_link4_3"/>
    <exclude body1="l_f_link4_2" body2="l_f_link4_4"/>
    <exclude body1="l_f_link4_2" body2="l_f_link5_1"/>
    <exclude body1="l_f_link4_2" body2="l_f_link5_2"/>
    <exclude body1="l_f_link4_2" body2="l_f_link5_3"/>
    <exclude body1="l_f_link4_2" body2="l_f_link5_4"/>
    <exclude body1="l_f_link4_3" body2="l_f_link4_4"/>
    <exclude body1="l_f_link4_3" body2="l_f_link5_1"/>
    <exclude body1="l_f_link4_3" body2="l_f_link5_2"/>
    <exclude body1="l_f_link4_3" body2="l_f_link5_3"/>
    <exclude body1="l_f_link4_3" body2="l_f_link5_4"/>
    <exclude body1="l_f_link4_4" body2="l_f_link5_1"/>
    <exclude body1="l_f_link4_4" body2="l_f_link5_2"/>
    <exclude body1="l_f_link4_4" body2="l_f_link5_3"/>
    <exclude body1="l_f_link5_1" body2="l_f_link5_2"/>
    <exclude body1="l_f_link5_1" body2="l_f_link5_3"/>
    <exclude body1="l_f_link5_1" body2="l_f_link5_4"/>
    <exclude body1="l_f_link5_2" body2="l_f_link5_3"/>
    <exclude body1="l_f_link5_2" body2="l_f_link5_4"/>
    <exclude body1="l_f_link5_3" body2="l_f_link5_4"/>
  </contact>
</mujoco>
