<?xml version="1.0" encoding="utf-8"?>
<mujoco model="dexhand021_left">
  <visual>
    <global offwidth="1920" offheight="1080"/>
  </visual>
  <option gravity="0 0 -9.81" iterations="100" solver="Newton" integrator="implicit" timestep="0.001"/>
  <default>
    <joint damping="1"/>
    <geom condim="3" solref="0.02 1" solimp="0.9 0.95 0.001" friction="2 2 2"/>
  </default>
  <size njmax="1000" nconmax="1000"/>
  <compiler angle="radian" meshdir="../meshes/dexhand021/"/>
  <asset>
    <mesh name="l_p_link0" file="l_p_link0.STL"/>
    <mesh name="l_f_link1_1" file="l_f_link1_1.STL"/>
    <mesh name="l_f_link1_2" file="l_f_link1_2.STL"/>
    <mesh name="l_f_link1_3" file="l_f_link1_3.STL"/>
    <mesh name="l_f_link1_4" file="l_f_link1_4.STL"/>
    <mesh name="l_f_link1_4_1" file="l_f_link1_4_1.STL"/>
    <mesh name="l_f_link1_4_2" file="l_f_link1_4_2.STL"/>
    <mesh name="l_f_link1_3_1" file="l_f_link1_3_1.STL"/>
    <mesh name="l_f_link1_3_2" file="l_f_link1_3_2.STL"/>
    <mesh name="l_f_link1_2_1" file="l_f_link1_2_1.STL"/>
    <mesh name="l_f_link1_2_2" file="l_f_link1_2_2.STL"/>
    <mesh name="l_f_link2_1" file="l_f_link2_1.STL"/>
    <mesh name="l_f_link2_2" file="l_f_link2_2.STL"/>
    <mesh name="l_f_link2_3" file="l_f_link2_3.STL"/>
    <mesh name="l_f_link2_4" file="l_f_link2_4.STL"/>
    <mesh name="l_f_link2_4_1" file="l_f_link2_4_1.STL"/>
    <mesh name="l_f_link2_4_2" file="l_f_link2_4_2.STL"/>
    <mesh name="l_f_link2_3_1" file="l_f_link2_3_1.STL"/>
    <mesh name="l_f_link2_3_2" file="l_f_link2_3_2.STL"/>
    <mesh name="l_f_link2_2_1" file="l_f_link2_2_1.STL"/>
    <mesh name="l_f_link2_2_2" file="l_f_link2_2_2.STL"/>
    <mesh name="l_f_link3_1" file="l_f_link3_1.STL"/>
    <mesh name="l_f_link3_2" file="l_f_link3_2.STL"/>
    <mesh name="l_f_link3_3" file="l_f_link3_3.STL"/>
    <mesh name="l_f_link3_4" file="l_f_link3_4.STL"/>
    <mesh name="l_f_link3_4_1" file="l_f_link3_4_1.STL"/>
    <mesh name="l_f_link3_4_2" file="l_f_link3_4_2.STL"/>
    <mesh name="l_f_link3_3_1" file="l_f_link3_3_1.STL"/>
    <mesh name="l_f_link3_3_2" file="l_f_link3_3_2.STL"/>
    <mesh name="l_f_link3_2_1" file="l_f_link3_2_1.STL"/>
    <mesh name="l_f_link3_2_2" file="l_f_link3_2_2.STL"/>
    <mesh name="l_f_link4_1" file="l_f_link4_1.STL"/>
    <mesh name="l_f_link4_2" file="l_f_link4_2.STL"/>
    <mesh name="l_f_link4_3" file="l_f_link4_3.STL"/>
    <mesh name="l_f_link4_4" file="l_f_link4_4.STL"/>
    <mesh name="l_f_link4_4_1" file="l_f_link4_4_1.STL"/>
    <mesh name="l_f_link4_4_2" file="l_f_link4_4_2.STL"/>
    <mesh name="l_f_link4_3_1" file="l_f_link4_3_1.STL"/>
    <mesh name="l_f_link4_3_2" file="l_f_link4_3_2.STL"/>
    <mesh name="l_f_link4_2_1" file="l_f_link4_2_1.STL"/>
    <mesh name="l_f_link4_2_2" file="l_f_link4_2_2.STL"/>
    <mesh name="l_f_link5_1" file="l_f_link5_1.STL"/>
    <mesh name="l_f_link5_2" file="l_f_link5_2.STL"/>
    <mesh name="l_f_link5_3" file="l_f_link5_3.STL"/>
    <mesh name="l_f_link5_4" file="l_f_link5_4.STL"/>
    <mesh name="l_f_link5_4_1" file="l_f_link5_4_1.STL"/>
    <mesh name="l_f_link5_4_2" file="l_f_link5_4_2.STL"/>
    <mesh name="l_f_link5_3_1" file="l_f_link5_3_1.STL"/>
    <mesh name="l_f_link5_3_2" file="l_f_link5_3_2.STL"/>
    <mesh name="l_f_link5_2_1" file="l_f_link5_2_1.STL"/>
    <mesh name="l_f_link5_2_2" file="l_f_link5_2_2.STL"/>
    <mesh name="l_p_link1" file="l_p_link1.STL"/>
    <mesh name="l_p_link2" file="l_p_link2.STL"/>
    <mesh name="l_p_link3" file="l_p_link3.STL"/>
    <mesh name="l_p_link4" file="l_p_link4.STL"/>
    <mesh name="l_p_link5" file="l_p_link5.STL"/>
    <mesh name="l_p_link6" file="l_p_link6.STL"/>
  </asset>
  <worldbody>
    <body name="left_hand_base" pos="0 0 0" quat="1 0 0 0">
      <geom pos="0 0 -0.17" quat="0.707388 0 0 0.706825" type="mesh" contype="0" conaffinity="0" group="1" density="0" rgba="0.3 0.3 0.3 1" mesh="l_p_link0"/>
      <geom pos="0 0 -0.17" quat="0.707388 0 0 0.706825" type="mesh" rgba="0.3 0.3 0.3 1" mesh="l_p_link0"/>
      <geom pos="0.031185 -0.0238798 0.10607" quat="0.788446 -0.0464709 -0.0600256 -0.610402" type="mesh" contype="0" conaffinity="0" group="1" density="0" rgba="0.3 0.3 0.3 1" mesh="l_p_link1"/>
      <geom pos="0.031185 -0.0238798 0.10607" quat="0.788446 -0.0464709 -0.0600256 -0.610402" type="mesh" rgba="0.3 0.3 0.3 1" mesh="l_p_link1"/>
      <geom pos="0.031185 -0.0238798 0.10607" quat="0.788446 -0.0464709 -0.0600256 -0.610402" type="mesh" contype="0" conaffinity="0" group="1" density="0" rgba="0.9 0.9 0.9 1" mesh="l_p_link2"/>
      <geom pos="0.031185 -0.0238798 0.10607" quat="0.788446 -0.0464709 -0.0600256 -0.610402" type="mesh" rgba="0.9 0.9 0.9 1" mesh="l_p_link2"/>
      <geom pos="0.031185 -0.0238798 0.10607" quat="0.788446 -0.0464709 -0.0600256 -0.610402" type="mesh" contype="0" conaffinity="0" group="1" density="0" rgba="0.3 0.3 0.3 1" mesh="l_p_link3"/>
      <geom pos="0.031185 -0.0238798 0.10607" quat="0.788446 -0.0464709 -0.0600256 -0.610402" type="mesh" rgba="0.3 0.3 0.3 1" mesh="l_p_link3"/>
      <geom pos="0.031185 -0.0238798 0.10607" quat="0.788446 -0.0464709 -0.0600256 -0.610402" type="mesh" contype="0" conaffinity="0" group="1" density="0" rgba="0.9 0.9 0.9 1" mesh="l_p_link4"/>
      <geom pos="0.031185 -0.0238798 0.10607" quat="0.788446 -0.0464709 -0.0600256 -0.610402" type="mesh" rgba="0.9 0.9 0.9 1" mesh="l_p_link4"/>
      <geom pos="0.031185 -0.0238798 0.10607" quat="0.788446 -0.0464709 -0.0600256 -0.610402" type="mesh" contype="0" conaffinity="0" group="1" density="0" rgba="0.3 0.3 0.3 1" mesh="l_p_link5"/>
      <geom pos="0.031185 -0.0238798 0.10607" quat="0.788446 -0.0464709 -0.0600256 -0.610402" type="mesh" rgba="0.3 0.3 0.3 1" mesh="l_p_link5"/>
      <geom pos="0.031185 -0.0238798 0.10607" quat="0.788446 -0.0464709 -0.0600256 -0.610402" type="mesh" contype="0" conaffinity="0" group="1" density="0" rgba="0.9 0.9 0.9 1" mesh="l_p_link6"/>
      <geom pos="0.031185 -0.0238798 0.10607" quat="0.788446 -0.0464709 -0.0600256 -0.610402" type="mesh" rgba="0.9 0.9 0.9 1" mesh="l_p_link6"/>
      <body name="l_f_link1_1" pos="0.031185 -0.0238798 0.10607" quat="0.788446 -0.0464709 -0.0600256 -0.610402">
        <inertial pos="0.00205223 -0.00527333 -0.0177664" quat="0.718029 -0.0456898 0.122436 0.683634" mass="0.00518035" diaginertia="1.21881e-09 1.15459e-09 2.51191e-10"/>
        <joint name="l_a_joint1_1" pos="0 0 0" axis="0 0.26521 0.964191" range="0 2.2" actuatorfrcrange="-10 10"/>
        <geom type="mesh" contype="0" conaffinity="0" group="1" density="0" rgba="0.3 0.3 0.3 1" mesh="l_f_link1_1"/>
        <geom type="mesh" rgba="0.3 0.3 0.3 1" mesh="l_f_link1_1"/>
        <body name="l_f_link1_2" pos="0.0083307 0 0" quat="0.795298 0.606144 -0.00578778 0.00759551">
          <inertial pos="0.0217194 -0.000635197 -0.00102982" quat="0.604156 0.543048 -0.461414 0.356639" mass="0.00931794" diaginertia="1.73539e-07 1.70521e-07 3.95581e-09"/>
          <joint name="l_f_joint1_2" pos="0 0 0" axis="0 0 1" range="0 1.3" actuatorfrcrange="-10 10"/>
          <geom type="mesh" contype="0" conaffinity="0" group="1" density="0" rgba="0.3 0.3 0.3 1" mesh="l_f_link1_2"/>
          <geom type="mesh" rgba="0.3 0.3 0.3 1" mesh="l_f_link1_2"/>
          <geom quat="0.000796327 1 0 0" type="mesh" contype="0" conaffinity="0" group="1" density="0" rgba="0.3 0.3 0.3 1" mesh="l_f_link1_2_1"/>
          <geom quat="0.000796327 1 0 0" type="mesh" rgba="0.3 0.3 0.3 1" mesh="l_f_link1_2_1"/>
          <geom quat="0.000796327 1 0 0" type="mesh" contype="0" conaffinity="0" group="1" density="0" rgba="0.9 0.9 0.9 1" mesh="l_f_link1_2_2"/>
          <geom quat="0.000796327 1 0 0" type="mesh" rgba="0.9 0.9 0.9 1" mesh="l_f_link1_2_2"/>
          <body name="l_f_link1_3" pos="0.043 0 0">
            <inertial pos="0.0130893 0.000676815 -0.00129681" quat="0.512449 0.490952 -0.508737 0.487389" mass="0.00492936" diaginertia="5.25091e-08 5.20908e-08 6.12707e-10"/>
            <joint name="l_f_joint1_3" pos="0 0 0" axis="0 0 1" range="0 1.3" actuatorfrcrange="-10 10"/>
            <geom quat="0.000796327 1 0 0" type="mesh" contype="0" conaffinity="0" group="1" density="0" rgba="0.3 0.3 0.3 1" mesh="l_f_link1_3"/>
            <geom quat="0.000796327 1 0 0" type="mesh" rgba="0.3 0.3 0.3 1" mesh="l_f_link1_3"/>
            <geom quat="0.000796327 1 0 0" type="mesh" contype="0" conaffinity="0" group="1" density="0" rgba="0.3 0.3 0.3 1" mesh="l_f_link1_3_1"/>
            <geom quat="0.000796327 1 0 0" type="mesh" rgba="0.3 0.3 0.3 1" mesh="l_f_link1_3_1"/>
            <geom quat="0.000796327 1 0 0" type="mesh" contype="0" conaffinity="0" group="1" density="0" rgba="0.9 0.9 0.9 1" mesh="l_f_link1_3_2"/>
            <geom quat="0.000796327 1 0 0" type="mesh" rgba="0.9 0.9 0.9 1" mesh="l_f_link1_3_2"/>
            <body name="l_f_link1_4" pos="0.025 0 0">
              <inertial pos="0.016544 0.00270681 -0.000471799" quat="0.816481 0.401082 0.27263 -0.313314" mass="0.00767734" diaginertia="1.20629e-07 7.7152e-08 5.84642e-08"/>
              <joint name="l_f_joint1_4" pos="0 0 0" axis="0 0 1" range="0 1.3" actuatorfrcrange="-10 10"/>
              <geom quat="0.000796327 1 0 0" type="mesh" contype="0" conaffinity="0" group="1" density="0" rgba="0.3 0.3 0.3 1" mesh="l_f_link1_4"/>
              <geom quat="0.000796327 1 0 0" type="mesh" rgba="0.3 0.3 0.3 1" mesh="l_f_link1_4"/>
              <geom quat="0.000796327 1 0 0" type="mesh" contype="0" conaffinity="0" group="1" density="0" rgba="0.3 0.3 0.3 1" mesh="l_f_link1_4_1"/>
              <geom quat="0.000796327 1 0 0" type="mesh" rgba="0.3 0.3 0.3 1" mesh="l_f_link1_4_1"/>
              <geom quat="0.000796327 1 0 0" type="mesh" contype="0" conaffinity="0" group="1" density="0" rgba="0.9 0.9 0.9 1" mesh="l_f_link1_4_2"/>
              <geom quat="0.000796327 1 0 0" type="mesh" rgba="0.9 0.9 0.9 1" mesh="l_f_link1_4_2"/>
              <geom size="0.002" pos="0.035 -0.004 0" contype="0" conaffinity="0" group="1" density="0" rgba="1 0 0 1"/>
              <geom size="0.002" pos="0.02 0 0" rgba="1 0 0 1"/>
              <site name="site_l_f_link1_4" pos="0.025 0.003 0" size="0.01" type="sphere"/>
            </body>
          </body>
        </body>
      </body>
      <body name="l_f_link2_1" pos="0.0054382 -0.0349163 0.1587" quat="0.000281544 0.707107 -0.000278947 0.707107">
        <inertial pos="0.00800686 1.83385e-05 -0.00158423" quat="0.365628 0.605241 0.605241 0.365628" mass="0.00351858" diaginertia="3.71985e-10 3.2371e-10 2.04965e-10"/>
        <joint name="l_f_joint2_1" pos="0 0 0" axis="0 0 1" range="0 0.6" actuatorfrcrange="-10 10"/>
        <geom type="mesh" contype="0" conaffinity="0" group="1" density="0" rgba="0.3 0.3 0.3 1" mesh="l_f_link2_1"/>
        <geom type="mesh" rgba="0.3 0.3 0.3 1" mesh="l_f_link2_1"/>
        <body name="l_f_link2_2" pos="0.017 0 0" quat="0.707105 0.707108 0 0">
          <inertial pos="0.0214625 -0.000312324 -0.000276541" quat="0.429174 0.502978 -0.498903 0.560284" mass="0.00860339" diaginertia="8.84152e-08 8.76929e-08 2.26454e-09"/>
          <joint name="l_f_joint2_2" pos="0 0 0" axis="0 0 1" range="0 1.3" actuatorfrcrange="-10 10"/>
          <geom type="mesh" contype="0" conaffinity="0" group="1" density="0" rgba="0.3 0.3 0.3 1" mesh="l_f_link2_2"/>
          <geom type="mesh" rgba="0.3 0.3 0.3 1" mesh="l_f_link2_2"/>
          <geom type="mesh" contype="0" conaffinity="0" group="1" density="0" rgba="0.3 0.3 0.3 1" mesh="l_f_link2_2_1"/>
          <geom type="mesh" rgba="0.3 0.3 0.3 1" mesh="l_f_link2_2_1"/>
          <geom type="mesh" contype="0" conaffinity="0" group="1" density="0" rgba="0.9 0.9 0.9 1" mesh="l_f_link2_2_2"/>
          <geom type="mesh" rgba="0.9 0.9 0.9 1" mesh="l_f_link2_2_2"/>
          <body name="l_f_link2_3" pos="0.043 0 0">
            <inertial pos="0.0131211 -0.000590719 -1.26084e-05" quat="0.492887 0.514667 -0.484932 0.506972" mass="0.00474675" diaginertia="5.29702e-08 5.24876e-08 6.6966e-10"/>
            <joint name="l_f_joint2_3" pos="0 0 0" axis="0 0 1" range="0 1.3" actuatorfrcrange="-10 10"/>
            <geom type="mesh" contype="0" conaffinity="0" group="1" density="0" rgba="0.3 0.3 0.3 1" mesh="l_f_link2_3"/>
            <geom type="mesh" rgba="0.3 0.3 0.3 1" mesh="l_f_link2_3"/>
            <geom type="mesh" contype="0" conaffinity="0" group="1" density="0" rgba="0.3 0.3 0.3 1" mesh="l_f_link2_3_1"/>
            <geom type="mesh" rgba="0.3 0.3 0.3 1" mesh="l_f_link2_3_1"/>
            <geom type="mesh" contype="0" conaffinity="0" group="1" density="0" rgba="0.9 0.9 0.9 1" mesh="l_f_link2_3_2"/>
            <geom type="mesh" rgba="0.9 0.9 0.9 1" mesh="l_f_link2_3_2"/>
            <body name="l_f_link2_4" pos="0.025 0 0">
              <inertial pos="0.0165327 -0.00269728 0.000649365" quat="0.274493 0.387094 -0.70656 0.524962" mass="0.0076892" diaginertia="1.1051e-07 7.05834e-08 5.20707e-08"/>
              <joint name="l_f_joint2_4" pos="0 0 0" axis="0 0 1" range="0 1.3" actuatorfrcrange="-10 10"/>
              <geom type="mesh" contype="0" conaffinity="0" group="1" density="0" rgba="0.3 0.3 0.3 1" mesh="l_f_link2_4"/>
              <geom type="mesh" rgba="0.3 0.3 0.3 1" mesh="l_f_link2_4"/>
              <geom type="mesh" contype="0" conaffinity="0" group="1" density="0" rgba="0.3 0.3 0.3 1" mesh="l_f_link2_4_1"/>
              <geom type="mesh" rgba="0.3 0.3 0.3 1" mesh="l_f_link2_4_1"/>
              <geom type="mesh" contype="0" conaffinity="0" group="1" density="0" rgba="0.9 0.9 0.9 1" mesh="l_f_link2_4_2"/>
              <geom type="mesh" rgba="0.9 0.9 0.9 1" mesh="l_f_link2_4_2"/>
              <geom size="0.002" pos="0.035 -0.004 0" contype="0" conaffinity="0" group="1" density="0" rgba="1 0 0 1"/>
              <geom size="0.002" pos="0.02 0 0" rgba="1 0 0 1"/>
              <site name="site_l_f_link2_4" pos="0.025 0.003 0" size="0.01" type="sphere"/>
            </body>
          </body>
        </body>
      </body>
      <body name="l_f_link3_1" pos="0.00545755 -0.0106163 0.1677" quat="0.000561789 0.707107 1.29867e-06 0.707107">
        <inertial pos="0.00800685 2.44308e-05 -0.00158423" quat="0.365626 0.605242 0.605242 0.365626" mass="0.00351858" diaginertia="3.71983e-10 3.23711e-10 2.04966e-10"/>
        <joint name="l_f_joint3_1" pos="0 0 0" axis="0 0 1" range="-0.001 0.001" actuatorfrcrange="-10 10"/>
        <geom type="mesh" contype="0" conaffinity="0" group="1" density="0" rgba="0.3 0.3 0.3 1" mesh="l_f_link3_1"/>
        <geom type="mesh" rgba="0.3 0.3 0.3 1" mesh="l_f_link3_1"/>
        <body name="l_f_link3_2" pos="0.017 1.2935e-05 0" quat="0.707105 0.707108 0.000269005 0.000269004">
          <inertial pos="0.0214625 -0.000312324 -0.000276541" quat="0.429174 0.502978 -0.498903 0.560284" mass="0.00860339" diaginertia="8.84152e-08 8.76929e-08 2.26454e-09"/>
          <joint name="l_f_joint3_2" pos="0 0 0" axis="0 0 1" range="0 1.3" actuatorfrcrange="-10 10"/>
          <geom type="mesh" contype="0" conaffinity="0" group="1" density="0" rgba="0.3 0.3 0.3 1" mesh="l_f_link3_2"/>
          <geom type="mesh" rgba="0.3 0.3 0.3 1" mesh="l_f_link3_2"/>
          <geom type="mesh" contype="0" conaffinity="0" group="1" density="0" rgba="0.3 0.3 0.3 1" mesh="l_f_link3_2_1"/>
          <geom type="mesh" rgba="0.3 0.3 0.3 1" mesh="l_f_link3_2_1"/>
          <geom type="mesh" contype="0" conaffinity="0" group="1" density="0" rgba="0.9 0.9 0.9 1" mesh="l_f_link3_2_2"/>
          <geom type="mesh" rgba="0.9 0.9 0.9 1" mesh="l_f_link3_2_2"/>
          <body name="l_f_link3_3" pos="0.043 0 0">
            <inertial pos="0.0131211 -0.000590719 -1.26084e-05" quat="0.492887 0.514667 -0.484932 0.506972" mass="0.00474675" diaginertia="5.29702e-08 5.24876e-08 6.6966e-10"/>
            <joint name="l_f_joint3_3" pos="0 0 0" axis="0 0 1" range="0 1.3" actuatorfrcrange="-10 10"/>
            <geom type="mesh" contype="0" conaffinity="0" group="1" density="0" rgba="0.3 0.3 0.3 1" mesh="l_f_link3_3"/>
            <geom type="mesh" rgba="0.3 0.3 0.3 1" mesh="l_f_link3_3"/>
            <geom type="mesh" contype="0" conaffinity="0" group="1" density="0" rgba="0.3 0.3 0.3 1" mesh="l_f_link3_3_1"/>
            <geom type="mesh" rgba="0.3 0.3 0.3 1" mesh="l_f_link3_3_1"/>
            <geom type="mesh" contype="0" conaffinity="0" group="1" density="0" rgba="0.9 0.9 0.9 1" mesh="l_f_link3_3_2"/>
            <geom type="mesh" rgba="0.9 0.9 0.9 1" mesh="l_f_link3_3_2"/>
            <body name="l_f_link3_4" pos="0.025 0 0">
              <inertial pos="0.0165327 -0.00269728 0.000649365" quat="0.274493 0.387094 -0.70656 0.524962" mass="0.0076892" diaginertia="1.1051e-07 7.05834e-08 5.20707e-08"/>
              <joint name="l_f_joint3_4" pos="0 0 0" axis="0 0 1" range="0 1.3" actuatorfrcrange="-10 10"/>
              <geom type="mesh" contype="0" conaffinity="0" group="1" density="0" rgba="0.3 0.3 0.3 1" mesh="l_f_link3_4"/>
              <geom type="mesh" rgba="0.3 0.3 0.3 1" mesh="l_f_link3_4"/>
              <geom type="mesh" contype="0" conaffinity="0" group="1" density="0" rgba="0.3 0.3 0.3 1" mesh="l_f_link3_4_1"/>
              <geom type="mesh" rgba="0.3 0.3 0.3 1" mesh="l_f_link3_4_1"/>
              <geom type="mesh" contype="0" conaffinity="0" group="1" density="0" rgba="0.9 0.9 0.9 1" mesh="l_f_link3_4_2"/>
              <geom type="mesh" rgba="0.9 0.9 0.9 1" mesh="l_f_link3_4_2"/>
              <geom size="0.002" pos="0.035 -0.004 0" contype="0" conaffinity="0" group="1" density="0" rgba="1 0 0 1"/>
              <geom size="0.002" pos="0.02 0 0" rgba="1 0 0 1"/>
              <site name="site_l_f_link3_4" pos="0.025 0.003 0" size="0.01" type="sphere"/>
            </body>
          </body>
        </body>
      </body>
      <body name="l_f_link4_1" pos="0.0054769 0.0136836 0.1587" quat="0.000561789 0.707107 1.29867e-06 0.707107">
        <inertial pos="0.00800685 2.44308e-05 -0.00158423" quat="0.365626 0.605242 0.605242 0.365626" mass="0.00351858" diaginertia="3.71983e-10 3.23711e-10 2.04966e-10"/>
        <joint name="l_f_joint4_1" pos="0 0 0" axis="0 0 -1" range="0 0.6" actuatorfrcrange="-10 10"/>
        <geom type="mesh" contype="0" conaffinity="0" group="1" density="0" rgba="0.3 0.3 0.3 1" mesh="l_f_link4_1"/>
        <geom type="mesh" rgba="0.3 0.3 0.3 1" mesh="l_f_link4_1"/>
        <body name="l_f_link4_2" pos="0.017 1.2935e-05 0" quat="0.707105 0.707108 0.000269005 0.000269004">
          <inertial pos="0.0214625 -0.000312324 -0.000276541" quat="0.429174 0.502978 -0.498903 0.560284" mass="0.00860339" diaginertia="8.84152e-08 8.76929e-08 2.26454e-09"/>
          <joint name="l_f_joint4_2" pos="0 0 0" axis="0 0 1" range="0 1.3" actuatorfrcrange="-10 10"/>
          <geom type="mesh" contype="0" conaffinity="0" group="1" density="0" rgba="0.3 0.3 0.3 1" mesh="l_f_link4_2"/>
          <geom type="mesh" rgba="0.3 0.3 0.3 1" mesh="l_f_link4_2"/>
          <geom type="mesh" contype="0" conaffinity="0" group="1" density="0" rgba="0.3 0.3 0.3 1" mesh="l_f_link4_2_1"/>
          <geom type="mesh" rgba="0.3 0.3 0.3 1" mesh="l_f_link4_2_1"/>
          <geom type="mesh" contype="0" conaffinity="0" group="1" density="0" rgba="0.9 0.9 0.9 1" mesh="l_f_link4_2_2"/>
          <geom type="mesh" rgba="0.9 0.9 0.9 1" mesh="l_f_link4_2_2"/>
          <body name="l_f_link4_3" pos="0.043 0 0">
            <inertial pos="0.0131211 -0.000590719 -1.26084e-05" quat="0.492887 0.514667 -0.484932 0.506972" mass="0.00474675" diaginertia="5.29702e-08 5.24876e-08 6.6966e-10"/>
            <joint name="l_f_joint4_3" pos="0 0 0" axis="0 0 1" range="0 1.3" actuatorfrcrange="-10 10"/>
            <geom type="mesh" contype="0" conaffinity="0" group="1" density="0" rgba="0.3 0.3 0.3 1" mesh="l_f_link4_3"/>
            <geom type="mesh" rgba="0.3 0.3 0.3 1" mesh="l_f_link4_3"/>
            <geom type="mesh" contype="0" conaffinity="0" group="1" density="0" rgba="0.3 0.3 0.3 1" mesh="l_f_link4_3_1"/>
            <geom type="mesh" rgba="0.3 0.3 0.3 1" mesh="l_f_link4_3_1"/>
            <geom type="mesh" contype="0" conaffinity="0" group="1" density="0" rgba="0.9 0.9 0.9 1" mesh="l_f_link4_3_2"/>
            <geom type="mesh" rgba="0.9 0.9 0.9 1" mesh="l_f_link4_3_2"/>
            <body name="l_f_link4_4" pos="0.025 0 0">
              <inertial pos="0.0165327 -0.00269728 0.000649365" quat="0.274493 0.387094 -0.70656 0.524962" mass="0.0076892" diaginertia="1.1051e-07 7.05834e-08 5.20707e-08"/>
              <joint name="l_f_joint4_4" pos="0 0 0" axis="0 0 1" range="0 1.3" actuatorfrcrange="-10 10"/>
              <geom type="mesh" contype="0" conaffinity="0" group="1" density="0" rgba="0.3 0.3 0.3 1" mesh="l_f_link4_4"/>
              <geom type="mesh" rgba="0.3 0.3 0.3 1" mesh="l_f_link4_4"/>
              <geom type="mesh" contype="0" conaffinity="0" group="1" density="0" rgba="0.3 0.3 0.3 1" mesh="l_f_link4_4_1"/>
              <geom type="mesh" rgba="0.3 0.3 0.3 1" mesh="l_f_link4_4_1"/>
              <geom type="mesh" contype="0" conaffinity="0" group="1" density="0" rgba="0.9 0.9 0.9 1" mesh="l_f_link4_4_2"/>
              <geom type="mesh" rgba="0.9 0.9 0.9 1" mesh="l_f_link4_4_2"/>
              <geom size="0.002" pos="0.035 -0.004 0" contype="0" conaffinity="0" group="1" density="0" rgba="1 0 0 1"/>
              <geom size="0.002" pos="0.02 0 0" rgba="1 0 0 1"/>
              <site name="site_l_f_link4_4" pos="0.025 0.003 0" size="0.01" type="sphere"/>
            </body>
          </body>
        </body>
      </body>
      <body name="l_f_link5_1" pos="0.00549625 0.0379836 0.1447" quat="0.000561789 0.707107 1.29867e-06 0.707107">
        <inertial pos="0.00800685 2.44308e-05 -0.00158423" quat="0.365626 0.605242 0.605242 0.365626" mass="0.00351858" diaginertia="3.71983e-10 3.23711e-10 2.04966e-10"/>
        <joint name="l_f_joint5_1" pos="0 0 0" axis="0 0 -1" range="0 0.6" actuatorfrcrange="-10 10"/>
        <geom type="mesh" contype="0" conaffinity="0" group="1" density="0" rgba="0.3 0.3 0.3 1" mesh="l_f_link5_1"/>
        <geom type="mesh" rgba="0.3 0.3 0.3 1" mesh="l_f_link5_1"/>
        <body name="l_f_link5_2" pos="0.017 1.2935e-05 0" quat="0.707105 0.707108 0.000269005 0.000269004">
          <inertial pos="0.0214625 -0.000312324 -0.000276541" quat="0.429174 0.502978 -0.498903 0.560284" mass="0.00860339" diaginertia="8.84152e-08 8.76929e-08 2.26454e-09"/>
          <joint name="l_f_joint5_2" pos="0 0 0" axis="0 0 1" range="0 1.3" actuatorfrcrange="-10 10"/>
          <geom type="mesh" contype="0" conaffinity="0" group="1" density="0" rgba="0.3 0.3 0.3 1" mesh="l_f_link5_2"/>
          <geom type="mesh" rgba="0.3 0.3 0.3 1" mesh="l_f_link5_2"/>
          <geom type="mesh" contype="0" conaffinity="0" group="1" density="0" rgba="0.3 0.3 0.3 1" mesh="l_f_link5_2_1"/>
          <geom type="mesh" rgba="0.3 0.3 0.3 1" mesh="l_f_link5_2_1"/>
          <geom type="mesh" contype="0" conaffinity="0" group="1" density="0" rgba="0.9 0.9 0.9 1" mesh="l_f_link5_2_2"/>
          <geom type="mesh" rgba="0.9 0.9 0.9 1" mesh="l_f_link5_2_2"/>
          <body name="l_f_link5_3" pos="0.043 0 0">
            <inertial pos="0.0131211 -0.000590719 -1.26084e-05" quat="0.492887 0.514667 -0.484932 0.506972" mass="0.00474675" diaginertia="5.29702e-08 5.24876e-08 6.6966e-10"/>
            <joint name="l_f_joint5_3" pos="0 0 0" axis="0 0 1" range="0 1.3" actuatorfrcrange="-10 10"/>
            <geom type="mesh" contype="0" conaffinity="0" group="1" density="0" rgba="0.3 0.3 0.3 1" mesh="l_f_link5_3"/>
            <geom type="mesh" rgba="0.3 0.3 0.3 1" mesh="l_f_link5_3"/>
            <geom type="mesh" contype="0" conaffinity="0" group="1" density="0" rgba="0.3 0.3 0.3 1" mesh="l_f_link5_3_1"/>
            <geom type="mesh" rgba="0.3 0.3 0.3 1" mesh="l_f_link5_3_1"/>
            <geom type="mesh" contype="0" conaffinity="0" group="1" density="0" rgba="0.9 0.9 0.9 1" mesh="l_f_link5_3_2"/>
            <geom type="mesh" rgba="0.9 0.9 0.9 1" mesh="l_f_link5_3_2"/>
            <body name="l_f_link5_4" pos="0.025 0 0">
              <inertial pos="0.0165327 -0.00269728 0.000649365" quat="0.274493 0.387094 -0.70656 0.524962" mass="0.0076892" diaginertia="1.1051e-07 7.05834e-08 5.20707e-08"/>
              <joint name="l_f_joint5_4" pos="0 0 0" axis="0 0 1" range="0 1.3" actuatorfrcrange="-10 10"/>
              <geom type="mesh" contype="0" conaffinity="0" group="1" density="0" rgba="0.3 0.3 0.3 1" mesh="l_f_link5_4"/>
              <geom type="mesh" rgba="0.3 0.3 0.3 1" mesh="l_f_link5_4"/>
              <geom type="mesh" contype="0" conaffinity="0" group="1" density="0" rgba="0.3 0.3 0.3 1" mesh="l_f_link5_4_1"/>
              <geom type="mesh" rgba="0.3 0.3 0.3 1" mesh="l_f_link5_4_1"/>
              <geom type="mesh" contype="0" conaffinity="0" group="1" density="0" rgba="0.9 0.9 0.9 1" mesh="l_f_link5_4_2"/>
              <geom type="mesh" rgba="0.9 0.9 0.9 1" mesh="l_f_link5_4_2"/>
              <geom size="0.002" pos="0.035 -0.004 0" contype="0" conaffinity="0" group="1" density="0" rgba="1 0 0 1"/>
              <geom size="0.002" pos="0.02 0 0" rgba="1 0 0 1"/>
              <site name="site_l_f_link5_4" pos="0.025 0.003 0" size="0.01" type="sphere"/>
            </body>
          </body>
        </body>
      </body>
    </body>
  </worldbody>
  <actuator>
    <position name="act_l_f_joint1_2" joint="l_f_joint1_2" kp="20" kv="0.1" ctrlrange="0 1.3" forcerange="-20 20"/>
    <position name="act_l_f_joint1_3" joint="l_f_joint1_3" kp="20" kv="0.1" ctrlrange="0 1.3" forcerange="-20 20"/>
    <position name="act_l_f_joint1_4" joint="l_f_joint1_4" kp="20" kv="0.1" ctrlrange="0 1.3" forcerange="-20 20"/>
    <position name="act_l_f_joint2_2" joint="l_f_joint2_2" kp="20" kv="0.1" ctrlrange="0 1.3" forcerange="-20 20"/>
    <position name="act_l_f_joint2_3" joint="l_f_joint2_3" kp="20" kv="0.1" ctrlrange="0 1.3" forcerange="-20 20"/>
    <position name="act_l_f_joint2_4" joint="l_f_joint2_4" kp="20" kv="0.1" ctrlrange="0 1.3" forcerange="-20 20"/>
    <position name="act_l_f_joint3_2" joint="l_f_joint3_2" kp="20" kv="0.1" ctrlrange="0 1.3" forcerange="-20 20"/>
    <position name="act_l_f_joint3_3" joint="l_f_joint3_3" kp="20" kv="0.1" ctrlrange="0 1.3" forcerange="-20 20"/>
    <position name="act_l_f_joint3_4" joint="l_f_joint3_4" kp="20" kv="0.1" ctrlrange="0 1.3" forcerange="-20 20"/>
    <position name="act_l_f_joint4_2" joint="l_f_joint4_2" kp="20" kv="0.1" ctrlrange="0 1.3" forcerange="-20 20"/>
    <position name="act_l_f_joint4_3" joint="l_f_joint4_3" kp="20" kv="0.1" ctrlrange="0 1.3" forcerange="-20 20"/>
    <position name="act_l_f_joint4_4" joint="l_f_joint4_4" kp="20" kv="0.1" ctrlrange="0 1.3" forcerange="-20 20"/>
    <position name="act_l_f_joint5_2" joint="l_f_joint5_2" kp="20" kv="0.1" ctrlrange="0 1.3" forcerange="-20 20"/>
    <position name="act_l_f_joint5_3" joint="l_f_joint5_3" kp="20" kv="0.1" ctrlrange="0 1.3" forcerange="-20 20"/>
    <position name="act_l_f_joint5_4" joint="l_f_joint5_4" kp="20" kv="0.1" ctrlrange="0 1.3" forcerange="-20 20"/>
    <position name="act_l_f_joint2_1" joint="l_f_joint2_1" kp="20" kv="1" ctrlrange="0 0.3" forcerange="-20 20"/>
    <position name="act_l_f_joint3_1" joint="l_f_joint3_1" kp="20" kv="1" ctrlrange="-0.0001 0.0001" forcerange="-20 20"/>
    <position name="act_l_f_joint4_1" joint="l_f_joint4_1" kp="20" kv="1" ctrlrange="0 0.3" forcerange="-20 20"/>
    <position name="act_l_f_joint5_1" joint="l_f_joint5_1" kp="20" kv="1" ctrlrange="0 0.6" forcerange="-20 20"/>
  </actuator>
  <sensor>
    <touch name="touch_l_f_link1_4" site="site_l_f_link1_4"/>
    <touch name="touch_l_f_link2_4" site="site_l_f_link2_4"/>
    <touch name="touch_l_f_link3_4" site="site_l_f_link3_4"/>
    <touch name="touch_l_f_link4_4" site="site_l_f_link4_4"/>
    <touch name="touch_l_f_link5_4" site="site_l_f_link5_4"/>
  </sensor>
  <contact>
    <exclude body1="left_hand_base" body2="l_f_link1_1"/>
    <exclude body1="left_hand_base" body2="l_f_link1_2"/>
    <exclude body1="left_hand_base" body2="l_f_link1_3"/>
    <exclude body1="left_hand_base" body2="l_f_link1_4"/>
    <exclude body1="left_hand_base" body2="l_f_link2_1"/>
    <exclude body1="left_hand_base" body2="l_f_link2_2"/>
    <exclude body1="left_hand_base" body2="l_f_link2_3"/>
    <exclude body1="left_hand_base" body2="l_f_link2_4"/>
    <exclude body1="left_hand_base" body2="l_f_link3_1"/>
    <exclude body1="left_hand_base" body2="l_f_link3_2"/>
    <exclude body1="left_hand_base" body2="l_f_link3_3"/>
    <exclude body1="left_hand_base" body2="l_f_link3_4"/>
    <exclude body1="left_hand_base" body2="l_f_link4_1"/>
    <exclude body1="left_hand_base" body2="l_f_link4_2"/>
    <exclude body1="left_hand_base" body2="l_f_link4_3"/>
    <exclude body1="left_hand_base" body2="l_f_link4_4"/>
    <exclude body1="left_hand_base" body2="l_f_link5_1"/>
    <exclude body1="left_hand_base" body2="l_f_link5_2"/>
    <exclude body1="left_hand_base" body2="l_f_link5_3"/>
    <exclude body1="left_hand_base" body2="l_f_link5_4"/>
    <exclude body1="l_f_link1_1" body2="l_f_link1_2"/>
    <exclude body1="l_f_link1_1" body2="l_f_link1_3"/>
    <exclude body1="l_f_link1_1" body2="l_f_link1_4"/>
    <exclude body1="l_f_link1_1" body2="l_f_link2_1"/>
    <exclude body1="l_f_link1_1" body2="l_f_link2_2"/>
    <exclude body1="l_f_link1_1" body2="l_f_link2_3"/>
    <exclude body1="l_f_link1_1" body2="l_f_link2_4"/>
    <exclude body1="l_f_link1_1" body2="l_f_link3_1"/>
    <exclude body1="l_f_link1_1" body2="l_f_link3_2"/>
    <exclude body1="l_f_link1_1" body2="l_f_link3_3"/>
    <exclude body1="l_f_link1_1" body2="l_f_link3_4"/>
    <exclude body1="l_f_link1_1" body2="l_f_link4_1"/>
    <exclude body1="l_f_link1_1" body2="l_f_link4_2"/>
    <exclude body1="l_f_link1_1" body2="l_f_link4_3"/>
    <exclude body1="l_f_link1_1" body2="l_f_link4_4"/>
    <exclude body1="l_f_link1_1" body2="l_f_link5_1"/>
    <exclude body1="l_f_link1_1" body2="l_f_link5_2"/>
    <exclude body1="l_f_link1_1" body2="l_f_link5_3"/>
    <exclude body1="l_f_link1_1" body2="l_f_link5_4"/>
    <exclude body1="l_f_link1_2" body2="l_f_link1_3"/>
    <exclude body1="l_f_link1_2" body2="l_f_link1_4"/>
    <exclude body1="l_f_link1_2" body2="l_f_link2_1"/>
    <exclude body1="l_f_link1_2" body2="l_f_link2_2"/>
    <exclude body1="l_f_link1_2" body2="l_f_link2_3"/>
    <exclude body1="l_f_link1_2" body2="l_f_link2_4"/>
    <exclude body1="l_f_link1_2" body2="l_f_link3_1"/>
    <exclude body1="l_f_link1_2" body2="l_f_link3_2"/>
    <exclude body1="l_f_link1_2" body2="l_f_link3_3"/>
    <exclude body1="l_f_link1_2" body2="l_f_link3_4"/>
    <exclude body1="l_f_link1_2" body2="l_f_link4_1"/>
    <exclude body1="l_f_link1_2" body2="l_f_link4_2"/>
    <exclude body1="l_f_link1_2" body2="l_f_link4_3"/>
    <exclude body1="l_f_link1_2" body2="l_f_link4_4"/>
    <exclude body1="l_f_link1_2" body2="l_f_link5_1"/>
    <exclude body1="l_f_link1_2" body2="l_f_link5_2"/>
    <exclude body1="l_f_link1_2" body2="l_f_link5_3"/>
    <exclude body1="l_f_link1_2" body2="l_f_link5_4"/>
    <exclude body1="l_f_link1_3" body2="l_f_link1_4"/>
    <exclude body1="l_f_link1_3" body2="l_f_link2_1"/>
    <exclude body1="l_f_link1_3" body2="l_f_link2_2"/>
    <exclude body1="l_f_link1_3" body2="l_f_link2_3"/>
    <exclude body1="l_f_link1_3" body2="l_f_link2_4"/>
    <exclude body1="l_f_link1_3" body2="l_f_link3_1"/>
    <exclude body1="l_f_link1_3" body2="l_f_link3_2"/>
    <exclude body1="l_f_link1_3" body2="l_f_link3_3"/>
    <exclude body1="l_f_link1_3" body2="l_f_link3_4"/>
    <exclude body1="l_f_link1_3" body2="l_f_link4_1"/>
    <exclude body1="l_f_link1_3" body2="l_f_link4_2"/>
    <exclude body1="l_f_link1_3" body2="l_f_link4_3"/>
    <exclude body1="l_f_link1_3" body2="l_f_link4_4"/>
    <exclude body1="l_f_link1_3" body2="l_f_link5_1"/>
    <exclude body1="l_f_link1_3" body2="l_f_link5_2"/>
    <exclude body1="l_f_link1_3" body2="l_f_link5_3"/>
    <exclude body1="l_f_link1_3" body2="l_f_link5_4"/>
    <exclude body1="l_f_link1_4" body2="l_f_link2_1"/>
    <exclude body1="l_f_link1_4" body2="l_f_link2_2"/>
    <exclude body1="l_f_link1_4" body2="l_f_link2_3"/>
    <exclude body1="l_f_link1_4" body2="l_f_link3_1"/>
    <exclude body1="l_f_link1_4" body2="l_f_link3_2"/>
    <exclude body1="l_f_link1_4" body2="l_f_link3_3"/>
    <exclude body1="l_f_link1_4" body2="l_f_link4_1"/>
    <exclude body1="l_f_link1_4" body2="l_f_link4_2"/>
    <exclude body1="l_f_link1_4" body2="l_f_link4_3"/>
    <exclude body1="l_f_link1_4" body2="l_f_link5_1"/>
    <exclude body1="l_f_link1_4" body2="l_f_link5_2"/>
    <exclude body1="l_f_link1_4" body2="l_f_link5_3"/>
    <exclude body1="l_f_link2_1" body2="l_f_link2_2"/>
    <exclude body1="l_f_link2_1" body2="l_f_link2_3"/>
    <exclude body1="l_f_link2_1" body2="l_f_link2_4"/>
    <exclude body1="l_f_link2_1" body2="l_f_link3_1"/>
    <exclude body1="l_f_link2_1" body2="l_f_link3_2"/>
    <exclude body1="l_f_link2_1" body2="l_f_link3_3"/>
    <exclude body1="l_f_link2_1" body2="l_f_link3_4"/>
    <exclude body1="l_f_link2_1" body2="l_f_link4_1"/>
    <exclude body1="l_f_link2_1" body2="l_f_link4_2"/>
    <exclude body1="l_f_link2_1" body2="l_f_link4_3"/>
    <exclude body1="l_f_link2_1" body2="l_f_link4_4"/>
    <exclude body1="l_f_link2_1" body2="l_f_link5_1"/>
    <exclude body1="l_f_link2_1" body2="l_f_link5_2"/>
    <exclude body1="l_f_link2_1" body2="l_f_link5_3"/>
    <exclude body1="l_f_link2_1" body2="l_f_link5_4"/>
    <exclude body1="l_f_link2_2" body2="l_f_link2_3"/>
    <exclude body1="l_f_link2_2" body2="l_f_link2_4"/>
    <exclude body1="l_f_link2_2" body2="l_f_link3_1"/>
    <exclude body1="l_f_link2_2" body2="l_f_link3_2"/>
    <exclude body1="l_f_link2_2" body2="l_f_link3_3"/>
    <exclude body1="l_f_link2_2" body2="l_f_link3_4"/>
    <exclude body1="l_f_link2_2" body2="l_f_link4_1"/>
    <exclude body1="l_f_link2_2" body2="l_f_link4_2"/>
    <exclude body1="l_f_link2_2" body2="l_f_link4_3"/>
    <exclude body1="l_f_link2_2" body2="l_f_link4_4"/>
    <exclude body1="l_f_link2_2" body2="l_f_link5_1"/>
    <exclude body1="l_f_link2_2" body2="l_f_link5_2"/>
    <exclude body1="l_f_link2_2" body2="l_f_link5_3"/>
    <exclude body1="l_f_link2_2" body2="l_f_link5_4"/>
    <exclude body1="l_f_link2_3" body2="l_f_link2_4"/>
    <exclude body1="l_f_link2_3" body2="l_f_link3_1"/>
    <exclude body1="l_f_link2_3" body2="l_f_link3_2"/>
    <exclude body1="l_f_link2_3" body2="l_f_link3_3"/>
    <exclude body1="l_f_link2_3" body2="l_f_link3_4"/>
    <exclude body1="l_f_link2_3" body2="l_f_link4_1"/>
    <exclude body1="l_f_link2_3" body2="l_f_link4_2"/>
    <exclude body1="l_f_link2_3" body2="l_f_link4_3"/>
    <exclude body1="l_f_link2_3" body2="l_f_link4_4"/>
    <exclude body1="l_f_link2_3" body2="l_f_link5_1"/>
    <exclude body1="l_f_link2_3" body2="l_f_link5_2"/>
    <exclude body1="l_f_link2_3" body2="l_f_link5_3"/>
    <exclude body1="l_f_link2_3" body2="l_f_link5_4"/>
    <exclude body1="l_f_link2_4" body2="l_f_link3_1"/>
    <exclude body1="l_f_link2_4" body2="l_f_link3_2"/>
    <exclude body1="l_f_link2_4" body2="l_f_link3_3"/>
    <exclude body1="l_f_link2_4" body2="l_f_link4_1"/>
    <exclude body1="l_f_link2_4" body2="l_f_link4_2"/>
    <exclude body1="l_f_link2_4" body2="l_f_link4_3"/>
    <exclude body1="l_f_link2_4" body2="l_f_link5_1"/>
    <exclude body1="l_f_link2_4" body2="l_f_link5_2"/>
    <exclude body1="l_f_link2_4" body2="l_f_link5_3"/>
    <exclude body1="l_f_link3_1" body2="l_f_link3_2"/>
    <exclude body1="l_f_link3_1" body2="l_f_link3_3"/>
    <exclude body1="l_f_link3_1" body2="l_f_link3_4"/>
    <exclude body1="l_f_link3_1" body2="l_f_link4_1"/>
    <exclude body1="l_f_link3_1" body2="l_f_link4_2"/>
    <exclude body1="l_f_link3_1" body2="l_f_link4_3"/>
    <exclude body1="l_f_link3_1" body2="l_f_link4_4"/>
    <exclude body1="l_f_link3_1" body2="l_f_link5_1"/>
    <exclude body1="l_f_link3_1" body2="l_f_link5_2"/>
    <exclude body1="l_f_link3_1" body2="l_f_link5_3"/>
    <exclude body1="l_f_link3_1" body2="l_f_link5_4"/>
    <exclude body1="l_f_link3_2" body2="l_f_link3_3"/>
    <exclude body1="l_f_link3_2" body2="l_f_link3_4"/>
    <exclude body1="l_f_link3_2" body2="l_f_link4_1"/>
    <exclude body1="l_f_link3_2" body2="l_f_link4_2"/>
    <exclude body1="l_f_link3_2" body2="l_f_link4_3"/>
    <exclude body1="l_f_link3_2" body2="l_f_link4_4"/>
    <exclude body1="l_f_link3_2" body2="l_f_link5_1"/>
    <exclude body1="l_f_link3_2" body2="l_f_link5_2"/>
    <exclude body1="l_f_link3_2" body2="l_f_link5_3"/>
    <exclude body1="l_f_link3_2" body2="l_f_link5_4"/>
    <exclude body1="l_f_link3_3" body2="l_f_link3_4"/>
    <exclude body1="l_f_link3_3" body2="l_f_link4_1"/>
    <exclude body1="l_f_link3_3" body2="l_f_link4_2"/>
    <exclude body1="l_f_link3_3" body2="l_f_link4_3"/>
    <exclude body1="l_f_link3_3" body2="l_f_link4_4"/>
    <exclude body1="l_f_link3_3" body2="l_f_link5_1"/>
    <exclude body1="l_f_link3_3" body2="l_f_link5_2"/>
    <exclude body1="l_f_link3_3" body2="l_f_link5_3"/>
    <exclude body1="l_f_link3_3" body2="l_f_link5_4"/>
    <exclude body1="l_f_link3_4" body2="l_f_link4_1"/>
    <exclude body1="l_f_link3_4" body2="l_f_link4_2"/>
    <exclude body1="l_f_link3_4" body2="l_f_link4_3"/>
    <exclude body1="l_f_link3_4" body2="l_f_link5_1"/>
    <exclude body1="l_f_link3_4" body2="l_f_link5_2"/>
    <exclude body1="l_f_link3_4" body2="l_f_link5_3"/>
    <exclude body1="l_f_link4_1" body2="l_f_link4_2"/>
    <exclude body1="l_f_link4_1" body2="l_f_link4_3"/>
    <exclude body1="l_f_link4_1" body2="l_f_link4_4"/>
    <exclude body1="l_f_link4_1" body2="l_f_link5_1"/>
    <exclude body1="l_f_link4_1" body2="l_f_link5_2"/>
    <exclude body1="l_f_link4_1" body2="l_f_link5_3"/>
    <exclude body1="l_f_link4_1" body2="l_f_link5_4"/>
    <exclude body1="l_f_link4_2" body2="l_f_link4_3"/>
    <exclude body1="l_f_link4_2" body2="l_f_link4_4"/>
    <exclude body1="l_f_link4_2" body2="l_f_link5_1"/>
    <exclude body1="l_f_link4_2" body2="l_f_link5_2"/>
    <exclude body1="l_f_link4_2" body2="l_f_link5_3"/>
    <exclude body1="l_f_link4_2" body2="l_f_link5_4"/>
    <exclude body1="l_f_link4_3" body2="l_f_link4_4"/>
    <exclude body1="l_f_link4_3" body2="l_f_link5_1"/>
    <exclude body1="l_f_link4_3" body2="l_f_link5_2"/>
    <exclude body1="l_f_link4_3" body2="l_f_link5_3"/>
    <exclude body1="l_f_link4_3" body2="l_f_link5_4"/>
    <exclude body1="l_f_link4_4" body2="l_f_link5_1"/>
    <exclude body1="l_f_link4_4" body2="l_f_link5_2"/>
    <exclude body1="l_f_link4_4" body2="l_f_link5_3"/>
    <exclude body1="l_f_link5_1" body2="l_f_link5_2"/>
    <exclude body1="l_f_link5_1" body2="l_f_link5_3"/>
    <exclude body1="l_f_link5_1" body2="l_f_link5_4"/>
    <exclude body1="l_f_link5_2" body2="l_f_link5_3"/>
    <exclude body1="l_f_link5_2" body2="l_f_link5_4"/>
    <exclude body1="l_f_link5_3" body2="l_f_link5_4"/>
  </contact>
</mujoco>
