<?xml version="1.0" encoding="utf-8"?>
<mujoco model="dexhand021_right_simplified">
  <visual>
    <global offwidth="1920" offheight="1080"/>
  </visual>
  <option gravity="0 0 -9.81" iterations="100" solver="Newton" integrator="implicit" timestep="0.001"/>
  <default>
    <joint damping="1"/>
    <geom condim="3" solref="0.02 1" solimp="0.9 0.95 0.001" friction="2 2 2"/>
  </default>
  <size njmax="1000" nconmax="1000"/>
  <compiler angle="radian" meshdir="../meshes/dexhand021_simplified/"/>
  <asset>
    <mesh name="right_hand_base" file="right_hand_base.STL"/>
    <mesh name="r_f_link1_1" file="r_f_link1_1.STL"/>
    <mesh name="r_f_link1_2" file="r_f_link1_2.STL"/>
    <mesh name="r_f_link1_3" file="r_f_link1_3.STL"/>
    <mesh name="r_f_link1_4" file="r_f_link1_4.STL"/>
    <mesh name="r_f_link2_1" file="r_f_link2_1.STL"/>
    <mesh name="r_f_link2_2" file="r_f_link2_2.STL"/>
    <mesh name="r_f_link2_3" file="r_f_link2_3.STL"/>
    <mesh name="r_f_link2_4" file="r_f_link2_4.STL"/>
    <mesh name="r_f_link3_1" file="r_f_link3_1.STL"/>
    <mesh name="r_f_link3_2" file="r_f_link3_2.STL"/>
    <mesh name="r_f_link3_3" file="r_f_link3_3.STL"/>
    <mesh name="r_f_link3_4" file="r_f_link3_4.STL"/>
    <mesh name="r_f_link4_1" file="r_f_link4_1.STL"/>
    <mesh name="r_f_link4_2" file="r_f_link4_2.STL"/>
    <mesh name="r_f_link4_3" file="r_f_link4_3.STL"/>
    <mesh name="r_f_link4_4" file="r_f_link4_4.STL"/>
    <mesh name="r_f_link5_1" file="r_f_link5_1.STL"/>
    <mesh name="r_f_link5_2" file="r_f_link5_2.STL"/>
    <mesh name="r_f_link5_3" file="r_f_link5_3.STL"/>
    <mesh name="r_f_link5_4" file="r_f_link5_4.STL"/>
  </asset>
  <worldbody>
    <body name="right_hand_base" pos="0 0 0" quat="1 0 0 0">
      <geom type="mesh" contype="0" conaffinity="0" group="1" density="0" rgba="0.75294 0.75294 0.75294 1" mesh="right_hand_base"/>
      <geom type="mesh" rgba="0.75294 0.75294 0.75294 1" mesh="right_hand_base" contype="0" conaffinity="0" group="1" density="0"/>
      <body name="r_f_link1_1" pos="0.032783 0.023781 0.11211" quat="0.151551 -0.775385 -0.612635 0.0221215">
        <inertial pos="0.0019855 -0.00034962 0.013484" quat="0.71629 -0.0780372 -0.0535872 0.691351" mass="0.0055264" diaginertia="5.52348e-07 4.77971e-07 2.4806e-07"/>
        <joint name="r_f_joint1_1" pos="0 0 0" axis="0 0 1" range="0 2.2" actuatorfrcrange="-10 10"/>
        <geom type="mesh" contype="0" conaffinity="0" group="1" density="0" rgba="0.6 0.6 0.6 1" mesh="r_f_link1_1"/>
        <geom type="mesh" rgba="0.6 0.6 0.6 1" mesh="r_f_link1_1" contype="0" conaffinity="0" group="1" density="0"/>
        <body name="r_f_link1_2" pos="0.0083307 0 0" quat="0.707105 -0.707108 0 0">
          <inertial pos="0.021437 0.00017315 -0.0012982" quat="0.0127346 0.706496 -0.016911 0.7074" mass="0.012462" diaginertia="2.145e-06 2.07718e-06 7.76292e-07"/>
          <joint name="r_f_joint1_2" pos="0 0 0" axis="0 0 1" range="0 1.3" actuatorfrcrange="-10 10"/>
          <geom type="mesh" contype="0" conaffinity="0" group="1" density="0" rgba="0.6 0.6 0.6 1" mesh="r_f_link1_2"/>
          <geom type="mesh" rgba="0.6 0.6 0.6 1" mesh="r_f_link1_2" contype="0" conaffinity="0" group="1" density="0"/>
          <body name="r_f_link1_3" pos="0.043 0 0">
            <inertial pos="0.013455 -0.00070242 -0.0012928" quat="0.0204223 0.706783 -0.0204207 0.70684" mass="0.005726" diaginertia="4.7655e-07 4.47482e-07 2.54788e-07"/>
            <joint name="r_f_joint1_3" pos="0 0 0" axis="0 0 1" range="0 1.3" actuatorfrcrange="-10 10"/>
            <geom type="mesh" contype="0" conaffinity="0" group="1" density="0" rgba="0.6 0.6 0.6 1" mesh="r_f_link1_3"/>
            <geom type="mesh" rgba="0.6 0.6 0.6 1" mesh="r_f_link1_3" contype="0" conaffinity="0" group="1" density="0"/>
            <body name="r_f_link1_4" pos="0.025 0 0">
              <inertial pos="-0.106463 -0.00117909 -0.0357483" quat="0.600225 0.415148 -0.487221 0.479581" mass="0.51236" diaginertia="0.00218672 0.00177093 0.000622187"/>
              <joint name="r_f_joint1_4" pos="0 0 0" axis="0 0 1" range="0 1.3" actuatorfrcrange="-10 10"/>
              <geom type="mesh" contype="0" conaffinity="0" group="1" density="0" rgba="0.6 0.6 0.6 1" mesh="r_f_link1_4"/>
              <geom type="mesh" rgba="0.6 0.6 0.6 1" mesh="r_f_link1_4" contype="0" conaffinity="0" group="1" density="0"/>
              <geom size="0.002" pos="0.035 -0.004 0" contype="0" conaffinity="0" group="1" density="0" rgba="1 0 0 1"/>
              <geom size="0.002" pos="0.02 0 0" rgba="1 0 0 1" contype="0" conaffinity="0" group="1" density="0"/>
              <site name="site_r_f_link1_4" pos="0.025 0.003 0" size="0.01" type="sphere"/>
              <geom name="col_r_f_link1_4" type="capsule" contype="1" conaffinity="1" group="3" size="0.0095" fromto="0.0 0 -0.001 0.027 -0.007 -0.001"/>
            </body>
            <geom name="col_r_f_link1_3" type="capsule" contype="1" conaffinity="1" group="3" size="0.007" fromto="0.0125 0.003 -0.0045 0.0125 0.003 0.0023"/>
          </body>
          <geom name="col_r_f_link1_2" type="capsule" contype="1" conaffinity="1" group="3" size="0.0095" fromto="0.0 0 0 0.03 0 -0.002"/>
        </body>
      </body>
      <body name="r_f_link2_1" pos="0.006966 0.034912 0.1644" quat="0.707105 0 -0.707108 0">
        <inertial pos="0.007003 2.619e-09 0.00096933" quat="0.601863 0.371162 0.371162 0.601863" mass="0.0051273" diaginertia="3.9879e-07 3.4058e-07 2.5589e-07"/>
        <joint name="r_f_joint2_1" pos="0 0 0" axis="0 0 1" range="0 0.6" actuatorfrcrange="-10 10"/>
        <geom type="mesh" contype="0" conaffinity="0" group="1" density="0" rgba="0.79216 0.81961 0.93333 1" mesh="r_f_link2_1"/>
        <geom type="mesh" rgba="0.79216 0.81961 0.93333 1" mesh="r_f_link2_1" contype="0" conaffinity="0" group="1" density="0"/>
        <body name="r_f_link2_2" pos="0.017 0 0" quat="0.707105 -0.707108 0 0">
          <inertial pos="0.02116 -0.00059146 -2.1984e-06" quat="0.507863 0.503147 0.496172 0.492678" mass="0.011802" diaginertia="2.07728e-06 2.0592e-06 6.94909e-07"/>
          <joint name="r_f_joint2_2" pos="0 0 0" axis="0 0 1" range="0 1.3" actuatorfrcrange="-10 10"/>
          <geom type="mesh" contype="0" conaffinity="0" group="1" density="0" rgba="0.6 0.6 0.6 1" mesh="r_f_link2_2"/>
          <geom type="mesh" rgba="0.6 0.6 0.6 1" mesh="r_f_link2_2" contype="0" conaffinity="0" group="1" density="0"/>
          <body name="r_f_link2_3" pos="0.043 0 0">
            <inertial pos="0.013455 -0.00070241 -3.5721e-07" quat="0.0204051 0.706783 -0.0204379 0.70684" mass="0.005726" diaginertia="4.7655e-07 4.47482e-07 2.54788e-07"/>
            <joint name="r_f_joint2_3" pos="0 0 0" axis="0 0 1" range="0 1.3" actuatorfrcrange="-10 10"/>
            <geom type="mesh" contype="0" conaffinity="0" group="1" density="0" rgba="0.6 0.6 0.6 1" mesh="r_f_link2_3"/>
            <geom type="mesh" rgba="0.6 0.6 0.6 1" mesh="r_f_link2_3" contype="0" conaffinity="0" group="1" density="0"/>
            <body name="r_f_link2_4" pos="0.025 0 0">
              <inertial pos="-0.13333 -0.0157552 -0.0325925" quat="0.521864 0.430738 0.552922 0.48621" mass="0.51236" diaginertia="0.00219668 0.00179214 0.000606036"/>
              <joint name="r_f_joint2_4" pos="0 0 0" axis="0 0 1" range="0 1.3" actuatorfrcrange="-10 10"/>
              <geom type="mesh" contype="0" conaffinity="0" group="1" density="0" rgba="0.6 0.6 0.6 1" mesh="r_f_link2_4"/>
              <geom type="mesh" rgba="0.6 0.6 0.6 1" mesh="r_f_link2_4" contype="0" conaffinity="0" group="1" density="0"/>
              <geom size="0.002" pos="0.035 -0.004 0" contype="0" conaffinity="0" group="1" density="0" rgba="1 0 0 1"/>
              <geom size="0.002" pos="0.02 0 0" rgba="1 0 0 1" contype="0" conaffinity="0" group="1" density="0"/>
              <site name="site_r_f_link2_4" pos="0.025 0.003 0" size="0.01" type="sphere"/>
              <geom name="col_r_f_link2_4" type="capsule" contype="1" conaffinity="1" group="3" size="0.0095" fromto="0.0 0 0 0.026 -0.007 0"/>
            </body>
            <geom name="col_r_f_link2_3" type="capsule" contype="1" conaffinity="1" group="3" size="0.007" fromto="0.012 0.003 -0.0035 0.012 0.003 0.0035"/>
          </body>
          <geom name="col_r_f_link2_2" type="capsule" contype="1" conaffinity="1" group="3" size="0.0095" fromto="0.005 0 0 0.03 0 0"/>
        </body>
      </body>
      <body name="r_f_link3_1" pos="0.006966 0.010612 0.1734" quat="0.707105 0 -0.707108 0">
        <inertial pos="0.007003 2.619e-09 0.00096932" quat="0.601863 0.371162 0.371162 0.601863" mass="0.0051273" diaginertia="3.9879e-07 3.4058e-07 2.5589e-07"/>
        <joint name="r_f_joint3_1" pos="0 0 0" axis="0 0 1" range="-0.001 0.001"/>
        <geom type="mesh" contype="0" conaffinity="0" group="1" density="0" rgba="0.79216 0.81961 0.93333 1" mesh="r_f_link3_1"/>
        <geom type="mesh" rgba="0.79216 0.81961 0.93333 1" mesh="r_f_link3_1" contype="0" conaffinity="0" group="1" density="0"/>
        <body name="r_f_link3_2" pos="0.017 0 0" quat="0.707105 -0.707108 0 0">
          <inertial pos="0.02116 -0.00059146 -2.1984e-06" quat="0.507863 0.503147 0.496172 0.492678" mass="0.011802" diaginertia="2.07728e-06 2.0592e-06 6.94909e-07"/>
          <joint name="r_f_joint3_2" pos="0 0 0" axis="0 0 1" range="0 1.3" actuatorfrcrange="-10 10"/>
          <geom type="mesh" contype="0" conaffinity="0" group="1" density="0" rgba="0.6 0.6 0.6 1" mesh="r_f_link3_2"/>
          <geom type="mesh" rgba="0.6 0.6 0.6 1" mesh="r_f_link3_2" contype="0" conaffinity="0" group="1" density="0"/>
          <body name="r_f_link3_3" pos="0.043 0 0">
            <inertial pos="0.013455 -0.00070241 -3.5721e-07" quat="0.0204051 0.706783 -0.0204379 0.70684" mass="0.005726" diaginertia="4.7655e-07 4.47482e-07 2.54788e-07"/>
            <joint name="r_f_joint3_3" pos="0 0 0" axis="0 0 1" range="0 1.3" actuatorfrcrange="-10 10"/>
            <geom type="mesh" contype="0" conaffinity="0" group="1" density="0" rgba="0.6 0.6 0.6 1" mesh="r_f_link3_3"/>
            <geom type="mesh" rgba="0.6 0.6 0.6 1" mesh="r_f_link3_3" contype="0" conaffinity="0" group="1" density="0"/>
            <body name="r_f_link3_4" pos="0.025 0 0">
              <inertial pos="-0.142313 -0.0157552 -0.00833951" quat="0.521187 0.431389 0.55381 0.485347" mass="0.51236" diaginertia="0.00219829 0.00179485 0.000604912"/>
              <joint name="r_f_joint3_4" pos="0 0 0" axis="0 0 1" range="0 1.3" actuatorfrcrange="-10 10"/>
              <geom type="mesh" contype="0" conaffinity="0" group="1" density="0" rgba="0.6 0.6 0.6 1" mesh="r_f_link3_4"/>
              <geom type="mesh" rgba="0.6 0.6 0.6 1" mesh="r_f_link3_4" contype="0" conaffinity="0" group="1" density="0"/>
              <geom size="0.002" pos="0.035 -0.004 0" contype="0" conaffinity="0" group="1" density="0" rgba="1 0 0 1"/>
              <geom size="0.002" pos="0.02 0 0" rgba="1 0 0 1" contype="0" conaffinity="0" group="1" density="0"/>
              <site name="site_r_f_link3_4" pos="0.025 0.003 0" size="0.01" type="sphere"/>
              <geom name="col_r_f_link3_4" type="capsule" contype="1" conaffinity="1" group="3" size="0.0095" fromto="0.0 0 0 0.026 -0.007 0"/>
            </body>
            <geom name="col_r_f_link3_3" type="capsule" contype="1" conaffinity="1" group="3" size="0.007" fromto="0.012 0.003 -0.0035 0.012 0.003 0.0035"/>
          </body>
          <geom name="col_r_f_link3_2" type="capsule" contype="1" conaffinity="1" group="3" size="0.0095" fromto="0.005 0 0 0.03 0 0"/>
        </body>
      </body>
      <body name="r_f_link4_1" pos="0.006966 -0.013688 0.1644" quat="-2.59734e-06 0.707105 2.59735e-06 0.707108">
        <inertial pos="0.007003 -2.619e-09 -0.00096933" quat="0.371162 0.601863 0.601863 0.371162" mass="0.0051273" diaginertia="3.9879e-07 3.4058e-07 2.5589e-07"/>
        <joint name="r_f_joint4_1" pos="0 0 0" axis="0 0 1" range="0 0.6" actuatorfrcrange="-10 10"/>
        <geom type="mesh" contype="0" conaffinity="0" group="1" density="0" rgba="0.79216 0.81961 0.93333 1" mesh="r_f_link4_1"/>
        <geom type="mesh" rgba="0.79216 0.81961 0.93333 1" mesh="r_f_link4_1" contype="0" conaffinity="0" group="1" density="0"/>
        <body name="r_f_link4_2" pos="0.017 0 0" quat="0.707105 0.707108 0 0">
          <inertial pos="0.02116 -0.00059146 -2.1984e-06" quat="0.507863 0.503147 0.496172 0.492678" mass="0.011802" diaginertia="2.07728e-06 2.0592e-06 6.94909e-07"/>
          <joint name="r_f_joint4_2" pos="0 0 0" axis="0 0 1" range="0 1.3" actuatorfrcrange="-10 10"/>
          <geom type="mesh" contype="0" conaffinity="0" group="1" density="0" rgba="0.6 0.6 0.6 1" mesh="r_f_link4_2"/>
          <geom type="mesh" rgba="0.6 0.6 0.6 1" mesh="r_f_link4_2" contype="0" conaffinity="0" group="1" density="0"/>
          <body name="r_f_link4_3" pos="0.043 0 0">
            <inertial pos="0.013455 -0.00070241 -3.572e-07" quat="0.0204051 0.706783 -0.0204379 0.70684" mass="0.005726" diaginertia="4.7655e-07 4.47482e-07 2.54788e-07"/>
            <joint name="r_f_joint4_3" pos="0 0 0" axis="0 0 1" range="0 1.3" actuatorfrcrange="-10 10"/>
            <geom type="mesh" contype="0" conaffinity="0" group="1" density="0" rgba="0.6 0.6 0.6 1" mesh="r_f_link4_3"/>
            <geom type="mesh" rgba="0.6 0.6 0.6 1" mesh="r_f_link4_3" contype="0" conaffinity="0" group="1" density="0"/>
            <body name="r_f_link4_4" pos="0.025 0 0">
              <inertial pos="-0.13333 -0.0157552 0.0159127" quat="0.520351 0.432138 0.554668 0.484598" mass="0.51236" diaginertia="0.00219538 0.00179193 0.000604955"/>
              <joint name="r_f_joint4_4" pos="0 0 0" axis="0 0 1" range="0 1.3" actuatorfrcrange="-10 10"/>
              <geom type="mesh" contype="0" conaffinity="0" group="1" density="0" rgba="0.6 0.6 0.6 1" mesh="r_f_link4_4"/>
              <geom type="mesh" rgba="0.6 0.6 0.6 1" mesh="r_f_link4_4" contype="0" conaffinity="0" group="1" density="0"/>
              <geom size="0.002" pos="0.035 -0.004 0" contype="0" conaffinity="0" group="1" density="0" rgba="1 0 0 1"/>
              <geom size="0.002" pos="0.02 0 0" rgba="1 0 0 1" contype="0" conaffinity="0" group="1" density="0"/>
              <site name="site_r_f_link4_4" pos="0.025 0.003 0" size="0.01" type="sphere"/>
              <geom name="col_r_f_link4_4" type="capsule" contype="1" conaffinity="1" group="3" size="0.0095" fromto="0.0 0 0 0.026 -0.007 0"/>
            </body>
            <geom name="col_r_f_link4_3" type="capsule" contype="1" conaffinity="1" group="3" size="0.007" fromto="0.012 0.003 -0.0035 0.012 0.003 0.0035"/>
          </body>
          <geom name="col_r_f_link4_2" type="capsule" contype="1" conaffinity="1" group="3" size="0.0095" fromto="0.005 0 0 0.03 0 0"/>
        </body>
      </body>
      <body name="r_f_link5_1" pos="0.006966 -0.037988 0.1504" quat="-2.59734e-06 0.707105 2.59735e-06 0.707108">
        <inertial pos="0.0080017 1.8833e-05 -0.0015869" quat="0.366604 0.60097 0.60931 0.364936" mass="0.003769" diaginertia="3.9885e-07 3.46938e-07 2.19942e-07"/>
        <joint name="r_f_joint5_1" pos="0 0 0" axis="0 0 1" range="0 0.6" actuatorfrcrange="-10 10"/>
        <geom type="mesh" contype="0" conaffinity="0" group="1" density="0" rgba="0.792157 0.819608 0.933333 1" mesh="r_f_link5_1"/>
        <geom type="mesh" rgba="0.792157 0.819608 0.933333 1" mesh="r_f_link5_1" contype="0" conaffinity="0" group="1" density="0"/>
        <body name="r_f_link5_2" pos="0.017 0 0" quat="0.707105 0.707108 0 0">
          <inertial pos="0.02116 -0.00059146 -2.1978e-06" quat="0.507864 0.503146 0.496173 0.492678" mass="0.011802" diaginertia="2.07728e-06 2.0592e-06 6.94909e-07"/>
          <joint name="r_f_joint5_2" pos="0 0 0" axis="0 0 1" range="0 1.3" actuatorfrcrange="-10 10"/>
          <geom type="mesh" contype="0" conaffinity="0" group="1" density="0" rgba="0.6 0.6 0.6 1" mesh="r_f_link5_2"/>
          <geom type="mesh" rgba="0.6 0.6 0.6 1" mesh="r_f_link5_2" contype="0" conaffinity="0" group="1" density="0"/>
          <body name="r_f_link5_3" pos="0.043 0 0">
            <inertial pos="0.013455 -0.00070241 -3.5727e-07" quat="0.0204052 0.706783 -0.0204379 0.70684" mass="0.005726" diaginertia="4.7655e-07 4.47482e-07 2.54788e-07"/>
            <joint name="r_f_joint5_3" pos="0 0 0" axis="0 0 1" range="0 1.3" actuatorfrcrange="-10 10"/>
            <geom type="mesh" contype="0" conaffinity="0" group="1" density="0" rgba="0.6 0.6 0.6 1" mesh="r_f_link5_3"/>
            <geom type="mesh" rgba="0.6 0.6 0.6 1" mesh="r_f_link5_3" contype="0" conaffinity="0" group="1" density="0"/>
            <body name="r_f_link5_4" pos="0.025 0 0">
              <inertial pos="-0.119357 -0.0157552 0.0401652" quat="0.519498 0.43292 0.555267 0.484129" mass="0.51236" diaginertia="0.00219233 0.00178783 0.000606145"/>
              <joint name="r_f_joint5_4" pos="0 0 0" axis="0 0 1" range="0 1.3" actuatorfrcrange="-10 10"/>
              <geom type="mesh" contype="0" conaffinity="0" group="1" density="0" rgba="0.6 0.6 0.6 1" mesh="r_f_link5_4"/>
              <geom type="mesh" rgba="0.6 0.6 0.6 1" mesh="r_f_link5_4" contype="0" conaffinity="0" group="1" density="0"/>
              <geom size="0.002" pos="0.035 -0.004 0" contype="0" conaffinity="0" group="1" density="0" rgba="1 0 0 1"/>
              <geom size="0.002" pos="0.02 0 0" rgba="1 0 0 1" contype="0" conaffinity="0" group="1" density="0"/>
              <site name="site_r_f_link5_4" pos="0.025 0.003 0" size="0.01" type="sphere"/>
              <geom name="col_r_f_link5_4" type="capsule" contype="1" conaffinity="1" group="3" size="0.0095" fromto="0.0 0 0 0.026 -0.007 0"/>
            </body>
            <geom name="col_r_f_link5_3" type="capsule" contype="1" conaffinity="1" group="3" size="0.007" fromto="0.012 0.003 -0.0035 0.012 0.003 0.0035"/>
          </body>
          <geom name="col_r_f_link5_2" type="capsule" contype="1" conaffinity="1" group="3" size="0.0095" fromto="0.005 0 0 0.03 0 0"/>
        </body>
      </body>
      <geom name="col_right_hand_base" type="box" contype="1" conaffinity="1" group="3" size="0.0273 0.05 0.05" pos="-0.0022 0 0.11"/>
    </body>
  </worldbody>
  <actuator>
    <position name="act_r_f_joint1_2" joint="r_f_joint1_2" kp="20" kv="0.1" ctrlrange="0 1.3" forcerange="-20 20"/>
    <position name="act_r_f_joint1_3" joint="r_f_joint1_3" kp="20" kv="0.1" ctrlrange="0 1.3" forcerange="-20 20"/>
    <position name="act_r_f_joint1_4" joint="r_f_joint1_4" kp="20" kv="0.1" ctrlrange="0 1.3" forcerange="-20 20"/>
    <position name="act_r_f_joint2_2" joint="r_f_joint2_2" kp="20" kv="0.1" ctrlrange="0 1.3" forcerange="-20 20"/>
    <position name="act_r_f_joint2_3" joint="r_f_joint2_3" kp="20" kv="0.1" ctrlrange="0 1.3" forcerange="-20 20"/>
    <position name="act_r_f_joint2_4" joint="r_f_joint2_4" kp="20" kv="0.1" ctrlrange="0 1.3" forcerange="-20 20"/>
    <position name="act_r_f_joint3_2" joint="r_f_joint3_2" kp="20" kv="0.1" ctrlrange="0 1.3" forcerange="-20 20"/>
    <position name="act_r_f_joint3_3" joint="r_f_joint3_3" kp="20" kv="0.1" ctrlrange="0 1.3" forcerange="-20 20"/>
    <position name="act_r_f_joint3_4" joint="r_f_joint3_4" kp="20" kv="0.1" ctrlrange="0 1.3" forcerange="-20 20"/>
    <position name="act_r_f_joint4_2" joint="r_f_joint4_2" kp="20" kv="0.1" ctrlrange="0 1.3" forcerange="-20 20"/>
    <position name="act_r_f_joint4_3" joint="r_f_joint4_3" kp="20" kv="0.1" ctrlrange="0 1.3" forcerange="-20 20"/>
    <position name="act_r_f_joint4_4" joint="r_f_joint4_4" kp="20" kv="0.1" ctrlrange="0 1.3" forcerange="-20 20"/>
    <position name="act_r_f_joint5_2" joint="r_f_joint5_2" kp="20" kv="0.1" ctrlrange="0 1.3" forcerange="-20 20"/>
    <position name="act_r_f_joint5_3" joint="r_f_joint5_3" kp="20" kv="0.1" ctrlrange="0 1.3" forcerange="-20 20"/>
    <position name="act_r_f_joint5_4" joint="r_f_joint5_4" kp="20" kv="0.1" ctrlrange="0 1.3" forcerange="-20 20"/>
    <position name="act_r_f_joint1_1" joint="r_f_joint1_1" kp="20" kv="1" ctrlrange="0 2.2" forcerange="-20 20"/>
    <position name="act_r_f_joint2_1" joint="r_f_joint2_1" kp="20" kv="1" ctrlrange="0 0.3" forcerange="-20 20"/>
    <position name="act_r_f_joint3_1" joint="r_f_joint3_1" kp="20" kv="1" ctrlrange="-0.0001 0.0001" forcerange="-20 20"/>
    <position name="act_r_f_joint4_1" joint="r_f_joint4_1" kp="20" kv="1" ctrlrange="0 0.3" forcerange="-20 20"/>
    <position name="act_r_f_joint5_1" joint="r_f_joint5_1" kp="20" kv="1" ctrlrange="0 0.6" forcerange="-20 20"/>
  </actuator>
  <sensor>
    <touch name="touch_r_f_link1_4" site="site_r_f_link1_4"/>
    <touch name="touch_r_f_link2_4" site="site_r_f_link2_4"/>
    <touch name="touch_r_f_link3_4" site="site_r_f_link3_4"/>
    <touch name="touch_r_f_link4_4" site="site_r_f_link4_4"/>
    <touch name="touch_r_f_link5_4" site="site_r_f_link5_4"/>
  </sensor>
  <contact>
    <exclude body1="right_hand_base" body2="r_f_link1_1"/>
    <exclude body1="right_hand_base" body2="r_f_link1_2"/>
    <exclude body1="right_hand_base" body2="r_f_link1_3"/>
    <exclude body1="right_hand_base" body2="r_f_link1_4"/>
    <exclude body1="right_hand_base" body2="r_f_link2_1"/>
    <exclude body1="right_hand_base" body2="r_f_link2_2"/>
    <exclude body1="right_hand_base" body2="r_f_link2_3"/>
    <exclude body1="right_hand_base" body2="r_f_link2_4"/>
    <exclude body1="right_hand_base" body2="r_f_link3_1"/>
    <exclude body1="right_hand_base" body2="r_f_link3_2"/>
    <exclude body1="right_hand_base" body2="r_f_link3_3"/>
    <exclude body1="right_hand_base" body2="r_f_link3_4"/>
    <exclude body1="right_hand_base" body2="r_f_link4_1"/>
    <exclude body1="right_hand_base" body2="r_f_link4_2"/>
    <exclude body1="right_hand_base" body2="r_f_link4_3"/>
    <exclude body1="right_hand_base" body2="r_f_link4_4"/>
    <exclude body1="right_hand_base" body2="r_f_link5_1"/>
    <exclude body1="right_hand_base" body2="r_f_link5_2"/>
    <exclude body1="right_hand_base" body2="r_f_link5_3"/>
    <exclude body1="right_hand_base" body2="r_f_link5_4"/>
    <exclude body1="r_f_link1_1" body2="r_f_link1_2"/>
    <exclude body1="r_f_link1_1" body2="r_f_link1_3"/>
    <exclude body1="r_f_link1_1" body2="r_f_link1_4"/>
    <exclude body1="r_f_link1_1" body2="r_f_link2_1"/>
    <exclude body1="r_f_link1_1" body2="r_f_link2_2"/>
    <exclude body1="r_f_link1_1" body2="r_f_link2_3"/>
    <exclude body1="r_f_link1_1" body2="r_f_link2_4"/>
    <exclude body1="r_f_link1_1" body2="r_f_link3_1"/>
    <exclude body1="r_f_link1_1" body2="r_f_link3_2"/>
    <exclude body1="r_f_link1_1" body2="r_f_link3_3"/>
    <exclude body1="r_f_link1_1" body2="r_f_link3_4"/>
    <exclude body1="r_f_link1_1" body2="r_f_link4_1"/>
    <exclude body1="r_f_link1_1" body2="r_f_link4_2"/>
    <exclude body1="r_f_link1_1" body2="r_f_link4_3"/>
    <exclude body1="r_f_link1_1" body2="r_f_link4_4"/>
    <exclude body1="r_f_link1_1" body2="r_f_link5_1"/>
    <exclude body1="r_f_link1_1" body2="r_f_link5_2"/>
    <exclude body1="r_f_link1_1" body2="r_f_link5_3"/>
    <exclude body1="r_f_link1_1" body2="r_f_link5_4"/>
    <exclude body1="r_f_link1_2" body2="r_f_link1_3"/>
    <exclude body1="r_f_link1_2" body2="r_f_link1_4"/>
    <exclude body1="r_f_link1_2" body2="r_f_link2_1"/>
    <exclude body1="r_f_link1_2" body2="r_f_link2_2"/>
    <exclude body1="r_f_link1_2" body2="r_f_link2_3"/>
    <exclude body1="r_f_link1_2" body2="r_f_link2_4"/>
    <exclude body1="r_f_link1_2" body2="r_f_link3_1"/>
    <exclude body1="r_f_link1_2" body2="r_f_link3_2"/>
    <exclude body1="r_f_link1_2" body2="r_f_link3_3"/>
    <exclude body1="r_f_link1_2" body2="r_f_link3_4"/>
    <exclude body1="r_f_link1_2" body2="r_f_link4_1"/>
    <exclude body1="r_f_link1_2" body2="r_f_link4_2"/>
    <exclude body1="r_f_link1_2" body2="r_f_link4_3"/>
    <exclude body1="r_f_link1_2" body2="r_f_link4_4"/>
    <exclude body1="r_f_link1_2" body2="r_f_link5_1"/>
    <exclude body1="r_f_link1_2" body2="r_f_link5_2"/>
    <exclude body1="r_f_link1_2" body2="r_f_link5_3"/>
    <exclude body1="r_f_link1_2" body2="r_f_link5_4"/>
    <exclude body1="r_f_link1_3" body2="r_f_link1_4"/>
    <exclude body1="r_f_link1_3" body2="r_f_link2_1"/>
    <exclude body1="r_f_link1_3" body2="r_f_link2_2"/>
    <exclude body1="r_f_link1_3" body2="r_f_link2_3"/>
    <exclude body1="r_f_link1_3" body2="r_f_link2_4"/>
    <exclude body1="r_f_link1_3" body2="r_f_link3_1"/>
    <exclude body1="r_f_link1_3" body2="r_f_link3_2"/>
    <exclude body1="r_f_link1_3" body2="r_f_link3_3"/>
    <exclude body1="r_f_link1_3" body2="r_f_link3_4"/>
    <exclude body1="r_f_link1_3" body2="r_f_link4_1"/>
    <exclude body1="r_f_link1_3" body2="r_f_link4_2"/>
    <exclude body1="r_f_link1_3" body2="r_f_link4_3"/>
    <exclude body1="r_f_link1_3" body2="r_f_link4_4"/>
    <exclude body1="r_f_link1_3" body2="r_f_link5_1"/>
    <exclude body1="r_f_link1_3" body2="r_f_link5_2"/>
    <exclude body1="r_f_link1_3" body2="r_f_link5_3"/>
    <exclude body1="r_f_link1_3" body2="r_f_link5_4"/>
    <exclude body1="r_f_link1_4" body2="r_f_link2_1"/>
    <exclude body1="r_f_link1_4" body2="r_f_link2_2"/>
    <exclude body1="r_f_link1_4" body2="r_f_link2_3"/>
    <exclude body1="r_f_link1_4" body2="r_f_link3_1"/>
    <exclude body1="r_f_link1_4" body2="r_f_link3_2"/>
    <exclude body1="r_f_link1_4" body2="r_f_link3_3"/>
    <exclude body1="r_f_link1_4" body2="r_f_link4_1"/>
    <exclude body1="r_f_link1_4" body2="r_f_link4_2"/>
    <exclude body1="r_f_link1_4" body2="r_f_link4_3"/>
    <exclude body1="r_f_link1_4" body2="r_f_link5_1"/>
    <exclude body1="r_f_link1_4" body2="r_f_link5_2"/>
    <exclude body1="r_f_link1_4" body2="r_f_link5_3"/>
    <exclude body1="r_f_link2_1" body2="r_f_link2_2"/>
    <exclude body1="r_f_link2_1" body2="r_f_link2_3"/>
    <exclude body1="r_f_link2_1" body2="r_f_link2_4"/>
    <exclude body1="r_f_link2_1" body2="r_f_link3_1"/>
    <exclude body1="r_f_link2_1" body2="r_f_link3_2"/>
    <exclude body1="r_f_link2_1" body2="r_f_link3_3"/>
    <exclude body1="r_f_link2_1" body2="r_f_link3_4"/>
    <exclude body1="r_f_link2_1" body2="r_f_link4_1"/>
    <exclude body1="r_f_link2_1" body2="r_f_link4_2"/>
    <exclude body1="r_f_link2_1" body2="r_f_link4_3"/>
    <exclude body1="r_f_link2_1" body2="r_f_link4_4"/>
    <exclude body1="r_f_link2_1" body2="r_f_link5_1"/>
    <exclude body1="r_f_link2_1" body2="r_f_link5_2"/>
    <exclude body1="r_f_link2_1" body2="r_f_link5_3"/>
    <exclude body1="r_f_link2_1" body2="r_f_link5_4"/>
    <exclude body1="r_f_link2_2" body2="r_f_link2_3"/>
    <exclude body1="r_f_link2_2" body2="r_f_link2_4"/>
    <exclude body1="r_f_link2_2" body2="r_f_link3_1"/>
    <exclude body1="r_f_link2_2" body2="r_f_link3_2"/>
    <exclude body1="r_f_link2_2" body2="r_f_link3_3"/>
    <exclude body1="r_f_link2_2" body2="r_f_link3_4"/>
    <exclude body1="r_f_link2_2" body2="r_f_link4_1"/>
    <exclude body1="r_f_link2_2" body2="r_f_link4_2"/>
    <exclude body1="r_f_link2_2" body2="r_f_link4_3"/>
    <exclude body1="r_f_link2_2" body2="r_f_link4_4"/>
    <exclude body1="r_f_link2_2" body2="r_f_link5_1"/>
    <exclude body1="r_f_link2_2" body2="r_f_link5_2"/>
    <exclude body1="r_f_link2_2" body2="r_f_link5_3"/>
    <exclude body1="r_f_link2_2" body2="r_f_link5_4"/>
    <exclude body1="r_f_link2_3" body2="r_f_link2_4"/>
    <exclude body1="r_f_link2_3" body2="r_f_link3_1"/>
    <exclude body1="r_f_link2_3" body2="r_f_link3_2"/>
    <exclude body1="r_f_link2_3" body2="r_f_link3_3"/>
    <exclude body1="r_f_link2_3" body2="r_f_link3_4"/>
    <exclude body1="r_f_link2_3" body2="r_f_link4_1"/>
    <exclude body1="r_f_link2_3" body2="r_f_link4_2"/>
    <exclude body1="r_f_link2_3" body2="r_f_link4_3"/>
    <exclude body1="r_f_link2_3" body2="r_f_link4_4"/>
    <exclude body1="r_f_link2_3" body2="r_f_link5_1"/>
    <exclude body1="r_f_link2_3" body2="r_f_link5_2"/>
    <exclude body1="r_f_link2_3" body2="r_f_link5_3"/>
    <exclude body1="r_f_link2_3" body2="r_f_link5_4"/>
    <exclude body1="r_f_link2_4" body2="r_f_link3_1"/>
    <exclude body1="r_f_link2_4" body2="r_f_link3_2"/>
    <exclude body1="r_f_link2_4" body2="r_f_link3_3"/>
    <exclude body1="r_f_link2_4" body2="r_f_link4_1"/>
    <exclude body1="r_f_link2_4" body2="r_f_link4_2"/>
    <exclude body1="r_f_link2_4" body2="r_f_link4_3"/>
    <exclude body1="r_f_link2_4" body2="r_f_link5_1"/>
    <exclude body1="r_f_link2_4" body2="r_f_link5_2"/>
    <exclude body1="r_f_link2_4" body2="r_f_link5_3"/>
    <exclude body1="r_f_link3_1" body2="r_f_link3_2"/>
    <exclude body1="r_f_link3_1" body2="r_f_link3_3"/>
    <exclude body1="r_f_link3_1" body2="r_f_link3_4"/>
    <exclude body1="r_f_link3_1" body2="r_f_link4_1"/>
    <exclude body1="r_f_link3_1" body2="r_f_link4_2"/>
    <exclude body1="r_f_link3_1" body2="r_f_link4_3"/>
    <exclude body1="r_f_link3_1" body2="r_f_link4_4"/>
    <exclude body1="r_f_link3_1" body2="r_f_link5_1"/>
    <exclude body1="r_f_link3_1" body2="r_f_link5_2"/>
    <exclude body1="r_f_link3_1" body2="r_f_link5_3"/>
    <exclude body1="r_f_link3_1" body2="r_f_link5_4"/>
    <exclude body1="r_f_link3_2" body2="r_f_link3_3"/>
    <exclude body1="r_f_link3_2" body2="r_f_link3_4"/>
    <exclude body1="r_f_link3_2" body2="r_f_link4_1"/>
    <exclude body1="r_f_link3_2" body2="r_f_link4_2"/>
    <exclude body1="r_f_link3_2" body2="r_f_link4_3"/>
    <exclude body1="r_f_link3_2" body2="r_f_link4_4"/>
    <exclude body1="r_f_link3_2" body2="r_f_link5_1"/>
    <exclude body1="r_f_link3_2" body2="r_f_link5_2"/>
    <exclude body1="r_f_link3_2" body2="r_f_link5_3"/>
    <exclude body1="r_f_link3_2" body2="r_f_link5_4"/>
    <exclude body1="r_f_link3_3" body2="r_f_link3_4"/>
    <exclude body1="r_f_link3_3" body2="r_f_link4_1"/>
    <exclude body1="r_f_link3_3" body2="r_f_link4_2"/>
    <exclude body1="r_f_link3_3" body2="r_f_link4_3"/>
    <exclude body1="r_f_link3_3" body2="r_f_link4_4"/>
    <exclude body1="r_f_link3_3" body2="r_f_link5_1"/>
    <exclude body1="r_f_link3_3" body2="r_f_link5_2"/>
    <exclude body1="r_f_link3_3" body2="r_f_link5_3"/>
    <exclude body1="r_f_link3_3" body2="r_f_link5_4"/>
    <exclude body1="r_f_link3_4" body2="r_f_link4_1"/>
    <exclude body1="r_f_link3_4" body2="r_f_link4_2"/>
    <exclude body1="r_f_link3_4" body2="r_f_link4_3"/>
    <exclude body1="r_f_link3_4" body2="r_f_link5_1"/>
    <exclude body1="r_f_link3_4" body2="r_f_link5_2"/>
    <exclude body1="r_f_link3_4" body2="r_f_link5_3"/>
    <exclude body1="r_f_link4_1" body2="r_f_link4_2"/>
    <exclude body1="r_f_link4_1" body2="r_f_link4_3"/>
    <exclude body1="r_f_link4_1" body2="r_f_link4_4"/>
    <exclude body1="r_f_link4_1" body2="r_f_link5_1"/>
    <exclude body1="r_f_link4_1" body2="r_f_link5_2"/>
    <exclude body1="r_f_link4_1" body2="r_f_link5_3"/>
    <exclude body1="r_f_link4_1" body2="r_f_link5_4"/>
    <exclude body1="r_f_link4_2" body2="r_f_link4_3"/>
    <exclude body1="r_f_link4_2" body2="r_f_link4_4"/>
    <exclude body1="r_f_link4_2" body2="r_f_link5_1"/>
    <exclude body1="r_f_link4_2" body2="r_f_link5_2"/>
    <exclude body1="r_f_link4_2" body2="r_f_link5_3"/>
    <exclude body1="r_f_link4_2" body2="r_f_link5_4"/>
    <exclude body1="r_f_link4_3" body2="r_f_link4_4"/>
    <exclude body1="r_f_link4_3" body2="r_f_link5_1"/>
    <exclude body1="r_f_link4_3" body2="r_f_link5_2"/>
    <exclude body1="r_f_link4_3" body2="r_f_link5_3"/>
    <exclude body1="r_f_link4_3" body2="r_f_link5_4"/>
    <exclude body1="r_f_link4_4" body2="r_f_link5_1"/>
    <exclude body1="r_f_link4_4" body2="r_f_link5_2"/>
    <exclude body1="r_f_link4_4" body2="r_f_link5_3"/>
    <exclude body1="r_f_link5_1" body2="r_f_link5_2"/>
    <exclude body1="r_f_link5_1" body2="r_f_link5_3"/>
    <exclude body1="r_f_link5_1" body2="r_f_link5_4"/>
    <exclude body1="r_f_link5_2" body2="r_f_link5_3"/>
    <exclude body1="r_f_link5_2" body2="r_f_link5_4"/>
    <exclude body1="r_f_link5_3" body2="r_f_link5_4"/>
  </contact>
</mujoco>
