<?xml version="1.0" encoding="utf-8"?>
<mujoco model="floating_base_dexhand021_right">
  <compiler meshdir=""/>
  <size njmax="1000" nconmax="1000"/>
  <default>
    <joint damping="1"/>
    <geom condim="3" solref="0.02 1" solimp="0.9 0.95 0.001" friction="2 2 2"/>
  </default>
  <option gravity="0 0 -9.81" iterations="100" solver="Newton" integrator="implicit" timestep="0.001"/>
  <visual>
    <global offwidth="1920" offheight="1080"/>
  </visual>
  <worldbody>
    <body name="floating_base">
      <inertial pos="0 0 0" quat="1 0 0 0" mass="0.01" diaginertia="0.01 0.01 0.01"/>
      <joint name="ARTx" pos="0 0 0" axis="1 0 0" type="slide" range="-1 1" damping="20"/>
      <joint name="ARTy" pos="0 0 0" axis="0 1 0" type="slide" range="-1 1" damping="20"/>
      <joint name="ARTz" pos="0 0 0" axis="0 0 1" type="slide" range="-1 1" damping="20"/>
      <joint name="ARRx" pos="0 0 0" axis="1 0 0" range="-3.14 3.14" damping="20"/>
      <joint name="ARRy" pos="0 0 0" axis="0 1 0" range="-3.14 3.14" damping="20"/>
      <joint name="ARRz" pos="0 0 0" axis="0 0 1" range="-3.14 3.14" damping="20"/>
      <body name="hand_base">
        <body name="right_hand_base" pos="0 0 0" quat="0.7071067811865476 0.0 0.7071067811865475 0.0">
          <geom pos="0 0 -0.17" quat="0.707388 0 0 -0.706825" type="mesh" contype="0" conaffinity="0" group="1" density="0" rgba="0.3 0.3 0.3 1" mesh="r_p_link0"/>
          <geom pos="0 0 -0.17" quat="0.707388 0 0 -0.706825" type="mesh" rgba="0.3 0.3 0.3 1" mesh="r_p_link0"/>
          <geom pos="0.032685 0.023881 0.10707" quat="0.775137 0.151553 0.0221905 0.612945" type="mesh" contype="0" conaffinity="0" group="1" density="0" rgba="0.3 0.3 0.3 1" mesh="r_p_link1"/>
          <geom pos="0.032685 0.023881 0.10707" quat="0.775137 0.151553 0.0221905 0.612945" type="mesh" rgba="0.3 0.3 0.3 1" mesh="r_p_link1"/>
          <geom pos="0.032685 0.023881 0.10707" quat="0.775137 0.151553 0.0221905 0.612945" type="mesh" contype="0" conaffinity="0" group="1" density="0" rgba="0.3 0.3 0.3 1" mesh="r_p_link3"/>
          <geom pos="0.032685 0.023881 0.10707" quat="0.775137 0.151553 0.0221905 0.612945" type="mesh" rgba="0.3 0.3 0.3 1" mesh="r_p_link3"/>
          <geom pos="0.032685 0.023881 0.10707" quat="0.775137 0.151553 0.0221905 0.612945" type="mesh" contype="0" conaffinity="0" group="1" density="0" rgba="0.9 0.9 0.9 1" mesh="r_p_link4"/>
          <geom pos="0.032685 0.023881 0.10707" quat="0.775137 0.151553 0.0221905 0.612945" type="mesh" rgba="0.9 0.9 0.9 1" mesh="r_p_link4"/>
          <geom pos="0.032685 0.023881 0.10707" quat="0.775137 0.151553 0.0221905 0.612945" type="mesh" contype="0" conaffinity="0" group="1" density="0" rgba="0.3 0.3 0.3 1" mesh="r_p_link5"/>
          <geom pos="0.032685 0.023881 0.10707" quat="0.775137 0.151553 0.0221905 0.612945" type="mesh" rgba="0.3 0.3 0.3 1" mesh="r_p_link5"/>
          <geom pos="0.032685 0.023881 0.10707" quat="0.775137 0.151553 0.0221905 0.612945" type="mesh" contype="0" conaffinity="0" group="1" density="0" rgba="0.9 0.9 0.9 1" mesh="r_p_link6"/>
          <geom pos="0.032685 0.023881 0.10707" quat="0.775137 0.151553 0.0221905 0.612945" type="mesh" rgba="0.9 0.9 0.9 1" mesh="r_p_link6"/>
          <geom pos="0.032685 0.023881 0.10707" quat="0.775137 0.151553 0.0221905 0.612945" type="mesh" contype="0" conaffinity="0" group="1" density="0" rgba="0.9 0.9 0.9 1" mesh="r_p_link2"/>
          <geom pos="0.032685 0.023881 0.10707" quat="0.775137 0.151553 0.0221905 0.612945" type="mesh" rgba="0.9 0.9 0.9 1" mesh="r_p_link2"/>
          <body name="r_f_link1_1" pos="0.032685 0.023881 0.10707" quat="0.775137 0.151553 0.0221905 0.612945">
            <inertial pos="0.00205223 -0.000372643 -0.0185288" quat="0.717691 0.0508717 0.02974 0.693864" mass="0.00518035" diaginertia="1.21881e-09 1.15459e-09 2.51191e-10"/>
            <joint name="r_f_joint1_1" pos="0 0 0" axis="0 0 -1" range="0 2.2" actuatorfrcrange="-10 10"/>
            <geom type="mesh" contype="0" conaffinity="0" group="1" density="0" rgba="0.3 0.3 0.3 1" mesh="r_f_link1_1"/>
            <geom type="mesh" rgba="0.3 0.3 0.3 1" mesh="r_f_link1_1"/>
            <body name="r_f_link1_2" pos="0.0083307 0 0" quat="0.707073 0.707076 0.0067524 -0.00675243">
              <inertial pos="0.0217194 0.000635197 0.00102982" quat="0.356639 0.461414 -0.543048 0.604156" mass="0.00931794" diaginertia="1.73539e-07 1.70521e-07 3.95581e-09"/>
              <joint name="r_f_joint1_2" pos="0 0 0" axis="0 0 1" range="0 1.3" actuatorfrcrange="-10 10"/>
              <geom type="mesh" contype="0" conaffinity="0" group="1" density="0" rgba="0.3 0.3 0.3 1" mesh="r_f_link1_2"/>
              <geom type="mesh" rgba="0.3 0.3 0.3 1" mesh="r_f_link1_2"/>
              <geom type="mesh" contype="0" conaffinity="0" group="1" density="0" rgba="0.3 0.3 0.3 1" mesh="r_f_link1_2_1"/>
              <geom type="mesh" rgba="0.3 0.3 0.3 1" mesh="r_f_link1_2_1"/>
              <geom type="mesh" contype="0" conaffinity="0" group="1" density="0" rgba="0.9 0.9 0.9 1" mesh="r_f_link1_2_2"/>
              <geom type="mesh" rgba="0.9 0.9 0.9 1" mesh="r_f_link1_2_2"/>
              <body name="r_f_link1_3" pos="0.043 0 0">
                <inertial pos="0.0130893 -0.000676815 0.00129681" quat="0.487389 0.508737 -0.490952 0.512449" mass="0.00492936" diaginertia="5.25091e-08 5.20908e-08 6.12707e-10"/>
                <joint name="r_f_joint1_3" pos="0 0 0" axis="0 0 1" range="0 1.3" actuatorfrcrange="-10 10"/>
                <geom type="mesh" contype="0" conaffinity="0" group="1" density="0" rgba="0.3 0.3 0.3 1" mesh="r_f_link1_3"/>
                <geom type="mesh" rgba="0.3 0.3 0.3 1" mesh="r_f_link1_3"/>
                <geom type="mesh" contype="0" conaffinity="0" group="1" density="0" rgba="0.3 0.3 0.3 1" mesh="r_f_link1_3_1"/>
                <geom type="mesh" rgba="0.3 0.3 0.3 1" mesh="r_f_link1_3_1"/>
                <geom type="mesh" contype="0" conaffinity="0" group="1" density="0" rgba="0.9 0.9 0.9 1" mesh="r_f_link1_3_2"/>
                <geom type="mesh" rgba="0.9 0.9 0.9 1" mesh="r_f_link1_3_2"/>
                <body name="r_f_link1_4" pos="0.025 0 0">
                  <inertial pos="0.016544 -0.00270681 0.00177433" quat="0.309089 0.436301 -0.628577 0.564798" mass="0.00767734" diaginertia="1.01491e-07 6.6472e-08 4.33595e-08"/>
                  <joint name="r_f_joint1_4" pos="0 0 0" axis="0 0 1" range="0 1.3" actuatorfrcrange="-10 10"/>
                  <geom type="mesh" contype="0" conaffinity="0" group="1" density="0" rgba="0.3 0.3 0.3 1" mesh="r_f_link1_4"/>
                  <geom type="mesh" rgba="0.3 0.3 0.3 1" mesh="r_f_link1_4"/>
                  <geom type="mesh" contype="0" conaffinity="0" group="1" density="0" rgba="0.3 0.3 0.3 1" mesh="r_f_link1_4_1"/>
                  <geom type="mesh" rgba="0.3 0.3 0.3 1" mesh="r_f_link1_4_1"/>
                  <geom type="mesh" contype="0" conaffinity="0" group="1" density="0" rgba="0.9 0.9 0.9 1" mesh="r_f_link1_4_2"/>
                  <geom type="mesh" rgba="0.9 0.9 0.9 1" mesh="r_f_link1_4_2"/>
                  <geom size="0.002" pos="0.035 -0.004 0" contype="0" conaffinity="0" group="1" density="0" rgba="1 0 0 1"/>
                  <geom size="0.002" pos="0.02 0 0" rgba="1 0 0 1"/>
                  <site name="site_r_f_link1_4" pos="0.025 0.003 0" size="0.01" type="sphere"/>
                </body>
              </body>
            </body>
          </body>
          <body name="r_f_link2_1" pos="0.0069382 0.0349175 0.1597" quat="0.000289373 -0.707107 -0.00029197 -0.707107">
            <inertial pos="0.00800686 1.83389e-05 -0.00158423" quat="0.365628 0.605241 0.605241 0.365628" mass="0.00351858" diaginertia="3.71985e-10 3.23711e-10 2.04965e-10"/>
            <joint name="r_f_joint2_1" pos="0 0 0" axis="0 0 -1" range="0 0.6" actuatorfrcrange="-10 10"/>
            <geom type="mesh" contype="0" conaffinity="0" group="1" density="0" rgba="0.3 0.3 0.3 1" mesh="r_f_link2_1"/>
            <geom type="mesh" rgba="0.3 0.3 0.3 1" mesh="r_f_link2_1"/>
            <body name="r_f_link2_2" pos="0.017 0 0" quat="0.707105 0.707108 0 0">
              <inertial pos="0.0214625 -0.000312324 -0.000276541" quat="0.429174 0.502978 -0.498903 0.560284" mass="0.00860339" diaginertia="8.84152e-08 8.76929e-08 2.26454e-09"/>
              <joint name="r_f_joint2_2" pos="0 0 0" axis="0 0 1" range="0 1.3" actuatorfrcrange="-10 10"/>
              <geom type="mesh" contype="0" conaffinity="0" group="1" density="0" rgba="0.3 0.3 0.3 1" mesh="r_f_link2_2"/>
              <geom type="mesh" rgba="0.3 0.3 0.3 1" mesh="r_f_link2_2"/>
              <geom type="mesh" contype="0" conaffinity="0" group="1" density="0" rgba="0.3 0.3 0.3 1" mesh="r_f_link2_2_1"/>
              <geom type="mesh" rgba="0.3 0.3 0.3 1" mesh="r_f_link2_2_1"/>
              <geom type="mesh" contype="0" conaffinity="0" group="1" density="0" rgba="0.9 0.9 0.9 1" mesh="r_f_link2_2_2"/>
              <geom type="mesh" rgba="0.9 0.9 0.9 1" mesh="r_f_link2_2_2"/>
              <body name="r_f_link2_3" pos="0.043 0 0">
                <inertial pos="0.0131211 -0.000590719 -1.26084e-05" quat="0.492887 0.514667 -0.484932 0.506972" mass="0.00474675" diaginertia="5.29702e-08 5.24876e-08 6.6966e-10"/>
                <joint name="r_f_joint2_3" pos="0 0 0" axis="0 0 1" range="0 1.3" actuatorfrcrange="-10 10"/>
                <geom type="mesh" contype="0" conaffinity="0" group="1" density="0" rgba="0.3 0.3 0.3 1" mesh="r_f_link2_3"/>
                <geom type="mesh" rgba="0.3 0.3 0.3 1" mesh="r_f_link2_3"/>
                <geom type="mesh" contype="0" conaffinity="0" group="1" density="0" rgba="0.3 0.3 0.3 1" mesh="r_f_link2_3_1"/>
                <geom type="mesh" rgba="0.3 0.3 0.3 1" mesh="r_f_link2_3_1"/>
                <geom type="mesh" contype="0" conaffinity="0" group="1" density="0" rgba="0.9 0.9 0.9 1" mesh="r_f_link2_3_2"/>
                <geom type="mesh" rgba="0.9 0.9 0.9 1" mesh="r_f_link2_3_2"/>
                <body name="r_f_link2_4" pos="0.025 0 0">
                  <inertial pos="0.0165327 -0.00269728 0.000649365" quat="0.274493 0.387094 -0.70656 0.524962" mass="0.0076892" diaginertia="1.1051e-07 7.05834e-08 5.20707e-08"/>
                  <joint name="r_f_joint2_4" pos="0 0 0" axis="0 0 1" range="0 1.3" actuatorfrcrange="-10 10"/>
                  <geom type="mesh" contype="0" conaffinity="0" group="1" density="0" rgba="0.3 0.3 0.3 1" mesh="r_f_link2_4"/>
                  <geom type="mesh" rgba="0.3 0.3 0.3 1" mesh="r_f_link2_4"/>
                  <geom type="mesh" contype="0" conaffinity="0" group="1" density="0" rgba="0.3 0.3 0.3 1" mesh="r_f_link2_4_1"/>
                  <geom type="mesh" rgba="0.3 0.3 0.3 1" mesh="r_f_link2_4_1"/>
                  <geom type="mesh" contype="0" conaffinity="0" group="1" density="0" rgba="0.9 0.9 0.9 1" mesh="r_f_link2_4_2"/>
                  <geom type="mesh" rgba="0.9 0.9 0.9 1" mesh="r_f_link2_4_2"/>
                  <geom size="0.002" pos="0.035 -0.004 0" contype="0" conaffinity="0" group="1" density="0" rgba="1 0 0 1"/>
                  <geom size="0.002" pos="0.02 0 0" rgba="1 0 0 1"/>
                  <site name="site_r_f_link2_4" pos="0.025 0.003 0" size="0.01" type="sphere"/>
                </body>
              </body>
            </body>
          </body>
          <body name="r_f_link3_1" pos="0.00695755 0.0106175 0.1687" quat="0.000278947 -0.707107 -0.000281544 -0.707107">
            <inertial pos="0.00800686 1.83389e-05 -0.00158423" quat="0.365628 0.605241 0.605241 0.365628" mass="0.00351858" diaginertia="3.71985e-10 3.23711e-10 2.04965e-10"/>
            <joint name="r_f_joint3_1" pos="0 0 0" axis="0 0 1" range="-0.001 0.001" actuatorfrcrange="-10 10"/>
            <geom type="mesh" contype="0" conaffinity="0" group="1" density="0" rgba="0.9 0.9 0.9 1" mesh="r_f_link3_1"/>
            <geom type="mesh" rgba="0.9 0.9 0.9 1" mesh="r_f_link3_1"/>
            <body name="r_f_link3_2" pos="0.017 0 0" quat="0.707105 0.707108 0 0">
              <inertial pos="0.0214625 -0.000312324 -0.000276541" quat="0.429174 0.502978 -0.498903 0.560284" mass="0.00860339" diaginertia="8.84152e-08 8.76929e-08 2.26454e-09"/>
              <joint name="r_f_joint3_2" pos="0 0 0" axis="0 0 1" range="0 1.3" actuatorfrcrange="-10 10"/>
              <geom type="mesh" contype="0" conaffinity="0" group="1" density="0" rgba="0.3 0.3 0.3 1" mesh="r_f_link3_2"/>
              <geom type="mesh" rgba="0.3 0.3 0.3 1" mesh="r_f_link3_2"/>
              <geom type="mesh" contype="0" conaffinity="0" group="1" density="0" rgba="0.3 0.3 0.3 1" mesh="r_f_link3_2_1"/>
              <geom type="mesh" rgba="0.3 0.3 0.3 1" mesh="r_f_link3_2_1"/>
              <geom type="mesh" contype="0" conaffinity="0" group="1" density="0" rgba="0.9 0.9 0.9 1" mesh="r_f_link3_2_2"/>
              <geom type="mesh" rgba="0.9 0.9 0.9 1" mesh="r_f_link3_2_2"/>
              <body name="r_f_link3_3" pos="0.043 0 0">
                <inertial pos="0.0131211 -0.000590719 -1.26084e-05" quat="0.492887 0.514667 -0.484932 0.506972" mass="0.00474675" diaginertia="5.29702e-08 5.24876e-08 6.6966e-10"/>
                <joint name="r_f_joint3_3" pos="0 0 0" axis="0 0 1" range="0 1.3" actuatorfrcrange="-10 10"/>
                <geom type="mesh" contype="0" conaffinity="0" group="1" density="0" rgba="0.3 0.3 0.3 1" mesh="r_f_link3_3"/>
                <geom type="mesh" rgba="0.3 0.3 0.3 1" mesh="r_f_link3_3"/>
                <geom type="mesh" contype="0" conaffinity="0" group="1" density="0" rgba="0.9 0.9 0.9 1" mesh="r_f_link3_3_1"/>
                <geom type="mesh" rgba="0.9 0.9 0.9 1" mesh="r_f_link3_3_1"/>
                <geom type="mesh" contype="0" conaffinity="0" group="1" density="0" rgba="0.9 0.9 0.9 1" mesh="r_f_link3_3_2"/>
                <geom type="mesh" rgba="0.9 0.9 0.9 1" mesh="r_f_link3_3_2"/>
                <body name="r_f_link3_4" pos="0.025 0 0">
                  <inertial pos="0.0165327 -0.00269728 0.000649365" quat="0.274493 0.387094 -0.70656 0.524962" mass="0.0076892" diaginertia="1.1051e-07 7.05834e-08 5.20707e-08"/>
                  <joint name="r_f_joint3_4" pos="0 0 0" axis="0 0 1" range="0 1.3" actuatorfrcrange="-10 10"/>
                  <geom type="mesh" contype="0" conaffinity="0" group="1" density="0" rgba="0.3 0.3 0.3 1" mesh="r_f_link3_4"/>
                  <geom type="mesh" rgba="0.3 0.3 0.3 1" mesh="r_f_link3_4"/>
                  <geom type="mesh" contype="0" conaffinity="0" group="1" density="0" rgba="0.3 0.3 0.3 1" mesh="r_f_link3_4_1"/>
                  <geom type="mesh" rgba="0.3 0.3 0.3 1" mesh="r_f_link3_4_1"/>
                  <geom type="mesh" contype="0" conaffinity="0" group="1" density="0" rgba="0.9 0.9 0.9 1" mesh="r_f_link3_4_2"/>
                  <geom type="mesh" rgba="0.9 0.9 0.9 1" mesh="r_f_link3_4_2"/>
                  <geom size="0.002" pos="0.035 -0.004 0" contype="0" conaffinity="0" group="1" density="0" rgba="1 0 0 1"/>
                  <geom size="0.002" pos="0.02 0 0" rgba="1 0 0 1"/>
                  <site name="site_r_f_link3_4" pos="0.025 0.003 0" size="0.01" type="sphere"/>
                </body>
              </body>
            </body>
          </body>
          <body name="r_f_link4_1" pos="0.0069769 -0.0136824 0.1597" quat="0.000278947 -0.707107 -0.000281544 -0.707107">
            <inertial pos="0.00800686 1.83389e-05 -0.00158423" quat="0.365628 0.605241 0.605241 0.365628" mass="0.00351858" diaginertia="3.71985e-10 3.23711e-10 2.04965e-10"/>
            <joint name="r_f_joint4_1" pos="0 0 0" axis="0 0 1" range="0 0.6" actuatorfrcrange="-10 10"/>
            <geom type="mesh" contype="0" conaffinity="0" group="1" density="0" rgba="0.9 0.9 0.9 1" mesh="r_f_link4_1"/>
            <geom type="mesh" rgba="0.9 0.9 0.9 1" mesh="r_f_link4_1"/>
            <body name="r_f_link4_2" pos="0.017 0 0" quat="0.707105 0.707108 0 0">
              <inertial pos="0.0214625 -0.000312324 -0.000276541" quat="0.429174 0.502978 -0.498903 0.560284" mass="0.00860339" diaginertia="8.84152e-08 8.76929e-08 2.26454e-09"/>
              <joint name="r_f_joint4_2" pos="0 0 0" axis="0 0 1" range="0 1.3" actuatorfrcrange="-10 10"/>
              <geom type="mesh" contype="0" conaffinity="0" group="1" density="0" rgba="0.3 0.3 0.3 1" mesh="r_f_link4_2"/>
              <geom type="mesh" rgba="0.3 0.3 0.3 1" mesh="r_f_link4_2"/>
              <geom type="mesh" contype="0" conaffinity="0" group="1" density="0" rgba="0.3 0.3 0.3 1" mesh="r_f_link4_2_1"/>
              <geom type="mesh" rgba="0.3 0.3 0.3 1" mesh="r_f_link4_2_1"/>
              <geom type="mesh" contype="0" conaffinity="0" group="1" density="0" rgba="0.9 0.9 0.9 1" mesh="r_f_link4_2_2"/>
              <geom type="mesh" rgba="0.9 0.9 0.9 1" mesh="r_f_link4_2_2"/>
              <body name="r_f_link4_3" pos="0.043 0 0">
                <inertial pos="0.0131211 -0.000590719 -1.26084e-05" quat="0.492887 0.514667 -0.484932 0.506972" mass="0.00474675" diaginertia="5.29702e-08 5.24876e-08 6.69661e-10"/>
                <joint name="r_f_joint4_3" pos="0 0 0" axis="0 0 1" range="0 1.3" actuatorfrcrange="-10 10"/>
                <geom type="mesh" contype="0" conaffinity="0" group="1" density="0" rgba="0.3 0.3 0.3 1" mesh="r_f_link4_3"/>
                <geom type="mesh" rgba="0.3 0.3 0.3 1" mesh="r_f_link4_3"/>
                <geom type="mesh" contype="0" conaffinity="0" group="1" density="0" rgba="0.9 0.9 0.9 1" mesh="r_f_link4_3_2"/>
                <geom type="mesh" rgba="0.9 0.9 0.9 1" mesh="r_f_link4_3_2"/>
                <geom type="mesh" contype="0" conaffinity="0" group="1" density="0" rgba="0.3 0.3 0.3 1" mesh="r_f_link4_3_1"/>
                <geom type="mesh" rgba="0.3 0.3 0.3 1" mesh="r_f_link4_3_1"/>
                <body name="r_f_link4_4" pos="0.025 0 0">
                  <inertial pos="0.0165327 -0.00269728 0.000649365" quat="0.274493 0.387094 -0.70656 0.524962" mass="0.0076892" diaginertia="1.1051e-07 7.05834e-08 5.20707e-08"/>
                  <joint name="r_f_joint4_4" pos="0 0 0" axis="0 0 1" range="0 1.3" actuatorfrcrange="-10 10"/>
                  <geom type="mesh" contype="0" conaffinity="0" group="1" density="0" rgba="0.3 0.3 0.3 1" mesh="r_f_link4_4"/>
                  <geom type="mesh" rgba="0.3 0.3 0.3 1" mesh="r_f_link4_4"/>
                  <geom type="mesh" contype="0" conaffinity="0" group="1" density="0" rgba="0.3 0.3 0.3 1" mesh="r_f_link4_4_1"/>
                  <geom type="mesh" rgba="0.3 0.3 0.3 1" mesh="r_f_link4_4_1"/>
                  <geom type="mesh" contype="0" conaffinity="0" group="1" density="0" rgba="0.9 0.9 0.9 1" mesh="r_f_link4_4_2"/>
                  <geom type="mesh" rgba="0.9 0.9 0.9 1" mesh="r_f_link4_4_2"/>
                  <geom size="0.002" pos="0.035 -0.004 0" contype="0" conaffinity="0" group="1" density="0" rgba="1 0 0 1"/>
                  <geom size="0.002" pos="0.02 0 0" rgba="1 0 0 1"/>
                  <site name="site_r_f_link4_4" pos="0.025 0.003 0" size="0.01" type="sphere"/>
                </body>
              </body>
            </body>
          </body>
          <body name="r_f_link5_1" pos="0.00699625 -0.0379824 0.1457" quat="0.000278947 -0.707107 -0.000281544 -0.707107">
            <inertial pos="0.00800686 1.83389e-05 -0.00158423" quat="0.365628 0.605241 0.605241 0.365628" mass="0.00351858" diaginertia="3.71985e-10 3.23711e-10 2.04965e-10"/>
            <joint name="r_f_joint5_1" pos="0 0 0" axis="0 0 1" range="0 0.6" actuatorfrcrange="-10 10"/>
            <geom type="mesh" contype="0" conaffinity="0" group="1" density="0" rgba="0.9 0.9 0.9 1" mesh="r_f_link5_1"/>
            <geom type="mesh" rgba="0.9 0.9 0.9 1" mesh="r_f_link5_1"/>
            <body name="r_f_link5_2" pos="0.017 0 0" quat="0.707105 0.707108 0 0">
              <inertial pos="0.0214625 -0.000312324 -0.000276541" quat="0.429174 0.502978 -0.498903 0.560284" mass="0.00860339" diaginertia="8.84152e-08 8.76929e-08 2.26454e-09"/>
              <joint name="r_f_joint5_2" pos="0 0 0" axis="0 0 1" range="0 1.3" actuatorfrcrange="-10 10"/>
              <geom type="mesh" contype="0" conaffinity="0" group="1" density="0" rgba="0.3 0.3 0.3 1" mesh="r_f_link5_2"/>
              <geom type="mesh" rgba="0.3 0.3 0.3 1" mesh="r_f_link5_2"/>
              <geom type="mesh" contype="0" conaffinity="0" group="1" density="0" rgba="0.3 0.3 0.3 1" mesh="r_f_link5_2_1"/>
              <geom type="mesh" rgba="0.3 0.3 0.3 1" mesh="r_f_link5_2_1"/>
              <geom type="mesh" contype="0" conaffinity="0" group="1" density="0" rgba="0.9 0.9 0.9 1" mesh="r_f_link5_2_2"/>
              <geom type="mesh" rgba="0.9 0.9 0.9 1" mesh="r_f_link5_2_2"/>
              <body name="r_f_link5_3" pos="0.043 0 0">
                <inertial pos="0.0131211 -0.000590719 -1.26084e-05" quat="0.492887 0.514667 -0.484932 0.506972" mass="0.00474675" diaginertia="5.29702e-08 5.24876e-08 6.6966e-10"/>
                <joint name="r_f_joint5_3" pos="0 0 0" axis="0 0 1" range="0 1.3" actuatorfrcrange="-10 10"/>
                <geom type="mesh" contype="0" conaffinity="0" group="1" density="0" rgba="0.3 0.3 0.3 1" mesh="r_f_link5_3"/>
                <geom type="mesh" rgba="0.3 0.3 0.3 1" mesh="r_f_link5_3"/>
                <geom type="mesh" contype="0" conaffinity="0" group="1" density="0" rgba="0.3 0.3 0.3 1" mesh="r_f_link5_3_1"/>
                <geom type="mesh" rgba="0.3 0.3 0.3 1" mesh="r_f_link5_3_1"/>
                <geom type="mesh" contype="0" conaffinity="0" group="1" density="0" rgba="0.9 0.9 0.9 1" mesh="r_f_link5_3_2"/>
                <geom type="mesh" rgba="0.9 0.9 0.9 1" mesh="r_f_link5_3_2"/>
                <body name="r_f_link5_4" pos="0.025 0 0">
                  <inertial pos="0.0165327 -0.00269728 0.000649365" quat="0.274493 0.387094 -0.70656 0.524962" mass="0.0076892" diaginertia="1.1051e-07 7.05834e-08 5.20707e-08"/>
                  <joint name="r_f_joint5_4" pos="0 0 0" axis="0 0 1" range="0 1.3" actuatorfrcrange="-10 10"/>
                  <geom type="mesh" contype="0" conaffinity="0" group="1" density="0" rgba="0.3 0.3 0.3 1" mesh="r_f_link5_4"/>
                  <geom type="mesh" rgba="0.3 0.3 0.3 1" mesh="r_f_link5_4"/>
                  <geom type="mesh" contype="0" conaffinity="0" group="1" density="0" rgba="0.3 0.3 0.3 1" mesh="r_f_link5_4_1"/>
                  <geom type="mesh" rgba="0.3 0.3 0.3 1" mesh="r_f_link5_4_1"/>
                  <geom type="mesh" contype="0" conaffinity="0" group="1" density="0" rgba="0.9 0.9 0.9 1" mesh="r_f_link5_4_2"/>
                  <geom type="mesh" rgba="0.9 0.9 0.9 1" mesh="r_f_link5_4_2"/>
                  <geom size="0.002" pos="0.035 -0.004 0" contype="0" conaffinity="0" group="1" density="0" rgba="1 0 0 1"/>
                  <geom size="0.002" pos="0.02 0 0" rgba="1 0 0 1"/>
                  <site name="site_r_f_link5_4" pos="0.025 0.003 0" size="0.01" type="sphere"/>
                </body>
              </body>
            </body>
          </body>
        </body>
      </body>
    </body>
  </worldbody>
  <actuator>
    <position name="act_ARTx" joint="ARTx" kp="10000" kv="500" ctrlrange="-1 1"/>
    <position name="act_ARTy" joint="ARTy" kp="10000" kv="500" ctrlrange="-1 1"/>
    <position name="act_ARTz" joint="ARTz" kp="10000" kv="500" ctrlrange="-1 1"/>
    <position name="act_ARRx" joint="ARRx" kp="10000" kv="500" ctrlrange="-3.14 3.14"/>
    <position name="act_ARRy" joint="ARRy" kp="10000" kv="500" ctrlrange="-3.14 3.14"/>
    <position name="act_ARRz" joint="ARRz" kp="10000" kv="500" ctrlrange="-3.14 3.14"/>
    <position name="act_r_f_joint1_2" joint="r_f_joint1_2" kp="20" kv="0.1" ctrlrange="0 1.3" forcerange="-20 20"/>
    <position name="act_r_f_joint1_3" joint="r_f_joint1_3" kp="20" kv="0.1" ctrlrange="0 1.3" forcerange="-20 20"/>
    <position name="act_r_f_joint1_4" joint="r_f_joint1_4" kp="20" kv="0.1" ctrlrange="0 1.3" forcerange="-20 20"/>
    <position name="act_r_f_joint2_2" joint="r_f_joint2_2" kp="20" kv="0.1" ctrlrange="0 1.3" forcerange="-20 20"/>
    <position name="act_r_f_joint2_3" joint="r_f_joint2_3" kp="20" kv="0.1" ctrlrange="0 1.3" forcerange="-20 20"/>
    <position name="act_r_f_joint2_4" joint="r_f_joint2_4" kp="20" kv="0.1" ctrlrange="0 1.3" forcerange="-20 20"/>
    <position name="act_r_f_joint3_2" joint="r_f_joint3_2" kp="20" kv="0.1" ctrlrange="0 1.3" forcerange="-20 20"/>
    <position name="act_r_f_joint3_3" joint="r_f_joint3_3" kp="20" kv="0.1" ctrlrange="0 1.3" forcerange="-20 20"/>
    <position name="act_r_f_joint3_4" joint="r_f_joint3_4" kp="20" kv="0.1" ctrlrange="0 1.3" forcerange="-20 20"/>
    <position name="act_r_f_joint4_2" joint="r_f_joint4_2" kp="20" kv="0.1" ctrlrange="0 1.3" forcerange="-20 20"/>
    <position name="act_r_f_joint4_3" joint="r_f_joint4_3" kp="20" kv="0.1" ctrlrange="0 1.3" forcerange="-20 20"/>
    <position name="act_r_f_joint4_4" joint="r_f_joint4_4" kp="20" kv="0.1" ctrlrange="0 1.3" forcerange="-20 20"/>
    <position name="act_r_f_joint5_2" joint="r_f_joint5_2" kp="20" kv="0.1" ctrlrange="0 1.3" forcerange="-20 20"/>
    <position name="act_r_f_joint5_3" joint="r_f_joint5_3" kp="20" kv="0.1" ctrlrange="0 1.3" forcerange="-20 20"/>
    <position name="act_r_f_joint5_4" joint="r_f_joint5_4" kp="20" kv="0.1" ctrlrange="0 1.3" forcerange="-20 20"/>
    <position name="act_r_f_joint1_1" joint="r_f_joint1_1" kp="20" kv="1" ctrlrange="0 2.2" forcerange="-20 20"/>
    <position name="act_r_f_joint2_1" joint="r_f_joint2_1" kp="20" kv="1" ctrlrange="0 0.3" forcerange="-20 20"/>
    <position name="act_r_f_joint3_1" joint="r_f_joint3_1" kp="20" kv="1" ctrlrange="-0.0001 0.0001" forcerange="-20 20"/>
    <position name="act_r_f_joint4_1" joint="r_f_joint4_1" kp="20" kv="1" ctrlrange="0 0.3" forcerange="-20 20"/>
    <position name="act_r_f_joint5_1" joint="r_f_joint5_1" kp="20" kv="1" ctrlrange="0 0.6" forcerange="-20 20"/>
  </actuator>
  <asset>
    <mesh name="r_p_link0" file="../meshes/dexhand021/r_p_link0.STL"/>
    <mesh name="r_f_link1_1" file="../meshes/dexhand021/r_f_link1_1.STL"/>
    <mesh name="r_f_link1_2" file="../meshes/dexhand021/r_f_link1_2.STL"/>
    <mesh name="r_f_link1_3" file="../meshes/dexhand021/r_f_link1_3.STL"/>
    <mesh name="r_f_link1_4" file="../meshes/dexhand021/r_f_link1_4.STL"/>
    <mesh name="r_f_link1_4_1" file="../meshes/dexhand021/r_f_link1_4_1.STL"/>
    <mesh name="r_f_link1_4_2" file="../meshes/dexhand021/r_f_link1_4_2.STL"/>
    <mesh name="r_f_link1_3_1" file="../meshes/dexhand021/r_f_link1_3_1.STL"/>
    <mesh name="r_f_link1_3_2" file="../meshes/dexhand021/r_f_link1_3_2.STL"/>
    <mesh name="r_f_link1_2_1" file="../meshes/dexhand021/r_f_link1_2_1.STL"/>
    <mesh name="r_f_link1_2_2" file="../meshes/dexhand021/r_f_link1_2_2.STL"/>
    <mesh name="r_f_link2_1" file="../meshes/dexhand021/r_f_link2_1.STL"/>
    <mesh name="r_f_link2_2" file="../meshes/dexhand021/r_f_link2_2.STL"/>
    <mesh name="r_f_link2_3" file="../meshes/dexhand021/r_f_link2_3.STL"/>
    <mesh name="r_f_link2_4" file="../meshes/dexhand021/r_f_link2_4.STL"/>
    <mesh name="r_f_link2_4_1" file="../meshes/dexhand021/r_f_link2_4_1.STL"/>
    <mesh name="r_f_link2_4_2" file="../meshes/dexhand021/r_f_link2_4_2.STL"/>
    <mesh name="r_f_link2_3_1" file="../meshes/dexhand021/r_f_link2_3_1.STL"/>
    <mesh name="r_f_link2_3_2" file="../meshes/dexhand021/r_f_link2_3_2.STL"/>
    <mesh name="r_f_link2_2_1" file="../meshes/dexhand021/r_f_link2_2_1.STL"/>
    <mesh name="r_f_link2_2_2" file="../meshes/dexhand021/r_f_link2_2_2.STL"/>
    <mesh name="r_f_link3_1" file="../meshes/dexhand021/r_f_link3_1.STL"/>
    <mesh name="r_f_link3_2" file="../meshes/dexhand021/r_f_link3_2.STL"/>
    <mesh name="r_f_link3_3" file="../meshes/dexhand021/r_f_link3_3.STL"/>
    <mesh name="r_f_link3_4" file="../meshes/dexhand021/r_f_link3_4.STL"/>
    <mesh name="r_f_link3_4_1" file="../meshes/dexhand021/r_f_link3_4_1.STL"/>
    <mesh name="r_f_link3_4_2" file="../meshes/dexhand021/r_f_link3_4_2.STL"/>
    <mesh name="r_f_link3_3_1" file="../meshes/dexhand021/r_f_link3_3_1.STL"/>
    <mesh name="r_f_link3_3_2" file="../meshes/dexhand021/r_f_link3_3_2.STL"/>
    <mesh name="r_f_link3_2_1" file="../meshes/dexhand021/r_f_link3_2_1.STL"/>
    <mesh name="r_f_link3_2_2" file="../meshes/dexhand021/r_f_link3_2_2.STL"/>
    <mesh name="r_f_link4_1" file="../meshes/dexhand021/r_f_link4_1.STL"/>
    <mesh name="r_f_link4_2" file="../meshes/dexhand021/r_f_link4_2.STL"/>
    <mesh name="r_f_link4_3" file="../meshes/dexhand021/r_f_link4_3.STL"/>
    <mesh name="r_f_link4_4" file="../meshes/dexhand021/r_f_link4_4.STL"/>
    <mesh name="r_f_link4_4_1" file="../meshes/dexhand021/r_f_link4_4_1.STL"/>
    <mesh name="r_f_link4_4_2" file="../meshes/dexhand021/r_f_link4_4_2.STL"/>
    <mesh name="r_f_link4_3_2" file="../meshes/dexhand021/r_f_link4_3_2.STL"/>
    <mesh name="r_f_link4_3_1" file="../meshes/dexhand021/r_f_link4_3_1.STL"/>
    <mesh name="r_f_link4_2_1" file="../meshes/dexhand021/r_f_link4_2_1.STL"/>
    <mesh name="r_f_link4_2_2" file="../meshes/dexhand021/r_f_link4_2_2.STL"/>
    <mesh name="r_f_link5_1" file="../meshes/dexhand021/r_f_link5_1.STL"/>
    <mesh name="r_f_link5_2" file="../meshes/dexhand021/r_f_link5_2.STL"/>
    <mesh name="r_f_link5_3" file="../meshes/dexhand021/r_f_link5_3.STL"/>
    <mesh name="r_f_link5_4" file="../meshes/dexhand021/r_f_link5_4.STL"/>
    <mesh name="r_f_link5_4_1" file="../meshes/dexhand021/r_f_link5_4_1.STL"/>
    <mesh name="r_f_link5_4_2" file="../meshes/dexhand021/r_f_link5_4_2.STL"/>
    <mesh name="r_f_link5_3_1" file="../meshes/dexhand021/r_f_link5_3_1.STL"/>
    <mesh name="r_f_link5_3_2" file="../meshes/dexhand021/r_f_link5_3_2.STL"/>
    <mesh name="r_f_link5_2_1" file="../meshes/dexhand021/r_f_link5_2_1.STL"/>
    <mesh name="r_f_link5_2_2" file="../meshes/dexhand021/r_f_link5_2_2.STL"/>
    <mesh name="r_p_link1" file="../meshes/dexhand021/r_p_link1.STL"/>
    <mesh name="r_p_link3" file="../meshes/dexhand021/r_p_link3.STL"/>
    <mesh name="r_p_link4" file="../meshes/dexhand021/r_p_link4.STL"/>
    <mesh name="r_p_link5" file="../meshes/dexhand021/r_p_link5.STL"/>
    <mesh name="r_p_link6" file="../meshes/dexhand021/r_p_link6.STL"/>
    <mesh name="r_p_link2" file="../meshes/dexhand021/r_p_link2.STL"/>
  </asset>
  <sensor>
    <touch name="touch_r_f_link1_4" site="site_r_f_link1_4"/>
    <touch name="touch_r_f_link2_4" site="site_r_f_link2_4"/>
    <touch name="touch_r_f_link3_4" site="site_r_f_link3_4"/>
    <touch name="touch_r_f_link4_4" site="site_r_f_link4_4"/>
    <touch name="touch_r_f_link5_4" site="site_r_f_link5_4"/>
  </sensor>
  <contact>
    <exclude body1="right_hand_base" body2="r_f_link1_1"/>
    <exclude body1="right_hand_base" body2="r_f_link1_2"/>
    <exclude body1="right_hand_base" body2="r_f_link1_3"/>
    <exclude body1="right_hand_base" body2="r_f_link1_4"/>
    <exclude body1="right_hand_base" body2="r_f_link2_1"/>
    <exclude body1="right_hand_base" body2="r_f_link2_2"/>
    <exclude body1="right_hand_base" body2="r_f_link2_3"/>
    <exclude body1="right_hand_base" body2="r_f_link2_4"/>
    <exclude body1="right_hand_base" body2="r_f_link3_1"/>
    <exclude body1="right_hand_base" body2="r_f_link3_2"/>
    <exclude body1="right_hand_base" body2="r_f_link3_3"/>
    <exclude body1="right_hand_base" body2="r_f_link3_4"/>
    <exclude body1="right_hand_base" body2="r_f_link4_1"/>
    <exclude body1="right_hand_base" body2="r_f_link4_2"/>
    <exclude body1="right_hand_base" body2="r_f_link4_3"/>
    <exclude body1="right_hand_base" body2="r_f_link4_4"/>
    <exclude body1="right_hand_base" body2="r_f_link5_1"/>
    <exclude body1="right_hand_base" body2="r_f_link5_2"/>
    <exclude body1="right_hand_base" body2="r_f_link5_3"/>
    <exclude body1="right_hand_base" body2="r_f_link5_4"/>
    <exclude body1="r_f_link1_1" body2="r_f_link1_2"/>
    <exclude body1="r_f_link1_1" body2="r_f_link1_3"/>
    <exclude body1="r_f_link1_1" body2="r_f_link1_4"/>
    <exclude body1="r_f_link1_1" body2="r_f_link2_1"/>
    <exclude body1="r_f_link1_1" body2="r_f_link2_2"/>
    <exclude body1="r_f_link1_1" body2="r_f_link2_3"/>
    <exclude body1="r_f_link1_1" body2="r_f_link2_4"/>
    <exclude body1="r_f_link1_1" body2="r_f_link3_1"/>
    <exclude body1="r_f_link1_1" body2="r_f_link3_2"/>
    <exclude body1="r_f_link1_1" body2="r_f_link3_3"/>
    <exclude body1="r_f_link1_1" body2="r_f_link3_4"/>
    <exclude body1="r_f_link1_1" body2="r_f_link4_1"/>
    <exclude body1="r_f_link1_1" body2="r_f_link4_2"/>
    <exclude body1="r_f_link1_1" body2="r_f_link4_3"/>
    <exclude body1="r_f_link1_1" body2="r_f_link4_4"/>
    <exclude body1="r_f_link1_1" body2="r_f_link5_1"/>
    <exclude body1="r_f_link1_1" body2="r_f_link5_2"/>
    <exclude body1="r_f_link1_1" body2="r_f_link5_3"/>
    <exclude body1="r_f_link1_1" body2="r_f_link5_4"/>
    <exclude body1="r_f_link1_2" body2="r_f_link1_3"/>
    <exclude body1="r_f_link1_2" body2="r_f_link1_4"/>
    <exclude body1="r_f_link1_2" body2="r_f_link2_1"/>
    <exclude body1="r_f_link1_2" body2="r_f_link2_2"/>
    <exclude body1="r_f_link1_2" body2="r_f_link2_3"/>
    <exclude body1="r_f_link1_2" body2="r_f_link2_4"/>
    <exclude body1="r_f_link1_2" body2="r_f_link3_1"/>
    <exclude body1="r_f_link1_2" body2="r_f_link3_2"/>
    <exclude body1="r_f_link1_2" body2="r_f_link3_3"/>
    <exclude body1="r_f_link1_2" body2="r_f_link3_4"/>
    <exclude body1="r_f_link1_2" body2="r_f_link4_1"/>
    <exclude body1="r_f_link1_2" body2="r_f_link4_2"/>
    <exclude body1="r_f_link1_2" body2="r_f_link4_3"/>
    <exclude body1="r_f_link1_2" body2="r_f_link4_4"/>
    <exclude body1="r_f_link1_2" body2="r_f_link5_1"/>
    <exclude body1="r_f_link1_2" body2="r_f_link5_2"/>
    <exclude body1="r_f_link1_2" body2="r_f_link5_3"/>
    <exclude body1="r_f_link1_2" body2="r_f_link5_4"/>
    <exclude body1="r_f_link1_3" body2="r_f_link1_4"/>
    <exclude body1="r_f_link1_3" body2="r_f_link2_1"/>
    <exclude body1="r_f_link1_3" body2="r_f_link2_2"/>
    <exclude body1="r_f_link1_3" body2="r_f_link2_3"/>
    <exclude body1="r_f_link1_3" body2="r_f_link2_4"/>
    <exclude body1="r_f_link1_3" body2="r_f_link3_1"/>
    <exclude body1="r_f_link1_3" body2="r_f_link3_2"/>
    <exclude body1="r_f_link1_3" body2="r_f_link3_3"/>
    <exclude body1="r_f_link1_3" body2="r_f_link3_4"/>
    <exclude body1="r_f_link1_3" body2="r_f_link4_1"/>
    <exclude body1="r_f_link1_3" body2="r_f_link4_2"/>
    <exclude body1="r_f_link1_3" body2="r_f_link4_3"/>
    <exclude body1="r_f_link1_3" body2="r_f_link4_4"/>
    <exclude body1="r_f_link1_3" body2="r_f_link5_1"/>
    <exclude body1="r_f_link1_3" body2="r_f_link5_2"/>
    <exclude body1="r_f_link1_3" body2="r_f_link5_3"/>
    <exclude body1="r_f_link1_3" body2="r_f_link5_4"/>
    <exclude body1="r_f_link1_4" body2="r_f_link2_1"/>
    <exclude body1="r_f_link1_4" body2="r_f_link2_2"/>
    <exclude body1="r_f_link1_4" body2="r_f_link2_3"/>
    <exclude body1="r_f_link1_4" body2="r_f_link3_1"/>
    <exclude body1="r_f_link1_4" body2="r_f_link3_2"/>
    <exclude body1="r_f_link1_4" body2="r_f_link3_3"/>
    <exclude body1="r_f_link1_4" body2="r_f_link4_1"/>
    <exclude body1="r_f_link1_4" body2="r_f_link4_2"/>
    <exclude body1="r_f_link1_4" body2="r_f_link4_3"/>
    <exclude body1="r_f_link1_4" body2="r_f_link5_1"/>
    <exclude body1="r_f_link1_4" body2="r_f_link5_2"/>
    <exclude body1="r_f_link1_4" body2="r_f_link5_3"/>
    <exclude body1="r_f_link2_1" body2="r_f_link2_2"/>
    <exclude body1="r_f_link2_1" body2="r_f_link2_3"/>
    <exclude body1="r_f_link2_1" body2="r_f_link2_4"/>
    <exclude body1="r_f_link2_1" body2="r_f_link3_1"/>
    <exclude body1="r_f_link2_1" body2="r_f_link3_2"/>
    <exclude body1="r_f_link2_1" body2="r_f_link3_3"/>
    <exclude body1="r_f_link2_1" body2="r_f_link3_4"/>
    <exclude body1="r_f_link2_1" body2="r_f_link4_1"/>
    <exclude body1="r_f_link2_1" body2="r_f_link4_2"/>
    <exclude body1="r_f_link2_1" body2="r_f_link4_3"/>
    <exclude body1="r_f_link2_1" body2="r_f_link4_4"/>
    <exclude body1="r_f_link2_1" body2="r_f_link5_1"/>
    <exclude body1="r_f_link2_1" body2="r_f_link5_2"/>
    <exclude body1="r_f_link2_1" body2="r_f_link5_3"/>
    <exclude body1="r_f_link2_1" body2="r_f_link5_4"/>
    <exclude body1="r_f_link2_2" body2="r_f_link2_3"/>
    <exclude body1="r_f_link2_2" body2="r_f_link2_4"/>
    <exclude body1="r_f_link2_2" body2="r_f_link3_1"/>
    <exclude body1="r_f_link2_2" body2="r_f_link3_2"/>
    <exclude body1="r_f_link2_2" body2="r_f_link3_3"/>
    <exclude body1="r_f_link2_2" body2="r_f_link3_4"/>
    <exclude body1="r_f_link2_2" body2="r_f_link4_1"/>
    <exclude body1="r_f_link2_2" body2="r_f_link4_2"/>
    <exclude body1="r_f_link2_2" body2="r_f_link4_3"/>
    <exclude body1="r_f_link2_2" body2="r_f_link4_4"/>
    <exclude body1="r_f_link2_2" body2="r_f_link5_1"/>
    <exclude body1="r_f_link2_2" body2="r_f_link5_2"/>
    <exclude body1="r_f_link2_2" body2="r_f_link5_3"/>
    <exclude body1="r_f_link2_2" body2="r_f_link5_4"/>
    <exclude body1="r_f_link2_3" body2="r_f_link2_4"/>
    <exclude body1="r_f_link2_3" body2="r_f_link3_1"/>
    <exclude body1="r_f_link2_3" body2="r_f_link3_2"/>
    <exclude body1="r_f_link2_3" body2="r_f_link3_3"/>
    <exclude body1="r_f_link2_3" body2="r_f_link3_4"/>
    <exclude body1="r_f_link2_3" body2="r_f_link4_1"/>
    <exclude body1="r_f_link2_3" body2="r_f_link4_2"/>
    <exclude body1="r_f_link2_3" body2="r_f_link4_3"/>
    <exclude body1="r_f_link2_3" body2="r_f_link4_4"/>
    <exclude body1="r_f_link2_3" body2="r_f_link5_1"/>
    <exclude body1="r_f_link2_3" body2="r_f_link5_2"/>
    <exclude body1="r_f_link2_3" body2="r_f_link5_3"/>
    <exclude body1="r_f_link2_3" body2="r_f_link5_4"/>
    <exclude body1="r_f_link2_4" body2="r_f_link3_1"/>
    <exclude body1="r_f_link2_4" body2="r_f_link3_2"/>
    <exclude body1="r_f_link2_4" body2="r_f_link3_3"/>
    <exclude body1="r_f_link2_4" body2="r_f_link4_1"/>
    <exclude body1="r_f_link2_4" body2="r_f_link4_2"/>
    <exclude body1="r_f_link2_4" body2="r_f_link4_3"/>
    <exclude body1="r_f_link2_4" body2="r_f_link5_1"/>
    <exclude body1="r_f_link2_4" body2="r_f_link5_2"/>
    <exclude body1="r_f_link2_4" body2="r_f_link5_3"/>
    <exclude body1="r_f_link3_1" body2="r_f_link3_2"/>
    <exclude body1="r_f_link3_1" body2="r_f_link3_3"/>
    <exclude body1="r_f_link3_1" body2="r_f_link3_4"/>
    <exclude body1="r_f_link3_1" body2="r_f_link4_1"/>
    <exclude body1="r_f_link3_1" body2="r_f_link4_2"/>
    <exclude body1="r_f_link3_1" body2="r_f_link4_3"/>
    <exclude body1="r_f_link3_1" body2="r_f_link4_4"/>
    <exclude body1="r_f_link3_1" body2="r_f_link5_1"/>
    <exclude body1="r_f_link3_1" body2="r_f_link5_2"/>
    <exclude body1="r_f_link3_1" body2="r_f_link5_3"/>
    <exclude body1="r_f_link3_1" body2="r_f_link5_4"/>
    <exclude body1="r_f_link3_2" body2="r_f_link3_3"/>
    <exclude body1="r_f_link3_2" body2="r_f_link3_4"/>
    <exclude body1="r_f_link3_2" body2="r_f_link4_1"/>
    <exclude body1="r_f_link3_2" body2="r_f_link4_2"/>
    <exclude body1="r_f_link3_2" body2="r_f_link4_3"/>
    <exclude body1="r_f_link3_2" body2="r_f_link4_4"/>
    <exclude body1="r_f_link3_2" body2="r_f_link5_1"/>
    <exclude body1="r_f_link3_2" body2="r_f_link5_2"/>
    <exclude body1="r_f_link3_2" body2="r_f_link5_3"/>
    <exclude body1="r_f_link3_2" body2="r_f_link5_4"/>
    <exclude body1="r_f_link3_3" body2="r_f_link3_4"/>
    <exclude body1="r_f_link3_3" body2="r_f_link4_1"/>
    <exclude body1="r_f_link3_3" body2="r_f_link4_2"/>
    <exclude body1="r_f_link3_3" body2="r_f_link4_3"/>
    <exclude body1="r_f_link3_3" body2="r_f_link4_4"/>
    <exclude body1="r_f_link3_3" body2="r_f_link5_1"/>
    <exclude body1="r_f_link3_3" body2="r_f_link5_2"/>
    <exclude body1="r_f_link3_3" body2="r_f_link5_3"/>
    <exclude body1="r_f_link3_3" body2="r_f_link5_4"/>
    <exclude body1="r_f_link3_4" body2="r_f_link4_1"/>
    <exclude body1="r_f_link3_4" body2="r_f_link4_2"/>
    <exclude body1="r_f_link3_4" body2="r_f_link4_3"/>
    <exclude body1="r_f_link3_4" body2="r_f_link5_1"/>
    <exclude body1="r_f_link3_4" body2="r_f_link5_2"/>
    <exclude body1="r_f_link3_4" body2="r_f_link5_3"/>
    <exclude body1="r_f_link4_1" body2="r_f_link4_2"/>
    <exclude body1="r_f_link4_1" body2="r_f_link4_3"/>
    <exclude body1="r_f_link4_1" body2="r_f_link4_4"/>
    <exclude body1="r_f_link4_1" body2="r_f_link5_1"/>
    <exclude body1="r_f_link4_1" body2="r_f_link5_2"/>
    <exclude body1="r_f_link4_1" body2="r_f_link5_3"/>
    <exclude body1="r_f_link4_1" body2="r_f_link5_4"/>
    <exclude body1="r_f_link4_2" body2="r_f_link4_3"/>
    <exclude body1="r_f_link4_2" body2="r_f_link4_4"/>
    <exclude body1="r_f_link4_2" body2="r_f_link5_1"/>
    <exclude body1="r_f_link4_2" body2="r_f_link5_2"/>
    <exclude body1="r_f_link4_2" body2="r_f_link5_3"/>
    <exclude body1="r_f_link4_2" body2="r_f_link5_4"/>
    <exclude body1="r_f_link4_3" body2="r_f_link4_4"/>
    <exclude body1="r_f_link4_3" body2="r_f_link5_1"/>
    <exclude body1="r_f_link4_3" body2="r_f_link5_2"/>
    <exclude body1="r_f_link4_3" body2="r_f_link5_3"/>
    <exclude body1="r_f_link4_3" body2="r_f_link5_4"/>
    <exclude body1="r_f_link4_4" body2="r_f_link5_1"/>
    <exclude body1="r_f_link4_4" body2="r_f_link5_2"/>
    <exclude body1="r_f_link4_4" body2="r_f_link5_3"/>
    <exclude body1="r_f_link5_1" body2="r_f_link5_2"/>
    <exclude body1="r_f_link5_1" body2="r_f_link5_3"/>
    <exclude body1="r_f_link5_1" body2="r_f_link5_4"/>
    <exclude body1="r_f_link5_2" body2="r_f_link5_3"/>
    <exclude body1="r_f_link5_2" body2="r_f_link5_4"/>
    <exclude body1="r_f_link5_3" body2="r_f_link5_4"/>
  </contact>
</mujoco>
