<?xml version="1.0" encoding="utf-8"?>
<mujoco model="dexhand021_left_simplified">
  <visual>
    <global offwidth="1920" offheight="1080"/>
  </visual>
  <option gravity="0 0 -9.81" iterations="100" solver="Newton" integrator="implicit" timestep="0.001"/>
  <default>
    <joint damping="1"/>
    <geom condim="3" solref="0.02 1" solimp="0.9 0.95 0.001" friction="2 2 2"/>
  </default>
  <size njmax="1000" nconmax="1000"/>
  <compiler angle="radian" meshdir="../meshes/dexhand021_simplified/"/>
  <asset>
    <mesh name="left_hand_base" file="left_hand_base.STL"/>
    <mesh name="l_f_link1_1" file="l_f_link1_1.STL"/>
    <mesh name="l_f_link1_2" file="l_f_link1_2.STL"/>
    <mesh name="l_f_link1_3" file="l_f_link1_3.STL"/>
    <mesh name="l_f_link1_4" file="l_f_link1_4.STL"/>
    <mesh name="l_f_link2_1" file="l_f_link2_1.STL"/>
    <mesh name="l_f_link2_2" file="l_f_link2_2.STL"/>
    <mesh name="l_f_link2_3" file="l_f_link2_3.STL"/>
    <mesh name="l_f_link2_4" file="l_f_link2_4.STL"/>
    <mesh name="l_f_link3_1" file="l_f_link3_1.STL"/>
    <mesh name="l_f_link3_2" file="l_f_link3_2.STL"/>
    <mesh name="l_f_link3_3" file="l_f_link3_3.STL"/>
    <mesh name="l_f_link3_4" file="l_f_link3_4.STL"/>
    <mesh name="l_f_link4_1" file="l_f_link4_1.STL"/>
    <mesh name="l_f_link4_2" file="l_f_link4_2.STL"/>
    <mesh name="l_f_link4_3" file="l_f_link4_3.STL"/>
    <mesh name="l_f_link4_4" file="l_f_link4_4.STL"/>
    <mesh name="l_f_link5_1" file="l_f_link5_1.STL"/>
    <mesh name="l_f_link5_2" file="l_f_link5_2.STL"/>
    <mesh name="l_f_link5_3" file="l_f_link5_3.STL"/>
    <mesh name="l_f_link5_4" file="l_f_link5_4.STL"/>
  </asset>
  <worldbody>
    <body name="left_hand_base" pos="0 0 0" quat="1 0 0 0">
      <geom type="mesh" contype="0" conaffinity="0" group="1" density="0" rgba="0.75294 0.75294 0.75294 1" mesh="left_hand_base"/>
      <geom type="mesh" rgba="0.75294 0.75294 0.75294 1" mesh="left_hand_base" contype="0" conaffinity="0" group="1" density="0"/>
      <body name="l_f_link1_1" pos="0.032783 -0.023781 0.11211" quat="0.775383 -0.151562 0.0221299 -0.612635">
        <inertial pos="0.00198057 -0.000351992 -0.0134513" quat="0.716563 0.0774262 0.0529366 0.691188" mass="0.00440965" diaginertia="5.49405e-10 4.74824e-10 2.47827e-10"/>
        <joint name="l_f_joint1_1" pos="0 0 0" axis="0 0 1" range="0 2.2" actuatorfrcrange="-10 10"/>
        <geom type="mesh" contype="0" conaffinity="0" group="1" density="0" rgba="0.6 0.6 0.6 1" mesh="l_f_link1_1"/>
        <geom type="mesh" rgba="0.6 0.6 0.6 1" mesh="l_f_link1_1" contype="0" conaffinity="0" group="1" density="0"/>
        <body name="l_f_link1_2" pos="0.0083307 0 0" quat="0.707105 0.707108 0 0">
          <inertial pos="0.021435 0.000179938 0.0012982" quat="0.0148182 0.707343 -0.0148346 0.706559" mass="0.00995163" diaginertia="2.13739e-09 2.06936e-09 7.73786e-10"/>
          <joint name="l_f_joint1_2" pos="0 0 0" axis="0 0 1" range="0 1.3" actuatorfrcrange="-10 10"/>
          <geom type="mesh" contype="0" conaffinity="0" group="1" density="0" rgba="0.6 0.6 0.6 1" mesh="l_f_link1_2"/>
          <geom type="mesh" rgba="0.6 0.6 0.6 1" mesh="l_f_link1_2" contype="0" conaffinity="0" group="1" density="0"/>
          <body name="l_f_link1_3" pos="0.043 0 0">
            <inertial pos="0.0134587 -0.000699415 0.00129313" quat="0.0206011 0.706807 -0.0206011 0.706807" mass="0.00457275" diaginertia="4.74657e-10 4.45639e-10 2.5398e-10"/>
            <joint name="l_f_joint1_3" pos="0 0 0" axis="0 0 1" range="0 1.3" actuatorfrcrange="-10 10"/>
            <geom type="mesh" contype="0" conaffinity="0" group="1" density="0" rgba="0.6 0.6 0.6 1" mesh="l_f_link1_3"/>
            <geom type="mesh" rgba="0.6 0.6 0.6 1" mesh="l_f_link1_3" contype="0" conaffinity="0" group="1" density="0"/>
            <body name="l_f_link1_4" pos="0.025 0 0">
              <inertial pos="0.0167833 -0.00318009 0.00181094" quat="0.751934 -0.097114 0.450588 0.471312" mass="0.00715824" diaginertia="3.75434e-08 3.70628e-08 1.84889e-09"/>
              <joint name="l_f_joint1_4" pos="0 0 0" axis="0 0 1" range="0 1.3" actuatorfrcrange="-10 10"/>
              <geom type="mesh" contype="0" conaffinity="0" group="1" density="0" rgba="0.6 0.6 0.6 1" mesh="l_f_link1_4"/>
              <geom type="mesh" rgba="0.6 0.6 0.6 1" mesh="l_f_link1_4" contype="0" conaffinity="0" group="1" density="0"/>
              <geom size="0.002" pos="0.035 -0.004 0" contype="0" conaffinity="0" group="1" density="0" rgba="1 0 0 1"/>
              <geom size="0.002" pos="0.02 0 0" rgba="1 0 0 1" contype="0" conaffinity="0" group="1" density="0"/>
              <site name="site_l_f_link1_4" pos="0.025 0.003 0" size="0.01" type="sphere"/>
              <geom name="col_l_f_link1_4" type="capsule" contype="1" conaffinity="1" group="3" size="0.0095" fromto="0.0 0 0.001 0.027 -0.007 0.001"/>
            </body>
            <geom name="col_l_f_link1_3" type="capsule" contype="1" conaffinity="1" group="3" size="0.007" fromto="0.0125 0.003 -0.002 0.0125 0.003 0.0042"/>
          </body>
          <geom name="col_l_f_link1_2" type="capsule" contype="1" conaffinity="1" group="3" size="0.0095" fromto="0.0 0 0 0.03 0 0.002"/>
        </body>
      </body>
      <body name="l_f_link2_1" pos="0.006966 -0.034912 0.1644" quat="-2.59734e-06 0.707105 2.59735e-06 0.707108">
        <inertial pos="0.00700212 1.08537e-07 -0.00096856" quat="0.370756 0.602113 0.602113 0.370756" mass="0.00409701" diaginertia="3.97653e-10 3.39654e-10 2.55255e-10"/>
        <joint name="l_f_joint2_1" pos="0 0 0" axis="0 0 1" range="0 0.6" actuatorfrcrange="-10 10"/>
        <geom type="mesh" contype="0" conaffinity="0" group="1" density="0" rgba="0.792157 0.819608 0.933333 1" mesh="l_f_link2_1"/>
        <geom type="mesh" rgba="0.792157 0.819608 0.933333 1" mesh="l_f_link2_1" contype="0" conaffinity="0" group="1" density="0"/>
        <body name="l_f_link2_2" pos="0.017 0 0" quat="0.707105 0.707108 0 0">
          <inertial pos="0.0211622 -0.000590378 2.72622e-06" quat="0.5052 0.505863 0.494731 0.494083" mass="0.0094283" diaginertia="2.07226e-09 2.05417e-09 6.929e-10"/>
          <joint name="l_f_joint2_2" pos="0 0 0" axis="0 0 1" range="0 1.3" actuatorfrcrange="-10 10"/>
          <geom type="mesh" contype="0" conaffinity="0" group="1" density="0" rgba="0.6 0.6 0.6 1" mesh="l_f_link2_2"/>
          <geom type="mesh" rgba="0.6 0.6 0.6 1" mesh="l_f_link2_2" contype="0" conaffinity="0" group="1" density="0"/>
          <body name="l_f_link2_3" pos="0.043 0 0">
            <inertial pos="0.0134587 -0.000699415 7.12893e-07" quat="0.0206011 0.706807 -0.0206011 0.706807" mass="0.00457275" diaginertia="4.74657e-10 4.45639e-10 2.5398e-10"/>
            <joint name="l_f_joint2_3" pos="0 0 0" axis="0 0 1" range="0 1.3" actuatorfrcrange="-10 10"/>
            <geom type="mesh" contype="0" conaffinity="0" group="1" density="0" rgba="0.6 0.6 0.6 1" mesh="l_f_link2_3"/>
            <geom type="mesh" rgba="0.6 0.6 0.6 1" mesh="l_f_link2_3" contype="0" conaffinity="0" group="1" density="0"/>
            <body name="l_f_link2_4" pos="0.025 0 0">
              <inertial pos="0.0167833 -0.00318009 0.000699111" quat="0.764722 -0.0731366 0.387992 0.509228" mass="0.00715824" diaginertia="4.72306e-08 4.672e-08 1.86403e-09"/>
              <joint name="l_f_joint2_4" pos="0 0 0" axis="0 0 1" range="0 1.3" actuatorfrcrange="-10 10"/>
              <geom type="mesh" contype="0" conaffinity="0" group="1" density="0" rgba="0.6 0.6 0.6 1" mesh="l_f_link2_4"/>
              <geom type="mesh" rgba="0.6 0.6 0.6 1" mesh="l_f_link2_4" contype="0" conaffinity="0" group="1" density="0"/>
              <geom size="0.002" pos="0.035 -0.004 0" contype="0" conaffinity="0" group="1" density="0" rgba="1 0 0 1"/>
              <geom size="0.002" pos="0.02 0 0" rgba="1 0 0 1" contype="0" conaffinity="0" group="1" density="0"/>
              <site name="site_l_f_link2_4" pos="0.025 0.003 0" size="0.01" type="sphere"/>
              <geom name="col_l_f_link2_4" type="capsule" contype="1" conaffinity="1" group="3" size="0.0095" fromto="0.0 0 0 0.026 -0.007 0"/>
            </body>
            <geom name="col_l_f_link2_3" type="capsule" contype="1" conaffinity="1" group="3" size="0.007" fromto="0.012 0.003 -0.0035 0.012 0.003 0.0035"/>
          </body>
          <geom name="col_l_f_link2_2" type="capsule" contype="1" conaffinity="1" group="3" size="0.0095" fromto="0.005 0 0 0.03 0 0"/>
        </body>
      </body>
      <body name="l_f_link3_1" pos="0.006966 -0.010612 0.1734" quat="-2.59734e-06 0.707105 2.59735e-06 0.707108">
        <inertial pos="0.00700212 1.07469e-07 -0.000968557" quat="0.370756 0.602113 0.602113 0.370756" mass="0.00409701" diaginertia="3.97653e-10 3.39654e-10 2.55254e-10"/>
        <joint name="l_f_joint3_1" pos="0 0 0" axis="0 0 1" range="-0.001 0.001" actuatorfrcrange="-10 10"/>
        <geom type="mesh" contype="0" conaffinity="0" group="1" density="0" rgba="0.792157 0.819608 0.933333 1" mesh="l_f_link3_1"/>
        <geom type="mesh" rgba="0.792157 0.819608 0.933333 1" mesh="l_f_link3_1" contype="0" conaffinity="0" group="1" density="0"/>
        <body name="l_f_link3_2" pos="0.017 0 0" quat="0.707105 0.707108 0 0">
          <inertial pos="0.0211622 -0.000590378 2.72622e-06" quat="0.5052 0.505863 0.494731 0.494083" mass="0.0094283" diaginertia="2.07226e-09 2.05417e-09 6.929e-10"/>
          <joint name="l_f_joint3_2" pos="0 0 0" axis="0 0 1" range="0 1.3" actuatorfrcrange="-10 10"/>
          <geom type="mesh" contype="0" conaffinity="0" group="1" density="0" rgba="0.6 0.6 0.6 1" mesh="l_f_link3_2"/>
          <geom type="mesh" rgba="0.6 0.6 0.6 1" mesh="l_f_link3_2" contype="0" conaffinity="0" group="1" density="0"/>
          <body name="l_f_link3_3" pos="0.043 0 0">
            <inertial pos="0.0134587 -0.000699415 7.12894e-07" quat="0.0206011 0.706807 -0.0206011 0.706807" mass="0.00457275" diaginertia="4.74657e-10 4.45639e-10 2.5398e-10"/>
            <joint name="l_f_joint3_3" pos="0 0 0" axis="0 0 1" range="0 1.3" actuatorfrcrange="-10 10"/>
            <geom type="mesh" contype="0" conaffinity="0" group="1" density="0" rgba="0.6 0.6 0.6 1" mesh="l_f_link3_3"/>
            <geom type="mesh" rgba="0.6 0.6 0.6 1" mesh="l_f_link3_3" contype="0" conaffinity="0" group="1" density="0"/>
            <body name="l_f_link3_4" pos="0.025 0 0">
              <inertial pos="0.0167833 -0.00318009 0.000699111" quat="0.764722 -0.0731366 0.387992 0.509228" mass="0.00715824" diaginertia="4.72306e-08 4.672e-08 1.86403e-09"/>
              <joint name="l_f_joint3_4" pos="0 0 0" axis="0 0 1" range="0 1.3" actuatorfrcrange="-10 10"/>
              <geom type="mesh" contype="0" conaffinity="0" group="1" density="0" rgba="0.6 0.6 0.6 1" mesh="l_f_link3_4"/>
              <geom type="mesh" rgba="0.6 0.6 0.6 1" mesh="l_f_link3_4" contype="0" conaffinity="0" group="1" density="0"/>
              <geom size="0.002" pos="0.035 -0.004 0" contype="0" conaffinity="0" group="1" density="0" rgba="1 0 0 1"/>
              <geom size="0.002" pos="0.02 0 0" rgba="1 0 0 1" contype="0" conaffinity="0" group="1" density="0"/>
              <site name="site_l_f_link3_4" pos="0.025 0.003 0" size="0.01" type="sphere"/>
              <geom name="col_l_f_link3_4" type="capsule" contype="1" conaffinity="1" group="3" size="0.0095" fromto="0.0 0 0 0.026 -0.007 0"/>
            </body>
            <geom name="col_l_f_link3_3" type="capsule" contype="1" conaffinity="1" group="3" size="0.007" fromto="0.012 0.003 -0.0035 0.012 0.003 0.0035"/>
          </body>
          <geom name="col_l_f_link3_2" type="capsule" contype="1" conaffinity="1" group="3" size="0.0095" fromto="0.005 0 0 0.03 0 0"/>
        </body>
      </body>
      <body name="l_f_link4_1" pos="0.006966 0.013688 0.1644" quat="0.707105 0 -0.707108 0">
        <inertial pos="0.00700212 -1.07487e-07 0.000968558" quat="0.602113 0.370756 0.370756 0.602113" mass="0.00409701" diaginertia="3.97653e-10 3.39654e-10 2.55254e-10"/>
        <joint name="l_f_joint4_1" pos="0 0 0" axis="0 0 1" range="0 0.6" actuatorfrcrange="-10 10"/>
        <geom type="mesh" contype="0" conaffinity="0" group="1" density="0" rgba="0.792157 0.819608 0.933333 1" mesh="l_f_link4_1"/>
        <geom type="mesh" rgba="0.792157 0.819608 0.933333 1" mesh="l_f_link4_1" contype="0" conaffinity="0" group="1" density="0"/>
        <body name="l_f_link4_2" pos="0.017 0 0" quat="0.707105 -0.707108 0 0">
          <inertial pos="0.0211622 -0.000590378 2.72622e-06" quat="0.5052 0.505863 0.494731 0.494083" mass="0.0094283" diaginertia="2.07226e-09 2.05417e-09 6.929e-10"/>
          <joint name="l_f_joint4_2" pos="0 0 0" axis="0 0 1" range="0 1.3" actuatorfrcrange="-10 10"/>
          <geom type="mesh" contype="0" conaffinity="0" group="1" density="0" rgba="0.6 0.6 0.6 1" mesh="l_f_link4_2"/>
          <geom type="mesh" rgba="0.6 0.6 0.6 1" mesh="l_f_link4_2" contype="0" conaffinity="0" group="1" density="0"/>
          <body name="l_f_link4_3" pos="0.043 0 0">
            <inertial pos="0.0134587 -0.000699415 7.12894e-07" quat="0.0206011 0.706807 -0.0206011 0.706807" mass="0.00457275" diaginertia="4.74657e-10 4.45639e-10 2.5398e-10"/>
            <joint name="l_f_joint4_3" pos="0 0 0" axis="0 0 1" range="0 1.3" actuatorfrcrange="-10 10"/>
            <geom type="mesh" contype="0" conaffinity="0" group="1" density="0" rgba="0.6 0.6 0.6 1" mesh="l_f_link4_3"/>
            <geom type="mesh" rgba="0.6 0.6 0.6 1" mesh="l_f_link4_3" contype="0" conaffinity="0" group="1" density="0"/>
            <body name="l_f_link4_4" pos="0.025 0 0">
              <inertial pos="0.0167833 -0.00318009 0.000699111" quat="0.764722 -0.0731366 0.387992 0.509228" mass="0.00715824" diaginertia="4.72306e-08 4.672e-08 1.86403e-09"/>
              <joint name="l_f_joint4_4" pos="0 0 0" axis="0 0 1" range="0 1.3" actuatorfrcrange="-10 10"/>
              <geom type="mesh" contype="0" conaffinity="0" group="1" density="0" rgba="0.6 0.6 0.6 1" mesh="l_f_link4_4"/>
              <geom type="mesh" rgba="0.6 0.6 0.6 1" mesh="l_f_link4_4" contype="0" conaffinity="0" group="1" density="0"/>
              <geom size="0.002" pos="0.035 -0.004 0" contype="0" conaffinity="0" group="1" density="0" rgba="1 0 0 1"/>
              <geom size="0.002" pos="0.02 0 0" rgba="1 0 0 1" contype="0" conaffinity="0" group="1" density="0"/>
              <site name="site_l_f_link4_4" pos="0.025 0.003 0" size="0.01" type="sphere"/>
              <geom name="col_l_f_link4_4" type="capsule" contype="1" conaffinity="1" group="3" size="0.0095" fromto="0.0 0 0 0.026 -0.007 0"/>
            </body>
            <geom name="col_l_f_link4_3" type="capsule" contype="1" conaffinity="1" group="3" size="0.007" fromto="0.012 0.003 -0.0035 0.012 0.003 0.0035"/>
          </body>
          <geom name="col_l_f_link4_2" type="capsule" contype="1" conaffinity="1" group="3" size="0.0095" fromto="0.005 0 0 0.03 0 0"/>
        </body>
      </body>
      <body name="l_f_link5_1" pos="0.006966 0.037988 0.1504" quat="0.707105 0 -0.707108 0">
        <inertial pos="0.00700212 -1.08915e-07 0.000968551" quat="0.602113 0.370756 0.370756 0.602113" mass="0.00409701" diaginertia="3.97652e-10 3.39654e-10 2.55254e-10"/>
        <joint name="l_f_joint5_1" pos="0 0 0" axis="0 0 1" range="0 0.6" actuatorfrcrange="-10 10"/>
        <geom type="mesh" contype="0" conaffinity="0" group="1" density="0" rgba="0.792157 0.819608 0.933333 1" mesh="l_f_link5_1"/>
        <geom type="mesh" rgba="0.792157 0.819608 0.933333 1" mesh="l_f_link5_1" contype="0" conaffinity="0" group="1" density="0"/>
        <body name="l_f_link5_2" pos="0.017 0 0" quat="0.707105 -0.707108 0 0">
          <inertial pos="0.0211622 -0.000590378 2.72622e-06" quat="0.5052 0.505863 0.494731 0.494083" mass="0.0094283" diaginertia="2.07226e-09 2.05417e-09 6.929e-10"/>
          <joint name="l_f_joint5_2" pos="0 0 0" axis="0 0 1" range="0 1.3" actuatorfrcrange="-10 10"/>
          <geom type="mesh" contype="0" conaffinity="0" group="1" density="0" rgba="0.6 0.6 0.6 1" mesh="l_f_link5_2"/>
          <geom type="mesh" rgba="0.6 0.6 0.6 1" mesh="l_f_link5_2" contype="0" conaffinity="0" group="1" density="0"/>
          <body name="l_f_link5_3" pos="0.043 0 0">
            <inertial pos="0.0134587 -0.000699415 7.12894e-07" quat="0.0206011 0.706807 -0.0206011 0.706807" mass="0.00457275" diaginertia="4.74657e-10 4.45639e-10 2.5398e-10"/>
            <joint name="l_f_joint5_3" pos="0 0 0" axis="0 0 1" range="0 1.3" actuatorfrcrange="-10 10"/>
            <geom type="mesh" contype="0" conaffinity="0" group="1" density="0" rgba="0.6 0.6 0.6 1" mesh="l_f_link5_3"/>
            <geom type="mesh" rgba="0.6 0.6 0.6 1" mesh="l_f_link5_3" contype="0" conaffinity="0" group="1" density="0"/>
            <body name="l_f_link5_4" pos="0.025 0 0">
              <inertial pos="0.0167833 -0.00318009 0.000699111" quat="0.764722 -0.0731366 0.387992 0.509228" mass="0.00715824" diaginertia="4.72306e-08 4.672e-08 1.86403e-09"/>
              <joint name="l_f_joint5_4" pos="0 0 0" axis="0 0 1" range="0 1.3" actuatorfrcrange="-10 10"/>
              <geom type="mesh" contype="0" conaffinity="0" group="1" density="0" rgba="0.6 0.6 0.6 1" mesh="l_f_link5_4"/>
              <geom type="mesh" rgba="0.6 0.6 0.6 1" mesh="l_f_link5_4" contype="0" conaffinity="0" group="1" density="0"/>
              <geom size="0.002" pos="0.035 -0.004 0" contype="0" conaffinity="0" group="1" density="0" rgba="1 0 0 1"/>
              <geom size="0.002" pos="0.02 0 0" rgba="1 0 0 1" contype="0" conaffinity="0" group="1" density="0"/>
              <site name="site_l_f_link5_4" pos="0.025 0.003 0" size="0.01" type="sphere"/>
              <geom name="col_l_f_link5_4" type="capsule" contype="1" conaffinity="1" group="3" size="0.0095" fromto="0.0 0 0 0.026 -0.007 0"/>
            </body>
            <geom name="col_l_f_link5_3" type="capsule" contype="1" conaffinity="1" group="3" size="0.007" fromto="0.012 0.003 -0.0035 0.012 0.003 0.0035"/>
          </body>
          <geom name="col_l_f_link5_2" type="capsule" contype="1" conaffinity="1" group="3" size="0.0095" fromto="0.005 0 0 0.03 0 0"/>
        </body>
      </body>
      <geom name="col_left_hand_base" type="box" contype="1" conaffinity="1" group="3" size="0.0273 0.05 0.05" pos="-0.0022 0 0.11"/>
    </body>
  </worldbody>
  <actuator>
    <position name="act_l_f_joint1_2" joint="l_f_joint1_2" kp="20" kv="0.1" ctrlrange="0 1.3" forcerange="-20 20"/>
    <position name="act_l_f_joint1_3" joint="l_f_joint1_3" kp="20" kv="0.1" ctrlrange="0 1.3" forcerange="-20 20"/>
    <position name="act_l_f_joint1_4" joint="l_f_joint1_4" kp="20" kv="0.1" ctrlrange="0 1.3" forcerange="-20 20"/>
    <position name="act_l_f_joint2_2" joint="l_f_joint2_2" kp="20" kv="0.1" ctrlrange="0 1.3" forcerange="-20 20"/>
    <position name="act_l_f_joint2_3" joint="l_f_joint2_3" kp="20" kv="0.1" ctrlrange="0 1.3" forcerange="-20 20"/>
    <position name="act_l_f_joint2_4" joint="l_f_joint2_4" kp="20" kv="0.1" ctrlrange="0 1.3" forcerange="-20 20"/>
    <position name="act_l_f_joint3_2" joint="l_f_joint3_2" kp="20" kv="0.1" ctrlrange="0 1.3" forcerange="-20 20"/>
    <position name="act_l_f_joint3_3" joint="l_f_joint3_3" kp="20" kv="0.1" ctrlrange="0 1.3" forcerange="-20 20"/>
    <position name="act_l_f_joint3_4" joint="l_f_joint3_4" kp="20" kv="0.1" ctrlrange="0 1.3" forcerange="-20 20"/>
    <position name="act_l_f_joint4_2" joint="l_f_joint4_2" kp="20" kv="0.1" ctrlrange="0 1.3" forcerange="-20 20"/>
    <position name="act_l_f_joint4_3" joint="l_f_joint4_3" kp="20" kv="0.1" ctrlrange="0 1.3" forcerange="-20 20"/>
    <position name="act_l_f_joint4_4" joint="l_f_joint4_4" kp="20" kv="0.1" ctrlrange="0 1.3" forcerange="-20 20"/>
    <position name="act_l_f_joint5_2" joint="l_f_joint5_2" kp="20" kv="0.1" ctrlrange="0 1.3" forcerange="-20 20"/>
    <position name="act_l_f_joint5_3" joint="l_f_joint5_3" kp="20" kv="0.1" ctrlrange="0 1.3" forcerange="-20 20"/>
    <position name="act_l_f_joint5_4" joint="l_f_joint5_4" kp="20" kv="0.1" ctrlrange="0 1.3" forcerange="-20 20"/>
    <position name="act_l_f_joint1_1" joint="l_f_joint1_1" kp="20" kv="1" ctrlrange="0 2.2" forcerange="-20 20"/>
    <position name="act_l_f_joint2_1" joint="l_f_joint2_1" kp="20" kv="1" ctrlrange="0 0.3" forcerange="-20 20"/>
    <position name="act_l_f_joint3_1" joint="l_f_joint3_1" kp="20" kv="1" ctrlrange="-0.0001 0.0001" forcerange="-20 20"/>
    <position name="act_l_f_joint4_1" joint="l_f_joint4_1" kp="20" kv="1" ctrlrange="0 0.3" forcerange="-20 20"/>
    <position name="act_l_f_joint5_1" joint="l_f_joint5_1" kp="20" kv="1" ctrlrange="0 0.6" forcerange="-20 20"/>
  </actuator>
  <sensor>
    <touch name="touch_l_f_link1_4" site="site_l_f_link1_4"/>
    <touch name="touch_l_f_link2_4" site="site_l_f_link2_4"/>
    <touch name="touch_l_f_link3_4" site="site_l_f_link3_4"/>
    <touch name="touch_l_f_link4_4" site="site_l_f_link4_4"/>
    <touch name="touch_l_f_link5_4" site="site_l_f_link5_4"/>
  </sensor>
  <contact>
    <exclude body1="left_hand_base" body2="l_f_link1_1"/>
    <exclude body1="left_hand_base" body2="l_f_link1_2"/>
    <exclude body1="left_hand_base" body2="l_f_link1_3"/>
    <exclude body1="left_hand_base" body2="l_f_link1_4"/>
    <exclude body1="left_hand_base" body2="l_f_link2_1"/>
    <exclude body1="left_hand_base" body2="l_f_link2_2"/>
    <exclude body1="left_hand_base" body2="l_f_link2_3"/>
    <exclude body1="left_hand_base" body2="l_f_link2_4"/>
    <exclude body1="left_hand_base" body2="l_f_link3_1"/>
    <exclude body1="left_hand_base" body2="l_f_link3_2"/>
    <exclude body1="left_hand_base" body2="l_f_link3_3"/>
    <exclude body1="left_hand_base" body2="l_f_link3_4"/>
    <exclude body1="left_hand_base" body2="l_f_link4_1"/>
    <exclude body1="left_hand_base" body2="l_f_link4_2"/>
    <exclude body1="left_hand_base" body2="l_f_link4_3"/>
    <exclude body1="left_hand_base" body2="l_f_link4_4"/>
    <exclude body1="left_hand_base" body2="l_f_link5_1"/>
    <exclude body1="left_hand_base" body2="l_f_link5_2"/>
    <exclude body1="left_hand_base" body2="l_f_link5_3"/>
    <exclude body1="left_hand_base" body2="l_f_link5_4"/>
    <exclude body1="l_f_link1_1" body2="l_f_link1_2"/>
    <exclude body1="l_f_link1_1" body2="l_f_link1_3"/>
    <exclude body1="l_f_link1_1" body2="l_f_link1_4"/>
    <exclude body1="l_f_link1_1" body2="l_f_link2_1"/>
    <exclude body1="l_f_link1_1" body2="l_f_link2_2"/>
    <exclude body1="l_f_link1_1" body2="l_f_link2_3"/>
    <exclude body1="l_f_link1_1" body2="l_f_link2_4"/>
    <exclude body1="l_f_link1_1" body2="l_f_link3_1"/>
    <exclude body1="l_f_link1_1" body2="l_f_link3_2"/>
    <exclude body1="l_f_link1_1" body2="l_f_link3_3"/>
    <exclude body1="l_f_link1_1" body2="l_f_link3_4"/>
    <exclude body1="l_f_link1_1" body2="l_f_link4_1"/>
    <exclude body1="l_f_link1_1" body2="l_f_link4_2"/>
    <exclude body1="l_f_link1_1" body2="l_f_link4_3"/>
    <exclude body1="l_f_link1_1" body2="l_f_link4_4"/>
    <exclude body1="l_f_link1_1" body2="l_f_link5_1"/>
    <exclude body1="l_f_link1_1" body2="l_f_link5_2"/>
    <exclude body1="l_f_link1_1" body2="l_f_link5_3"/>
    <exclude body1="l_f_link1_1" body2="l_f_link5_4"/>
    <exclude body1="l_f_link1_2" body2="l_f_link1_3"/>
    <exclude body1="l_f_link1_2" body2="l_f_link1_4"/>
    <exclude body1="l_f_link1_2" body2="l_f_link2_1"/>
    <exclude body1="l_f_link1_2" body2="l_f_link2_2"/>
    <exclude body1="l_f_link1_2" body2="l_f_link2_3"/>
    <exclude body1="l_f_link1_2" body2="l_f_link2_4"/>
    <exclude body1="l_f_link1_2" body2="l_f_link3_1"/>
    <exclude body1="l_f_link1_2" body2="l_f_link3_2"/>
    <exclude body1="l_f_link1_2" body2="l_f_link3_3"/>
    <exclude body1="l_f_link1_2" body2="l_f_link3_4"/>
    <exclude body1="l_f_link1_2" body2="l_f_link4_1"/>
    <exclude body1="l_f_link1_2" body2="l_f_link4_2"/>
    <exclude body1="l_f_link1_2" body2="l_f_link4_3"/>
    <exclude body1="l_f_link1_2" body2="l_f_link4_4"/>
    <exclude body1="l_f_link1_2" body2="l_f_link5_1"/>
    <exclude body1="l_f_link1_2" body2="l_f_link5_2"/>
    <exclude body1="l_f_link1_2" body2="l_f_link5_3"/>
    <exclude body1="l_f_link1_2" body2="l_f_link5_4"/>
    <exclude body1="l_f_link1_3" body2="l_f_link1_4"/>
    <exclude body1="l_f_link1_3" body2="l_f_link2_1"/>
    <exclude body1="l_f_link1_3" body2="l_f_link2_2"/>
    <exclude body1="l_f_link1_3" body2="l_f_link2_3"/>
    <exclude body1="l_f_link1_3" body2="l_f_link2_4"/>
    <exclude body1="l_f_link1_3" body2="l_f_link3_1"/>
    <exclude body1="l_f_link1_3" body2="l_f_link3_2"/>
    <exclude body1="l_f_link1_3" body2="l_f_link3_3"/>
    <exclude body1="l_f_link1_3" body2="l_f_link3_4"/>
    <exclude body1="l_f_link1_3" body2="l_f_link4_1"/>
    <exclude body1="l_f_link1_3" body2="l_f_link4_2"/>
    <exclude body1="l_f_link1_3" body2="l_f_link4_3"/>
    <exclude body1="l_f_link1_3" body2="l_f_link4_4"/>
    <exclude body1="l_f_link1_3" body2="l_f_link5_1"/>
    <exclude body1="l_f_link1_3" body2="l_f_link5_2"/>
    <exclude body1="l_f_link1_3" body2="l_f_link5_3"/>
    <exclude body1="l_f_link1_3" body2="l_f_link5_4"/>
    <exclude body1="l_f_link1_4" body2="l_f_link2_1"/>
    <exclude body1="l_f_link1_4" body2="l_f_link2_2"/>
    <exclude body1="l_f_link1_4" body2="l_f_link2_3"/>
    <exclude body1="l_f_link1_4" body2="l_f_link3_1"/>
    <exclude body1="l_f_link1_4" body2="l_f_link3_2"/>
    <exclude body1="l_f_link1_4" body2="l_f_link3_3"/>
    <exclude body1="l_f_link1_4" body2="l_f_link4_1"/>
    <exclude body1="l_f_link1_4" body2="l_f_link4_2"/>
    <exclude body1="l_f_link1_4" body2="l_f_link4_3"/>
    <exclude body1="l_f_link1_4" body2="l_f_link5_1"/>
    <exclude body1="l_f_link1_4" body2="l_f_link5_2"/>
    <exclude body1="l_f_link1_4" body2="l_f_link5_3"/>
    <exclude body1="l_f_link2_1" body2="l_f_link2_2"/>
    <exclude body1="l_f_link2_1" body2="l_f_link2_3"/>
    <exclude body1="l_f_link2_1" body2="l_f_link2_4"/>
    <exclude body1="l_f_link2_1" body2="l_f_link3_1"/>
    <exclude body1="l_f_link2_1" body2="l_f_link3_2"/>
    <exclude body1="l_f_link2_1" body2="l_f_link3_3"/>
    <exclude body1="l_f_link2_1" body2="l_f_link3_4"/>
    <exclude body1="l_f_link2_1" body2="l_f_link4_1"/>
    <exclude body1="l_f_link2_1" body2="l_f_link4_2"/>
    <exclude body1="l_f_link2_1" body2="l_f_link4_3"/>
    <exclude body1="l_f_link2_1" body2="l_f_link4_4"/>
    <exclude body1="l_f_link2_1" body2="l_f_link5_1"/>
    <exclude body1="l_f_link2_1" body2="l_f_link5_2"/>
    <exclude body1="l_f_link2_1" body2="l_f_link5_3"/>
    <exclude body1="l_f_link2_1" body2="l_f_link5_4"/>
    <exclude body1="l_f_link2_2" body2="l_f_link2_3"/>
    <exclude body1="l_f_link2_2" body2="l_f_link2_4"/>
    <exclude body1="l_f_link2_2" body2="l_f_link3_1"/>
    <exclude body1="l_f_link2_2" body2="l_f_link3_2"/>
    <exclude body1="l_f_link2_2" body2="l_f_link3_3"/>
    <exclude body1="l_f_link2_2" body2="l_f_link3_4"/>
    <exclude body1="l_f_link2_2" body2="l_f_link4_1"/>
    <exclude body1="l_f_link2_2" body2="l_f_link4_2"/>
    <exclude body1="l_f_link2_2" body2="l_f_link4_3"/>
    <exclude body1="l_f_link2_2" body2="l_f_link4_4"/>
    <exclude body1="l_f_link2_2" body2="l_f_link5_1"/>
    <exclude body1="l_f_link2_2" body2="l_f_link5_2"/>
    <exclude body1="l_f_link2_2" body2="l_f_link5_3"/>
    <exclude body1="l_f_link2_2" body2="l_f_link5_4"/>
    <exclude body1="l_f_link2_3" body2="l_f_link2_4"/>
    <exclude body1="l_f_link2_3" body2="l_f_link3_1"/>
    <exclude body1="l_f_link2_3" body2="l_f_link3_2"/>
    <exclude body1="l_f_link2_3" body2="l_f_link3_3"/>
    <exclude body1="l_f_link2_3" body2="l_f_link3_4"/>
    <exclude body1="l_f_link2_3" body2="l_f_link4_1"/>
    <exclude body1="l_f_link2_3" body2="l_f_link4_2"/>
    <exclude body1="l_f_link2_3" body2="l_f_link4_3"/>
    <exclude body1="l_f_link2_3" body2="l_f_link4_4"/>
    <exclude body1="l_f_link2_3" body2="l_f_link5_1"/>
    <exclude body1="l_f_link2_3" body2="l_f_link5_2"/>
    <exclude body1="l_f_link2_3" body2="l_f_link5_3"/>
    <exclude body1="l_f_link2_3" body2="l_f_link5_4"/>
    <exclude body1="l_f_link2_4" body2="l_f_link3_1"/>
    <exclude body1="l_f_link2_4" body2="l_f_link3_2"/>
    <exclude body1="l_f_link2_4" body2="l_f_link3_3"/>
    <exclude body1="l_f_link2_4" body2="l_f_link4_1"/>
    <exclude body1="l_f_link2_4" body2="l_f_link4_2"/>
    <exclude body1="l_f_link2_4" body2="l_f_link4_3"/>
    <exclude body1="l_f_link2_4" body2="l_f_link5_1"/>
    <exclude body1="l_f_link2_4" body2="l_f_link5_2"/>
    <exclude body1="l_f_link2_4" body2="l_f_link5_3"/>
    <exclude body1="l_f_link3_1" body2="l_f_link3_2"/>
    <exclude body1="l_f_link3_1" body2="l_f_link3_3"/>
    <exclude body1="l_f_link3_1" body2="l_f_link3_4"/>
    <exclude body1="l_f_link3_1" body2="l_f_link4_1"/>
    <exclude body1="l_f_link3_1" body2="l_f_link4_2"/>
    <exclude body1="l_f_link3_1" body2="l_f_link4_3"/>
    <exclude body1="l_f_link3_1" body2="l_f_link4_4"/>
    <exclude body1="l_f_link3_1" body2="l_f_link5_1"/>
    <exclude body1="l_f_link3_1" body2="l_f_link5_2"/>
    <exclude body1="l_f_link3_1" body2="l_f_link5_3"/>
    <exclude body1="l_f_link3_1" body2="l_f_link5_4"/>
    <exclude body1="l_f_link3_2" body2="l_f_link3_3"/>
    <exclude body1="l_f_link3_2" body2="l_f_link3_4"/>
    <exclude body1="l_f_link3_2" body2="l_f_link4_1"/>
    <exclude body1="l_f_link3_2" body2="l_f_link4_2"/>
    <exclude body1="l_f_link3_2" body2="l_f_link4_3"/>
    <exclude body1="l_f_link3_2" body2="l_f_link4_4"/>
    <exclude body1="l_f_link3_2" body2="l_f_link5_1"/>
    <exclude body1="l_f_link3_2" body2="l_f_link5_2"/>
    <exclude body1="l_f_link3_2" body2="l_f_link5_3"/>
    <exclude body1="l_f_link3_2" body2="l_f_link5_4"/>
    <exclude body1="l_f_link3_3" body2="l_f_link3_4"/>
    <exclude body1="l_f_link3_3" body2="l_f_link4_1"/>
    <exclude body1="l_f_link3_3" body2="l_f_link4_2"/>
    <exclude body1="l_f_link3_3" body2="l_f_link4_3"/>
    <exclude body1="l_f_link3_3" body2="l_f_link4_4"/>
    <exclude body1="l_f_link3_3" body2="l_f_link5_1"/>
    <exclude body1="l_f_link3_3" body2="l_f_link5_2"/>
    <exclude body1="l_f_link3_3" body2="l_f_link5_3"/>
    <exclude body1="l_f_link3_3" body2="l_f_link5_4"/>
    <exclude body1="l_f_link3_4" body2="l_f_link4_1"/>
    <exclude body1="l_f_link3_4" body2="l_f_link4_2"/>
    <exclude body1="l_f_link3_4" body2="l_f_link4_3"/>
    <exclude body1="l_f_link3_4" body2="l_f_link5_1"/>
    <exclude body1="l_f_link3_4" body2="l_f_link5_2"/>
    <exclude body1="l_f_link3_4" body2="l_f_link5_3"/>
    <exclude body1="l_f_link4_1" body2="l_f_link4_2"/>
    <exclude body1="l_f_link4_1" body2="l_f_link4_3"/>
    <exclude body1="l_f_link4_1" body2="l_f_link4_4"/>
    <exclude body1="l_f_link4_1" body2="l_f_link5_1"/>
    <exclude body1="l_f_link4_1" body2="l_f_link5_2"/>
    <exclude body1="l_f_link4_1" body2="l_f_link5_3"/>
    <exclude body1="l_f_link4_1" body2="l_f_link5_4"/>
    <exclude body1="l_f_link4_2" body2="l_f_link4_3"/>
    <exclude body1="l_f_link4_2" body2="l_f_link4_4"/>
    <exclude body1="l_f_link4_2" body2="l_f_link5_1"/>
    <exclude body1="l_f_link4_2" body2="l_f_link5_2"/>
    <exclude body1="l_f_link4_2" body2="l_f_link5_3"/>
    <exclude body1="l_f_link4_2" body2="l_f_link5_4"/>
    <exclude body1="l_f_link4_3" body2="l_f_link4_4"/>
    <exclude body1="l_f_link4_3" body2="l_f_link5_1"/>
    <exclude body1="l_f_link4_3" body2="l_f_link5_2"/>
    <exclude body1="l_f_link4_3" body2="l_f_link5_3"/>
    <exclude body1="l_f_link4_3" body2="l_f_link5_4"/>
    <exclude body1="l_f_link4_4" body2="l_f_link5_1"/>
    <exclude body1="l_f_link4_4" body2="l_f_link5_2"/>
    <exclude body1="l_f_link4_4" body2="l_f_link5_3"/>
    <exclude body1="l_f_link5_1" body2="l_f_link5_2"/>
    <exclude body1="l_f_link5_1" body2="l_f_link5_3"/>
    <exclude body1="l_f_link5_1" body2="l_f_link5_4"/>
    <exclude body1="l_f_link5_2" body2="l_f_link5_3"/>
    <exclude body1="l_f_link5_2" body2="l_f_link5_4"/>
    <exclude body1="l_f_link5_3" body2="l_f_link5_4"/>
  </contact>
</mujoco>
