<?xml version="1.0" encoding="utf-8"?>
<mujoco model="floating_base_dexhand021_right">
  <compiler meshdir=""/>
  <size njmax="1000" nconmax="1000"/>
  <default>
    <joint damping="1"/>
    <geom condim="3" solref="0.02 1" solimp="0.9 0.95 0.001" friction="2 2 2"/>
  </default>
  <option gravity="0 0 -9.81" iterations="100" solver="Newton" integrator="implicit" timestep="0.001"/>
  <visual>
    <global offwidth="1920" offheight="1080"/>
  </visual>
  <worldbody>
    <body name="floating_base">
      <inertial pos="0 0 0" quat="1 0 0 0" mass="0.01" diaginertia="0.01 0.01 0.01"/>
      <joint name="ARTx" pos="0 0 0" axis="1 0 0" type="slide" range="-1 1" damping="20"/>
      <joint name="ARTy" pos="0 0 0" axis="0 1 0" type="slide" range="-1 1" damping="20"/>
      <joint name="ARTz" pos="0 0 0" axis="0 0 1" type="slide" range="-1 1" damping="20"/>
      <joint name="ARRx" pos="0 0 0" axis="1 0 0" range="-3.14 3.14" damping="20"/>
      <joint name="ARRy" pos="0 0 0" axis="0 1 0" range="-3.14 3.14" damping="20"/>
      <joint name="ARRz" pos="0 0 0" axis="0 0 1" range="-3.14 3.14" damping="20"/>
      <body name="hand_base">
        <body name="right_hand_base" pos="0 0 0" quat="0.7071067811865476 0.0 0.7071067811865475 0.0">
          <geom pos="0 0 -0.17" quat="0.707388 0 0 -0.706825" type="mesh" contype="0" conaffinity="0" group="1" density="0" rgba="0.3 0.3 0.3 1" mesh="r_p_link0"/>
          <geom pos="0 0 -0.17" quat="0.707388 0 0 -0.706825" type="mesh" rgba="0.3 0.3 0.3 1" mesh="r_p_link0"/>
          <geom pos="0.032685 0.023881 0.10707" quat="0.775137 0.151553 0.0221905 0.612945" type="mesh" contype="0" conaffinity="0" group="1" density="0" rgba="0.3 0.3 0.3 1" mesh="r_p_link1"/>
          <geom pos="0.032685 0.023881 0.10707" quat="0.775137 0.151553 0.0221905 0.612945" type="mesh" rgba="0.3 0.3 0.3 1" mesh="r_p_link1"/>
          <geom pos="0.032685 0.023881 0.10707" quat="0.775137 0.151553 0.0221905 0.612945" type="mesh" contype="0" conaffinity="0" group="1" density="0" rgba="0.3 0.3 0.3 1" mesh="r_p_link3"/>
          <geom pos="0.032685 0.023881 0.10707" quat="0.775137 0.151553 0.0221905 0.612945" type="mesh" rgba="0.3 0.3 0.3 1" mesh="r_p_link3"/>
          <geom pos="0.032685 0.023881 0.10707" quat="0.775137 0.151553 0.0221905 0.612945" type="mesh" contype="0" conaffinity="0" group="1" density="0" rgba="0.9 0.9 0.9 1" mesh="r_p_link4"/>
          <geom pos="0.032685 0.023881 0.10707" quat="0.775137 0.151553 0.0221905 0.612945" type="mesh" rgba="0.9 0.9 0.9 1" mesh="r_p_link4"/>
          <geom pos="0.032685 0.023881 0.10707" quat="0.775137 0.151553 0.0221905 0.612945" type="mesh" contype="0" conaffinity="0" group="1" density="0" rgba="0.3 0.3 0.3 1" mesh="r_p_link5"/>
          <geom pos="0.032685 0.023881 0.10707" quat="0.775137 0.151553 0.0221905 0.612945" type="mesh" rgba="0.3 0.3 0.3 1" mesh="r_p_link5"/>
          <geom pos="0.032685 0.023881 0.10707" quat="0.775137 0.151553 0.0221905 0.612945" type="mesh" contype="0" conaffinity="0" group="1" density="0" rgba="0.9 0.9 0.9 1" mesh="r_p_link6"/>
          <geom pos="0.032685 0.023881 0.10707" quat="0.775137 0.151553 0.0221905 0.612945" type="mesh" rgba="0.9 0.9 0.9 1" mesh="r_p_link6"/>
          <geom pos="0.032685 0.023881 0.10707" quat="0.775137 0.151553 0.0221905 0.612945" type="mesh" contype="0" conaffinity="0" group="1" density="0" rgba="0.9 0.9 0.9 1" mesh="r_p_link2"/>
          <geom pos="0.032685 0.023881 0.10707" quat="0.775137 0.151553 0.0221905 0.612945" type="mesh" rgba="0.9 0.9 0.9 1" mesh="r_p_link2"/>
          <body name="r_f_link1_1" pos="0.032685 0.023881 0.10707" quat="0.775137 0.151553 0.0221905 0.612945">
            <inertial pos="0.0020615 -0.00037197 -0.018564" quat="0.718228 0.0801509 0.0449536 0.689713" mass="0.0055494" diaginertia="3.99834e-07 3.48639e-07 2.47866e-07"/>
            <joint name="r_f_joint1_1" pos="0 0 0" axis="0 0 -1" range="0 2.2" actuatorfrcrange="-10 10"/>
            <geom type="mesh" contype="0" conaffinity="0" group="1" density="0" rgba="0.3 0.3 0.3 1" mesh="r_f_link1_1"/>
            <geom type="mesh" rgba="0.3 0.3 0.3 1" mesh="r_f_link1_1"/>
            <body name="r_f_link1_2" pos="0.0083307 0 0" quat="0.707073 0.707076 0.0067524 -0.00675243">
              <inertial pos="0.0217231 0.000632322 0.00102791" quat="-0.0120879 0.705572 -0.0459737 0.707042" mass="0.0099742" diaginertia="1.94387e-06 1.89318e-06 6.90006e-07"/>
              <joint name="r_f_joint1_2" pos="0 0 0" axis="0 0 1" range="0 1.3" actuatorfrcrange="-10 10"/>
              <geom type="mesh" contype="0" conaffinity="0" group="1" density="0" rgba="0.3 0.3 0.3 1" mesh="r_f_link1_2"/>
              <geom type="mesh" rgba="0.3 0.3 0.3 1" mesh="r_f_link1_2"/>
              <geom type="mesh" contype="0" conaffinity="0" group="1" density="0" rgba="0.3 0.3 0.3 1" mesh="r_f_link1_2_1"/>
              <geom type="mesh" rgba="0.3 0.3 0.3 1" mesh="r_f_link1_2_1"/>
              <geom type="mesh" contype="0" conaffinity="0" group="1" density="0" rgba="0.9 0.9 0.9 1" mesh="r_f_link1_2_2"/>
              <geom type="mesh" rgba="0.9 0.9 0.9 1" mesh="r_f_link1_2_2"/>
              <body name="r_f_link1_3" pos="0.043 0 0">
                <inertial pos="0.0130871 -0.000679265 0.00129588" quat="0.0231911 0.703963 -0.0269081 0.709347" mass="0.00527423" diaginertia="4.60778e-07 4.30817e-07 2.36596e-07"/>
                <joint name="r_f_joint1_3" pos="0 0 0" axis="0 0 1" range="0 1.3" actuatorfrcrange="-10 10"/>
                <geom type="mesh" contype="0" conaffinity="0" group="1" density="0" rgba="0.3 0.3 0.3 1" mesh="r_f_link1_3"/>
                <geom type="mesh" rgba="0.3 0.3 0.3 1" mesh="r_f_link1_3"/>
                <geom type="mesh" contype="0" conaffinity="0" group="1" density="0" rgba="0.3 0.3 0.3 1" mesh="r_f_link1_3_1"/>
                <geom type="mesh" rgba="0.3 0.3 0.3 1" mesh="r_f_link1_3_1"/>
                <geom type="mesh" contype="0" conaffinity="0" group="1" density="0" rgba="0.9 0.9 0.9 1" mesh="r_f_link1_3_2"/>
                <geom type="mesh" rgba="0.9 0.9 0.9 1" mesh="r_f_link1_3_2"/>
                <body name="r_f_link1_4" pos="0.025 0 0">
                  <inertial pos="0.0133604 0.00223169 0.00160031" quat="0.639352 0.595148 0.345372 0.34314" mass="0.0120157" diaginertia="1.02545e-06 8.47469e-07 3.73279e-07"/>
                  <joint name="r_f_joint1_4" pos="0 0 0" axis="0 0 1" range="0 1.3" actuatorfrcrange="-10 10"/>
                  <geom type="mesh" contype="0" conaffinity="0" group="1" density="0" rgba="0.3 0.3 0.3 1" mesh="r_f_link1_4"/>
                  <geom type="mesh" rgba="0.3 0.3 0.3 1" mesh="r_f_link1_4"/>
                  <geom type="mesh" contype="0" conaffinity="0" group="1" density="0" rgba="0.3 0.3 0.3 1" mesh="r_f_link1_4_1"/>
                  <geom type="mesh" rgba="0.3 0.3 0.3 1" mesh="r_f_link1_4_1"/>
                  <geom type="mesh" contype="0" conaffinity="0" group="1" density="0" rgba="0.9 0.9 0.9 1" mesh="r_f_link1_4_2"/>
                  <geom type="mesh" rgba="0.9 0.9 0.9 1" mesh="r_f_link1_4_2"/>
                  <geom size="0.002" pos="0.035 -0.004 0" contype="0" conaffinity="0" group="1" density="0" rgba="1 0 0 1"/>
                  <geom size="0.002" pos="0.02 0 0" rgba="1 0 0 1"/>
                  <site name="site_r_f_link1_4" pos="0.025 0.003 0" size="0.01" type="sphere"/>
                </body>
              </body>
            </body>
          </body>
          <body name="r_f_link2_1" pos="0.0069382 0.0349175 0.1597" quat="0.000289373 -0.707107 -0.00029197 -0.707107">
            <inertial pos="0.0080017 1.8833e-05 -0.0015869" quat="0.366604 0.60097 0.60931 0.364936" mass="0.003769" diaginertia="3.9885e-07 3.46938e-07 2.19942e-07"/>
            <joint name="r_f_joint2_1" pos="0 0 0" axis="0 0 -1" range="0 0.6" actuatorfrcrange="-10 10"/>
            <geom type="mesh" contype="0" conaffinity="0" group="1" density="0" rgba="0.3 0.3 0.3 1" mesh="r_f_link2_1"/>
            <geom type="mesh" rgba="0.3 0.3 0.3 1" mesh="r_f_link2_1"/>
            <body name="r_f_link2_2" pos="0.017 0 0" quat="0.707105 0.707108 0 0">
              <inertial pos="0.0214621 -0.000317178 -0.000279087" quat="0.515426 0.495684 0.504138 0.484229" mass="0.0092144" diaginertia="1.92287e-06 1.88786e-06 6.04775e-07"/>
              <joint name="r_f_joint2_2" pos="0 0 0" axis="0 0 1" range="0 1.3" actuatorfrcrange="-10 10"/>
              <geom type="mesh" contype="0" conaffinity="0" group="1" density="0" rgba="0.3 0.3 0.3 1" mesh="r_f_link2_2"/>
              <geom type="mesh" rgba="0.3 0.3 0.3 1" mesh="r_f_link2_2"/>
              <geom type="mesh" contype="0" conaffinity="0" group="1" density="0" rgba="0.3 0.3 0.3 1" mesh="r_f_link2_2_1"/>
              <geom type="mesh" rgba="0.3 0.3 0.3 1" mesh="r_f_link2_2_1"/>
              <geom type="mesh" contype="0" conaffinity="0" group="1" density="0" rgba="0.9 0.9 0.9 1" mesh="r_f_link2_2_2"/>
              <geom type="mesh" rgba="0.9 0.9 0.9 1" mesh="r_f_link2_2_2"/>
              <body name="r_f_link2_3" pos="0.043 0 0">
                <inertial pos="0.0131191 -0.000594087 -1.28443e-05" quat="0.0241845 0.703776 -0.0291852 0.70941" mass="0.00507867" diaginertia="4.55549e-07 4.23953e-07 2.29611e-07"/>
                <joint name="r_f_joint2_3" pos="0 0 0" axis="0 0 1" range="0 1.3" actuatorfrcrange="-10 10"/>
                <geom type="mesh" contype="0" conaffinity="0" group="1" density="0" rgba="0.3 0.3 0.3 1" mesh="r_f_link2_3"/>
                <geom type="mesh" rgba="0.3 0.3 0.3 1" mesh="r_f_link2_3"/>
                <geom type="mesh" contype="0" conaffinity="0" group="1" density="0" rgba="0.3 0.3 0.3 1" mesh="r_f_link2_3_1"/>
                <geom type="mesh" rgba="0.3 0.3 0.3 1" mesh="r_f_link2_3_1"/>
                <geom type="mesh" contype="0" conaffinity="0" group="1" density="0" rgba="0.9 0.9 0.9 1" mesh="r_f_link2_3_2"/>
                <geom type="mesh" rgba="0.9 0.9 0.9 1" mesh="r_f_link2_3_2"/>
                <body name="r_f_link2_4" pos="0.025 0 0">
                  <inertial pos="-0.805245 0.185279 -0.168684" quat="0.653631 0.44917 0.44687 0.413908" mass="0.0170943" diaginertia="0.00697625 0.00697615 1.98869e-07"/>
                  <joint name="r_f_joint2_4" pos="0 0 0" axis="0 0 1" range="0 1.3" actuatorfrcrange="-10 10"/>
                  <geom type="mesh" contype="0" conaffinity="0" group="1" density="0" rgba="0.3 0.3 0.3 1" mesh="r_f_link2_4"/>
                  <geom type="mesh" rgba="0.3 0.3 0.3 1" mesh="r_f_link2_4"/>
                  <geom type="mesh" contype="0" conaffinity="0" group="1" density="0" rgba="0.3 0.3 0.3 1" mesh="r_f_link2_4_1"/>
                  <geom type="mesh" rgba="0.3 0.3 0.3 1" mesh="r_f_link2_4_1"/>
                  <geom type="mesh" contype="0" conaffinity="0" group="1" density="0" rgba="0.9 0.9 0.9 1" mesh="r_f_link2_4_2"/>
                  <geom type="mesh" rgba="0.9 0.9 0.9 1" mesh="r_f_link2_4_2"/>
                  <geom size="0.002" pos="0.035 -0.004 0" contype="0" conaffinity="0" group="1" density="0" rgba="1 0 0 1"/>
                  <geom size="0.002" pos="0.02 0 0" rgba="1 0 0 1"/>
                  <site name="site_r_f_link2_4" pos="0.025 0.003 0" size="0.01" type="sphere"/>
                </body>
              </body>
            </body>
          </body>
          <body name="r_f_link3_1" pos="0.00695755 0.0106175 0.1687" quat="0.000278947 -0.707107 -0.000281544 -0.707107">
            <inertial pos="0.0080017 1.8833e-05 -0.0015869" quat="0.366604 0.60097 0.60931 0.364936" mass="0.003769" diaginertia="3.9885e-07 3.46938e-07 2.19942e-07"/>
            <joint name="r_f_joint3_1" pos="0 0 0" axis="0 0 1" range="-0.001 0.001" actuatorfrcrange="-10 10"/>
            <geom type="mesh" contype="0" conaffinity="0" group="1" density="0" rgba="0.9 0.9 0.9 1" mesh="r_f_link3_1"/>
            <geom type="mesh" rgba="0.9 0.9 0.9 1" mesh="r_f_link3_1"/>
            <body name="r_f_link3_2" pos="0.017 0 0" quat="0.707105 0.707108 0 0">
              <inertial pos="0.0214621 -0.000317178 -0.000279085" quat="0.515427 0.495683 0.504139 0.484228" mass="0.0092144" diaginertia="1.92287e-06 1.88786e-06 6.04775e-07"/>
              <joint name="r_f_joint3_2" pos="0 0 0" axis="0 0 1" range="0 1.3" actuatorfrcrange="-10 10"/>
              <geom type="mesh" contype="0" conaffinity="0" group="1" density="0" rgba="0.3 0.3 0.3 1" mesh="r_f_link3_2"/>
              <geom type="mesh" rgba="0.3 0.3 0.3 1" mesh="r_f_link3_2"/>
              <geom type="mesh" contype="0" conaffinity="0" group="1" density="0" rgba="0.3 0.3 0.3 1" mesh="r_f_link3_2_1"/>
              <geom type="mesh" rgba="0.3 0.3 0.3 1" mesh="r_f_link3_2_1"/>
              <geom type="mesh" contype="0" conaffinity="0" group="1" density="0" rgba="0.9 0.9 0.9 1" mesh="r_f_link3_2_2"/>
              <geom type="mesh" rgba="0.9 0.9 0.9 1" mesh="r_f_link3_2_2"/>
              <body name="r_f_link3_3" pos="0.043 0 0">
                <inertial pos="0.0131191 -0.000594087 -1.28443e-05" quat="0.0241845 0.703776 -0.0291852 0.70941" mass="0.00507867" diaginertia="4.55549e-07 4.23953e-07 2.29611e-07"/>
                <joint name="r_f_joint3_3" pos="0 0 0" axis="0 0 1" range="0 1.3" actuatorfrcrange="-10 10"/>
                <geom type="mesh" contype="0" conaffinity="0" group="1" density="0" rgba="0.3 0.3 0.3 1" mesh="r_f_link3_3"/>
                <geom type="mesh" rgba="0.3 0.3 0.3 1" mesh="r_f_link3_3"/>
                <geom type="mesh" contype="0" conaffinity="0" group="1" density="0" rgba="0.9 0.9 0.9 1" mesh="r_f_link3_3_1"/>
                <geom type="mesh" rgba="0.9 0.9 0.9 1" mesh="r_f_link3_3_1"/>
                <geom type="mesh" contype="0" conaffinity="0" group="1" density="0" rgba="0.9 0.9 0.9 1" mesh="r_f_link3_3_2"/>
                <geom type="mesh" rgba="0.9 0.9 0.9 1" mesh="r_f_link3_3_2"/>
                <body name="r_f_link3_4" pos="0.025 0 0">
                  <inertial pos="-0.811045 0.185279 -0.153025" quat="0.647204 0.455114 0.451324 0.41268" mass="0.0170943" diaginertia="0.00701876 0.00701865 1.97514e-07"/>
                  <joint name="r_f_joint3_4" pos="0 0 0" axis="0 0 1" range="0 1.3" actuatorfrcrange="-10 10"/>
                  <geom type="mesh" contype="0" conaffinity="0" group="1" density="0" rgba="0.3 0.3 0.3 1" mesh="r_f_link3_4"/>
                  <geom type="mesh" rgba="0.3 0.3 0.3 1" mesh="r_f_link3_4"/>
                  <geom type="mesh" contype="0" conaffinity="0" group="1" density="0" rgba="0.3 0.3 0.3 1" mesh="r_f_link3_4_1"/>
                  <geom type="mesh" rgba="0.3 0.3 0.3 1" mesh="r_f_link3_4_1"/>
                  <geom type="mesh" contype="0" conaffinity="0" group="1" density="0" rgba="0.9 0.9 0.9 1" mesh="r_f_link3_4_2"/>
                  <geom type="mesh" rgba="0.9 0.9 0.9 1" mesh="r_f_link3_4_2"/>
                  <geom size="0.002" pos="0.035 -0.004 0" contype="0" conaffinity="0" group="1" density="0" rgba="1 0 0 1"/>
                  <geom size="0.002" pos="0.02 0 0" rgba="1 0 0 1"/>
                  <site name="site_r_f_link3_4" pos="0.025 0.003 0" size="0.01" type="sphere"/>
                </body>
              </body>
            </body>
          </body>
          <body name="r_f_link4_1" pos="0.0069769 -0.0136824 0.1597" quat="0.000278947 -0.707107 -0.000281544 -0.707107">
            <inertial pos="0.0080017 1.8833e-05 -0.0015869" quat="0.366604 0.60097 0.60931 0.364936" mass="0.003769" diaginertia="3.9885e-07 3.46938e-07 2.19942e-07"/>
            <joint name="r_f_joint4_1" pos="0 0 0" axis="0 0 1" range="0 0.6" actuatorfrcrange="-10 10"/>
            <geom type="mesh" contype="0" conaffinity="0" group="1" density="0" rgba="0.9 0.9 0.9 1" mesh="r_f_link4_1"/>
            <geom type="mesh" rgba="0.9 0.9 0.9 1" mesh="r_f_link4_1"/>
            <body name="r_f_link4_2" pos="0.017 0 0" quat="0.707105 0.707108 0 0">
              <inertial pos="0.0211585 0.00187282 -0.000350334" quat="-0.0468834 0.703985 -0.0687872 0.70532" mass="0.0073387" diaginertia="1.31205e-06 1.26861e-06 3.83265e-07"/>
              <joint name="r_f_joint4_2" pos="0 0 0" axis="0 0 1" range="0 1.3" actuatorfrcrange="-10 10"/>
              <geom type="mesh" contype="0" conaffinity="0" group="1" density="0" rgba="0.3 0.3 0.3 1" mesh="r_f_link4_2"/>
              <geom type="mesh" rgba="0.3 0.3 0.3 1" mesh="r_f_link4_2"/>
              <geom type="mesh" contype="0" conaffinity="0" group="1" density="0" rgba="0.3 0.3 0.3 1" mesh="r_f_link4_2_1"/>
              <geom type="mesh" rgba="0.3 0.3 0.3 1" mesh="r_f_link4_2_1"/>
              <geom type="mesh" contype="0" conaffinity="0" group="1" density="0" rgba="0.9 0.9 0.9 1" mesh="r_f_link4_2_2"/>
              <geom type="mesh" rgba="0.9 0.9 0.9 1" mesh="r_f_link4_2_2"/>
              <body name="r_f_link4_3" pos="0.043 0 0">
                <inertial pos="0.0131191 -0.000594087 -1.28443e-05" quat="0.0241861 0.703776 -0.0291868 0.70941" mass="0.00507867" diaginertia="4.55549e-07 4.23953e-07 2.29611e-07"/>
                <joint name="r_f_joint4_3" pos="0 0 0" axis="0 0 1" range="0 1.3" actuatorfrcrange="-10 10"/>
                <geom type="mesh" contype="0" conaffinity="0" group="1" density="0" rgba="0.3 0.3 0.3 1" mesh="r_f_link4_3"/>
                <geom type="mesh" rgba="0.3 0.3 0.3 1" mesh="r_f_link4_3"/>
                <geom type="mesh" contype="0" conaffinity="0" group="1" density="0" rgba="0.9 0.9 0.9 1" mesh="r_f_link4_3_2"/>
                <geom type="mesh" rgba="0.9 0.9 0.9 1" mesh="r_f_link4_3_2"/>
                <geom type="mesh" contype="0" conaffinity="0" group="1" density="0" rgba="0.3 0.3 0.3 1" mesh="r_f_link4_3_1"/>
                <geom type="mesh" rgba="0.3 0.3 0.3 1" mesh="r_f_link4_3_1"/>
                <body name="r_f_link4_4" pos="0.025 0 0">
                  <inertial pos="-0.805245 0.185279 -0.137366" quat="0.64153 0.461595 0.453936 0.411476" mass="0.0170943" diaginertia="0.00688535 0.00688525 1.96188e-07"/>
                  <joint name="r_f_joint4_4" pos="0 0 0" axis="0 0 1" range="0 1.3" actuatorfrcrange="-10 10"/>
                  <geom type="mesh" contype="0" conaffinity="0" group="1" density="0" rgba="0.3 0.3 0.3 1" mesh="r_f_link4_4"/>
                  <geom type="mesh" rgba="0.3 0.3 0.3 1" mesh="r_f_link4_4"/>
                  <geom type="mesh" contype="0" conaffinity="0" group="1" density="0" rgba="0.3 0.3 0.3 1" mesh="r_f_link4_4_1"/>
                  <geom type="mesh" rgba="0.3 0.3 0.3 1" mesh="r_f_link4_4_1"/>
                  <geom type="mesh" contype="0" conaffinity="0" group="1" density="0" rgba="0.9 0.9 0.9 1" mesh="r_f_link4_4_2"/>
                  <geom type="mesh" rgba="0.9 0.9 0.9 1" mesh="r_f_link4_4_2"/>
                  <geom size="0.002" pos="0.035 -0.004 0" contype="0" conaffinity="0" group="1" density="0" rgba="1 0 0 1"/>
                  <geom size="0.002" pos="0.02 0 0" rgba="1 0 0 1"/>
                  <site name="site_r_f_link4_4" pos="0.025 0.003 0" size="0.01" type="sphere"/>
                </body>
              </body>
            </body>
          </body>
          <body name="r_f_link5_1" pos="0.00699625 -0.0379824 0.1457" quat="0.000278947 -0.707107 -0.000281544 -0.707107">
            <inertial pos="0.0080017 1.8833e-05 -0.0015869" quat="0.366604 0.60097 0.60931 0.364936" mass="0.003769" diaginertia="3.9885e-07 3.46938e-07 2.19942e-07"/>
            <joint name="r_f_joint5_1" pos="0 0 0" axis="0 0 1" range="0 0.6" actuatorfrcrange="-10 10"/>
            <geom type="mesh" contype="0" conaffinity="0" group="1" density="0" rgba="0.9 0.9 0.9 1" mesh="r_f_link5_1"/>
            <geom type="mesh" rgba="0.9 0.9 0.9 1" mesh="r_f_link5_1"/>
            <body name="r_f_link5_2" pos="0.017 0 0" quat="0.707105 0.707108 0 0">
              <inertial pos="0.0214621 -0.000317231 -0.000279089" quat="0.515425 0.495685 0.504137 0.484231" mass="0.00921437" diaginertia="1.92287e-06 1.88786e-06 6.04775e-07"/>
              <joint name="r_f_joint5_2" pos="0 0 0" axis="0 0 1" range="0 1.3" actuatorfrcrange="-10 10"/>
              <geom type="mesh" contype="0" conaffinity="0" group="1" density="0" rgba="0.3 0.3 0.3 1" mesh="r_f_link5_2"/>
              <geom type="mesh" rgba="0.3 0.3 0.3 1" mesh="r_f_link5_2"/>
              <geom type="mesh" contype="0" conaffinity="0" group="1" density="0" rgba="0.3 0.3 0.3 1" mesh="r_f_link5_2_1"/>
              <geom type="mesh" rgba="0.3 0.3 0.3 1" mesh="r_f_link5_2_1"/>
              <geom type="mesh" contype="0" conaffinity="0" group="1" density="0" rgba="0.9 0.9 0.9 1" mesh="r_f_link5_2_2"/>
              <geom type="mesh" rgba="0.9 0.9 0.9 1" mesh="r_f_link5_2_2"/>
              <body name="r_f_link5_3" pos="0.043 0 0">
                <inertial pos="-0.00100656 -0.000954128 -9.50334e-06" quat="0.483005 0.482548 0.516706 0.516593" mass="0.00696211" diaginertia="3.06637e-06 3.02329e-06 4.22157e-07"/>
                <joint name="r_f_joint5_3" pos="0 0 0" axis="0 0 1" range="0 1.3" actuatorfrcrange="-10 10"/>
                <geom type="mesh" contype="0" conaffinity="0" group="1" density="0" rgba="0.3 0.3 0.3 1" mesh="r_f_link5_3"/>
                <geom type="mesh" rgba="0.3 0.3 0.3 1" mesh="r_f_link5_3"/>
                <geom type="mesh" contype="0" conaffinity="0" group="1" density="0" rgba="0.3 0.3 0.3 1" mesh="r_f_link5_3_1"/>
                <geom type="mesh" rgba="0.3 0.3 0.3 1" mesh="r_f_link5_3_1"/>
                <geom type="mesh" contype="0" conaffinity="0" group="1" density="0" rgba="0.9 0.9 0.9 1" mesh="r_f_link5_3_2"/>
                <geom type="mesh" rgba="0.9 0.9 0.9 1" mesh="r_f_link5_3_2"/>
                <body name="r_f_link5_4" pos="0.025 0 0">
                  <inertial pos="-0.796224 0.185279 -0.121707" quat="0.635882 0.468415 0.456 0.410251" mass="0.0170943" diaginertia="0.00670768 0.00670758 1.94937e-07"/>
                  <joint name="r_f_joint5_4" pos="0 0 0" axis="0 0 1" range="0 1.3" actuatorfrcrange="-10 10"/>
                  <geom type="mesh" contype="0" conaffinity="0" group="1" density="0" rgba="0.3 0.3 0.3 1" mesh="r_f_link5_4"/>
                  <geom type="mesh" rgba="0.3 0.3 0.3 1" mesh="r_f_link5_4"/>
                  <geom type="mesh" contype="0" conaffinity="0" group="1" density="0" rgba="0.3 0.3 0.3 1" mesh="r_f_link5_4_1"/>
                  <geom type="mesh" rgba="0.3 0.3 0.3 1" mesh="r_f_link5_4_1"/>
                  <geom type="mesh" contype="0" conaffinity="0" group="1" density="0" rgba="0.9 0.9 0.9 1" mesh="r_f_link5_4_2"/>
                  <geom type="mesh" rgba="0.9 0.9 0.9 1" mesh="r_f_link5_4_2"/>
                  <geom size="0.002" pos="0.035 -0.004 0" contype="0" conaffinity="0" group="1" density="0" rgba="1 0 0 1"/>
                  <geom size="0.002" pos="0.02 0 0" rgba="1 0 0 1"/>
                  <site name="site_r_f_link5_4" pos="0.025 0.003 0" size="0.01" type="sphere"/>
                </body>
              </body>
            </body>
          </body>
        </body>
      </body>
    </body>
  </worldbody>
  <actuator>
    <position name="act_ARTx" joint="ARTx" kp="10000" kv="500" ctrlrange="-1 1"/>
    <position name="act_ARTy" joint="ARTy" kp="10000" kv="500" ctrlrange="-1 1"/>
    <position name="act_ARTz" joint="ARTz" kp="10000" kv="500" ctrlrange="-1 1"/>
    <position name="act_ARRx" joint="ARRx" kp="10000" kv="500" ctrlrange="-3.14 3.14"/>
    <position name="act_ARRy" joint="ARRy" kp="10000" kv="500" ctrlrange="-3.14 3.14"/>
    <position name="act_ARRz" joint="ARRz" kp="10000" kv="500" ctrlrange="-3.14 3.14"/>
    <position name="act_r_f_joint1_2" joint="r_f_joint1_2" kp="20" kv="0.1" ctrlrange="0 1.3" forcerange="-20 20"/>
    <position name="act_r_f_joint1_3" joint="r_f_joint1_3" kp="20" kv="0.1" ctrlrange="0 1.3" forcerange="-20 20"/>
    <position name="act_r_f_joint1_4" joint="r_f_joint1_4" kp="20" kv="0.1" ctrlrange="0 1.3" forcerange="-20 20"/>
    <position name="act_r_f_joint2_2" joint="r_f_joint2_2" kp="20" kv="0.1" ctrlrange="0 1.3" forcerange="-20 20"/>
    <position name="act_r_f_joint2_3" joint="r_f_joint2_3" kp="20" kv="0.1" ctrlrange="0 1.3" forcerange="-20 20"/>
    <position name="act_r_f_joint2_4" joint="r_f_joint2_4" kp="20" kv="0.1" ctrlrange="0 1.3" forcerange="-20 20"/>
    <position name="act_r_f_joint3_2" joint="r_f_joint3_2" kp="20" kv="0.1" ctrlrange="0 1.3" forcerange="-20 20"/>
    <position name="act_r_f_joint3_3" joint="r_f_joint3_3" kp="20" kv="0.1" ctrlrange="0 1.3" forcerange="-20 20"/>
    <position name="act_r_f_joint3_4" joint="r_f_joint3_4" kp="20" kv="0.1" ctrlrange="0 1.3" forcerange="-20 20"/>
    <position name="act_r_f_joint4_2" joint="r_f_joint4_2" kp="20" kv="0.1" ctrlrange="0 1.3" forcerange="-20 20"/>
    <position name="act_r_f_joint4_3" joint="r_f_joint4_3" kp="20" kv="0.1" ctrlrange="0 1.3" forcerange="-20 20"/>
    <position name="act_r_f_joint4_4" joint="r_f_joint4_4" kp="20" kv="0.1" ctrlrange="0 1.3" forcerange="-20 20"/>
    <position name="act_r_f_joint5_2" joint="r_f_joint5_2" kp="20" kv="0.1" ctrlrange="0 1.3" forcerange="-20 20"/>
    <position name="act_r_f_joint5_3" joint="r_f_joint5_3" kp="20" kv="0.1" ctrlrange="0 1.3" forcerange="-20 20"/>
    <position name="act_r_f_joint5_4" joint="r_f_joint5_4" kp="20" kv="0.1" ctrlrange="0 1.3" forcerange="-20 20"/>
    <position name="act_r_f_joint1_1" joint="r_f_joint1_1" kp="20" kv="1" ctrlrange="0 2.2" forcerange="-20 20"/>
    <position name="act_r_f_joint2_1" joint="r_f_joint2_1" kp="20" kv="1" ctrlrange="0 0.3" forcerange="-20 20"/>
    <position name="act_r_f_joint3_1" joint="r_f_joint3_1" kp="20" kv="1" ctrlrange="-0.0001 0.0001" forcerange="-20 20"/>
    <position name="act_r_f_joint4_1" joint="r_f_joint4_1" kp="20" kv="1" ctrlrange="0 0.3" forcerange="-20 20"/>
    <position name="act_r_f_joint5_1" joint="r_f_joint5_1" kp="20" kv="1" ctrlrange="0 0.6" forcerange="-20 20"/>
  </actuator>
  <asset>
    <mesh name="r_p_link0" file="../meshes/dexhand021/r_p_link0.STL"/>
    <mesh name="r_f_link1_1" file="../meshes/dexhand021/r_f_link1_1.STL"/>
    <mesh name="r_f_link1_2" file="../meshes/dexhand021/r_f_link1_2.STL"/>
    <mesh name="r_f_link1_3" file="../meshes/dexhand021/r_f_link1_3.STL"/>
    <mesh name="r_f_link1_4" file="../meshes/dexhand021/r_f_link1_4.STL"/>
    <mesh name="r_f_link1_4_1" file="../meshes/dexhand021/r_f_link1_4_1.STL"/>
    <mesh name="r_f_link1_4_2" file="../meshes/dexhand021/r_f_link1_4_2.STL"/>
    <mesh name="r_f_link1_3_1" file="../meshes/dexhand021/r_f_link1_3_1.STL"/>
    <mesh name="r_f_link1_3_2" file="../meshes/dexhand021/r_f_link1_3_2.STL"/>
    <mesh name="r_f_link1_2_1" file="../meshes/dexhand021/r_f_link1_2_1.STL"/>
    <mesh name="r_f_link1_2_2" file="../meshes/dexhand021/r_f_link1_2_2.STL"/>
    <mesh name="r_f_link2_1" file="../meshes/dexhand021/r_f_link2_1.STL"/>
    <mesh name="r_f_link2_2" file="../meshes/dexhand021/r_f_link2_2.STL"/>
    <mesh name="r_f_link2_3" file="../meshes/dexhand021/r_f_link2_3.STL"/>
    <mesh name="r_f_link2_4" file="../meshes/dexhand021/r_f_link2_4.STL"/>
    <mesh name="r_f_link2_4_1" file="../meshes/dexhand021/r_f_link2_4_1.STL"/>
    <mesh name="r_f_link2_4_2" file="../meshes/dexhand021/r_f_link2_4_2.STL"/>
    <mesh name="r_f_link2_3_1" file="../meshes/dexhand021/r_f_link2_3_1.STL"/>
    <mesh name="r_f_link2_3_2" file="../meshes/dexhand021/r_f_link2_3_2.STL"/>
    <mesh name="r_f_link2_2_1" file="../meshes/dexhand021/r_f_link2_2_1.STL"/>
    <mesh name="r_f_link2_2_2" file="../meshes/dexhand021/r_f_link2_2_2.STL"/>
    <mesh name="r_f_link3_1" file="../meshes/dexhand021/r_f_link3_1.STL"/>
    <mesh name="r_f_link3_2" file="../meshes/dexhand021/r_f_link3_2.STL"/>
    <mesh name="r_f_link3_3" file="../meshes/dexhand021/r_f_link3_3.STL"/>
    <mesh name="r_f_link3_4" file="../meshes/dexhand021/r_f_link3_4.STL"/>
    <mesh name="r_f_link3_4_1" file="../meshes/dexhand021/r_f_link3_4_1.STL"/>
    <mesh name="r_f_link3_4_2" file="../meshes/dexhand021/r_f_link3_4_2.STL"/>
    <mesh name="r_f_link3_3_1" file="../meshes/dexhand021/r_f_link3_3_1.STL"/>
    <mesh name="r_f_link3_3_2" file="../meshes/dexhand021/r_f_link3_3_2.STL"/>
    <mesh name="r_f_link3_2_1" file="../meshes/dexhand021/r_f_link3_2_1.STL"/>
    <mesh name="r_f_link3_2_2" file="../meshes/dexhand021/r_f_link3_2_2.STL"/>
    <mesh name="r_f_link4_1" file="../meshes/dexhand021/r_f_link4_1.STL"/>
    <mesh name="r_f_link4_2" file="../meshes/dexhand021/r_f_link4_2.STL"/>
    <mesh name="r_f_link4_3" file="../meshes/dexhand021/r_f_link4_3.STL"/>
    <mesh name="r_f_link4_4" file="../meshes/dexhand021/r_f_link4_4.STL"/>
    <mesh name="r_f_link4_4_1" file="../meshes/dexhand021/r_f_link4_4_1.STL"/>
    <mesh name="r_f_link4_4_2" file="../meshes/dexhand021/r_f_link4_4_2.STL"/>
    <mesh name="r_f_link4_3_2" file="../meshes/dexhand021/r_f_link4_3_2.STL"/>
    <mesh name="r_f_link4_3_1" file="../meshes/dexhand021/r_f_link4_3_1.STL"/>
    <mesh name="r_f_link4_2_1" file="../meshes/dexhand021/r_f_link4_2_1.STL"/>
    <mesh name="r_f_link4_2_2" file="../meshes/dexhand021/r_f_link4_2_2.STL"/>
    <mesh name="r_f_link5_1" file="../meshes/dexhand021/r_f_link5_1.STL"/>
    <mesh name="r_f_link5_2" file="../meshes/dexhand021/r_f_link5_2.STL"/>
    <mesh name="r_f_link5_3" file="../meshes/dexhand021/r_f_link5_3.STL"/>
    <mesh name="r_f_link5_4" file="../meshes/dexhand021/r_f_link5_4.STL"/>
    <mesh name="r_f_link5_4_1" file="../meshes/dexhand021/r_f_link5_4_1.STL"/>
    <mesh name="r_f_link5_4_2" file="../meshes/dexhand021/r_f_link5_4_2.STL"/>
    <mesh name="r_f_link5_3_1" file="../meshes/dexhand021/r_f_link5_3_1.STL"/>
    <mesh name="r_f_link5_3_2" file="../meshes/dexhand021/r_f_link5_3_2.STL"/>
    <mesh name="r_f_link5_2_1" file="../meshes/dexhand021/r_f_link5_2_1.STL"/>
    <mesh name="r_f_link5_2_2" file="../meshes/dexhand021/r_f_link5_2_2.STL"/>
    <mesh name="r_p_link1" file="../meshes/dexhand021/r_p_link1.STL"/>
    <mesh name="r_p_link3" file="../meshes/dexhand021/r_p_link3.STL"/>
    <mesh name="r_p_link4" file="../meshes/dexhand021/r_p_link4.STL"/>
    <mesh name="r_p_link5" file="../meshes/dexhand021/r_p_link5.STL"/>
    <mesh name="r_p_link6" file="../meshes/dexhand021/r_p_link6.STL"/>
    <mesh name="r_p_link2" file="../meshes/dexhand021/r_p_link2.STL"/>
  </asset>
  <sensor>
    <touch name="touch_r_f_link1_4" site="site_r_f_link1_4"/>
    <touch name="touch_r_f_link2_4" site="site_r_f_link2_4"/>
    <touch name="touch_r_f_link3_4" site="site_r_f_link3_4"/>
    <touch name="touch_r_f_link4_4" site="site_r_f_link4_4"/>
    <touch name="touch_r_f_link5_4" site="site_r_f_link5_4"/>
  </sensor>
  <contact>
    <exclude body1="right_hand_base" body2="r_f_link1_1"/>
    <exclude body1="right_hand_base" body2="r_f_link1_2"/>
    <exclude body1="right_hand_base" body2="r_f_link1_3"/>
    <exclude body1="right_hand_base" body2="r_f_link1_4"/>
    <exclude body1="right_hand_base" body2="r_f_link2_1"/>
    <exclude body1="right_hand_base" body2="r_f_link2_2"/>
    <exclude body1="right_hand_base" body2="r_f_link2_3"/>
    <exclude body1="right_hand_base" body2="r_f_link2_4"/>
    <exclude body1="right_hand_base" body2="r_f_link3_1"/>
    <exclude body1="right_hand_base" body2="r_f_link3_2"/>
    <exclude body1="right_hand_base" body2="r_f_link3_3"/>
    <exclude body1="right_hand_base" body2="r_f_link3_4"/>
    <exclude body1="right_hand_base" body2="r_f_link4_1"/>
    <exclude body1="right_hand_base" body2="r_f_link4_2"/>
    <exclude body1="right_hand_base" body2="r_f_link4_3"/>
    <exclude body1="right_hand_base" body2="r_f_link4_4"/>
    <exclude body1="right_hand_base" body2="r_f_link5_1"/>
    <exclude body1="right_hand_base" body2="r_f_link5_2"/>
    <exclude body1="right_hand_base" body2="r_f_link5_3"/>
    <exclude body1="right_hand_base" body2="r_f_link5_4"/>
    <exclude body1="r_f_link1_1" body2="r_f_link1_2"/>
    <exclude body1="r_f_link1_1" body2="r_f_link1_3"/>
    <exclude body1="r_f_link1_1" body2="r_f_link1_4"/>
    <exclude body1="r_f_link1_1" body2="r_f_link2_1"/>
    <exclude body1="r_f_link1_1" body2="r_f_link2_2"/>
    <exclude body1="r_f_link1_1" body2="r_f_link2_3"/>
    <exclude body1="r_f_link1_1" body2="r_f_link2_4"/>
    <exclude body1="r_f_link1_1" body2="r_f_link3_1"/>
    <exclude body1="r_f_link1_1" body2="r_f_link3_2"/>
    <exclude body1="r_f_link1_1" body2="r_f_link3_3"/>
    <exclude body1="r_f_link1_1" body2="r_f_link3_4"/>
    <exclude body1="r_f_link1_1" body2="r_f_link4_1"/>
    <exclude body1="r_f_link1_1" body2="r_f_link4_2"/>
    <exclude body1="r_f_link1_1" body2="r_f_link4_3"/>
    <exclude body1="r_f_link1_1" body2="r_f_link4_4"/>
    <exclude body1="r_f_link1_1" body2="r_f_link5_1"/>
    <exclude body1="r_f_link1_1" body2="r_f_link5_2"/>
    <exclude body1="r_f_link1_1" body2="r_f_link5_3"/>
    <exclude body1="r_f_link1_1" body2="r_f_link5_4"/>
    <exclude body1="r_f_link1_2" body2="r_f_link1_3"/>
    <exclude body1="r_f_link1_2" body2="r_f_link1_4"/>
    <exclude body1="r_f_link1_2" body2="r_f_link2_1"/>
    <exclude body1="r_f_link1_2" body2="r_f_link2_2"/>
    <exclude body1="r_f_link1_2" body2="r_f_link2_3"/>
    <exclude body1="r_f_link1_2" body2="r_f_link2_4"/>
    <exclude body1="r_f_link1_2" body2="r_f_link3_1"/>
    <exclude body1="r_f_link1_2" body2="r_f_link3_2"/>
    <exclude body1="r_f_link1_2" body2="r_f_link3_3"/>
    <exclude body1="r_f_link1_2" body2="r_f_link3_4"/>
    <exclude body1="r_f_link1_2" body2="r_f_link4_1"/>
    <exclude body1="r_f_link1_2" body2="r_f_link4_2"/>
    <exclude body1="r_f_link1_2" body2="r_f_link4_3"/>
    <exclude body1="r_f_link1_2" body2="r_f_link4_4"/>
    <exclude body1="r_f_link1_2" body2="r_f_link5_1"/>
    <exclude body1="r_f_link1_2" body2="r_f_link5_2"/>
    <exclude body1="r_f_link1_2" body2="r_f_link5_3"/>
    <exclude body1="r_f_link1_2" body2="r_f_link5_4"/>
    <exclude body1="r_f_link1_3" body2="r_f_link1_4"/>
    <exclude body1="r_f_link1_3" body2="r_f_link2_1"/>
    <exclude body1="r_f_link1_3" body2="r_f_link2_2"/>
    <exclude body1="r_f_link1_3" body2="r_f_link2_3"/>
    <exclude body1="r_f_link1_3" body2="r_f_link2_4"/>
    <exclude body1="r_f_link1_3" body2="r_f_link3_1"/>
    <exclude body1="r_f_link1_3" body2="r_f_link3_2"/>
    <exclude body1="r_f_link1_3" body2="r_f_link3_3"/>
    <exclude body1="r_f_link1_3" body2="r_f_link3_4"/>
    <exclude body1="r_f_link1_3" body2="r_f_link4_1"/>
    <exclude body1="r_f_link1_3" body2="r_f_link4_2"/>
    <exclude body1="r_f_link1_3" body2="r_f_link4_3"/>
    <exclude body1="r_f_link1_3" body2="r_f_link4_4"/>
    <exclude body1="r_f_link1_3" body2="r_f_link5_1"/>
    <exclude body1="r_f_link1_3" body2="r_f_link5_2"/>
    <exclude body1="r_f_link1_3" body2="r_f_link5_3"/>
    <exclude body1="r_f_link1_3" body2="r_f_link5_4"/>
    <exclude body1="r_f_link1_4" body2="r_f_link2_1"/>
    <exclude body1="r_f_link1_4" body2="r_f_link2_2"/>
    <exclude body1="r_f_link1_4" body2="r_f_link2_3"/>
    <exclude body1="r_f_link1_4" body2="r_f_link3_1"/>
    <exclude body1="r_f_link1_4" body2="r_f_link3_2"/>
    <exclude body1="r_f_link1_4" body2="r_f_link3_3"/>
    <exclude body1="r_f_link1_4" body2="r_f_link4_1"/>
    <exclude body1="r_f_link1_4" body2="r_f_link4_2"/>
    <exclude body1="r_f_link1_4" body2="r_f_link4_3"/>
    <exclude body1="r_f_link1_4" body2="r_f_link5_1"/>
    <exclude body1="r_f_link1_4" body2="r_f_link5_2"/>
    <exclude body1="r_f_link1_4" body2="r_f_link5_3"/>
    <exclude body1="r_f_link2_1" body2="r_f_link2_2"/>
    <exclude body1="r_f_link2_1" body2="r_f_link2_3"/>
    <exclude body1="r_f_link2_1" body2="r_f_link2_4"/>
    <exclude body1="r_f_link2_1" body2="r_f_link3_1"/>
    <exclude body1="r_f_link2_1" body2="r_f_link3_2"/>
    <exclude body1="r_f_link2_1" body2="r_f_link3_3"/>
    <exclude body1="r_f_link2_1" body2="r_f_link3_4"/>
    <exclude body1="r_f_link2_1" body2="r_f_link4_1"/>
    <exclude body1="r_f_link2_1" body2="r_f_link4_2"/>
    <exclude body1="r_f_link2_1" body2="r_f_link4_3"/>
    <exclude body1="r_f_link2_1" body2="r_f_link4_4"/>
    <exclude body1="r_f_link2_1" body2="r_f_link5_1"/>
    <exclude body1="r_f_link2_1" body2="r_f_link5_2"/>
    <exclude body1="r_f_link2_1" body2="r_f_link5_3"/>
    <exclude body1="r_f_link2_1" body2="r_f_link5_4"/>
    <exclude body1="r_f_link2_2" body2="r_f_link2_3"/>
    <exclude body1="r_f_link2_2" body2="r_f_link2_4"/>
    <exclude body1="r_f_link2_2" body2="r_f_link3_1"/>
    <exclude body1="r_f_link2_2" body2="r_f_link3_2"/>
    <exclude body1="r_f_link2_2" body2="r_f_link3_3"/>
    <exclude body1="r_f_link2_2" body2="r_f_link3_4"/>
    <exclude body1="r_f_link2_2" body2="r_f_link4_1"/>
    <exclude body1="r_f_link2_2" body2="r_f_link4_2"/>
    <exclude body1="r_f_link2_2" body2="r_f_link4_3"/>
    <exclude body1="r_f_link2_2" body2="r_f_link4_4"/>
    <exclude body1="r_f_link2_2" body2="r_f_link5_1"/>
    <exclude body1="r_f_link2_2" body2="r_f_link5_2"/>
    <exclude body1="r_f_link2_2" body2="r_f_link5_3"/>
    <exclude body1="r_f_link2_2" body2="r_f_link5_4"/>
    <exclude body1="r_f_link2_3" body2="r_f_link2_4"/>
    <exclude body1="r_f_link2_3" body2="r_f_link3_1"/>
    <exclude body1="r_f_link2_3" body2="r_f_link3_2"/>
    <exclude body1="r_f_link2_3" body2="r_f_link3_3"/>
    <exclude body1="r_f_link2_3" body2="r_f_link3_4"/>
    <exclude body1="r_f_link2_3" body2="r_f_link4_1"/>
    <exclude body1="r_f_link2_3" body2="r_f_link4_2"/>
    <exclude body1="r_f_link2_3" body2="r_f_link4_3"/>
    <exclude body1="r_f_link2_3" body2="r_f_link4_4"/>
    <exclude body1="r_f_link2_3" body2="r_f_link5_1"/>
    <exclude body1="r_f_link2_3" body2="r_f_link5_2"/>
    <exclude body1="r_f_link2_3" body2="r_f_link5_3"/>
    <exclude body1="r_f_link2_3" body2="r_f_link5_4"/>
    <exclude body1="r_f_link2_4" body2="r_f_link3_1"/>
    <exclude body1="r_f_link2_4" body2="r_f_link3_2"/>
    <exclude body1="r_f_link2_4" body2="r_f_link3_3"/>
    <exclude body1="r_f_link2_4" body2="r_f_link4_1"/>
    <exclude body1="r_f_link2_4" body2="r_f_link4_2"/>
    <exclude body1="r_f_link2_4" body2="r_f_link4_3"/>
    <exclude body1="r_f_link2_4" body2="r_f_link5_1"/>
    <exclude body1="r_f_link2_4" body2="r_f_link5_2"/>
    <exclude body1="r_f_link2_4" body2="r_f_link5_3"/>
    <exclude body1="r_f_link3_1" body2="r_f_link3_2"/>
    <exclude body1="r_f_link3_1" body2="r_f_link3_3"/>
    <exclude body1="r_f_link3_1" body2="r_f_link3_4"/>
    <exclude body1="r_f_link3_1" body2="r_f_link4_1"/>
    <exclude body1="r_f_link3_1" body2="r_f_link4_2"/>
    <exclude body1="r_f_link3_1" body2="r_f_link4_3"/>
    <exclude body1="r_f_link3_1" body2="r_f_link4_4"/>
    <exclude body1="r_f_link3_1" body2="r_f_link5_1"/>
    <exclude body1="r_f_link3_1" body2="r_f_link5_2"/>
    <exclude body1="r_f_link3_1" body2="r_f_link5_3"/>
    <exclude body1="r_f_link3_1" body2="r_f_link5_4"/>
    <exclude body1="r_f_link3_2" body2="r_f_link3_3"/>
    <exclude body1="r_f_link3_2" body2="r_f_link3_4"/>
    <exclude body1="r_f_link3_2" body2="r_f_link4_1"/>
    <exclude body1="r_f_link3_2" body2="r_f_link4_2"/>
    <exclude body1="r_f_link3_2" body2="r_f_link4_3"/>
    <exclude body1="r_f_link3_2" body2="r_f_link4_4"/>
    <exclude body1="r_f_link3_2" body2="r_f_link5_1"/>
    <exclude body1="r_f_link3_2" body2="r_f_link5_2"/>
    <exclude body1="r_f_link3_2" body2="r_f_link5_3"/>
    <exclude body1="r_f_link3_2" body2="r_f_link5_4"/>
    <exclude body1="r_f_link3_3" body2="r_f_link3_4"/>
    <exclude body1="r_f_link3_3" body2="r_f_link4_1"/>
    <exclude body1="r_f_link3_3" body2="r_f_link4_2"/>
    <exclude body1="r_f_link3_3" body2="r_f_link4_3"/>
    <exclude body1="r_f_link3_3" body2="r_f_link4_4"/>
    <exclude body1="r_f_link3_3" body2="r_f_link5_1"/>
    <exclude body1="r_f_link3_3" body2="r_f_link5_2"/>
    <exclude body1="r_f_link3_3" body2="r_f_link5_3"/>
    <exclude body1="r_f_link3_3" body2="r_f_link5_4"/>
    <exclude body1="r_f_link3_4" body2="r_f_link4_1"/>
    <exclude body1="r_f_link3_4" body2="r_f_link4_2"/>
    <exclude body1="r_f_link3_4" body2="r_f_link4_3"/>
    <exclude body1="r_f_link3_4" body2="r_f_link5_1"/>
    <exclude body1="r_f_link3_4" body2="r_f_link5_2"/>
    <exclude body1="r_f_link3_4" body2="r_f_link5_3"/>
    <exclude body1="r_f_link4_1" body2="r_f_link4_2"/>
    <exclude body1="r_f_link4_1" body2="r_f_link4_3"/>
    <exclude body1="r_f_link4_1" body2="r_f_link4_4"/>
    <exclude body1="r_f_link4_1" body2="r_f_link5_1"/>
    <exclude body1="r_f_link4_1" body2="r_f_link5_2"/>
    <exclude body1="r_f_link4_1" body2="r_f_link5_3"/>
    <exclude body1="r_f_link4_1" body2="r_f_link5_4"/>
    <exclude body1="r_f_link4_2" body2="r_f_link4_3"/>
    <exclude body1="r_f_link4_2" body2="r_f_link4_4"/>
    <exclude body1="r_f_link4_2" body2="r_f_link5_1"/>
    <exclude body1="r_f_link4_2" body2="r_f_link5_2"/>
    <exclude body1="r_f_link4_2" body2="r_f_link5_3"/>
    <exclude body1="r_f_link4_2" body2="r_f_link5_4"/>
    <exclude body1="r_f_link4_3" body2="r_f_link4_4"/>
    <exclude body1="r_f_link4_3" body2="r_f_link5_1"/>
    <exclude body1="r_f_link4_3" body2="r_f_link5_2"/>
    <exclude body1="r_f_link4_3" body2="r_f_link5_3"/>
    <exclude body1="r_f_link4_3" body2="r_f_link5_4"/>
    <exclude body1="r_f_link4_4" body2="r_f_link5_1"/>
    <exclude body1="r_f_link4_4" body2="r_f_link5_2"/>
    <exclude body1="r_f_link4_4" body2="r_f_link5_3"/>
    <exclude body1="r_f_link5_1" body2="r_f_link5_2"/>
    <exclude body1="r_f_link5_1" body2="r_f_link5_3"/>
    <exclude body1="r_f_link5_1" body2="r_f_link5_4"/>
    <exclude body1="r_f_link5_2" body2="r_f_link5_3"/>
    <exclude body1="r_f_link5_2" body2="r_f_link5_4"/>
    <exclude body1="r_f_link5_3" body2="r_f_link5_4"/>
  </contact>
</mujoco>
