<?xml version="1.0" encoding="utf-8"?>
<mujoco model="dexhand021_left_simplified">
  <visual>
    <global offwidth="1920" offheight="1080"/>
  </visual>
  <option gravity="0 0 -9.81" iterations="100" solver="Newton" integrator="implicit" timestep="0.001"/>
  <default>
    <joint damping="1"/>
    <geom condim="3" solref="0.01 0.9" solimp="0.9 0.999 0.005" friction="3. 2. 2."/>
  </default>
  <size njmax="1000" nconmax="1000"/>
  <compiler angle="radian" meshdir="../meshes/dexhand021_simplified/"/>
  <asset>
    <mesh name="left_hand_base" file="left_hand_base.STL"/>
    <mesh name="l_f_link1_1" file="l_f_link1_1.STL"/>
    <mesh name="l_f_link1_2" file="l_f_link1_2.STL"/>
    <mesh name="l_f_link1_3" file="l_f_link1_3.STL"/>
    <mesh name="l_f_link1_4" file="l_f_link1_4.STL"/>
    <mesh name="l_f_link2_1" file="l_f_link2_1.STL"/>
    <mesh name="l_f_link2_2" file="l_f_link2_2.STL"/>
    <mesh name="l_f_link2_3" file="l_f_link2_3.STL"/>
    <mesh name="l_f_link2_4" file="l_f_link2_4.STL"/>
    <mesh name="l_f_link3_1" file="l_f_link3_1.STL"/>
    <mesh name="l_f_link3_2" file="l_f_link3_2.STL"/>
    <mesh name="l_f_link3_3" file="l_f_link3_3.STL"/>
    <mesh name="l_f_link3_4" file="l_f_link3_4.STL"/>
    <mesh name="l_f_link4_1" file="l_f_link4_1.STL"/>
    <mesh name="l_f_link4_2" file="l_f_link4_2.STL"/>
    <mesh name="l_f_link4_3" file="l_f_link4_3.STL"/>
    <mesh name="l_f_link4_4" file="l_f_link4_4.STL"/>
    <mesh name="l_f_link5_1" file="l_f_link5_1.STL"/>
    <mesh name="l_f_link5_2" file="l_f_link5_2.STL"/>
    <mesh name="l_f_link5_3" file="l_f_link5_3.STL"/>
    <mesh name="l_f_link5_4" file="l_f_link5_4.STL"/>
  </asset>
  <worldbody>
    <body name="left_hand_base" pos="0 0 0" quat="1 0 0 0">
      <geom type="mesh" contype="0" conaffinity="0" group="1" density="0" rgba="0.75294 0.75294 0.75294 1" mesh="left_hand_base"/>
      <geom type="mesh" rgba="0.75294 0.75294 0.75294 1" mesh="left_hand_base" contype="0" conaffinity="0" group="1" density="0"/>
      <body name="l_f_link1_1" pos="0.032783 -0.023781 0.11211" quat="0.775383 -0.151562 0.0221299 -0.612635">
        <inertial pos="0.00198057 -0.000351992 -0.0134513" quat="0.716547 0.0775675 0.0530798 0.691178" mass="0.00440965" diaginertia="4.39524e-07 3.79859e-07 1.98262e-07"/>
        <joint name="l_f_joint1_1" pos="0 0 0" axis="0 0 1" range="0 2.2" actuatorfrcrange="-10 10"/>
        <geom type="mesh" contype="0" conaffinity="0" group="1" density="0" rgba="0.6 0.6 0.6 1" mesh="l_f_link1_1"/>
        <geom type="mesh" rgba="0.6 0.6 0.6 1" mesh="l_f_link1_1" contype="0" conaffinity="0" group="1" density="0"/>
        <body name="l_f_link1_2" pos="0.0083307 0 0" quat="0.707105 0.707108 0 0">
          <inertial pos="0.021435 0.000179938 0.0012982" quat="0.016958 0.707385 -0.0126923 0.706511" mass="0.00995163" diaginertia="1.70991e-06 1.65549e-06 6.19029e-07"/>
          <joint name="l_f_joint1_2" pos="0 0 0" axis="0 0 1" range="0 1.3" actuatorfrcrange="-10 10"/>
          <geom type="mesh" contype="0" conaffinity="0" group="1" density="0" rgba="0.6 0.6 0.6 1" mesh="l_f_link1_2"/>
          <geom type="mesh" rgba="0.6 0.6 0.6 1" mesh="l_f_link1_2" contype="0" conaffinity="0" group="1" density="0"/>
          <body name="l_f_link1_3" pos="0.043 0 0">
            <inertial pos="0.0134587 -0.000699415 0.00129313" quat="0.0207134 0.706891 -0.0204889 0.706722" mass="0.00457275" diaginertia="3.79726e-07 3.56511e-07 2.03184e-07"/>
            <joint name="l_f_joint1_3" pos="0 0 0" axis="0 0 1" range="0 1.3" actuatorfrcrange="-10 10"/>
            <geom type="mesh" contype="0" conaffinity="0" group="1" density="0" rgba="0.6 0.6 0.6 1" mesh="l_f_link1_3"/>
            <geom type="mesh" rgba="0.6 0.6 0.6 1" mesh="l_f_link1_3" contype="0" conaffinity="0" group="1" density="0"/>
            <body name="l_f_link1_4" pos="0.025 0 0">
              <inertial pos="0.0197516 -0.00297416 0.00109866" quat="0.101158 0.716582 0.0177497 0.689901" mass="0.00815824" diaginertia="1.11886e-06 1.10162e-06 3.47e-07"/>
              <joint name="l_f_joint1_4" pos="0 0 0" axis="0 0 1" range="0 1.3" actuatorfrcrange="-10 10"/>
              <geom type="mesh" contype="0" conaffinity="0" group="1" density="0" rgba="0.6 0.6 0.6 1" mesh="l_f_link1_4"/>
              <geom type="mesh" rgba="0.6 0.6 0.6 1" mesh="l_f_link1_4" contype="0" conaffinity="0" group="1" density="0"/>
              <geom size="0.002" pos="0.035 -0.004 0" contype="0" conaffinity="0" group="1" density="0" rgba="1 0 0 1"/>
              <geom size="0.002" pos="0.035 -0.004 0" rgba="1 0 0 1" contype="0" conaffinity="0" group="1" density="0"/>
              <geom size="0.006 0.0005 0.003" pos="0.026 0.0025 0.001" quat="0.974794 0 0 -0.223106" type="box" contype="0" conaffinity="0" group="1" density="0" rgba="0 1 0 1"/>
              <geom size="0.006 0.0005 0.003" pos="0.026 0.0025 0.001" quat="0.974794 0 0 -0.223106" type="box" rgba="0 1 0 1" contype="0" conaffinity="0" group="1" density="0"/>
              <site name="site_l_f_link1_tip" pos="0.035 -0.004 0" quat="1.0 0.0 0.0 0.0" type="sphere" size="0.002" rgba="1 0 0 1"/>
              <site name="site_l_f_link1_pad" pos="0.026 0.0025 0.001" quat="0.9747941070689433 0.0 0.0 -0.22310636213174545" type="box" size="0.006 0.0005 0.003" rgba="0 1 0 1"/>
              <geom name="col_l_f_link1_4" type="capsule" contype="1" conaffinity="1" group="3" size="0.0095" fromto="0.0 0 0.001 0.027 -0.007 0.001"/>
            </body>
            <geom name="col_l_f_link1_3" type="capsule" contype="1" conaffinity="1" group="3" size="0.007" fromto="0.0125 0.003 -0.002 0.0125 0.003 0.0042"/>
          </body>
          <geom name="col_l_f_link1_2" type="capsule" contype="1" conaffinity="1" group="3" size="0.0095" fromto="0.0 0 0 0.03 0 0.002"/>
        </body>
      </body>
      <body name="l_f_link2_1" pos="0.006966 -0.034912 0.1644" quat="-2.59734e-06 0.707105 2.59735e-06 0.707108">
        <inertial pos="0.00700212 1.08537e-07 -0.00096856" quat="0.370763 0.602117 0.602108 0.370749" mass="0.00409701" diaginertia="3.18122e-07 2.71723e-07 2.04204e-07"/>
        <joint name="l_f_joint2_1" pos="0 0 0" axis="0 0 1" range="0 0.6" actuatorfrcrange="-10 10"/>
        <geom type="mesh" contype="0" conaffinity="0" group="1" density="0" rgba="0.792157 0.819608 0.933333 1" mesh="l_f_link2_1"/>
        <geom type="mesh" rgba="0.792157 0.819608 0.933333 1" mesh="l_f_link2_1" contype="0" conaffinity="0" group="1" density="0"/>
        <body name="l_f_link2_2" pos="0.017 0 0" quat="0.707105 0.707108 0 0">
          <inertial pos="0.0211622 -0.000590378 2.72622e-06" quat="0.502474 0.508577 0.49194 0.496854" mass="0.0094283" diaginertia="1.65781e-06 1.64333e-06 5.5432e-07"/>
          <joint name="l_f_joint2_2" pos="0 0 0" axis="0 0 1" range="0 1.3" actuatorfrcrange="-10 10"/>
          <geom type="mesh" contype="0" conaffinity="0" group="1" density="0" rgba="0.6 0.6 0.6 1" mesh="l_f_link2_2"/>
          <geom type="mesh" rgba="0.6 0.6 0.6 1" mesh="l_f_link2_2" contype="0" conaffinity="0" group="1" density="0"/>
          <body name="l_f_link2_3" pos="0.043 0 0">
            <inertial pos="0.0134587 -0.000699415 7.12893e-07" quat="0.0207134 0.706891 -0.0204889 0.706722" mass="0.00457275" diaginertia="3.79726e-07 3.56511e-07 2.03184e-07"/>
            <joint name="l_f_joint2_3" pos="0 0 0" axis="0 0 1" range="0 1.3" actuatorfrcrange="-10 10"/>
            <geom type="mesh" contype="0" conaffinity="0" group="1" density="0" rgba="0.6 0.6 0.6 1" mesh="l_f_link2_3"/>
            <geom type="mesh" rgba="0.6 0.6 0.6 1" mesh="l_f_link2_3" contype="0" conaffinity="0" group="1" density="0"/>
            <body name="l_f_link2_4" pos="0.025 0 0">
              <inertial pos="0.0197516 -0.00297416 5.40083e-07" quat="0.0429662 0.705803 -0.0424926 0.705826" mass="0.00815824" diaginertia="1.11778e-06 1.10066e-06 3.46138e-07"/>
              <joint name="l_f_joint2_4" pos="0 0 0" axis="0 0 1" range="0 1.3" actuatorfrcrange="-10 10"/>
              <geom type="mesh" contype="0" conaffinity="0" group="1" density="0" rgba="0.6 0.6 0.6 1" mesh="l_f_link2_4"/>
              <geom type="mesh" rgba="0.6 0.6 0.6 1" mesh="l_f_link2_4" contype="0" conaffinity="0" group="1" density="0"/>
              <geom size="0.002" pos="0.035 -0.004 0" contype="0" conaffinity="0" group="1" density="0" rgba="1 0 0 1"/>
              <geom size="0.002" pos="0.035 -0.004 0" rgba="1 0 0 1" contype="0" conaffinity="0" group="1" density="0"/>
              <geom size="0.006 0.0005 0.003" pos="0.026 0.0025 0" quat="0.974794 0 0 -0.223106" type="box" contype="0" conaffinity="0" group="1" density="0" rgba="0 1 0 1"/>
              <geom size="0.006 0.0005 0.003" pos="0.026 0.0025 0" quat="0.974794 0 0 -0.223106" type="box" rgba="0 1 0 1" contype="0" conaffinity="0" group="1" density="0"/>
              <site name="site_l_f_link2_tip" pos="0.035 -0.004 0" quat="1.0 0.0 0.0 0.0" type="sphere" size="0.002" rgba="1 0 0 1"/>
              <site name="site_l_f_link2_pad" pos="0.026 0.0025 0.000" quat="0.9747941070689433 0.0 0.0 -0.22310636213174545" type="box" size="0.006 0.0005 0.003" rgba="0 1 0 1"/>
              <geom name="col_l_f_link2_4" type="capsule" contype="1" conaffinity="1" group="3" size="0.0095" fromto="0.0 0 0 0.026 -0.007 0"/>
            </body>
            <geom name="col_l_f_link2_3" type="capsule" contype="1" conaffinity="1" group="3" size="0.007" fromto="0.012 0.003 -0.0035 0.012 0.003 0.0035"/>
          </body>
          <geom name="col_l_f_link2_2" type="capsule" contype="1" conaffinity="1" group="3" size="0.0095" fromto="0.005 0 0 0.03 0 0"/>
        </body>
      </body>
      <body name="l_f_link3_1" pos="0.006966 -0.010612 0.1734" quat="-2.59734e-06 0.707105 2.59735e-06 0.707108">
        <inertial pos="0.00700212 1.07469e-07 -0.000968557" quat="0.370763 0.602117 0.602109 0.370749" mass="0.00409701" diaginertia="3.18122e-07 2.71723e-07 2.04204e-07"/>
        <joint name="l_f_joint3_1" pos="0 0 0" axis="0 0 1" range="-0.001 0.001" actuatorfrcrange="-10 10"/>
        <geom type="mesh" contype="0" conaffinity="0" group="1" density="0" rgba="0.792157 0.819608 0.933333 1" mesh="l_f_link3_1"/>
        <geom type="mesh" rgba="0.792157 0.819608 0.933333 1" mesh="l_f_link3_1" contype="0" conaffinity="0" group="1" density="0"/>
        <body name="l_f_link3_2" pos="0.017 0 0" quat="0.707105 0.707108 0 0">
          <inertial pos="0.0211622 -0.000590378 2.72622e-06" quat="0.502474 0.508577 0.49194 0.496854" mass="0.0094283" diaginertia="1.65781e-06 1.64333e-06 5.5432e-07"/>
          <joint name="l_f_joint3_2" pos="0 0 0" axis="0 0 1" range="0 1.3" actuatorfrcrange="-10 10"/>
          <geom type="mesh" contype="0" conaffinity="0" group="1" density="0" rgba="0.6 0.6 0.6 1" mesh="l_f_link3_2"/>
          <geom type="mesh" rgba="0.6 0.6 0.6 1" mesh="l_f_link3_2" contype="0" conaffinity="0" group="1" density="0"/>
          <body name="l_f_link3_3" pos="0.043 0 0">
            <inertial pos="0.0134587 -0.000699415 7.12894e-07" quat="0.0207134 0.706891 -0.0204889 0.706722" mass="0.00457275" diaginertia="3.79726e-07 3.56511e-07 2.03184e-07"/>
            <joint name="l_f_joint3_3" pos="0 0 0" axis="0 0 1" range="0 1.3" actuatorfrcrange="-10 10"/>
            <geom type="mesh" contype="0" conaffinity="0" group="1" density="0" rgba="0.6 0.6 0.6 1" mesh="l_f_link3_3"/>
            <geom type="mesh" rgba="0.6 0.6 0.6 1" mesh="l_f_link3_3" contype="0" conaffinity="0" group="1" density="0"/>
            <body name="l_f_link3_4" pos="0.025 0 0">
              <inertial pos="0.0197516 -0.00297416 5.40083e-07" quat="0.0429662 0.705803 -0.0424926 0.705826" mass="0.00815824" diaginertia="1.11778e-06 1.10066e-06 3.46138e-07"/>
              <joint name="l_f_joint3_4" pos="0 0 0" axis="0 0 1" range="0 1.3" actuatorfrcrange="-10 10"/>
              <geom type="mesh" contype="0" conaffinity="0" group="1" density="0" rgba="0.6 0.6 0.6 1" mesh="l_f_link3_4"/>
              <geom type="mesh" rgba="0.6 0.6 0.6 1" mesh="l_f_link3_4" contype="0" conaffinity="0" group="1" density="0"/>
              <geom size="0.002" pos="0.035 -0.004 0" contype="0" conaffinity="0" group="1" density="0" rgba="1 0 0 1"/>
              <geom size="0.002" pos="0.035 -0.004 0" rgba="1 0 0 1" contype="0" conaffinity="0" group="1" density="0"/>
              <geom size="0.006 0.0005 0.003" pos="0.026 0.0025 0" quat="0.974794 0 0 -0.223106" type="box" contype="0" conaffinity="0" group="1" density="0" rgba="0 1 0 1"/>
              <geom size="0.006 0.0005 0.003" pos="0.026 0.0025 0" quat="0.974794 0 0 -0.223106" type="box" rgba="0 1 0 1" contype="0" conaffinity="0" group="1" density="0"/>
              <site name="site_l_f_link3_tip" pos="0.035 -0.004 0" quat="1.0 0.0 0.0 0.0" type="sphere" size="0.002" rgba="1 0 0 1"/>
              <site name="site_l_f_link3_pad" pos="0.026 0.0025 0.000" quat="0.9747941070689433 0.0 0.0 -0.22310636213174545" type="box" size="0.006 0.0005 0.003" rgba="0 1 0 1"/>
              <geom name="col_l_f_link3_4" type="capsule" contype="1" conaffinity="1" group="3" size="0.0095" fromto="0.0 0 0 0.026 -0.007 0"/>
            </body>
            <geom name="col_l_f_link3_3" type="capsule" contype="1" conaffinity="1" group="3" size="0.007" fromto="0.012 0.003 -0.0035 0.012 0.003 0.0035"/>
          </body>
          <geom name="col_l_f_link3_2" type="capsule" contype="1" conaffinity="1" group="3" size="0.0095" fromto="0.005 0 0 0.03 0 0"/>
        </body>
      </body>
      <body name="l_f_link4_1" pos="0.006966 0.013688 0.1644" quat="0.707105 0 -0.707108 0">
        <inertial pos="0.00700212 -1.07487e-07 0.000968558" quat="0.602109 0.370749 0.370763 0.602117" mass="0.00409701" diaginertia="3.18122e-07 2.71723e-07 2.04204e-07"/>
        <joint name="l_f_joint4_1" pos="0 0 0" axis="0 0 1" range="0 0.6" actuatorfrcrange="-10 10"/>
        <geom type="mesh" contype="0" conaffinity="0" group="1" density="0" rgba="0.792157 0.819608 0.933333 1" mesh="l_f_link4_1"/>
        <geom type="mesh" rgba="0.792157 0.819608 0.933333 1" mesh="l_f_link4_1" contype="0" conaffinity="0" group="1" density="0"/>
        <body name="l_f_link4_2" pos="0.017 0 0" quat="0.707105 -0.707108 0 0">
          <inertial pos="0.0211622 -0.000590378 2.72622e-06" quat="0.502474 0.508577 0.49194 0.496854" mass="0.0094283" diaginertia="1.65781e-06 1.64333e-06 5.5432e-07"/>
          <joint name="l_f_joint4_2" pos="0 0 0" axis="0 0 1" range="0 1.3" actuatorfrcrange="-10 10"/>
          <geom type="mesh" contype="0" conaffinity="0" group="1" density="0" rgba="0.6 0.6 0.6 1" mesh="l_f_link4_2"/>
          <geom type="mesh" rgba="0.6 0.6 0.6 1" mesh="l_f_link4_2" contype="0" conaffinity="0" group="1" density="0"/>
          <body name="l_f_link4_3" pos="0.043 0 0">
            <inertial pos="0.0134587 -0.000699415 7.12894e-07" quat="0.0207134 0.706891 -0.0204889 0.706722" mass="0.00457275" diaginertia="3.79726e-07 3.56511e-07 2.03184e-07"/>
            <joint name="l_f_joint4_3" pos="0 0 0" axis="0 0 1" range="0 1.3" actuatorfrcrange="-10 10"/>
            <geom type="mesh" contype="0" conaffinity="0" group="1" density="0" rgba="0.6 0.6 0.6 1" mesh="l_f_link4_3"/>
            <geom type="mesh" rgba="0.6 0.6 0.6 1" mesh="l_f_link4_3" contype="0" conaffinity="0" group="1" density="0"/>
            <body name="l_f_link4_4" pos="0.025 0 0">
              <inertial pos="0.0197516 -0.00297416 5.40083e-07" quat="0.0429662 0.705803 -0.0424926 0.705826" mass="0.00815824" diaginertia="1.11778e-06 1.10066e-06 3.46138e-07"/>
              <joint name="l_f_joint4_4" pos="0 0 0" axis="0 0 1" range="0 1.3" actuatorfrcrange="-10 10"/>
              <geom type="mesh" contype="0" conaffinity="0" group="1" density="0" rgba="0.6 0.6 0.6 1" mesh="l_f_link4_4"/>
              <geom type="mesh" rgba="0.6 0.6 0.6 1" mesh="l_f_link4_4" contype="0" conaffinity="0" group="1" density="0"/>
              <geom size="0.002" pos="0.035 -0.004 0" contype="0" conaffinity="0" group="1" density="0" rgba="1 0 0 1"/>
              <geom size="0.002" pos="0.035 -0.004 0" rgba="1 0 0 1" contype="0" conaffinity="0" group="1" density="0"/>
              <geom size="0.006 0.0005 0.003" pos="0.026 0.0025 0" quat="0.974794 0 0 -0.223106" type="box" contype="0" conaffinity="0" group="1" density="0" rgba="0 1 0 1"/>
              <geom size="0.006 0.0005 0.003" pos="0.026 0.0025 0" quat="0.974794 0 0 -0.223106" type="box" rgba="0 1 0 1" contype="0" conaffinity="0" group="1" density="0"/>
              <site name="site_l_f_link4_tip" pos="0.035 -0.004 0" quat="1.0 0.0 0.0 0.0" type="sphere" size="0.002" rgba="1 0 0 1"/>
              <site name="site_l_f_link4_pad" pos="0.026 0.0025 0.000" quat="0.9747941070689433 0.0 0.0 -0.22310636213174545" type="box" size="0.006 0.0005 0.003" rgba="0 1 0 1"/>
              <geom name="col_l_f_link4_4" type="capsule" contype="1" conaffinity="1" group="3" size="0.0095" fromto="0.0 0 0 0.026 -0.007 0"/>
            </body>
            <geom name="col_l_f_link4_3" type="capsule" contype="1" conaffinity="1" group="3" size="0.007" fromto="0.012 0.003 -0.0035 0.012 0.003 0.0035"/>
          </body>
          <geom name="col_l_f_link4_2" type="capsule" contype="1" conaffinity="1" group="3" size="0.0095" fromto="0.005 0 0 0.03 0 0"/>
        </body>
      </body>
      <body name="l_f_link5_1" pos="0.006966 0.037988 0.1504" quat="0.707105 0 -0.707108 0">
        <inertial pos="0.00700212 -1.08915e-07 0.000968551" quat="0.602109 0.370749 0.370763 0.602117" mass="0.00409701" diaginertia="3.18122e-07 2.71723e-07 2.04203e-07"/>
        <joint name="l_f_joint5_1" pos="0 0 0" axis="0 0 1" range="0 0.6" actuatorfrcrange="-10 10"/>
        <geom type="mesh" contype="0" conaffinity="0" group="1" density="0" rgba="0.792157 0.819608 0.933333 1" mesh="l_f_link5_1"/>
        <geom type="mesh" rgba="0.792157 0.819608 0.933333 1" mesh="l_f_link5_1" contype="0" conaffinity="0" group="1" density="0"/>
        <body name="l_f_link5_2" pos="0.017 0 0" quat="0.707105 -0.707108 0 0">
          <inertial pos="0.0211622 -0.000590378 2.72622e-06" quat="0.502474 0.508577 0.49194 0.496854" mass="0.0094283" diaginertia="1.65781e-06 1.64333e-06 5.5432e-07"/>
          <joint name="l_f_joint5_2" pos="0 0 0" axis="0 0 1" range="0 1.3" actuatorfrcrange="-10 10"/>
          <geom type="mesh" contype="0" conaffinity="0" group="1" density="0" rgba="0.6 0.6 0.6 1" mesh="l_f_link5_2"/>
          <geom type="mesh" rgba="0.6 0.6 0.6 1" mesh="l_f_link5_2" contype="0" conaffinity="0" group="1" density="0"/>
          <body name="l_f_link5_3" pos="0.043 0 0">
            <inertial pos="0.0134587 -0.000699415 7.12894e-07" quat="0.0207134 0.706891 -0.0204889 0.706722" mass="0.00457275" diaginertia="3.79726e-07 3.56511e-07 2.03184e-07"/>
            <joint name="l_f_joint5_3" pos="0 0 0" axis="0 0 1" range="0 1.3" actuatorfrcrange="-10 10"/>
            <geom type="mesh" contype="0" conaffinity="0" group="1" density="0" rgba="0.6 0.6 0.6 1" mesh="l_f_link5_3"/>
            <geom type="mesh" rgba="0.6 0.6 0.6 1" mesh="l_f_link5_3" contype="0" conaffinity="0" group="1" density="0"/>
            <body name="l_f_link5_4" pos="0.025 0 0">
              <inertial pos="0.0197516 -0.00297416 5.40083e-07" quat="0.0429662 0.705803 -0.0424926 0.705826" mass="0.00815824" diaginertia="1.11778e-06 1.10066e-06 3.46138e-07"/>
              <joint name="l_f_joint5_4" pos="0 0 0" axis="0 0 1" range="0 1.3" actuatorfrcrange="-10 10"/>
              <geom type="mesh" contype="0" conaffinity="0" group="1" density="0" rgba="0.6 0.6 0.6 1" mesh="l_f_link5_4"/>
              <geom type="mesh" rgba="0.6 0.6 0.6 1" mesh="l_f_link5_4" contype="0" conaffinity="0" group="1" density="0"/>
              <geom size="0.002" pos="0.035 -0.004 0" contype="0" conaffinity="0" group="1" density="0" rgba="1 0 0 1"/>
              <geom size="0.002" pos="0.035 -0.004 0" rgba="1 0 0 1" contype="0" conaffinity="0" group="1" density="0"/>
              <geom size="0.006 0.0005 0.003" pos="0.026 0.0025 0" quat="0.974794 0 0 -0.223106" type="box" contype="0" conaffinity="0" group="1" density="0" rgba="0 1 0 1"/>
              <geom size="0.006 0.0005 0.003" pos="0.026 0.0025 0" quat="0.974794 0 0 -0.223106" type="box" rgba="0 1 0 1" contype="0" conaffinity="0" group="1" density="0"/>
              <site name="site_l_f_link5_tip" pos="0.035 -0.004 0" quat="1.0 0.0 0.0 0.0" type="sphere" size="0.002" rgba="1 0 0 1"/>
              <site name="site_l_f_link5_pad" pos="0.026 0.0025 0.000" quat="0.9747941070689433 0.0 0.0 -0.22310636213174545" type="box" size="0.006 0.0005 0.003" rgba="0 1 0 1"/>
              <geom name="col_l_f_link5_4" type="capsule" contype="1" conaffinity="1" group="3" size="0.0095" fromto="0.0 0 0 0.026 -0.007 0"/>
            </body>
            <geom name="col_l_f_link5_3" type="capsule" contype="1" conaffinity="1" group="3" size="0.007" fromto="0.012 0.003 -0.0035 0.012 0.003 0.0035"/>
          </body>
          <geom name="col_l_f_link5_2" type="capsule" contype="1" conaffinity="1" group="3" size="0.0095" fromto="0.005 0 0 0.03 0 0"/>
        </body>
      </body>
      <geom name="col_left_hand_base" type="box" contype="1" conaffinity="1" group="3" size="0.0273 0.05 0.05" pos="-0.0022 0 0.11"/>
    </body>
  </worldbody>
  <actuator>
    <position name="act_l_f_joint1_2" joint="l_f_joint1_2" kp="20" kv="0.1" ctrlrange="0 1.3" forcerange="-20 20"/>
    <position name="act_l_f_joint1_3" joint="l_f_joint1_3" kp="20" kv="0.1" ctrlrange="0 1.3" forcerange="-20 20"/>
    <position name="act_l_f_joint1_4" joint="l_f_joint1_4" kp="20" kv="0.1" ctrlrange="0 1.3" forcerange="-20 20"/>
    <position name="act_l_f_joint2_2" joint="l_f_joint2_2" kp="20" kv="0.1" ctrlrange="0 1.3" forcerange="-20 20"/>
    <position name="act_l_f_joint2_3" joint="l_f_joint2_3" kp="20" kv="0.1" ctrlrange="0 1.3" forcerange="-20 20"/>
    <position name="act_l_f_joint2_4" joint="l_f_joint2_4" kp="20" kv="0.1" ctrlrange="0 1.3" forcerange="-20 20"/>
    <position name="act_l_f_joint3_2" joint="l_f_joint3_2" kp="20" kv="0.1" ctrlrange="0 1.3" forcerange="-20 20"/>
    <position name="act_l_f_joint3_3" joint="l_f_joint3_3" kp="20" kv="0.1" ctrlrange="0 1.3" forcerange="-20 20"/>
    <position name="act_l_f_joint3_4" joint="l_f_joint3_4" kp="20" kv="0.1" ctrlrange="0 1.3" forcerange="-20 20"/>
    <position name="act_l_f_joint4_2" joint="l_f_joint4_2" kp="20" kv="0.1" ctrlrange="0 1.3" forcerange="-20 20"/>
    <position name="act_l_f_joint4_3" joint="l_f_joint4_3" kp="20" kv="0.1" ctrlrange="0 1.3" forcerange="-20 20"/>
    <position name="act_l_f_joint4_4" joint="l_f_joint4_4" kp="20" kv="0.1" ctrlrange="0 1.3" forcerange="-20 20"/>
    <position name="act_l_f_joint5_2" joint="l_f_joint5_2" kp="20" kv="0.1" ctrlrange="0 1.3" forcerange="-20 20"/>
    <position name="act_l_f_joint5_3" joint="l_f_joint5_3" kp="20" kv="0.1" ctrlrange="0 1.3" forcerange="-20 20"/>
    <position name="act_l_f_joint5_4" joint="l_f_joint5_4" kp="20" kv="0.1" ctrlrange="0 1.3" forcerange="-20 20"/>
    <position name="act_l_f_joint1_1" joint="l_f_joint1_1" kp="20" kv="1" ctrlrange="0 2.2" forcerange="-20 20"/>
    <position name="act_l_f_joint2_1" joint="l_f_joint2_1" kp="20" kv="1" ctrlrange="0 0.3" forcerange="-20 20"/>
    <position name="act_l_f_joint3_1" joint="l_f_joint3_1" kp="20" kv="1" ctrlrange="-0.0001 0.0001" forcerange="-20 20"/>
    <position name="act_l_f_joint4_1" joint="l_f_joint4_1" kp="20" kv="1" ctrlrange="0 0.3" forcerange="-20 20"/>
    <position name="act_l_f_joint5_1" joint="l_f_joint5_1" kp="20" kv="1" ctrlrange="0 0.6" forcerange="-20 20"/>
  </actuator>
  <sensor>
    <touch name="touch_l_f_link1_pad" site="site_l_f_link1_pad"/>
    <touch name="touch_l_f_link2_pad" site="site_l_f_link2_pad"/>
    <touch name="touch_l_f_link3_pad" site="site_l_f_link3_pad"/>
    <touch name="touch_l_f_link4_pad" site="site_l_f_link4_pad"/>
    <touch name="touch_l_f_link5_pad" site="site_l_f_link5_pad"/>
  </sensor>
  <contact>
    <exclude body1="left_hand_base" body2="l_f_link1_1"/>
    <exclude body1="left_hand_base" body2="l_f_link1_2"/>
    <exclude body1="left_hand_base" body2="l_f_link1_3"/>
    <exclude body1="left_hand_base" body2="l_f_link1_4"/>
    <exclude body1="left_hand_base" body2="l_f_link2_1"/>
    <exclude body1="left_hand_base" body2="l_f_link2_2"/>
    <exclude body1="left_hand_base" body2="l_f_link2_3"/>
    <exclude body1="left_hand_base" body2="l_f_link2_4"/>
    <exclude body1="left_hand_base" body2="l_f_link3_1"/>
    <exclude body1="left_hand_base" body2="l_f_link3_2"/>
    <exclude body1="left_hand_base" body2="l_f_link3_3"/>
    <exclude body1="left_hand_base" body2="l_f_link3_4"/>
    <exclude body1="left_hand_base" body2="l_f_link4_1"/>
    <exclude body1="left_hand_base" body2="l_f_link4_2"/>
    <exclude body1="left_hand_base" body2="l_f_link4_3"/>
    <exclude body1="left_hand_base" body2="l_f_link4_4"/>
    <exclude body1="left_hand_base" body2="l_f_link5_1"/>
    <exclude body1="left_hand_base" body2="l_f_link5_2"/>
    <exclude body1="left_hand_base" body2="l_f_link5_3"/>
    <exclude body1="left_hand_base" body2="l_f_link5_4"/>
    <exclude body1="l_f_link1_1" body2="l_f_link1_2"/>
    <exclude body1="l_f_link1_1" body2="l_f_link1_3"/>
    <exclude body1="l_f_link1_1" body2="l_f_link1_4"/>
    <exclude body1="l_f_link1_1" body2="l_f_link2_1"/>
    <exclude body1="l_f_link1_1" body2="l_f_link2_2"/>
    <exclude body1="l_f_link1_1" body2="l_f_link2_3"/>
    <exclude body1="l_f_link1_1" body2="l_f_link2_4"/>
    <exclude body1="l_f_link1_1" body2="l_f_link3_1"/>
    <exclude body1="l_f_link1_1" body2="l_f_link3_2"/>
    <exclude body1="l_f_link1_1" body2="l_f_link3_3"/>
    <exclude body1="l_f_link1_1" body2="l_f_link3_4"/>
    <exclude body1="l_f_link1_1" body2="l_f_link4_1"/>
    <exclude body1="l_f_link1_1" body2="l_f_link4_2"/>
    <exclude body1="l_f_link1_1" body2="l_f_link4_3"/>
    <exclude body1="l_f_link1_1" body2="l_f_link4_4"/>
    <exclude body1="l_f_link1_1" body2="l_f_link5_1"/>
    <exclude body1="l_f_link1_1" body2="l_f_link5_2"/>
    <exclude body1="l_f_link1_1" body2="l_f_link5_3"/>
    <exclude body1="l_f_link1_1" body2="l_f_link5_4"/>
    <exclude body1="l_f_link1_2" body2="l_f_link1_3"/>
    <exclude body1="l_f_link1_2" body2="l_f_link1_4"/>
    <exclude body1="l_f_link1_2" body2="l_f_link2_1"/>
    <exclude body1="l_f_link1_2" body2="l_f_link2_2"/>
    <exclude body1="l_f_link1_2" body2="l_f_link2_3"/>
    <exclude body1="l_f_link1_2" body2="l_f_link2_4"/>
    <exclude body1="l_f_link1_2" body2="l_f_link3_1"/>
    <exclude body1="l_f_link1_2" body2="l_f_link3_2"/>
    <exclude body1="l_f_link1_2" body2="l_f_link3_3"/>
    <exclude body1="l_f_link1_2" body2="l_f_link3_4"/>
    <exclude body1="l_f_link1_2" body2="l_f_link4_1"/>
    <exclude body1="l_f_link1_2" body2="l_f_link4_2"/>
    <exclude body1="l_f_link1_2" body2="l_f_link4_3"/>
    <exclude body1="l_f_link1_2" body2="l_f_link4_4"/>
    <exclude body1="l_f_link1_2" body2="l_f_link5_1"/>
    <exclude body1="l_f_link1_2" body2="l_f_link5_2"/>
    <exclude body1="l_f_link1_2" body2="l_f_link5_3"/>
    <exclude body1="l_f_link1_2" body2="l_f_link5_4"/>
    <exclude body1="l_f_link1_3" body2="l_f_link1_4"/>
    <exclude body1="l_f_link1_3" body2="l_f_link2_1"/>
    <exclude body1="l_f_link1_3" body2="l_f_link2_2"/>
    <exclude body1="l_f_link1_3" body2="l_f_link2_3"/>
    <exclude body1="l_f_link1_3" body2="l_f_link2_4"/>
    <exclude body1="l_f_link1_3" body2="l_f_link3_1"/>
    <exclude body1="l_f_link1_3" body2="l_f_link3_2"/>
    <exclude body1="l_f_link1_3" body2="l_f_link3_3"/>
    <exclude body1="l_f_link1_3" body2="l_f_link3_4"/>
    <exclude body1="l_f_link1_3" body2="l_f_link4_1"/>
    <exclude body1="l_f_link1_3" body2="l_f_link4_2"/>
    <exclude body1="l_f_link1_3" body2="l_f_link4_3"/>
    <exclude body1="l_f_link1_3" body2="l_f_link4_4"/>
    <exclude body1="l_f_link1_3" body2="l_f_link5_1"/>
    <exclude body1="l_f_link1_3" body2="l_f_link5_2"/>
    <exclude body1="l_f_link1_3" body2="l_f_link5_3"/>
    <exclude body1="l_f_link1_3" body2="l_f_link5_4"/>
    <exclude body1="l_f_link1_4" body2="l_f_link2_1"/>
    <exclude body1="l_f_link1_4" body2="l_f_link2_2"/>
    <exclude body1="l_f_link1_4" body2="l_f_link2_3"/>
    <exclude body1="l_f_link1_4" body2="l_f_link3_1"/>
    <exclude body1="l_f_link1_4" body2="l_f_link3_2"/>
    <exclude body1="l_f_link1_4" body2="l_f_link3_3"/>
    <exclude body1="l_f_link1_4" body2="l_f_link4_1"/>
    <exclude body1="l_f_link1_4" body2="l_f_link4_2"/>
    <exclude body1="l_f_link1_4" body2="l_f_link4_3"/>
    <exclude body1="l_f_link1_4" body2="l_f_link5_1"/>
    <exclude body1="l_f_link1_4" body2="l_f_link5_2"/>
    <exclude body1="l_f_link1_4" body2="l_f_link5_3"/>
    <exclude body1="l_f_link2_1" body2="l_f_link2_2"/>
    <exclude body1="l_f_link2_1" body2="l_f_link2_3"/>
    <exclude body1="l_f_link2_1" body2="l_f_link2_4"/>
    <exclude body1="l_f_link2_1" body2="l_f_link3_1"/>
    <exclude body1="l_f_link2_1" body2="l_f_link3_2"/>
    <exclude body1="l_f_link2_1" body2="l_f_link3_3"/>
    <exclude body1="l_f_link2_1" body2="l_f_link3_4"/>
    <exclude body1="l_f_link2_1" body2="l_f_link4_1"/>
    <exclude body1="l_f_link2_1" body2="l_f_link4_2"/>
    <exclude body1="l_f_link2_1" body2="l_f_link4_3"/>
    <exclude body1="l_f_link2_1" body2="l_f_link4_4"/>
    <exclude body1="l_f_link2_1" body2="l_f_link5_1"/>
    <exclude body1="l_f_link2_1" body2="l_f_link5_2"/>
    <exclude body1="l_f_link2_1" body2="l_f_link5_3"/>
    <exclude body1="l_f_link2_1" body2="l_f_link5_4"/>
    <exclude body1="l_f_link2_2" body2="l_f_link2_3"/>
    <exclude body1="l_f_link2_2" body2="l_f_link2_4"/>
    <exclude body1="l_f_link2_2" body2="l_f_link3_1"/>
    <exclude body1="l_f_link2_2" body2="l_f_link3_2"/>
    <exclude body1="l_f_link2_2" body2="l_f_link3_3"/>
    <exclude body1="l_f_link2_2" body2="l_f_link3_4"/>
    <exclude body1="l_f_link2_2" body2="l_f_link4_1"/>
    <exclude body1="l_f_link2_2" body2="l_f_link4_2"/>
    <exclude body1="l_f_link2_2" body2="l_f_link4_3"/>
    <exclude body1="l_f_link2_2" body2="l_f_link4_4"/>
    <exclude body1="l_f_link2_2" body2="l_f_link5_1"/>
    <exclude body1="l_f_link2_2" body2="l_f_link5_2"/>
    <exclude body1="l_f_link2_2" body2="l_f_link5_3"/>
    <exclude body1="l_f_link2_2" body2="l_f_link5_4"/>
    <exclude body1="l_f_link2_3" body2="l_f_link2_4"/>
    <exclude body1="l_f_link2_3" body2="l_f_link3_1"/>
    <exclude body1="l_f_link2_3" body2="l_f_link3_2"/>
    <exclude body1="l_f_link2_3" body2="l_f_link3_3"/>
    <exclude body1="l_f_link2_3" body2="l_f_link3_4"/>
    <exclude body1="l_f_link2_3" body2="l_f_link4_1"/>
    <exclude body1="l_f_link2_3" body2="l_f_link4_2"/>
    <exclude body1="l_f_link2_3" body2="l_f_link4_3"/>
    <exclude body1="l_f_link2_3" body2="l_f_link4_4"/>
    <exclude body1="l_f_link2_3" body2="l_f_link5_1"/>
    <exclude body1="l_f_link2_3" body2="l_f_link5_2"/>
    <exclude body1="l_f_link2_3" body2="l_f_link5_3"/>
    <exclude body1="l_f_link2_3" body2="l_f_link5_4"/>
    <exclude body1="l_f_link2_4" body2="l_f_link3_1"/>
    <exclude body1="l_f_link2_4" body2="l_f_link3_2"/>
    <exclude body1="l_f_link2_4" body2="l_f_link3_3"/>
    <exclude body1="l_f_link2_4" body2="l_f_link4_1"/>
    <exclude body1="l_f_link2_4" body2="l_f_link4_2"/>
    <exclude body1="l_f_link2_4" body2="l_f_link4_3"/>
    <exclude body1="l_f_link2_4" body2="l_f_link5_1"/>
    <exclude body1="l_f_link2_4" body2="l_f_link5_2"/>
    <exclude body1="l_f_link2_4" body2="l_f_link5_3"/>
    <exclude body1="l_f_link3_1" body2="l_f_link3_2"/>
    <exclude body1="l_f_link3_1" body2="l_f_link3_3"/>
    <exclude body1="l_f_link3_1" body2="l_f_link3_4"/>
    <exclude body1="l_f_link3_1" body2="l_f_link4_1"/>
    <exclude body1="l_f_link3_1" body2="l_f_link4_2"/>
    <exclude body1="l_f_link3_1" body2="l_f_link4_3"/>
    <exclude body1="l_f_link3_1" body2="l_f_link4_4"/>
    <exclude body1="l_f_link3_1" body2="l_f_link5_1"/>
    <exclude body1="l_f_link3_1" body2="l_f_link5_2"/>
    <exclude body1="l_f_link3_1" body2="l_f_link5_3"/>
    <exclude body1="l_f_link3_1" body2="l_f_link5_4"/>
    <exclude body1="l_f_link3_2" body2="l_f_link3_3"/>
    <exclude body1="l_f_link3_2" body2="l_f_link3_4"/>
    <exclude body1="l_f_link3_2" body2="l_f_link4_1"/>
    <exclude body1="l_f_link3_2" body2="l_f_link4_2"/>
    <exclude body1="l_f_link3_2" body2="l_f_link4_3"/>
    <exclude body1="l_f_link3_2" body2="l_f_link4_4"/>
    <exclude body1="l_f_link3_2" body2="l_f_link5_1"/>
    <exclude body1="l_f_link3_2" body2="l_f_link5_2"/>
    <exclude body1="l_f_link3_2" body2="l_f_link5_3"/>
    <exclude body1="l_f_link3_2" body2="l_f_link5_4"/>
    <exclude body1="l_f_link3_3" body2="l_f_link3_4"/>
    <exclude body1="l_f_link3_3" body2="l_f_link4_1"/>
    <exclude body1="l_f_link3_3" body2="l_f_link4_2"/>
    <exclude body1="l_f_link3_3" body2="l_f_link4_3"/>
    <exclude body1="l_f_link3_3" body2="l_f_link4_4"/>
    <exclude body1="l_f_link3_3" body2="l_f_link5_1"/>
    <exclude body1="l_f_link3_3" body2="l_f_link5_2"/>
    <exclude body1="l_f_link3_3" body2="l_f_link5_3"/>
    <exclude body1="l_f_link3_3" body2="l_f_link5_4"/>
    <exclude body1="l_f_link3_4" body2="l_f_link4_1"/>
    <exclude body1="l_f_link3_4" body2="l_f_link4_2"/>
    <exclude body1="l_f_link3_4" body2="l_f_link4_3"/>
    <exclude body1="l_f_link3_4" body2="l_f_link5_1"/>
    <exclude body1="l_f_link3_4" body2="l_f_link5_2"/>
    <exclude body1="l_f_link3_4" body2="l_f_link5_3"/>
    <exclude body1="l_f_link4_1" body2="l_f_link4_2"/>
    <exclude body1="l_f_link4_1" body2="l_f_link4_3"/>
    <exclude body1="l_f_link4_1" body2="l_f_link4_4"/>
    <exclude body1="l_f_link4_1" body2="l_f_link5_1"/>
    <exclude body1="l_f_link4_1" body2="l_f_link5_2"/>
    <exclude body1="l_f_link4_1" body2="l_f_link5_3"/>
    <exclude body1="l_f_link4_1" body2="l_f_link5_4"/>
    <exclude body1="l_f_link4_2" body2="l_f_link4_3"/>
    <exclude body1="l_f_link4_2" body2="l_f_link4_4"/>
    <exclude body1="l_f_link4_2" body2="l_f_link5_1"/>
    <exclude body1="l_f_link4_2" body2="l_f_link5_2"/>
    <exclude body1="l_f_link4_2" body2="l_f_link5_3"/>
    <exclude body1="l_f_link4_2" body2="l_f_link5_4"/>
    <exclude body1="l_f_link4_3" body2="l_f_link4_4"/>
    <exclude body1="l_f_link4_3" body2="l_f_link5_1"/>
    <exclude body1="l_f_link4_3" body2="l_f_link5_2"/>
    <exclude body1="l_f_link4_3" body2="l_f_link5_3"/>
    <exclude body1="l_f_link4_3" body2="l_f_link5_4"/>
    <exclude body1="l_f_link4_4" body2="l_f_link5_1"/>
    <exclude body1="l_f_link4_4" body2="l_f_link5_2"/>
    <exclude body1="l_f_link4_4" body2="l_f_link5_3"/>
    <exclude body1="l_f_link5_1" body2="l_f_link5_2"/>
    <exclude body1="l_f_link5_1" body2="l_f_link5_3"/>
    <exclude body1="l_f_link5_1" body2="l_f_link5_4"/>
    <exclude body1="l_f_link5_2" body2="l_f_link5_3"/>
    <exclude body1="l_f_link5_2" body2="l_f_link5_4"/>
    <exclude body1="l_f_link5_3" body2="l_f_link5_4"/>
  </contact>
</mujoco>
