<?xml version="1.0" encoding="utf-8"?>
<mujoco model="dexhand021_right_simplified">
  <visual>
    <global offwidth="1920" offheight="1080"/>
  </visual>
  <option gravity="0 0 -9.81" iterations="100" solver="Newton" integrator="implicit" timestep="0.001"/>
  <default>
    <joint damping="1"/>
    <geom condim="3" solref="0.02 1" solimp="0.9 0.95 0.001" friction="2 2 2"/>
  </default>
  <size njmax="1000" nconmax="1000"/>
  <compiler angle="radian" meshdir="../meshes/dexhand021_simplified/"/>
  <asset>
    <mesh name="right_hand_base" file="right_hand_base.STL"/>
    <mesh name="r_f_link1_1" file="r_f_link1_1.STL"/>
    <mesh name="r_f_link1_2" file="r_f_link1_2.STL"/>
    <mesh name="r_f_link1_3" file="r_f_link1_3.STL"/>
    <mesh name="r_f_link1_4" file="r_f_link1_4.STL"/>
    <mesh name="r_f_link2_1" file="r_f_link2_1.STL"/>
    <mesh name="r_f_link2_2" file="r_f_link2_2.STL"/>
    <mesh name="r_f_link2_3" file="r_f_link2_3.STL"/>
    <mesh name="r_f_link2_4" file="r_f_link2_4.STL"/>
    <mesh name="r_f_link3_1" file="r_f_link3_1.STL"/>
    <mesh name="r_f_link3_2" file="r_f_link3_2.STL"/>
    <mesh name="r_f_link3_3" file="r_f_link3_3.STL"/>
    <mesh name="r_f_link3_4" file="r_f_link3_4.STL"/>
    <mesh name="r_f_link4_1" file="r_f_link4_1.STL"/>
    <mesh name="r_f_link4_2" file="r_f_link4_2.STL"/>
    <mesh name="r_f_link4_3" file="r_f_link4_3.STL"/>
    <mesh name="r_f_link4_4" file="r_f_link4_4.STL"/>
    <mesh name="r_f_link5_1" file="r_f_link5_1.STL"/>
    <mesh name="r_f_link5_2" file="r_f_link5_2.STL"/>
    <mesh name="r_f_link5_3" file="r_f_link5_3.STL"/>
    <mesh name="r_f_link5_4" file="r_f_link5_4.STL"/>
  </asset>
  <worldbody>
    <body name="right_hand_base" pos="0 0 0" quat="1 0 0 0">
      <geom type="mesh" contype="0" conaffinity="0" group="1" density="0" rgba="0.75294 0.75294 0.75294 1" mesh="right_hand_base"/>
      <geom type="mesh" rgba="0.75294 0.75294 0.75294 1" mesh="right_hand_base" contype="0" conaffinity="0" group="1" density="0"/>
      <body name="r_f_link1_1" pos="0.032783 0.023781 0.11211" quat="0.151551 -0.775385 -0.612635 0.0221215">
        <inertial pos="0.00197785 -0.000351482 0.0134505" quat="0.716223 -0.0774322 -0.0528539 0.691545" mass="0.00440996" diaginertia="5.49477e-10 4.74828e-10 2.47887e-10"/>
        <joint name="r_f_joint1_1" pos="0 0 0" axis="0 0 1" range="0 2.2" actuatorfrcrange="-10 10"/>
        <geom type="mesh" contype="0" conaffinity="0" group="1" density="0" rgba="0.6 0.6 0.6 1" mesh="r_f_link1_1"/>
        <geom type="mesh" rgba="0.6 0.6 0.6 1" mesh="r_f_link1_1" contype="0" conaffinity="0" group="1" density="0"/>
        <body name="r_f_link1_2" pos="0.0083307 0 0" quat="0.707105 -0.707108 0 0">
          <inertial pos="0.0214331 0.000179495 -0.00129805" quat="0.0147975 0.706538 -0.0147802 0.707366" mass="0.00995222" diaginertia="2.13766e-09 2.06968e-09 7.73846e-10"/>
          <joint name="r_f_joint1_2" pos="0 0 0" axis="0 0 1" range="0 1.3" actuatorfrcrange="-10 10"/>
          <geom type="mesh" contype="0" conaffinity="0" group="1" density="0" rgba="0.6 0.6 0.6 1" mesh="r_f_link1_2"/>
          <geom type="mesh" rgba="0.6 0.6 0.6 1" mesh="r_f_link1_2" contype="0" conaffinity="0" group="1" density="0"/>
          <body name="r_f_link1_3" pos="0.043 0 0">
            <inertial pos="0.0134587 -0.000699996 -0.00129335" quat="0.0206042 0.706807 -0.0206042 0.706807" mass="0.00457333" diaginertia="4.74688e-10 4.45715e-10 2.54052e-10"/>
            <joint name="r_f_joint1_3" pos="0 0 0" axis="0 0 1" range="0 1.3" actuatorfrcrange="-10 10"/>
            <geom type="mesh" contype="0" conaffinity="0" group="1" density="0" rgba="0.6 0.6 0.6 1" mesh="r_f_link1_3"/>
            <geom type="mesh" rgba="0.6 0.6 0.6 1" mesh="r_f_link1_3" contype="0" conaffinity="0" group="1" density="0"/>
            <body name="r_f_link1_4" pos="0.025 0 0">
              <inertial pos="0.0167832 -0.00318045 -0.000413119" quat="0.772949 -0.0577446 0.336575 0.534727" mass="0.00715928" diaginertia="5.97968e-08 5.92632e-08 1.8762e-09"/>
              <joint name="r_f_joint1_4" pos="0 0 0" axis="0 0 1" range="0 1.3" actuatorfrcrange="-10 10"/>
              <geom type="mesh" contype="0" conaffinity="0" group="1" density="0" rgba="0.6 0.6 0.6 1" mesh="r_f_link1_4"/>
              <geom type="mesh" rgba="0.6 0.6 0.6 1" mesh="r_f_link1_4" contype="0" conaffinity="0" group="1" density="0"/>
              <geom size="0.002" pos="0.035 -0.004 0" contype="0" conaffinity="0" group="1" density="0" rgba="1 0 0 1"/>
              <geom size="0.002" pos="0.02 0 0" rgba="1 0 0 1" contype="0" conaffinity="0" group="1" density="0"/>
              <site name="site_r_f_link1_4" pos="0.025 0.003 0" size="0.01" type="sphere"/>
              <geom name="col_r_f_link1_4" type="capsule" contype="1" conaffinity="1" group="3" size="0.0095" fromto="0.0 0 -0.001 0.027 -0.007 -0.001"/>
            </body>
            <geom name="col_r_f_link1_3" type="capsule" contype="1" conaffinity="1" group="3" size="0.007" fromto="0.0125 0.003 -0.0045 0.0125 0.003 0.0023"/>
          </body>
          <geom name="col_r_f_link1_2" type="capsule" contype="1" conaffinity="1" group="3" size="0.0095" fromto="0.0 0 0 0.03 0 -0.002"/>
        </body>
      </body>
      <body name="r_f_link2_1" pos="0.006966 0.034912 0.1644" quat="0.707105 0 -0.707108 0">
        <inertial pos="0.00700207 9.3578e-08 0.000968546" quat="0.602113 0.370756 0.370756 0.602113" mass="0.00409704" diaginertia="3.97657e-10 3.39658e-10 2.5526e-10"/>
        <joint name="r_f_joint2_1" pos="0 0 0" axis="0 0 1" range="0 0.6" actuatorfrcrange="-10 10"/>
        <geom type="mesh" contype="0" conaffinity="0" group="1" density="0" rgba="0.79216 0.81961 0.93333 1" mesh="r_f_link2_1"/>
        <geom type="mesh" rgba="0.79216 0.81961 0.93333 1" mesh="r_f_link2_1" contype="0" conaffinity="0" group="1" density="0"/>
        <body name="r_f_link2_2" pos="0.017 0 0" quat="0.707105 -0.707108 0 0">
          <inertial pos="0.0211623 -0.000590509 -2.03591e-06" quat="0.505873 0.5052 0.494072 0.49473" mass="0.0094284" diaginertia="2.07218e-09 2.05412e-09 6.92926e-10"/>
          <joint name="r_f_joint2_2" pos="0 0 0" axis="0 0 1" range="0 1.3" actuatorfrcrange="-10 10"/>
          <geom type="mesh" contype="0" conaffinity="0" group="1" density="0" rgba="0.6 0.6 0.6 1" mesh="r_f_link2_2"/>
          <geom type="mesh" rgba="0.6 0.6 0.6 1" mesh="r_f_link2_2" contype="0" conaffinity="0" group="1" density="0"/>
          <body name="r_f_link2_3" pos="0.043 0 0">
            <inertial pos="0.0134587 -0.000699996 -9.33093e-07" quat="0.0206042 0.706807 -0.0206042 0.706807" mass="0.00457333" diaginertia="4.74688e-10 4.45715e-10 2.54052e-10"/>
            <joint name="r_f_joint2_3" pos="0 0 0" axis="0 0 1" range="0 1.3" actuatorfrcrange="-10 10"/>
            <geom type="mesh" contype="0" conaffinity="0" group="1" density="0" rgba="0.6 0.6 0.6 1" mesh="r_f_link2_3"/>
            <geom type="mesh" rgba="0.6 0.6 0.6 1" mesh="r_f_link2_3" contype="0" conaffinity="0" group="1" density="0"/>
            <body name="r_f_link2_4" pos="0.025 0 0">
              <inertial pos="0.0167832 -0.00318045 0.000698736" quat="0.764727 -0.0731551 0.387984 0.509225" mass="0.00715928" diaginertia="4.72367e-08 4.67261e-08 1.86419e-09"/>
              <joint name="r_f_joint2_4" pos="0 0 0" axis="0 0 1" range="0 1.3" actuatorfrcrange="-10 10"/>
              <geom type="mesh" contype="0" conaffinity="0" group="1" density="0" rgba="0.6 0.6 0.6 1" mesh="r_f_link2_4"/>
              <geom type="mesh" rgba="0.6 0.6 0.6 1" mesh="r_f_link2_4" contype="0" conaffinity="0" group="1" density="0"/>
              <geom size="0.002" pos="0.035 -0.004 0" contype="0" conaffinity="0" group="1" density="0" rgba="1 0 0 1"/>
              <geom size="0.002" pos="0.02 0 0" rgba="1 0 0 1" contype="0" conaffinity="0" group="1" density="0"/>
              <site name="site_r_f_link2_4" pos="0.025 0.003 0" size="0.01" type="sphere"/>
              <geom name="col_r_f_link2_4" type="capsule" contype="1" conaffinity="1" group="3" size="0.0095" fromto="0.0 0 0 0.026 -0.007 0"/>
            </body>
            <geom name="col_r_f_link2_3" type="capsule" contype="1" conaffinity="1" group="3" size="0.007" fromto="0.012 0.003 -0.0035 0.012 0.003 0.0035"/>
          </body>
          <geom name="col_r_f_link2_2" type="capsule" contype="1" conaffinity="1" group="3" size="0.0095" fromto="0.005 0 0 0.03 0 0"/>
        </body>
      </body>
      <body name="r_f_link3_1" pos="0.006966 0.010612 0.1734" quat="0.707105 0 -0.707108 0">
        <inertial pos="0.00700207 9.45418e-08 0.000968552" quat="0.602113 0.370756 0.370756 0.602113" mass="0.00409704" diaginertia="3.97657e-10 3.39658e-10 2.55261e-10"/>
        <joint name="r_f_joint3_1" pos="0 0 0" axis="0 0 1" range="-0.001 0.001"/>
        <geom type="mesh" contype="0" conaffinity="0" group="1" density="0" rgba="0.79216 0.81961 0.93333 1" mesh="r_f_link3_1"/>
        <geom type="mesh" rgba="0.79216 0.81961 0.93333 1" mesh="r_f_link3_1" contype="0" conaffinity="0" group="1" density="0"/>
        <body name="r_f_link3_2" pos="0.017 0 0" quat="0.707105 -0.707108 0 0">
          <inertial pos="0.0211623 -0.000590509 -2.03591e-06" quat="0.505873 0.5052 0.494072 0.49473" mass="0.0094284" diaginertia="2.07218e-09 2.05412e-09 6.92926e-10"/>
          <joint name="r_f_joint3_2" pos="0 0 0" axis="0 0 1" range="0 1.3" actuatorfrcrange="-10 10"/>
          <geom type="mesh" contype="0" conaffinity="0" group="1" density="0" rgba="0.6 0.6 0.6 1" mesh="r_f_link3_2"/>
          <geom type="mesh" rgba="0.6 0.6 0.6 1" mesh="r_f_link3_2" contype="0" conaffinity="0" group="1" density="0"/>
          <body name="r_f_link3_3" pos="0.043 0 0">
            <inertial pos="0.0134587 -0.000699996 -9.33093e-07" quat="0.0206042 0.706807 -0.0206042 0.706807" mass="0.00457333" diaginertia="4.74688e-10 4.45715e-10 2.54052e-10"/>
            <joint name="r_f_joint3_3" pos="0 0 0" axis="0 0 1" range="0 1.3" actuatorfrcrange="-10 10"/>
            <geom type="mesh" contype="0" conaffinity="0" group="1" density="0" rgba="0.6 0.6 0.6 1" mesh="r_f_link3_3"/>
            <geom type="mesh" rgba="0.6 0.6 0.6 1" mesh="r_f_link3_3" contype="0" conaffinity="0" group="1" density="0"/>
            <body name="r_f_link3_4" pos="0.025 0 0">
              <inertial pos="0.0167832 -0.00318045 0.000698736" quat="0.764727 -0.0731551 0.387984 0.509225" mass="0.00715928" diaginertia="4.72367e-08 4.67261e-08 1.86419e-09"/>
              <joint name="r_f_joint3_4" pos="0 0 0" axis="0 0 1" range="0 1.3" actuatorfrcrange="-10 10"/>
              <geom type="mesh" contype="0" conaffinity="0" group="1" density="0" rgba="0.6 0.6 0.6 1" mesh="r_f_link3_4"/>
              <geom type="mesh" rgba="0.6 0.6 0.6 1" mesh="r_f_link3_4" contype="0" conaffinity="0" group="1" density="0"/>
              <geom size="0.002" pos="0.035 -0.004 0" contype="0" conaffinity="0" group="1" density="0" rgba="1 0 0 1"/>
              <geom size="0.002" pos="0.02 0 0" rgba="1 0 0 1" contype="0" conaffinity="0" group="1" density="0"/>
              <site name="site_r_f_link3_4" pos="0.025 0.003 0" size="0.01" type="sphere"/>
              <geom name="col_r_f_link3_4" type="capsule" contype="1" conaffinity="1" group="3" size="0.0095" fromto="0.0 0 0 0.026 -0.007 0"/>
            </body>
            <geom name="col_r_f_link3_3" type="capsule" contype="1" conaffinity="1" group="3" size="0.007" fromto="0.012 0.003 -0.0035 0.012 0.003 0.0035"/>
          </body>
          <geom name="col_r_f_link3_2" type="capsule" contype="1" conaffinity="1" group="3" size="0.0095" fromto="0.005 0 0 0.03 0 0"/>
        </body>
      </body>
      <body name="r_f_link4_1" pos="0.006966 -0.013688 0.1644" quat="-2.59734e-06 0.707105 2.59735e-06 0.707108">
        <inertial pos="0.00700206 -9.456e-08 -0.000968554" quat="0.370756 0.602113 0.602113 0.370756" mass="0.00409704" diaginertia="3.97657e-10 3.39658e-10 2.55261e-10"/>
        <joint name="r_f_joint4_1" pos="0 0 0" axis="0 0 1" range="0 0.6" actuatorfrcrange="-10 10"/>
        <geom type="mesh" contype="0" conaffinity="0" group="1" density="0" rgba="0.79216 0.81961 0.93333 1" mesh="r_f_link4_1"/>
        <geom type="mesh" rgba="0.79216 0.81961 0.93333 1" mesh="r_f_link4_1" contype="0" conaffinity="0" group="1" density="0"/>
        <body name="r_f_link4_2" pos="0.017 0 0" quat="0.707105 0.707108 0 0">
          <inertial pos="0.0211623 -0.000590509 -2.03591e-06" quat="0.505873 0.5052 0.494072 0.49473" mass="0.0094284" diaginertia="2.07218e-09 2.05412e-09 6.92926e-10"/>
          <joint name="r_f_joint4_2" pos="0 0 0" axis="0 0 1" range="0 1.3" actuatorfrcrange="-10 10"/>
          <geom type="mesh" contype="0" conaffinity="0" group="1" density="0" rgba="0.6 0.6 0.6 1" mesh="r_f_link4_2"/>
          <geom type="mesh" rgba="0.6 0.6 0.6 1" mesh="r_f_link4_2" contype="0" conaffinity="0" group="1" density="0"/>
          <body name="r_f_link4_3" pos="0.043 0 0">
            <inertial pos="0.0134587 -0.000699996 -9.33093e-07" quat="0.0206042 0.706807 -0.0206042 0.706807" mass="0.00457333" diaginertia="4.74688e-10 4.45715e-10 2.54052e-10"/>
            <joint name="r_f_joint4_3" pos="0 0 0" axis="0 0 1" range="0 1.3" actuatorfrcrange="-10 10"/>
            <geom type="mesh" contype="0" conaffinity="0" group="1" density="0" rgba="0.6 0.6 0.6 1" mesh="r_f_link4_3"/>
            <geom type="mesh" rgba="0.6 0.6 0.6 1" mesh="r_f_link4_3" contype="0" conaffinity="0" group="1" density="0"/>
            <body name="r_f_link4_4" pos="0.025 0 0">
              <inertial pos="0.0167832 -0.00318045 0.000698736" quat="0.764727 -0.0731551 0.387984 0.509225" mass="0.00715928" diaginertia="4.72367e-08 4.67261e-08 1.86419e-09"/>
              <joint name="r_f_joint4_4" pos="0 0 0" axis="0 0 1" range="0 1.3" actuatorfrcrange="-10 10"/>
              <geom type="mesh" contype="0" conaffinity="0" group="1" density="0" rgba="0.6 0.6 0.6 1" mesh="r_f_link4_4"/>
              <geom type="mesh" rgba="0.6 0.6 0.6 1" mesh="r_f_link4_4" contype="0" conaffinity="0" group="1" density="0"/>
              <geom size="0.002" pos="0.035 -0.004 0" contype="0" conaffinity="0" group="1" density="0" rgba="1 0 0 1"/>
              <geom size="0.002" pos="0.02 0 0" rgba="1 0 0 1" contype="0" conaffinity="0" group="1" density="0"/>
              <site name="site_r_f_link4_4" pos="0.025 0.003 0" size="0.01" type="sphere"/>
              <geom name="col_r_f_link4_4" type="capsule" contype="1" conaffinity="1" group="3" size="0.0095" fromto="0.0 0 0 0.026 -0.007 0"/>
            </body>
            <geom name="col_r_f_link4_3" type="capsule" contype="1" conaffinity="1" group="3" size="0.007" fromto="0.012 0.003 -0.0035 0.012 0.003 0.0035"/>
          </body>
          <geom name="col_r_f_link4_2" type="capsule" contype="1" conaffinity="1" group="3" size="0.0095" fromto="0.005 0 0 0.03 0 0"/>
        </body>
      </body>
      <body name="r_f_link5_1" pos="0.006966 -0.037988 0.1504" quat="-2.59734e-06 0.707105 2.59735e-06 0.707108">
        <inertial pos="0.00700207 -9.35677e-08 -0.000968542" quat="0.370756 0.602113 0.602113 0.370756" mass="0.00409703" diaginertia="3.97656e-10 3.39658e-10 2.5526e-10"/>
        <joint name="r_f_joint5_1" pos="0 0 0" axis="0 0 1" range="0 0.6" actuatorfrcrange="-10 10"/>
        <geom type="mesh" contype="0" conaffinity="0" group="1" density="0" rgba="0.792157 0.819608 0.933333 1" mesh="r_f_link5_1"/>
        <geom type="mesh" rgba="0.792157 0.819608 0.933333 1" mesh="r_f_link5_1" contype="0" conaffinity="0" group="1" density="0"/>
        <body name="r_f_link5_2" pos="0.017 0 0" quat="0.707105 0.707108 0 0">
          <inertial pos="0.0211623 -0.000590509 -2.03591e-06" quat="0.505873 0.5052 0.494072 0.49473" mass="0.0094284" diaginertia="2.07218e-09 2.05412e-09 6.92926e-10"/>
          <joint name="r_f_joint5_2" pos="0 0 0" axis="0 0 1" range="0 1.3" actuatorfrcrange="-10 10"/>
          <geom type="mesh" contype="0" conaffinity="0" group="1" density="0" rgba="0.6 0.6 0.6 1" mesh="r_f_link5_2"/>
          <geom type="mesh" rgba="0.6 0.6 0.6 1" mesh="r_f_link5_2" contype="0" conaffinity="0" group="1" density="0"/>
          <body name="r_f_link5_3" pos="0.043 0 0">
            <inertial pos="0.0134587 -0.000699996 -9.33093e-07" quat="0.0206042 0.706807 -0.0206042 0.706807" mass="0.00457333" diaginertia="4.74688e-10 4.45715e-10 2.54052e-10"/>
            <joint name="r_f_joint5_3" pos="0 0 0" axis="0 0 1" range="0 1.3" actuatorfrcrange="-10 10"/>
            <geom type="mesh" contype="0" conaffinity="0" group="1" density="0" rgba="0.6 0.6 0.6 1" mesh="r_f_link5_3"/>
            <geom type="mesh" rgba="0.6 0.6 0.6 1" mesh="r_f_link5_3" contype="0" conaffinity="0" group="1" density="0"/>
            <body name="r_f_link5_4" pos="0.025 0 0">
              <inertial pos="0.0167832 -0.00318045 0.000698736" quat="0.764727 -0.0731551 0.387984 0.509225" mass="0.00715928" diaginertia="4.72367e-08 4.67261e-08 1.86419e-09"/>
              <joint name="r_f_joint5_4" pos="0 0 0" axis="0 0 1" range="0 1.3" actuatorfrcrange="-10 10"/>
              <geom type="mesh" contype="0" conaffinity="0" group="1" density="0" rgba="0.6 0.6 0.6 1" mesh="r_f_link5_4"/>
              <geom type="mesh" rgba="0.6 0.6 0.6 1" mesh="r_f_link5_4" contype="0" conaffinity="0" group="1" density="0"/>
              <geom size="0.002" pos="0.035 -0.004 0" contype="0" conaffinity="0" group="1" density="0" rgba="1 0 0 1"/>
              <geom size="0.002" pos="0.02 0 0" rgba="1 0 0 1" contype="0" conaffinity="0" group="1" density="0"/>
              <site name="site_r_f_link5_4" pos="0.025 0.003 0" size="0.01" type="sphere"/>
              <geom name="col_r_f_link5_4" type="capsule" contype="1" conaffinity="1" group="3" size="0.0095" fromto="0.0 0 0 0.026 -0.007 0"/>
            </body>
            <geom name="col_r_f_link5_3" type="capsule" contype="1" conaffinity="1" group="3" size="0.007" fromto="0.012 0.003 -0.0035 0.012 0.003 0.0035"/>
          </body>
          <geom name="col_r_f_link5_2" type="capsule" contype="1" conaffinity="1" group="3" size="0.0095" fromto="0.005 0 0 0.03 0 0"/>
        </body>
      </body>
      <geom name="col_right_hand_base" type="box" contype="1" conaffinity="1" group="3" size="0.0273 0.05 0.05" pos="-0.0022 0 0.11"/>
    </body>
  </worldbody>
  <actuator>
    <position name="act_r_f_joint1_2" joint="r_f_joint1_2" kp="20" kv="0.1" ctrlrange="0 1.3" forcerange="-20 20"/>
    <position name="act_r_f_joint1_3" joint="r_f_joint1_3" kp="20" kv="0.1" ctrlrange="0 1.3" forcerange="-20 20"/>
    <position name="act_r_f_joint1_4" joint="r_f_joint1_4" kp="20" kv="0.1" ctrlrange="0 1.3" forcerange="-20 20"/>
    <position name="act_r_f_joint2_2" joint="r_f_joint2_2" kp="20" kv="0.1" ctrlrange="0 1.3" forcerange="-20 20"/>
    <position name="act_r_f_joint2_3" joint="r_f_joint2_3" kp="20" kv="0.1" ctrlrange="0 1.3" forcerange="-20 20"/>
    <position name="act_r_f_joint2_4" joint="r_f_joint2_4" kp="20" kv="0.1" ctrlrange="0 1.3" forcerange="-20 20"/>
    <position name="act_r_f_joint3_2" joint="r_f_joint3_2" kp="20" kv="0.1" ctrlrange="0 1.3" forcerange="-20 20"/>
    <position name="act_r_f_joint3_3" joint="r_f_joint3_3" kp="20" kv="0.1" ctrlrange="0 1.3" forcerange="-20 20"/>
    <position name="act_r_f_joint3_4" joint="r_f_joint3_4" kp="20" kv="0.1" ctrlrange="0 1.3" forcerange="-20 20"/>
    <position name="act_r_f_joint4_2" joint="r_f_joint4_2" kp="20" kv="0.1" ctrlrange="0 1.3" forcerange="-20 20"/>
    <position name="act_r_f_joint4_3" joint="r_f_joint4_3" kp="20" kv="0.1" ctrlrange="0 1.3" forcerange="-20 20"/>
    <position name="act_r_f_joint4_4" joint="r_f_joint4_4" kp="20" kv="0.1" ctrlrange="0 1.3" forcerange="-20 20"/>
    <position name="act_r_f_joint5_2" joint="r_f_joint5_2" kp="20" kv="0.1" ctrlrange="0 1.3" forcerange="-20 20"/>
    <position name="act_r_f_joint5_3" joint="r_f_joint5_3" kp="20" kv="0.1" ctrlrange="0 1.3" forcerange="-20 20"/>
    <position name="act_r_f_joint5_4" joint="r_f_joint5_4" kp="20" kv="0.1" ctrlrange="0 1.3" forcerange="-20 20"/>
    <position name="act_r_f_joint1_1" joint="r_f_joint1_1" kp="20" kv="1" ctrlrange="0 2.2" forcerange="-20 20"/>
    <position name="act_r_f_joint2_1" joint="r_f_joint2_1" kp="20" kv="1" ctrlrange="0 0.3" forcerange="-20 20"/>
    <position name="act_r_f_joint3_1" joint="r_f_joint3_1" kp="20" kv="1" ctrlrange="-0.0001 0.0001" forcerange="-20 20"/>
    <position name="act_r_f_joint4_1" joint="r_f_joint4_1" kp="20" kv="1" ctrlrange="0 0.3" forcerange="-20 20"/>
    <position name="act_r_f_joint5_1" joint="r_f_joint5_1" kp="20" kv="1" ctrlrange="0 0.6" forcerange="-20 20"/>
  </actuator>
  <sensor>
    <touch name="touch_r_f_link1_4" site="site_r_f_link1_4"/>
    <touch name="touch_r_f_link2_4" site="site_r_f_link2_4"/>
    <touch name="touch_r_f_link3_4" site="site_r_f_link3_4"/>
    <touch name="touch_r_f_link4_4" site="site_r_f_link4_4"/>
    <touch name="touch_r_f_link5_4" site="site_r_f_link5_4"/>
  </sensor>
  <contact>
    <exclude body1="right_hand_base" body2="r_f_link1_1"/>
    <exclude body1="right_hand_base" body2="r_f_link1_2"/>
    <exclude body1="right_hand_base" body2="r_f_link1_3"/>
    <exclude body1="right_hand_base" body2="r_f_link1_4"/>
    <exclude body1="right_hand_base" body2="r_f_link2_1"/>
    <exclude body1="right_hand_base" body2="r_f_link2_2"/>
    <exclude body1="right_hand_base" body2="r_f_link2_3"/>
    <exclude body1="right_hand_base" body2="r_f_link2_4"/>
    <exclude body1="right_hand_base" body2="r_f_link3_1"/>
    <exclude body1="right_hand_base" body2="r_f_link3_2"/>
    <exclude body1="right_hand_base" body2="r_f_link3_3"/>
    <exclude body1="right_hand_base" body2="r_f_link3_4"/>
    <exclude body1="right_hand_base" body2="r_f_link4_1"/>
    <exclude body1="right_hand_base" body2="r_f_link4_2"/>
    <exclude body1="right_hand_base" body2="r_f_link4_3"/>
    <exclude body1="right_hand_base" body2="r_f_link4_4"/>
    <exclude body1="right_hand_base" body2="r_f_link5_1"/>
    <exclude body1="right_hand_base" body2="r_f_link5_2"/>
    <exclude body1="right_hand_base" body2="r_f_link5_3"/>
    <exclude body1="right_hand_base" body2="r_f_link5_4"/>
    <exclude body1="r_f_link1_1" body2="r_f_link1_2"/>
    <exclude body1="r_f_link1_1" body2="r_f_link1_3"/>
    <exclude body1="r_f_link1_1" body2="r_f_link1_4"/>
    <exclude body1="r_f_link1_1" body2="r_f_link2_1"/>
    <exclude body1="r_f_link1_1" body2="r_f_link2_2"/>
    <exclude body1="r_f_link1_1" body2="r_f_link2_3"/>
    <exclude body1="r_f_link1_1" body2="r_f_link2_4"/>
    <exclude body1="r_f_link1_1" body2="r_f_link3_1"/>
    <exclude body1="r_f_link1_1" body2="r_f_link3_2"/>
    <exclude body1="r_f_link1_1" body2="r_f_link3_3"/>
    <exclude body1="r_f_link1_1" body2="r_f_link3_4"/>
    <exclude body1="r_f_link1_1" body2="r_f_link4_1"/>
    <exclude body1="r_f_link1_1" body2="r_f_link4_2"/>
    <exclude body1="r_f_link1_1" body2="r_f_link4_3"/>
    <exclude body1="r_f_link1_1" body2="r_f_link4_4"/>
    <exclude body1="r_f_link1_1" body2="r_f_link5_1"/>
    <exclude body1="r_f_link1_1" body2="r_f_link5_2"/>
    <exclude body1="r_f_link1_1" body2="r_f_link5_3"/>
    <exclude body1="r_f_link1_1" body2="r_f_link5_4"/>
    <exclude body1="r_f_link1_2" body2="r_f_link1_3"/>
    <exclude body1="r_f_link1_2" body2="r_f_link1_4"/>
    <exclude body1="r_f_link1_2" body2="r_f_link2_1"/>
    <exclude body1="r_f_link1_2" body2="r_f_link2_2"/>
    <exclude body1="r_f_link1_2" body2="r_f_link2_3"/>
    <exclude body1="r_f_link1_2" body2="r_f_link2_4"/>
    <exclude body1="r_f_link1_2" body2="r_f_link3_1"/>
    <exclude body1="r_f_link1_2" body2="r_f_link3_2"/>
    <exclude body1="r_f_link1_2" body2="r_f_link3_3"/>
    <exclude body1="r_f_link1_2" body2="r_f_link3_4"/>
    <exclude body1="r_f_link1_2" body2="r_f_link4_1"/>
    <exclude body1="r_f_link1_2" body2="r_f_link4_2"/>
    <exclude body1="r_f_link1_2" body2="r_f_link4_3"/>
    <exclude body1="r_f_link1_2" body2="r_f_link4_4"/>
    <exclude body1="r_f_link1_2" body2="r_f_link5_1"/>
    <exclude body1="r_f_link1_2" body2="r_f_link5_2"/>
    <exclude body1="r_f_link1_2" body2="r_f_link5_3"/>
    <exclude body1="r_f_link1_2" body2="r_f_link5_4"/>
    <exclude body1="r_f_link1_3" body2="r_f_link1_4"/>
    <exclude body1="r_f_link1_3" body2="r_f_link2_1"/>
    <exclude body1="r_f_link1_3" body2="r_f_link2_2"/>
    <exclude body1="r_f_link1_3" body2="r_f_link2_3"/>
    <exclude body1="r_f_link1_3" body2="r_f_link2_4"/>
    <exclude body1="r_f_link1_3" body2="r_f_link3_1"/>
    <exclude body1="r_f_link1_3" body2="r_f_link3_2"/>
    <exclude body1="r_f_link1_3" body2="r_f_link3_3"/>
    <exclude body1="r_f_link1_3" body2="r_f_link3_4"/>
    <exclude body1="r_f_link1_3" body2="r_f_link4_1"/>
    <exclude body1="r_f_link1_3" body2="r_f_link4_2"/>
    <exclude body1="r_f_link1_3" body2="r_f_link4_3"/>
    <exclude body1="r_f_link1_3" body2="r_f_link4_4"/>
    <exclude body1="r_f_link1_3" body2="r_f_link5_1"/>
    <exclude body1="r_f_link1_3" body2="r_f_link5_2"/>
    <exclude body1="r_f_link1_3" body2="r_f_link5_3"/>
    <exclude body1="r_f_link1_3" body2="r_f_link5_4"/>
    <exclude body1="r_f_link1_4" body2="r_f_link2_1"/>
    <exclude body1="r_f_link1_4" body2="r_f_link2_2"/>
    <exclude body1="r_f_link1_4" body2="r_f_link2_3"/>
    <exclude body1="r_f_link1_4" body2="r_f_link3_1"/>
    <exclude body1="r_f_link1_4" body2="r_f_link3_2"/>
    <exclude body1="r_f_link1_4" body2="r_f_link3_3"/>
    <exclude body1="r_f_link1_4" body2="r_f_link4_1"/>
    <exclude body1="r_f_link1_4" body2="r_f_link4_2"/>
    <exclude body1="r_f_link1_4" body2="r_f_link4_3"/>
    <exclude body1="r_f_link1_4" body2="r_f_link5_1"/>
    <exclude body1="r_f_link1_4" body2="r_f_link5_2"/>
    <exclude body1="r_f_link1_4" body2="r_f_link5_3"/>
    <exclude body1="r_f_link2_1" body2="r_f_link2_2"/>
    <exclude body1="r_f_link2_1" body2="r_f_link2_3"/>
    <exclude body1="r_f_link2_1" body2="r_f_link2_4"/>
    <exclude body1="r_f_link2_1" body2="r_f_link3_1"/>
    <exclude body1="r_f_link2_1" body2="r_f_link3_2"/>
    <exclude body1="r_f_link2_1" body2="r_f_link3_3"/>
    <exclude body1="r_f_link2_1" body2="r_f_link3_4"/>
    <exclude body1="r_f_link2_1" body2="r_f_link4_1"/>
    <exclude body1="r_f_link2_1" body2="r_f_link4_2"/>
    <exclude body1="r_f_link2_1" body2="r_f_link4_3"/>
    <exclude body1="r_f_link2_1" body2="r_f_link4_4"/>
    <exclude body1="r_f_link2_1" body2="r_f_link5_1"/>
    <exclude body1="r_f_link2_1" body2="r_f_link5_2"/>
    <exclude body1="r_f_link2_1" body2="r_f_link5_3"/>
    <exclude body1="r_f_link2_1" body2="r_f_link5_4"/>
    <exclude body1="r_f_link2_2" body2="r_f_link2_3"/>
    <exclude body1="r_f_link2_2" body2="r_f_link2_4"/>
    <exclude body1="r_f_link2_2" body2="r_f_link3_1"/>
    <exclude body1="r_f_link2_2" body2="r_f_link3_2"/>
    <exclude body1="r_f_link2_2" body2="r_f_link3_3"/>
    <exclude body1="r_f_link2_2" body2="r_f_link3_4"/>
    <exclude body1="r_f_link2_2" body2="r_f_link4_1"/>
    <exclude body1="r_f_link2_2" body2="r_f_link4_2"/>
    <exclude body1="r_f_link2_2" body2="r_f_link4_3"/>
    <exclude body1="r_f_link2_2" body2="r_f_link4_4"/>
    <exclude body1="r_f_link2_2" body2="r_f_link5_1"/>
    <exclude body1="r_f_link2_2" body2="r_f_link5_2"/>
    <exclude body1="r_f_link2_2" body2="r_f_link5_3"/>
    <exclude body1="r_f_link2_2" body2="r_f_link5_4"/>
    <exclude body1="r_f_link2_3" body2="r_f_link2_4"/>
    <exclude body1="r_f_link2_3" body2="r_f_link3_1"/>
    <exclude body1="r_f_link2_3" body2="r_f_link3_2"/>
    <exclude body1="r_f_link2_3" body2="r_f_link3_3"/>
    <exclude body1="r_f_link2_3" body2="r_f_link3_4"/>
    <exclude body1="r_f_link2_3" body2="r_f_link4_1"/>
    <exclude body1="r_f_link2_3" body2="r_f_link4_2"/>
    <exclude body1="r_f_link2_3" body2="r_f_link4_3"/>
    <exclude body1="r_f_link2_3" body2="r_f_link4_4"/>
    <exclude body1="r_f_link2_3" body2="r_f_link5_1"/>
    <exclude body1="r_f_link2_3" body2="r_f_link5_2"/>
    <exclude body1="r_f_link2_3" body2="r_f_link5_3"/>
    <exclude body1="r_f_link2_3" body2="r_f_link5_4"/>
    <exclude body1="r_f_link2_4" body2="r_f_link3_1"/>
    <exclude body1="r_f_link2_4" body2="r_f_link3_2"/>
    <exclude body1="r_f_link2_4" body2="r_f_link3_3"/>
    <exclude body1="r_f_link2_4" body2="r_f_link4_1"/>
    <exclude body1="r_f_link2_4" body2="r_f_link4_2"/>
    <exclude body1="r_f_link2_4" body2="r_f_link4_3"/>
    <exclude body1="r_f_link2_4" body2="r_f_link5_1"/>
    <exclude body1="r_f_link2_4" body2="r_f_link5_2"/>
    <exclude body1="r_f_link2_4" body2="r_f_link5_3"/>
    <exclude body1="r_f_link3_1" body2="r_f_link3_2"/>
    <exclude body1="r_f_link3_1" body2="r_f_link3_3"/>
    <exclude body1="r_f_link3_1" body2="r_f_link3_4"/>
    <exclude body1="r_f_link3_1" body2="r_f_link4_1"/>
    <exclude body1="r_f_link3_1" body2="r_f_link4_2"/>
    <exclude body1="r_f_link3_1" body2="r_f_link4_3"/>
    <exclude body1="r_f_link3_1" body2="r_f_link4_4"/>
    <exclude body1="r_f_link3_1" body2="r_f_link5_1"/>
    <exclude body1="r_f_link3_1" body2="r_f_link5_2"/>
    <exclude body1="r_f_link3_1" body2="r_f_link5_3"/>
    <exclude body1="r_f_link3_1" body2="r_f_link5_4"/>
    <exclude body1="r_f_link3_2" body2="r_f_link3_3"/>
    <exclude body1="r_f_link3_2" body2="r_f_link3_4"/>
    <exclude body1="r_f_link3_2" body2="r_f_link4_1"/>
    <exclude body1="r_f_link3_2" body2="r_f_link4_2"/>
    <exclude body1="r_f_link3_2" body2="r_f_link4_3"/>
    <exclude body1="r_f_link3_2" body2="r_f_link4_4"/>
    <exclude body1="r_f_link3_2" body2="r_f_link5_1"/>
    <exclude body1="r_f_link3_2" body2="r_f_link5_2"/>
    <exclude body1="r_f_link3_2" body2="r_f_link5_3"/>
    <exclude body1="r_f_link3_2" body2="r_f_link5_4"/>
    <exclude body1="r_f_link3_3" body2="r_f_link3_4"/>
    <exclude body1="r_f_link3_3" body2="r_f_link4_1"/>
    <exclude body1="r_f_link3_3" body2="r_f_link4_2"/>
    <exclude body1="r_f_link3_3" body2="r_f_link4_3"/>
    <exclude body1="r_f_link3_3" body2="r_f_link4_4"/>
    <exclude body1="r_f_link3_3" body2="r_f_link5_1"/>
    <exclude body1="r_f_link3_3" body2="r_f_link5_2"/>
    <exclude body1="r_f_link3_3" body2="r_f_link5_3"/>
    <exclude body1="r_f_link3_3" body2="r_f_link5_4"/>
    <exclude body1="r_f_link3_4" body2="r_f_link4_1"/>
    <exclude body1="r_f_link3_4" body2="r_f_link4_2"/>
    <exclude body1="r_f_link3_4" body2="r_f_link4_3"/>
    <exclude body1="r_f_link3_4" body2="r_f_link5_1"/>
    <exclude body1="r_f_link3_4" body2="r_f_link5_2"/>
    <exclude body1="r_f_link3_4" body2="r_f_link5_3"/>
    <exclude body1="r_f_link4_1" body2="r_f_link4_2"/>
    <exclude body1="r_f_link4_1" body2="r_f_link4_3"/>
    <exclude body1="r_f_link4_1" body2="r_f_link4_4"/>
    <exclude body1="r_f_link4_1" body2="r_f_link5_1"/>
    <exclude body1="r_f_link4_1" body2="r_f_link5_2"/>
    <exclude body1="r_f_link4_1" body2="r_f_link5_3"/>
    <exclude body1="r_f_link4_1" body2="r_f_link5_4"/>
    <exclude body1="r_f_link4_2" body2="r_f_link4_3"/>
    <exclude body1="r_f_link4_2" body2="r_f_link4_4"/>
    <exclude body1="r_f_link4_2" body2="r_f_link5_1"/>
    <exclude body1="r_f_link4_2" body2="r_f_link5_2"/>
    <exclude body1="r_f_link4_2" body2="r_f_link5_3"/>
    <exclude body1="r_f_link4_2" body2="r_f_link5_4"/>
    <exclude body1="r_f_link4_3" body2="r_f_link4_4"/>
    <exclude body1="r_f_link4_3" body2="r_f_link5_1"/>
    <exclude body1="r_f_link4_3" body2="r_f_link5_2"/>
    <exclude body1="r_f_link4_3" body2="r_f_link5_3"/>
    <exclude body1="r_f_link4_3" body2="r_f_link5_4"/>
    <exclude body1="r_f_link4_4" body2="r_f_link5_1"/>
    <exclude body1="r_f_link4_4" body2="r_f_link5_2"/>
    <exclude body1="r_f_link4_4" body2="r_f_link5_3"/>
    <exclude body1="r_f_link5_1" body2="r_f_link5_2"/>
    <exclude body1="r_f_link5_1" body2="r_f_link5_3"/>
    <exclude body1="r_f_link5_1" body2="r_f_link5_4"/>
    <exclude body1="r_f_link5_2" body2="r_f_link5_3"/>
    <exclude body1="r_f_link5_2" body2="r_f_link5_4"/>
    <exclude body1="r_f_link5_3" body2="r_f_link5_4"/>
  </contact>
</mujoco>
