<?xml version="1.0" encoding="utf-8"?>
<mujoco model="floating_base">
  <worldbody>
    <body name="floating_base">
      <inertial pos="0 0 0" quat="1 0 0 0" mass="0.01" diaginertia="0.01 0.01 0.01" />
      <joint name="ARTx" pos="0 0 0" axis="1 0 0" type="slide" range="-1 1" damping="20" />
      <joint name="ARTy" pos="0 0 0" axis="0 1 0" type="slide" range="-1 1" damping="20" />
      <joint name="ARTz" pos="0 0 0" axis="0 0 1" type="slide" range="-1 1" damping="20" />
      <joint name="ARRx" pos="0 0 0" axis="1 0 0" range="-3.14 3.14" damping="20" />
      <joint name="ARRy" pos="0 0 0" axis="0 1 0" range="-3.14 3.14" damping="20" />
      <joint name="ARRz" pos="0 0 0" axis="0 0 1" range="-3.14 3.14" damping="20" />
      <body name="hand_base" />
    </body>
  </worldbody>
  <actuator>
    <position name="act_ARTx" joint="ARTx" kp="10000" kv="500" ctrlrange="-1 1" />
    <position name="act_ARTy" joint="ARTy" kp="10000" kv="500" ctrlrange="-1 1" />
    <position name="act_ARTz" joint="ARTz" kp="10000" kv="500" ctrlrange="-1 1" />
    <position name="act_ARRx" joint="ARRx" kp="10000" kv="500" ctrlrange="-3.14 3.14" />
    <position name="act_ARRy" joint="ARRy" kp="10000" kv="500" ctrlrange="-3.14 3.14" />
    <position name="act_ARRz" joint="ARRz" kp="10000" kv="500" ctrlrange="-3.14 3.14" />
  </actuator>
</mujoco>
