<?xml version="1.0" encoding="utf-8"?>
<mujoco model="floating_base">
  <compiler angle="radian"/>
  <worldbody>
    <body name="floating_base_root">
      <inertial pos="0 0 0" quat="1 0 0 0" mass="0.01" diaginertia="0.01 0.01 0.01"/>
      <body name="floating_base" pos="0 0 0">
        <inertial pos="0 0 0" quat="1 0 0 0" mass="0.01" diaginertia="0.01 0.01 0.01"/>
        <joint name="ARTx" pos="0 0 0" axis="1 0 0" type="slide" range="-1 1" limited="true" damping="20" armature="0.01" frictionloss="0.1" forcerange="-500 500" forcelimited="true"/>
        <body name="ARTx_child" pos="0 0 0">
          <inertial pos="0 0 0" quat="1 0 0 0" mass="0.001" diaginertia="0.001 0.001 0.001"/>
          <joint name="ARTy" pos="0 0 0" axis="0 1 0" type="slide" range="-1 1" limited="true" damping="20" armature="0.01" frictionloss="0.1" forcerange="-500 500" forcelimited="true"/>
          <body name="ARTy_child" pos="0 0 0">
            <inertial pos="0 0 0" quat="1 0 0 0" mass="0.001" diaginertia="0.001 0.001 0.001"/>
            <joint name="ARTz" pos="0 0 0" axis="0 0 1" type="slide" range="-1 1" limited="true" damping="20" armature="0.01" frictionloss="0.1" forcerange="-500 500" forcelimited="true"/>
            <body name="ARTz_child" pos="0 0 0">
              <inertial pos="0 0 0" quat="1 0 0 0" mass="0.001" diaginertia="0.001 0.001 0.001"/>
              <joint name="ARRx" pos="0 0 0" axis="1 0 0" type="hinge" range="-3.14 3.14" limited="true" damping="20" armature="0.01" frictionloss="0.1" forcerange="-100 100" forcelimited="true"/>
              <body name="ARRx_child" pos="0 0 0">
                <inertial pos="0 0 0" quat="1 0 0 0" mass="0.001" diaginertia="0.001 0.001 0.001"/>
                <joint name="ARRy" pos="0 0 0" axis="0 1 0" type="hinge" range="-3.14 3.14" limited="true" damping="20" armature="0.01" frictionloss="0.1" forcerange="-100 100" forcelimited="true"/>
                <body name="ARRy_child" pos="0 0 0">
                  <inertial pos="0 0 0" quat="1 0 0 0" mass="0.001" diaginertia="0.001 0.001 0.001"/>
                  <joint name="ARRz" pos="0 0 0" axis="0 0 1" type="hinge" range="-3.14 3.14" limited="true" damping="20" armature="0.01" frictionloss="0.1" forcerange="-100 100" forcelimited="true"/>
                  <body name="hand_base"/>
                </body>
              </body>
            </body>
          </body>
        </body>
      </body>
    </body>
  </worldbody>
  <actuator>
    <position name="act_ARTx" joint="ARTx" kp="10000" kv="500" ctrlrange="-1 1" forcerange="-500 500" forcelimited="true"/>
    <position name="act_ARTy" joint="ARTy" kp="10000" kv="500" ctrlrange="-1 1" forcerange="-500 500" forcelimited="true"/>
    <position name="act_ARTz" joint="ARTz" kp="10000" kv="500" ctrlrange="-1 1" forcerange="-500 500" forcelimited="true"/>
    <position name="act_ARRx" joint="ARRx" kp="10000" kv="500" ctrlrange="-3.14 3.14" forcerange="-100 100" forcelimited="true"/>
    <position name="act_ARRy" joint="ARRy" kp="10000" kv="500" ctrlrange="-3.14 3.14" forcerange="-100 100" forcelimited="true"/>
    <position name="act_ARRz" joint="ARRz" kp="10000" kv="500" ctrlrange="-3.14 3.14" forcerange="-100 100" forcelimited="true"/>
  </actuator>
</mujoco>
