<mujoco model="jaka_zu7_right">
  <compiler angle="radian" />
  <visual>
    <global offwidth="1920" offheight="1080" />
  </visual>
  <option gravity='0 0 -9.81' iterations='100' solver='Newton' integrator='implicit'
    timestep='0.001' />
  <default>
    <joint damping="1" />
    <geom condim="3" solref="0.01 0.9" solimp="0.9 0.999 0.005" friction="3. 2. 2." />
  </default>
  <size njmax='1000' nconmax='1000' />

  <asset>
    <mesh name="r_a_link0" file="../meshes/jaka_zu7/link0.STL" />
    <mesh name="r_a_link1" file="../meshes/jaka_zu7/link1.STL" />
    <mesh name="r_a_link2" file="../meshes/jaka_zu7/link2.STL" />
    <mesh name="r_a_link3" file="../meshes/jaka_zu7/link3.STL" />
    <mesh name="r_a_link4" file="../meshes/jaka_zu7/link4.STL" />
    <mesh name="r_a_link5" file="../meshes/jaka_zu7/link5.STL" />
    <mesh name="r_a_link6" file="../meshes/jaka_zu7/link6.STL" />
  </asset>

  <worldbody>
    <body name="r_a_base">
      <body name="r_a_link0" pos="0 0 0.125">
        <inertial pos="-2.5186e-07 0.0033226 -0.001509" quat="1 0.00057182 1.47362e-05 -1.17746e-05"
          mass="3.856" diaginertia="0.011287 0.010978 0.0077763" />
        <geom type="mesh" contype="0" conaffinity="0" group="1" density="0" rgba="1 0 0 1"
          mesh="r_a_link0" />

        <body name="r_a_link1">
          <inertial pos="-2.5186e-07 0.0033226 -0.001509"
            quat="1 0.00057182 1.47362e-05 -1.17746e-05"
            mass="3.856" diaginertia="0.011287 0.010978 0.0077763" />
          <joint name="r_a_joint1" pos="0 0 0" axis="0 0 1" range="-6.18 6.18" />
          <geom type="mesh" contype="0" conaffinity="0" group="1" density="0" rgba="1 0.647 0 1"
            mesh="r_a_link1" />

          <body name="r_a_link2" quat="0.499998 -0.5 -0.5 -0.500002">
            <inertial pos="0.18 3.4142e-07 0.14305" quat="0.5 0.5 0.5 0.5" mass="10.92"
              diaginertia="0.28317 0.27617 0.025808" />
            <joint name="r_a_joint2" pos="0 0 0" axis="0 0 1" range="-1.45 4.6" />
            <geom type="mesh" contype="0" conaffinity="0" group="1" density="0" rgba="1 1 0 1"
              mesh="r_a_link2" />

            <body name="r_a_link3" pos="0.36 0 0" quat="-3.67321e-06 1 0 0">
              <inertial pos="0.15497 4.5333e-07 -0.012632"
                quat="0.534952 0.462406 0.462397 0.534973"
                mass="4.2153" diaginertia="0.026862 0.026061 0.00482155" />
              <joint name="r_a_joint3" pos="0 0 0" axis="0 0 1" range="-3 3" />
              <geom type="mesh" contype="0" conaffinity="0" group="1" density="0" rgba="0 0.5 0 1"
                mesh="r_a_link3" />

              <body name="r_a_link4" pos="0.3035 0 0"
                quat="-2.59734e-06 -0.707105 0.707108 2.59735e-06">
                <inertial pos="1.9775e-06 -0.0058918 0.11234"
                  quat="0.780888 0.624671 9.57706e-05 -0.000188834" mass="1.4124"
                  diaginertia="0.0018059 0.00176733 0.00129387" />
                <joint name="r_a_joint4" pos="0 0 0" axis="0 0 1" range="-1.49 4.69" />
                <geom type="mesh" contype="0" conaffinity="0" group="1" density="0" rgba="0 0 1 1"
                  mesh="r_a_link4" />

                <body name="r_a_link5" pos="0 0 0.11501" quat="0.707105 0.707108 0 0">
                  <inertial pos="1.9094e-06 0.0028891 0.11116"
                    quat="0.704864 0.709342 8.93242e-07 -1.17161e-05" mass="1.6137"
                    diaginertia="0.0032918 0.00321727 0.00148913" />
                  <joint name="r_a_joint5" pos="0 0 0" axis="0 0 1" range="-6.18 6.18" />
                  <geom type="mesh" contype="0" conaffinity="0" group="1" density="0"
                    rgba="0.29 0 0.51 1" mesh="r_a_link5" />

                  <body name="r_a_link6" pos="0 0 0.1135" quat="0.707105 0.707108 0 0">
                    <inertial pos="1.7341e-05 -5.3205e-05 0.089903"
                      quat="-0.0179456 0.706386 0.0215903 0.707269" mass="0.42"
                      diaginertia="0.000315863 0.000201076 0.000198201" />
                    <joint name="r_a_joint6" pos="0 0 0" axis="0 0 1" range="-6.18 6.18" />
                    <geom type="mesh" contype="0" conaffinity="0" group="1" density="0"
                      rgba="0.93 0.51 0.93 1" mesh="r_a_link6" />

                    <body name="hand_base" pos="0 0 0.115" quat="1 0 0 0" />
                  </body>
                </body>
              </body>
            </body>
          </body>
        </body>
      </body>
    </body>
  </worldbody>

  <actuator>
    <position name="act_r_a_joint1" joint="r_a_joint1" kp="1000" kv="100" ctrlrange="-6.18 6.18"
      forcerange="-1000 1000" />
    <position name="act_r_a_joint2" joint="r_a_joint2" kp="1000" kv="100" ctrlrange="-1.45 4.6"
      forcerange="-1000 1000" />
    <position name="act_r_a_joint3" joint="r_a_joint3" kp="1000" kv="100" ctrlrange="-3 3"
      forcerange="-1000 1000" />
    <position name="act_r_a_joint4" joint="r_a_joint4" kp="1000" kv="100" ctrlrange="-1.49 4.69"
      forcerange="-1000 1000" />
    <position name="act_r_a_joint5" joint="r_a_joint5" kp="1000" kv="100" ctrlrange="-6.18 6.18"
      forcerange="-1000 1000" />
    <position name="act_r_a_joint6" joint="r_a_joint6" kp="1000" kv="100" ctrlrange="-6.18 6.18"
      forcerange="-1000 1000" />
  </actuator>
</mujoco>
